Workbook

Sheet Task List
A1: PlantProcess IQ — Phase-Grouped Task List (v5 · 30 May 2026)
A2: 79 open tasks across 13 phases. Supersedes v4 P01–P03 (schema mapping + two-stage delta import), now done in substance. ML/AI subsystem expanded per the engine + assistant design.
A4: Task ID | B4: Task Name | C4: Phase ID | D4: Severity | E4: Track | F4: Module | G4: Submodule | H4: Description | I4: Task Type | J4: Validation | K4: Effort (hrs)
A5: Phase 01 — Hotfixes & Build-Green Closeout | 8 tasks | 18.5 hrs
A6: PPIQ-T201 | B6: Fix Jenkins npm build failure (Node unavailable, exit 127) | C6: P01 | D6: critical | E6: Track 2 — Hardening | F6: Infrastructure | G6: CI / Build Agent | H6: The pipeline still fails at stage '2b. Phase 5/6 UI quality gates' with 'npm: not found' (exit 127): npm ci runs directly on `agent any` with no Node runtime. Run the UI gates inside a Node container (docker run --rm -v "$PWD":/app -w /app node:20-alpine sh -c 'npm ci && npm run validate:phase5-phase6:strict ...'), OR configure the Jenkins NodeJS tool ('node20') and wrap the stage in tools{ nodejs 'node20' }, OR install Node on the agent and ensure it is on the non-interactive PATH. Stages 3-5 must stop being skipped. | I6: Bug Fix | J6: 1) A full pipeline run reaches 'Build images' and 'Recreate containers' without the npm step failing. 2) `npm ci` and the validate/test:visual/test:a11y scripts run with a pinned Node 20. 3) A green build is produced end to end. 4) The fix is committed in the Jenkinsfile, not applied ad hoc on the agent. | K6: 2
A7: PPIQ-T202 | B7: Reconcile migration 117 audit-table schema (still broken) | C7: P01 | D7: critical | E7: Track 2 — Hardening | F7: Database | G7: Migration / Widget Audit | H7: Script 117 still uses CREATE TABLE IF NOT EXISTS for dashboard_widget_expression_audit with created_at_utc, but 113 already created that table with executed_at_utc — so IF NOT EXISTS is a no-op, created_at_utc never lands, and the index on it fails (silently, under ON_ERROR_STOP=0). The audit layer is on the stale schema. Replace 117's body with DROP TABLE IF EXISTS dashboard_widget_expression_audit; then CREATE TABLE with the EF-entity schema (id, dashboard_widget_definition_id, expression_version smallint, validation_status smallint, validation_message, query_expression, advanced_expression_json jsonb, created_at_utc) + the index. Make 113 and 117 not both CREATE the same table (113 becomes guard-only or canonical). Apply on the Hetzner staging clone. | I7: Bug Fix | J7: 1) Fresh Postgres 17 + ordered scripts apply with zero errors and the audit table has created_at_utc. 2) Re-apply on the staging clone is clean. 3) EF reads/writes against the audit table succeed (smallint enum + created_at_utc). 4) Exactly one migration CREATEs the table. | K7: 2
A8: PPIQ-T203 | B8: Switch SQL migration runner to ON_ERROR_STOP=1 | C8: P01 | D8: very important | E8: Track 2 — Hardening | F8: Infrastructure | G8: CI / Migration Safety | H8: The Jenkins 'Apply SQL scripts' stage runs psql with ON_ERROR_STOP=0, so a rolled-back migration (e.g. 117) reports success and the deploy proceeds onto a half-migrated schema. After T202 is fixed, change the runner to ON_ERROR_STOP=1 so any failing migration fails the build loudly. Audit the existing scripts first to ensure none rely on the permissive mode. | I8: Bug Fix | J8: 1) Runner uses ON_ERROR_STOP=1. 2) A deliberately broken script in a scratch branch turns the build red at the migration stage. 3) The full ordered script set still applies clean on a fresh DB and on staging. 4) No script depends on error-swallowing. | K8: 1.5
A9: PPIQ-T204 | B9: Complete the JWT auth-matrix to full tier coverage | C9: P01 | D9: very important | E9: Track 2 — Hardening | F9: App Backend | G9: Auth / Endpoint Authorization | H9: Closes the residual of v4 PPIQ-T101. An auth-matrix-admin.spec.ts and test:auth-matrix exist, but the confirmed backend assertions only cover anonymous=>401/403 and valid-login=>token. Extend to the full matrix: every admin endpoint group (/admin/jobs-monitor, /admin/schema-mapping, /admin/two-stage-import, /admin/license, /admin/phase1, /admin/phase2, /admin/widgets, /admin/users, /demo-lifecycle, /diagnostics, and the new /api/ml/*) under three identities — no token (401), operator-tier JWT (403 on admin, 200 on operator), admin-tier JWT (200) — emitting a matrix artifact and wired as a red-on-deviation Jenkins gate. | I9: Bug Fix | J9: 1) The probe exercises all three identities across every admin group, not just anonymous. 2) Removing an [Authorize] on any admin endpoint fails the probe. 3) Output archived per deploy. 4) Jenkins goes red on any deviation. | K9: 3
A10: PPIQ-T205 | B10: Verify standard-import ESLint block is an enforced Jenkins gate | C10: P01 | D10: important | E10: Track 2 — Hardening | F10: Infrastructure | G10: CI / Quality Gate | H10: Closes the residual of v4 PPIQ-T106. The forbidden-phrase sweep and auth-matrix are referenced in Jenkins stage 2c, but confirm the non-standard-import rule (no native <button>/<input>/<select>/<table>/<textarea> in src/pages|features; no import from src/hardening/*) actually fails the build, not just warns. Wire pnpm/npm lint as a failing stage with a clear offender list and canonical-replacement hint; add the pre-commit hook. | I10: Enhancement | J10: 1) A native <button> in src/pages/* fails the build naming the file + replacement. 2) An import from src/hardening/* fails lint. 3) Stage runs on every push. 4) Pre-commit blocks locally. | K10: 1.5
A11: PPIQ-T206 | B11: Confirm SchemaViewResolver typed errors + join SafeSqlValidator | C11: P01 | D11: important | E11: Track 1 — Workflow | F11: App Backend | G11: Schema Mapping / Validation Hardening | H11: Closes residual rigor on v4 PPIQ-T108/T110 (capability shipped in GenericSchemaMappingEndpoints.cs but specific guarantees unconfirmed). Ensure /resolve returns distinct, testable errors — NoSuchView, NoSuchColumn, InvalidAggregateForType — not a generic failure, and that /joins/preview and /joins/materialize run SafeSqlValidator on the generated join SQL (blocking DDL/cross-tenant injection) and reject type-mismatched key pairs with a clear message. Add unit/integration tests for each path. | I11: Bug Fix | J11: 1) Resolver returns the three named error types on bad view/column/aggregate. 2) Malicious join SQL is blocked at preview and materialize. 3) Type-mismatched key pair rejected with a clear error. 4) Tests cover each case and run in CI. | K11: 3
A12: PPIQ-T207 | B12: Add delta-import integration + resumability tests (T118 was unstarted) | C12: P01 | D12: very important | E12: Track 2 — Hardening | F12: App Backend | G12: Import / Test Coverage | H12: Closes v4 PPIQ-T118, which had no implementation. The two-stage pipeline (source_table_dump_registry, two_stage_import_runs, two_stage_processed_watermarks; stage1/stage2/run-full-cycle endpoints) ships without tests. Author integration tests against seeded sources: cold full-load, incremental delta (only new rows beyond last_index), mid-run crash + resume (no duplicates), schema drift detection, idempotency. Opt-in via PPIQ_RUN_CONNECTOR_INTEGRATION=1; wire to the post-deploy gate. | I12: New Feature | J12: 1) Cold load then incremental delta imports only new rows. 2) Simulated crash resumes from last_index with no duplicates. 3) Source schema drift is detected and surfaced. 4) Suite < 60s, wired to Jenkins. | K12: 4
A13: PPIQ-T208 | B13: Finish loopback-binding audit for all infra services + external scan proof | C13: P01 | D13: important | E13: Track 2 — Hardening | F13: Infrastructure | G13: Docker Compose / Network Exposure | H13: Closes residual of v4 PPIQ-T105 (only Postgres proven on 127.0.0.1). Audit redis, seq, jaeger, grafana, prometheus, jenkins, workers in docker-compose.demo.yml; bind each published port to 127.0.0.1 unless intentionally public (Caddy 80/443; Jenkins :9090 behind basicauth). Prove with an external nmap and document each decision in Infrastructure/deploy/README.md. | I13: Bug Fix | J13: 1) External nmap of 178.105.152.180 shows only 80, 443, 9090 open; all data/observability ports filtered. 2) Internal health checks green. 3) README documents each binding. | K13: 1.5
A14: Phase 02 — ML Engine — Data Foundation & Feature Store (Vision §3 prerequisite) | 5 tasks | 32 hrs
A15: PPIQ-T209 | B15: Multi-grain feature store schema (heat/strand/coil/location) | C15: P02 | D15: very important | E15: Track 1 — Workflow | F15: Database | G15: ML Engine / Feature Store | H15: Per design doc §1.1: build the multi-grain feature store the entire engine learns from, materialized from the canonical generic schema (P02/P03 of v4). Each feature and outcome carries its native grain and the genealogy keys (heat_id, sequence_id, strand, slab_id, coil_id) needed to join across grains. Tables for feature definitions, feature values per grain, and outcome values; EF entities + configuration + migration. Refreshed by the stage-2 import job. Versioned. | I15: New Feature | J15: 1) Migration applies clean; feature/outcome tables exist with grain + genealogy keys. 2) A heat-level parameter can be joined to a coil-level outcome via genealogy. 3) Refresh from canonical schema populates expected counts. 4) Effective sample size (independent units) is derivable, not just row count. | K15: 8
A16: PPIQ-T210 | B16: FeatureEngineeringService — metallurgical derived features | C16: P02 | D16: very important | E16: Track 1 — Workflow | F16: App Backend | G16: ML Engine / Feature Engineering | H16: Per design doc §1.2: extend FeatureEngineeringService to assemble the feature matrix at a SELECTABLE grain (coil-level default; heat-level option) and compute derived features: carbon equivalent (CEV) from chemistry; true superheat = tundish temp − liquidus (liquidus estimated from composition); casting-speed aggregates (mean/max/std/range, count of speed changes, time in transition); reduction ratio; cooling rate; specific energy; time-above-temperature; categorical encodings (grade family, gauge band, spec class, strand, crew/shift). Explicit missingness handling (pairwise deletion with n per pair; 'missing' as informative category; flag features whose missingness correlates with the outcome). | I16: New Feature | J16: 1) Matrix builds at coil and heat grain on demand. 2) CEV and true superheat computed correctly for sample heats. 3) Speed aggregates and reduction/cooling features present. 4) Missingness reported per feature, not silently imputed. | K16: 8
A17: PPIQ-T211 | B17: Outcome definitions: defect-rate/class/severity/position, cascade-downtime, KPI-as-view | C17: P02 | D17: important | E17: Track 1 — Workflow | F17: App Backend | G17: ML Engine / Outcome Modeling | H17: Per design doc §1.3: model outcomes rigorously rather than yes/no. Defects as a rate normalized to coil area/tonnage (defects per m²), plus class (multinomial), severity (graded), and position (head/body/tail, edge/center). Downtime using the plant taxonomy (production stoppage vs equipment failure; electrical/operation/production/mechanical/hydraulic) against CASCADE-adjusted duration, not the raw event. KPIs defined as canonical views (prime yield, energy/ton, throughput) via the KPI-as-view layer. | I17: New Feature | J17: 1) Defect outcomes expose rate, class, severity, position. 2) Downtime outcome uses cascade-adjusted duration with the reason taxonomy. 3) KPI outcomes resolve from canonical KPI views. 4) Each outcome is selectable as an ML target. | K17: 5
A18: PPIQ-T212 | B18: ICorrelationComputeEngine interface + .NET default implementation | C18: P02 | D18: very important | E18: Track 1 — Workflow | F18: App Backend | G18: ML Engine / Compute Abstraction | H18: Per design doc §2.4 / §6: define ICorrelationComputeEngine so the compute is swappable. Default implementation is .NET in-process (Math.NET Numerics for statistics, ML.NET for regularized regression / tree importances), with PostgreSQL doing heavy data reduction (corr(), regr_*, group-bys). Keep one runtime; deterministic, auditable math in the repo. The interface is the escape hatch for a future Python implementation (mixed-effects, survival, defect-image CV) without touching the job system, persistence, governance, or UI. | I18: New Feature | J18: 1) Interface defines compute over a (features, outcome, window, grain) request. 2) .NET implementation runs against the feature store. 3) Math methods are unit-tested for correctness vs known values. 4) Swapping implementations requires no change to callers. | K18: 6
A19: PPIQ-T213 | B19: pgvector knowledge base provisioning (assistant prerequisite) | C19: P02 | D19: important | E19: Track 1 — Workflow | F19: Database | G19: ML Assistant / Vector Store | H19: Per design doc §4.3: enable the pgvector extension in PostgreSQL 17 and provision the knowledge-base tables the §3.3 assistant retrieves from — embeddings + metadata for (a) learned findings, (b) case memory, (c) domain knowledge documents — with structured columns (area, defect class, grade, line, window, q-value) to support HYBRID retrieval (semantic + SQL filter). No new datastore or service. EF entities + migration; IEmbeddingProvider interface (API-default, self-hostable). | I19: New Feature | J19: 1) pgvector enabled; KB tables exist with vector + structured columns. 2) An item can be embedded and retrieved by similarity AND filtered by structured fields. 3) IEmbeddingProvider abstracts the embedding model. 4) Migration applies clean. | K19: 5
A20: Phase 03 — ML Engine — Scheduled Correlation Learning (Vision §3.1) | 6 tasks | 38 hrs
A21: PPIQ-T214 | B21: Define the four learning job types + EnsureMlJobDefinitions (Vision §3.1.1–3.1.4) | C21: P03 | D21: very important | E21: Track 1 — Workflow | F21: App Backend | G21: ML Engine / Job Definitions | H21: Per design doc §2.1: formalize the four scheduled jobs as first-class JobDefinitionType entries — (1) process-params × defect-id, (2) × downtime-id, (3) × KPI-id (daily, off-hours, user-overridable), (4) weekly overall pass across all data. Extend the existing EnsureMlJobDefinitions/IsMlJob scaffolding. Each flows through the unified job model so it appears in the Jobs Monitor (§3.1.5). | I21: New Feature | J21: 1) The four jobs registered with correct default schedules (daily off-hours; weekly overall). 2) Schedules user-overridable per job. 3) Jobs appear in the Jobs Monitor. 4) IsMlJob classifies each correctly. | K21: 3
A22: PPIQ-T215 | B22: Learning worker — type-aware statistical association engine | C22: P03 | D22: critical | E22: Track 1 — Workflow | F22: App Backend | G22: ML Engine / Learning Worker | H22: Per design doc §2.2: implement the worker that runs the four jobs off-hours via ICorrelationComputeEngine. For each (feature, outcome) pair choose the type-appropriate measure: Pearson+Spearman (cont×cont); point-biserial + Cohen's d + Mann-Whitney (cont×binary); chi-square + Cramér's V (cat×cat); Spearman + quantile bucketing (cont×count); mutual information + L1/Elastic-Net rank for the multivariate non-linear pass (optional ML.NET tree importances as cross-check, never a predictor). Honest framing only. Long-run safety: chunked compute, checkpointing per (target,batch), cancellation, concurrency cap 1/job, backoff. | I22: New Feature | J22: 1) Running a job persists results with coefficient, effect size, sample size. 2) Each pair uses the type-correct method. 3) Deterministic for fixed data+seed (two runs match). 4) Cancellation mid-run leaves a clean failed state. 5) No forbidden claim language in any output. | K22: 12
A23: PPIQ-T216 | B23: Statistical validity machinery (FDR, effect-size, power, stability, confounding, VIF) | C23: P03 | D23: critical | E23: Track 2 — Hardening | F23: App Backend | G23: ML Engine / Statistical Rigor | H23: Per design doc §2.3 — the rigor that separates professional from naive. Wrap every result with: effect-size-first strength buckets (not p); Benjamini–Hochberg q-values across the full test family; a power/minimum-effective-n gate; bootstrap stability (CI on r itself + replication across time sub-windows; flag unstable findings); confounding handling (stratify by grade/line + partial-correlation adjustment, warn when an association collapses after adjustment); multicollinearity reporting (VIF; present grouped drivers, not duplicates). Cluster-robust standard errors by heat to correct pseudo-replication from coils nested in heats. | I23: New Feature | J23: 1) Every result carries effect size, q-value, CI, effective-n, stability flag. 2) Under-powered pairs are gated out. 3) A planted-noise column does not survive FDR. 4) A confounded association is flagged after stratification. 5) Effective-n reflects heat-clustering, not raw coil count. | K23: 10
A24: PPIQ-T217 | B24: Per-job scheduling, backoff & MlReadiness governance gates | C24: P03 | D24: important | E24: Track 1 — Workflow | F24: App Backend | G24: ML Engine / Scheduling & Governance | H24: Per design doc §2 + §3.1: add per-job off-hours scheduling with failure backoff and concurrency control, and extend MlReadinessService into governance gates — minimum sample size, label completeness, feature freshness, and a training-window selector (last week/month/year). The engine refuses to learn on insufficient/ungoverned data and reports why (preserving the no_production_prediction honesty). | I24: Enhancement | J24: 1) A job below the sample/label threshold is blocked with a clear readiness reason. 2) Backoff doubles the retry interval up to a cap. 3) Window selector changes the data range used. 4) Readiness gates reflect the real governance state. | K24: 5
A25: PPIQ-T218 | B25: Persist correlation_result (extended) + Jobs Monitor integration | C25: P03 | D25: important | E25: Track 1 — Workflow | F25: Database | G25: ML Engine / Results Persistence | H25: Per design doc §2.5 / §2.6: extend CorrelationResult with model_version_id, feature_key+grain, outcome_key+type, method, coefficient, effect_size(+type), p_value, q_value, ci_low/high, effective_n, stratum, stability_score+is_stable, window. Ensure all four learning jobs surface in Administrator → Jobs Monitor (status OK/crash/timeout, last-run, duration, next-run, run-now/pause, active progress). | I25: Enhancement | J25: 1) Results persist with the full evidence columns incl. q-value and effective-n. 2) Learning jobs appear in the Jobs Monitor with correct status/last-run/duration/next-run. 3) Run-now triggers a job and progress ticks. 4) A crashed job shows failed + last error. | K25: 4
A26: PPIQ-T219 | B26: ML learning engine tests on golden datasets | C26: P03 | D26: very important | E26: Track 2 — Hardening | F26: App Backend | G26: ML Engine / Test Coverage | H26: Per design doc §2.3: tests with deterministic golden datasets where correct correlations are known by construction (planted signal + noise). Assert the engine recovers planted associations within tolerance, ranks them correctly, rejects pure noise after FDR, respects governance gates, persists correct provenance, and is reproducible for a fixed seed. Performance test bounds the run on the standard demo size. | I26: New Feature | J26: 1) Engine recovers planted associations and rejects noise columns. 2) Ranking matches known ground-truth order. 3) Governance gate blocks an under-sampled run. 4) Deterministic; wired to the Jenkins gate. | K26: 4
A27: Phase 04 — ML Engine — Inspection Jobs to Generated Pages (Vision §3.2) | 6 tasks | 31 hrs
A28: PPIQ-T220 | B28: Inspection Job domain + persistence + endpoints | C28: P04 | D28: very important | E28: Track 1 — Workflow | F28: App Backend | G28: ML Engine / Inspection Jobs | H28: Per design doc §3.2.1 (Vision §3.2.1): user selects one defect-id / downtime-id / KPI-id + window (last week/month/year) + a name. Implement InspectionJob entity + EF config + migration + endpoints (create/list/get/run/schedule/delete). Back the already-wired SaveInspectionJobModal with the real POST. Authorization + license gating (Pro Plus/Enterprise). | I28: New Feature | J28: 1) Creating an inspection job from the modal persists it and returns an id. 2) Listing shows target, window, schedule. 3) Non-licensed tier is gated with a clear hint. 4) Audit row on create/run/schedule. | K28: 5
A29: PPIQ-T221 | B29: Inspection Job runner — on-demand analysis with progress | C29: P04 | D29: very important | E29: Track 1 — Workflow | F29: App Backend | G29: ML Engine / Inspection Runner | H29: Per design doc §3.2.2 (Vision §3.2.2): the runner executes an inspection job via the learning engine over the selected target + window and produces a ranked 'most influential parameters' result with evidence (coefficient, q-value, effect size, supporting slices, stability). Returns a structured InspectionResult the page generator consumes. Run-now returns 202 + progress (reuse the demo-lifecycle progress pattern). | I29: New Feature | J29: 1) Run-now over a demo target returns a ranked contributor list with evidence in bounded time. 2) Progress endpoint ticks through stages. 3) Same input+window => deterministic ranking. 4) Results persisted and linked to the job. | K29: 6
A30: PPIQ-T222 | B30: Auto-generate analysis page from inspection result (no hardcoding) | C30: P04 | D30: very important | E30: Track 1 — Workflow | F30: App Backend | G30: ML Engine / Page Generation | H30: Per design doc §3.2.2 + Track-3 golden rule: on completion, auto-compose a dashboard page from REAL widget definitions bound to the result — top-contributors bar, contributor trend over the window, distribution by target, correlation matrix — emitted into the page model (P08), the same definitions a user could build by hand. Regenerating after a re-run updates the page in place. No hardcoded layout. | I30: New Feature | J30: 1) A completed run produces a saved-page definition referencing real widgets bound to result data. 2) Opening the page renders live widgets. 3) Re-run updates the page in place. 4) The page round-trips through the page model — zero hardcoded layout. | K30: 6
A31: PPIQ-T223 | B31: Correlation Page shell — tabbed generated pages (replace stub) | C31: P04 | D31: very important | E31: Track 1 — Workflow | F31: App Frontend | G31: ML Engine / Correlation Page | H31: Per design doc §3.2.x (Vision §3.2): replace the 5-line CorrelationPage.tsx stub with the full ML Correlation area — a StandardTabs surface where each generated inspection-job page is a tab, with run-now, a save toggle, and a schedule control (hourly/daily) per tab. Standard* primitives, license gating, DataFetchBoundary states. | I31: New Feature | J31: 1) Page lists inspection jobs as tabs; selecting one renders its generated widgets. 2) Run-now refreshes the tab via the runner with a progress panel. 3) Save persists the page; Schedule enqueues a periodic job in the Jobs Monitor. 4) Standard* primitives only; visual regression baseline captured. | K31: 6
A32: PPIQ-T224 | B32: Schedule inspection jobs periodically + Jobs Monitor integration | C32: P04 | D32: important | E32: Track 1 — Workflow | F32: App Backend | G32: ML Engine / Scheduling | H32: Per design doc §3.2.3 (Vision §3.2.3): allow a saved inspection job to run periodically (hourly/daily/user-defined) or on demand. Register scheduled inspection runs in the unified job model so they appear in the Jobs Monitor with status/last-run/duration, and a periodic run regenerates the saved page. Rate-limited to avoid overlap. | I32: Enhancement | J32: 1) Scheduling a job enqueues a recurring run visible in the Jobs Monitor. 2) Each periodic run regenerates the page and records last-run/duration. 3) Pausing/deleting the schedule stops future runs. 4) Rate-limited against overlap. | K32: 4
A33: PPIQ-T225 | B33: E2E + integration tests for run -> generate -> save -> schedule loop | C33: P04 | D33: important | E33: Track 2 — Hardening | F33: App Frontend | G33: ML Engine / Test Coverage | H33: Per design doc §3.2: Playwright e2e + backend integration covering the full loop — create inspection job => run-now => generated page renders contributors => save => schedule => periodic run regenerates. Assert absence of the forbidden phrase and forbidden ML claims. | I33: New Feature | J33: 1) The full loop passes against staging. 2) Generated page shows the expected top contributor for a planted-signal demo target. 3) Forbidden-phrase + forbidden-claim assertions pass. 4) Test < 120s, wired to the post-deploy gate. | K33: 4
A34: Phase 05 — ML Assistant — Suggestion Feed (Vision §3.3 proactive) | 4 tasks | 21 hrs
A35: PPIQ-T226 | B35: Suggestion engine — rule-based, evidence-linked, impact-ranked | C35: P05 | D35: very important | E35: Track 1 — Workflow | F35: App Backend | G35: ML Assistant / Suggestion Engine | H35: Per design doc §4.2/§4.4 (Vision §3.3 proactive): synthesize ranked recommendations from the §3.1 learning outputs, inspection results, and data-quality findings. Each suggestion carries confidence, effective-n, q-value, effect size, and links to the supporting evidence. Rank by impact score ≈ effect size × prevalence × actionability × confidence/stability; dedup/group correlated drivers (multicollinearity); boost newly-emerged/changed relationships (changepoint). Strictly honest framing. | I35: New Feature | J35: 1) The engine emits ranked suggestions, each with confidence, n, q-value, evidence link. 2) Correlated drivers are grouped, not duplicated. 3) A newly-changed relationship surfaces higher. 4) Suggestions update after a new learning run. 5) No forbidden claim language (guarded). | K35: 8
A36: PPIQ-T227 | B36: /api/suggestions endpoint + context filtering + license gating | C36: P05 | D36: important | E36: Track 1 — Workflow | F36: App Backend | G36: ML Assistant / Suggestions API | H36: Implement GET /api/suggestions (the previously-stubbed route) returning ranked recommendations, filterable by current investigation context (material/area/line/window) and license tier. ProblemDetails error paths; pagination; audit of which suggestions were surfaced. | I36: New Feature | J36: 1) Endpoint returns ranked suggestions with reasoning + evidence links. 2) Context filters narrow results correctly. 3) Non-licensed tier gated. 4) Integration tests cover happy/empty/filtered. | K36: 4
A37: PPIQ-T228 | B37: Suggestions & Recommendations Page (proactive feed UI) | C37: P05 | D37: very important | E37: Track 1 — Workflow | F37: App Frontend | G37: ML Assistant / Suggestions Page | H37: Per design doc §4.2 (the 'Page' half of Vision §3.3): an evidence-grade ranked feed — 'the top things to look at this week' — with reasoning, confidence, sample size, and drill-through to the supporting correlation/inspection page. Standard* primitives, DataFetchBoundary states, license gating, and an honest empty state ('no strong signal yet'). Brand voice throughout. | I37: New Feature | J37: 1) Page renders ranked recommendations with reasoning + evidence drill-through. 2) Drill-through opens the supporting analysis page. 3) Empty/loading/error use Standard* and the 'Refreshing…' pattern. 4) Standard* primitives only; visual regression baseline captured. | K37: 6
A38: PPIQ-T229 | B38: Suggestion ranking + evidence-linkage tests | C38: P05 | D38: important | E38: Track 2 — Hardening | F38: App Backend | G38: ML Assistant / Test Coverage | H38: Tests asserting suggestion ranking order on golden inputs, evidence links resolve to the correct underlying results, context-filtering correctness, dedup/grouping of correlated drivers, and license gating. Determinism check. | I38: New Feature | J38: 1) Ranking matches known ground truth on golden inputs. 2) Every evidence link resolves to the correct correlation/inspection record. 3) Correlated drivers are grouped. 4) Deterministic; wired to the gate. | K38: 3
A39: Phase 06 — ML Assistant — Conversational RAG Agent (Vision §3.3 conversational) | 6 tasks | 39 hrs
A40: PPIQ-T230 | B40: Knowledge-base ingestion (findings, cases, domain docs) | C40: P06 | D40: very important | E40: Track 1 — Workflow | F40: App Backend | G40: ML Assistant / KB Ingestion | H40: Per design doc §4.1/§4.3: ingest the three growing knowledge sources into the pgvector KB (T213). (a) Learned findings rendered as evidence cards with structured metadata; (b) case memory (past inspection jobs, resolved excursions, downtime root-cause notes, acted-on recommendations + outcomes); (c) curated domain knowledge (grade specs, flat-steel failure modes, operating ranges, SOPs). Embed via IEmbeddingProvider; keep structured columns for hybrid retrieval. Re-ingest incrementally as data accumulates. | I40: New Feature | J40: 1) Findings, cases, and domain docs are embedded and retrievable. 2) New findings/cases are ingested incrementally. 3) Each item retains structured fields (area, defect class, grade, window, q-value). 4) Re-ingestion is idempotent. | K40: 6
A41: PPIQ-T231 | B41: Hybrid retrieval pipeline (semantic + structured filter) | C41: P06 | D41: very important | E41: Track 1 — Workflow | F41: App Backend | G41: ML Assistant / Retrieval | H41: Per design doc §4.3: implement retrieval that combines pgvector semantic similarity with structured SQL filters over the findings (area, defect class, grade, line, time window, q-value threshold). Question => embed => semantic + filtered search => top-k evidence with citations. Tunable k; relevance + recency weighting. | I41: New Feature | J41: 1) A query returns top-k evidence combining semantic match and structured filters. 2) Filtering by grade/defect/window narrows correctly. 3) Each retrieved item is citeable back to its source finding/case. 4) Retrieval latency is bounded and logged. | K41: 6
...

Sheet How to Use
A1: How to Use This Workbook (v5)
A3: Relationship to v4 | B3: v5 contains only OPEN work. v4 Phases 1–3 (PPIQ-T101–T118: schema mapping + two-stage delta import) were validated >90% on 30 May and are not repeated — their residuals are folded into P01 here. IDs continue from the prior series and start at PPIQ-T201 so they never collide with T101–T118.
A4: What changed from v4 | B4: (1) v4 P01–P03 removed as done. (2) Three new build-green hotfixes added (npm-in-Jenkins, migration-117 reconcile, ON_ERROR_STOP=1) plus carried residuals (full auth-matrix, ESLint gate, resolver/join hardening, delta-import tests, loopback scan). (3) The ML/AI subsystem is rebuilt per the engine + assistant design: a data-foundation phase, the learning engine with full statistical rigor, inspection→pages, a split suggestion-feed vs conversational-RAG-agent, and a risk-scorer/governance phase.
A5: Audience | B5: Founder / lead developer (Karim) and future contributors. Single source of truth for what 'finished' means against the 4-Track Vision, now including the transparent statistical ML engine and the honest, evidence-cited AI assistant.
A6: Sheets | B6: Task List (79 tasks, 13 phases); How to Use; Phase Summary (formula-driven); UI Standards Reference; Rollups (formula-driven).
A7: Severity scale | B7: critical > very important > important > normal > optional. Phase 1 is build-green: until the npm fix (T201), migration-117 reconcile (T202) and ON_ERROR_STOP=1 (T203) land, the pipeline stays red and deploys onto a half-migrated DB.
A8: ML/AI honesty contract | B8: The analytical core is deterministic, in-house, and statistical. The LLM is the VOICE, never the brain — it phrases already-computed, evidence-backed findings, never computes or invents numbers. 'Experience' lives in the accumulating knowledge base, not in model weights. Every finding carries effective-n, q-value, effect size, stability flag, and an evidence link. Forbidden: 'prediction', 'guaranteed root cause', 'AI-powered prediction', 'production-ready AI'. Approved: 'suspected contributor', 'statistical correlation', 'rule-based risk scoring'.
A9: In-house vs API | B9: The statistical engine is always in-house (not an LLM task). The natural-language layer sits behind INarrativeProvider/IEmbeddingProvider — API-default for quality/speed, self-hostable for air-gapped or governance-sensitive customers; only abstracted findings ever cross an external boundary. 'Works fully air-gapped; AI narration optional' is a selling point.
A10: Tracks / Modules | B10: Tracks: Workflow / Hardening / Demo / Website. Modules: App Frontend, App Backend, Database, Infrastructure, Web, Documentation.
A11: Effort | B11: Hours for one experienced full-stack engineer. Days = hours / 6. Add 25–35% buffer for review/integration/validation. Totals computed on Phase Summary and Rollups.
A12: Validation | B12: A task is Done only when every validation step passes. CI gates and post-deploy probes enforce this where possible. Recommended order is strictly top-to-bottom: P01 build-green first; P02 the ML data foundation; P03–P07 the engine, pages, assistant, scorer; P08 the page builder; P09 demo-at-scale; P10 hardening; P11 storytelling; P12 website; P13 legal/docs.
A13: Vision alignment | B13: Completing every task brings the 4-Track Vision to 100% at the depth specified — generic data lifecycle, a transparent ML engine with scheduled learning + generated analysis pages + an evidence-cited conversational assistant, a hardened HMI, a live-configurable demo at scale, and a 5-product website.

Sheet Phase Summary
A1: Phase Summary — effort, severity, and module distribution
A2: Recommended execution order: top-to-bottom. Counts and effort computed live from the Task List sheet.
A3: Phase ID | B3: Phase Name | C3: Tasks | D3: Critical | E3: Very Important | F3: Important | G3: Normal | H3: Effort (hrs) | I3: Effort (days)
A4: P01 | B4: Hotfixes & Build-Green Closeout | C4: =COUNTIF('Task List'!$C$6:$C$96,A4) -> 8 | D4: =COUNTIFS('Task List'!$C$6:$C$96,A4,'Task List'!$D$6:$D$96,"critical") -> 2 | E4: =COUNTIFS('Task List'!$C$6:$C$96,A4,'Task List'!$D$6:$D$96,"very important") -> 3 | F4: =COUNTIFS('Task List'!$C$6:$C$96,A4,'Task List'!$D$6:$D$96,"important") -> 3 | G4: =COUNTIFS('Task List'!$C$6:$C$96,A4,'Task List'!$D$6:$D$96,"normal") -> 0 | H4: =SUMIF('Task List'!$C$6:$C$96,A4,'Task List'!$K$6:$K$96) -> 18.5 | I4: =H4/6 -> 3.0833333
A5: P02 | B5: ML Engine — Data Foundation & Feature Store (Vision §3 prerequisite) | C5: =COUNTIF('Task List'!$C$6:$C$96,A5) -> 5 | D5: =COUNTIFS('Task List'!$C$6:$C$96,A5,'Task List'!$D$6:$D$96,"critical") -> 0 | E5: =COUNTIFS('Task List'!$C$6:$C$96,A5,'Task List'!$D$6:$D$96,"very important") -> 3 | F5: =COUNTIFS('Task List'!$C$6:$C$96,A5,'Task List'!$D$6:$D$96,"important") -> 2 | G5: =COUNTIFS('Task List'!$C$6:$C$96,A5,'Task List'!$D$6:$D$96,"normal") -> 0 | H5: =SUMIF('Task List'!$C$6:$C$96,A5,'Task List'!$K$6:$K$96) -> 32 | I5: =H5/6 -> 5.3333333
A6: P03 | B6: ML Engine — Scheduled Correlation Learning (Vision §3.1) | C6: =COUNTIF('Task List'!$C$6:$C$96,A6) -> 6 | D6: =COUNTIFS('Task List'!$C$6:$C$96,A6,'Task List'!$D$6:$D$96,"critical") -> 2 | E6: =COUNTIFS('Task List'!$C$6:$C$96,A6,'Task List'!$D$6:$D$96,"very important") -> 2 | F6: =COUNTIFS('Task List'!$C$6:$C$96,A6,'Task List'!$D$6:$D$96,"important") -> 2 | G6: =COUNTIFS('Task List'!$C$6:$C$96,A6,'Task List'!$D$6:$D$96,"normal") -> 0 | H6: =SUMIF('Task List'!$C$6:$C$96,A6,'Task List'!$K$6:$K$96) -> 38 | I6: =H6/6 -> 6.3333333
A7: P04 | B7: ML Engine — Inspection Jobs to Generated Pages (Vision §3.2) | C7: =COUNTIF('Task List'!$C$6:$C$96,A7) -> 6 | D7: =COUNTIFS('Task List'!$C$6:$C$96,A7,'Task List'!$D$6:$D$96,"critical") -> 0 | E7: =COUNTIFS('Task List'!$C$6:$C$96,A7,'Task List'!$D$6:$D$96,"very important") -> 4 | F7: =COUNTIFS('Task List'!$C$6:$C$96,A7,'Task List'!$D$6:$D$96,"important") -> 2 | G7: =COUNTIFS('Task List'!$C$6:$C$96,A7,'Task List'!$D$6:$D$96,"normal") -> 0 | H7: =SUMIF('Task List'!$C$6:$C$96,A7,'Task List'!$K$6:$K$96) -> 31 | I7: =H7/6 -> 5.1666667
A8: P05 | B8: ML Assistant — Suggestion Feed (Vision §3.3 proactive) | C8: =COUNTIF('Task List'!$C$6:$C$96,A8) -> 4 | D8: =COUNTIFS('Task List'!$C$6:$C$96,A8,'Task List'!$D$6:$D$96,"critical") -> 0 | E8: =COUNTIFS('Task List'!$C$6:$C$96,A8,'Task List'!$D$6:$D$96,"very important") -> 2 | F8: =COUNTIFS('Task List'!$C$6:$C$96,A8,'Task List'!$D$6:$D$96,"important") -> 2 | G8: =COUNTIFS('Task List'!$C$6:$C$96,A8,'Task List'!$D$6:$D$96,"normal") -> 0 | H8: =SUMIF('Task List'!$C$6:$C$96,A8,'Task List'!$K$6:$K$96) -> 21 | I8: =H8/6 -> 3.5
A9: P06 | B9: ML Assistant — Conversational RAG Agent (Vision §3.3 conversational) | C9: =COUNTIF('Task List'!$C$6:$C$96,A9) -> 6 | D9: =COUNTIFS('Task List'!$C$6:$C$96,A9,'Task List'!$D$6:$D$96,"critical") -> 0 | E9: =COUNTIFS('Task List'!$C$6:$C$96,A9,'Task List'!$D$6:$D$96,"very important") -> 5 | F9: =COUNTIFS('Task List'!$C$6:$C$96,A9,'Task List'!$D$6:$D$96,"important") -> 1 | G9: =COUNTIFS('Task List'!$C$6:$C$96,A9,'Task List'!$D$6:$D$96,"normal") -> 0 | H9: =SUMIF('Task List'!$C$6:$C$96,A9,'Task List'!$K$6:$K$96) -> 39 | I9: =H9/6 -> 6.5
A10: P07 | B10: Risk Scorer & Model Governance (Vision §3 cross-cutting) | C10: =COUNTIF('Task List'!$C$6:$C$96,A10) -> 4 | D10: =COUNTIFS('Task List'!$C$6:$C$96,A10,'Task List'!$D$6:$D$96,"critical") -> 0 | E10: =COUNTIFS('Task List'!$C$6:$C$96,A10,'Task List'!$D$6:$D$96,"very important") -> 0 | F10: =COUNTIFS('Task List'!$C$6:$C$96,A10,'Task List'!$D$6:$D$96,"important") -> 3 | G10: =COUNTIFS('Task List'!$C$6:$C$96,A10,'Task List'!$D$6:$D$96,"normal") -> 1 | H10: =SUMIF('Task List'!$C$6:$C$96,A10,'Task List'!$K$6:$K$96) -> 18 | I10: =H10/6 -> 3
A11: P08 | B11: Page Builder & Widget Library (Vision §2.1–2.2) | C11: =COUNTIF('Task List'!$C$6:$C$96,A11) -> 5 | D11: =COUNTIFS('Task List'!$C$6:$C$96,A11,'Task List'!$D$6:$D$96,"critical") -> 0 | E11: =COUNTIFS('Task List'!$C$6:$C$96,A11,'Task List'!$D$6:$D$96,"very important") -> 3 | F11: =COUNTIFS('Task List'!$C$6:$C$96,A11,'Task List'!$D$6:$D$96,"important") -> 2 | G11: =COUNTIFS('Task List'!$C$6:$C$96,A11,'Task List'!$D$6:$D$96,"normal") -> 0 | H11: =SUMIF('Task List'!$C$6:$C$96,A11,'Task List'!$K$6:$K$96) -> 30 | I11: =H11/6 -> 5
A12: P09 | B12: Demo Source-Database Suite at Real Scale (Vision Track 3) | C12: =COUNTIF('Task List'!$C$6:$C$96,A12) -> 4 | D12: =COUNTIFS('Task List'!$C$6:$C$96,A12,'Task List'!$D$6:$D$96,"critical") -> 0 | E12: =COUNTIFS('Task List'!$C$6:$C$96,A12,'Task List'!$D$6:$D$96,"very important") -> 3 | F12: =COUNTIFS('Task List'!$C$6:$C$96,A12,'Task List'!$D$6:$D$96,"important") -> 1 | G12: =COUNTIFS('Task List'!$C$6:$C$96,A12,'Task List'!$D$6:$D$96,"normal") -> 0 | H12: =SUMIF('Task List'!$C$6:$C$96,A12,'Task List'!$K$6:$K$96) -> 25 | I12: =H12/6 -> 4.1666667
A13: P10 | B13: Hardening Completion & Resilience (Vision Track 2) | C13: =COUNTIF('Task List'!$C$6:$C$96,A13) -> 8 | D13: =COUNTIFS('Task List'!$C$6:$C$96,A13,'Task List'!$D$6:$D$96,"critical") -> 0 | E13: =COUNTIFS('Task List'!$C$6:$C$96,A13,'Task List'!$D$6:$D$96,"very important") -> 2 | F13: =COUNTIFS('Task List'!$C$6:$C$96,A13,'Task List'!$D$6:$D$96,"important") -> 6 | G13: =COUNTIFS('Task List'!$C$6:$C$96,A13,'Task List'!$D$6:$D$96,"normal") -> 0 | H13: =SUMIF('Task List'!$C$6:$C$96,A13,'Task List'!$K$6:$K$96) -> 35 | I13: =H13/6 -> 5.8333333
A14: P11 | B14: Demo Storytelling, Personas & Recording (Vision Track 3) | C14: =COUNTIF('Task List'!$C$6:$C$96,A14) -> 6 | D14: =COUNTIFS('Task List'!$C$6:$C$96,A14,'Task List'!$D$6:$D$96,"critical") -> 0 | E14: =COUNTIFS('Task List'!$C$6:$C$96,A14,'Task List'!$D$6:$D$96,"very important") -> 4 | F14: =COUNTIFS('Task List'!$C$6:$C$96,A14,'Task List'!$D$6:$D$96,"important") -> 2 | G14: =COUNTIFS('Task List'!$C$6:$C$96,A14,'Task List'!$D$6:$D$96,"normal") -> 0 | H14: =SUMIF('Task List'!$C$6:$C$96,A14,'Task List'!$K$6:$K$96) -> 20 | I14: =H14/6 -> 3.3333333
A15: P12 | B15: Website Track — 5-Product Showcase & Brand (Vision Track 4) | C15: =COUNTIF('Task List'!$C$6:$C$96,A15) -> 9 | D15: =COUNTIFS('Task List'!$C$6:$C$96,A15,'Task List'!$D$6:$D$96,"critical") -> 0 | E15: =COUNTIFS('Task List'!$C$6:$C$96,A15,'Task List'!$D$6:$D$96,"very important") -> 1 | F15: =COUNTIFS('Task List'!$C$6:$C$96,A15,'Task List'!$D$6:$D$96,"important") -> 7 | G15: =COUNTIFS('Task List'!$C$6:$C$96,A15,'Task List'!$D$6:$D$96,"normal") -> 1 | H15: =SUMIF('Task List'!$C$6:$C$96,A15,'Task List'!$K$6:$K$96) -> 28 | I15: =H15/6 -> 4.6666667
A16: P13 | B16: Legal Templates, Runbooks & Documentation | C16: =COUNTIF('Task List'!$C$6:$C$96,A16) -> 8 | D16: =COUNTIFS('Task List'!$C$6:$C$96,A16,'Task List'!$D$6:$D$96,"critical") -> 0 | E16: =COUNTIFS('Task List'!$C$6:$C$96,A16,'Task List'!$D$6:$D$96,"very important") -> 0 | F16: =COUNTIFS('Task List'!$C$6:$C$96,A16,'Task List'!$D$6:$D$96,"important") -> 8 | G16: =COUNTIFS('Task List'!$C$6:$C$96,A16,'Task List'!$D$6:$D$96,"normal") -> 0 | H16: =SUMIF('Task List'!$C$6:$C$96,A16,'Task List'!$K$6:$K$96) -> 25.5 | I16: =H16/6 -> 4.25
A17: TOTAL | B17: All open phases | C17: =SUM(C4:C16) -> 79 | D17: =SUM(D4:D16) -> 4 | E17: =SUM(E4:E16) -> 32 | F17: =SUM(F4:F16) -> 41 | G17: =SUM(G4:G16) -> 2 | H17: =SUM(H4:H16) -> 361 | I17: =H17/6 -> 60.166667
A19: Effort-days assume 6 productive engineering hours per workday. Add 25–35% buffer for review, integration, and validation.

Sheet UI Standards Reference
A1: UI Standards — Canonical Component Contract (enforced)
A2: Every interactive element across all existing AND new pages (incl. ML Correlation, Suggestions, Assistant, Schema Mapping, Two-Stage Import) must conform. Enforced via ESLint, CI lint, review, Storybook.
A3: Component | B3: Canonical Path | C3: Variants / Modes | D3: Required Props | E3: Required States
A4: StandardButton | B4: src/components/standard/StandardButton.tsx | C4: primary | secondary | ghost | danger | success | icon-only | D4: variant, size, leadingIcon, trailingIcon, isLoading, isDisabled, fullWidth, onClick, type, ariaLabel | E4: default, hover, focus (cyan ring), active, disabled (40%), loading (spinner + aria-busy)
A5: StandardTable | B5: src/components/standard/StandardTable.tsx | C5: client | server | virtualized (>500 rows) | D5: columns, data, isLoading, hasError, onRetry, totalCount, onRowClick, density, selectable, exportable | E5: loading (skeleton), error ('Refreshing X…' + retry), empty, populated, sorted, filtered, paginated
A6: StandardTabs | B6: src/components/standard/StandardTabs.tsx | C6: horizontal | vertical | scroll-on-overflow | D6: items, value, onChange, orientation, lazy, urlParam | E6: default, active (indicator), hover, disabled, overflow-scrollable, keyboard-focused
A7: StandardInput / Select / TextArea | B7: src/components/standard/StandardFields.tsx | C7: text/email/password/number/search; single/multi/searchable; default/code | D7: label, helperText, error, value, onChange, required, disabled, isLoading, size, (options, multiple, searchable) | E7: default, focus, error (helper-text), disabled, with-value, code-mode (mono)
A8: StandardCard / Modal / Toast | B8: src/components/standard/StandardSurface.tsx | C8: flat/raised/floating; sm-xl; info/success/warning/error/loading | D8: title, actions, elevation, open, onClose, size, dismiss flags, variant, duration | E8: default, hover, with-actions, open (focus-trapped), dirty-blocked, toast slide-in + progress
A9: DataFetchBoundary | B9: src/components/standard/DataFetchBoundary.tsx | C9: default | skeleton-mirror | D9: isLoading, hasError, onRetry, loadingFallback, errorFallback, children | E9: loading ('Refreshing X…'), error (+retry, auto-retry-5s), success
A10: ErrorBoundary | B10: src/components/standard/ErrorBoundary.tsx | C10: app | route | component | D10: fallback, onError, resetKeys, children | E10: caught (fallback + /diagnostics/client-error beacon), retrying, recovered
A12: FORBIDDEN PATTERNS (CI-enforced)
A13: Forbidden phrase | B13: 'could not be loaded' / 'could not load' | C13: Use the 'Refreshing X…' pattern. Founder's #1 non-negotiable (Vision §2).
A14: Forbidden ML claims | B14: 'guaranteed root cause' / 'AI-powered prediction' / 'production-ready AI' / 'predicts' | C14: Use 'suspected contributor' / 'statistical correlation' / 'rule-based risk scoring'. Enforced on ML + assistant surfaces.
A15: Native element | B15: <button>/<input>/<select>/<table>/<textarea> in src/pages|features | C15: Use Standard* primitives (ESLint no-restricted-syntax).
A16: Deprecated path | B16: import from src/components/hardening/* or src/hardening/* | C16: Use src/components/standard/*.
A17: LLM invents numbers | B17: assistant emits a figure not present in retrieved evidence/tool results | C17: The LLM phrases evidence it is handed; it never computes or invents. Grounding tests enforce.

Sheet Rollups
A1: Rollups — by Severity, Track, Module, Type (computed live)
A2: By Severity | E2: By Track | I2: By Module | M2: By Type
A3: Severity | B3: Count | C3: Effort (hrs) | E3: Track | F3: Count | G3: Effort (hrs) | I3: Module | J3: Count | K3: Effort (hrs) | M3: Type | N3: Count | O3: Effort (hrs)
A4: critical | B4: =COUNTIF('Task List'!$D$6:$D$96,A4) -> 4 | C4: =SUMIF('Task List'!$D$6:$D$96,A4,'Task List'!$K$6:$K$96) -> 26 | E4: Track 1 — Workflow | F4: =COUNTIF('Task List'!$E$6:$E$96,E4) -> 32 | G4: =SUMIF('Task List'!$E$6:$E$96,E4,'Task List'!$K$6:$K$96) -> 186 | I4: App Frontend | J4: =COUNTIF('Task List'!$F$6:$F$96,I4) -> 15 | K4: =SUMIF('Task List'!$F$6:$F$96,I4,'Task List'!$K$6:$K$96) -> 82 | M4: New Feature | N4: =COUNTIF('Task List'!$I$6:$I$96,M4) -> 57 | O4: =SUMIF('Task List'!$I$6:$I$96,M4,'Task List'!$K$6:$K$96) -> 280.5
A5: very important | B5: =COUNTIF('Task List'!$D$6:$D$96,A5) -> 32 | C5: =SUMIF('Task List'!$D$6:$D$96,A5,'Task List'!$K$6:$K$96) -> 180.5 | E5: Track 2 — Hardening | F5: =COUNTIF('Task List'!$E$6:$E$96,E5) -> 26 | G5: =SUMIF('Task List'!$E$6:$E$96,E5,'Task List'!$K$6:$K$96) -> 101 | I5: App Backend | J5: =COUNTIF('Task List'!$F$6:$F$96,I5) -> 29 | K5: =SUMIF('Task List'!$F$6:$F$96,I5,'Task List'!$K$6:$K$96) -> 160 | M5: Enhancement | N5: =COUNTIF('Task List'!$I$6:$I$96,M5) -> 15 | O5: =SUMIF('Task List'!$I$6:$I$96,M5,'Task List'!$K$6:$K$96) -> 65.5
A6: important | B6: =COUNTIF('Task List'!$D$6:$D$96,A6) -> 41 | C6: =SUMIF('Task List'!$D$6:$D$96,A6,'Task List'!$K$6:$K$96) -> 148.5 | E6: Track 3 — Demo | F6: =COUNTIF('Task List'!$E$6:$E$96,E6) -> 8 | G6: =SUMIF('Task List'!$E$6:$E$96,E6,'Task List'!$K$6:$K$96) -> 35 | I6: Database | J6: =COUNTIF('Task List'!$F$6:$F$96,I6) -> 9 | K6: =SUMIF('Task List'!$F$6:$F$96,I6,'Task List'!$K$6:$K$96) -> 40 | M6: Bug Fix | N6: =COUNTIF('Task List'!$I$6:$I$96,M6) -> 7 | O6: =SUMIF('Task List'!$I$6:$I$96,M6,'Task List'!$K$6:$K$96) -> 15
A7: normal | B7: =COUNTIF('Task List'!$D$6:$D$96,A7) -> 2 | C7: =SUMIF('Task List'!$D$6:$D$96,A7,'Task List'!$K$6:$K$96) -> 6 | E7: Track 4 — Website | F7: =COUNTIF('Task List'!$E$6:$E$96,E7) -> 13 | G7: =SUMIF('Task List'!$E$6:$E$96,E7,'Task List'!$K$6:$K$96) -> 39 | I7: Infrastructure | J7: =COUNTIF('Task List'!$F$6:$F$96,I7) -> 5 | K7: =SUMIF('Task List'!$F$6:$F$96,I7,'Task List'!$K$6:$K$96) -> 12.5 | M7: TOTAL | N7: =SUM(N4:N6) -> 79 | O7: =SUM(O4:O6) -> 361
A8: optional | B8: =COUNTIF('Task List'!$D$6:$D$96,A8) -> 0 | C8: =SUMIF('Task List'!$D$6:$D$96,A8,'Task List'!$K$6:$K$96) -> 0 | E8: TOTAL | F8: =SUM(F4:F7) -> 79 | G8: =SUM(G4:G7) -> 361 | I8: Web | J8: =COUNTIF('Task List'!$F$6:$F$96,I8) -> 9 | K8: =SUMIF('Task List'!$F$6:$F$96,I8,'Task List'!$K$6:$K$96) -> 28
A9: TOTAL | B9: =SUM(B4:B8) -> 79 | C9: =SUM(C4:C8) -> 361 | I9: Documentation | J9: =COUNTIF('Task List'!$F$6:$F$96,I9) -> 12 | K9: =SUMIF('Task List'!$F$6:$F$96,I9,'Task List'!$K$6:$K$96) -> 38.5
I10: TOTAL | J10: =SUM(J4:J9) -> 79 | K10: =SUM(K4:K9) -> 361
