Workbook

Sheet Read Me
A1: PlantProcess IQ — Task List v13 · 31 May 2026
A2: Net-new backlog. Canonical base: Product Vision & Engineering Doctrine v2.0 (via the Version Improvement Analysis). Every task is 0% done.
A3: What this workbook is | B3: A from-scratch backlog of the work that REMAINS to reach the canonical target. It deliberately contains no Done or Partial items - every task is scoped to its unbuilt slice, so the whole list is 0% complete and can be executed top-to-bottom without parsing statuses.
A4: The base (target state) | B4: Product Vision & Engineering Doctrine v2.0 is the single source of truth, with Architecture v3 as its design companion (per the Version Improvement Analysis recommendation). Each task carries a 'Spec Anchor' back to the exact doctrine section it satisfies.
A5: The current state | B5: Derived from the 31-May implementation snapshot (1,004 files) as captured in the Implementation Validation report and confirmed by direct code search. Capabilities already built are excluded (see the 'Excluded - Already Built' sheet for the audit trail).
A6: How a task qualifies | B6: A task appears here only if its concrete deliverable does NOT yet exist in the code. For capabilities that are partially built, only the missing slice is listed, re-scoped as a clean, self-contained, 0%-done task with a fresh ID.
A7: Relationship to the old list | B7: v13 is not a re-status of the prior list. It is a clean re-derivation of remaining work; prior Done/Partial/Not-Started labels are not carried over. Where a v13 task corresponds to the unfinished part of an older item, the Description + Spec Anchor make the new scope explicit.
A8: ID scheme | B8: PPIQ-N### (N = net-new). 75 tasks across 11 execution phases (N-P1 ... N-P11), sequenced by dependency and commercial priority. Status is uniformly 'Not Started' and Completion % is uniformly 0 by design.
A9: Column legend | B9: Spec Anchor = the Vision/Architecture/Validation reference the task satisfies. Dependencies = task IDs that should land first. Acceptance Criteria = the testable 'done' bar. Effort = engineering hours (indicative).
A10: Sheets | B10: 'v13 Backlog' = the tasks. 'Phase Plan' = execution order with live counts + effort. 'Coverage Map' = every Vision v2.0 area -> the tasks that complete it. 'Excluded - Already Built' = what was left out and why.

Sheet v13 Backlog
A1: v13 Backlog — net-new remaining work (every task 0% done)
A2: Task ID | B2: Task Name | C2: Phase | D2: Track | E2: Module | F2: Submodule | G2: Severity | H2: Description | I2: Acceptance Criteria | J2: Spec Anchor | K2: Dependencies | L2: Task Type | M2: Effort (hrs) | N2: Status | O2: Completion %
A3: N-P1 · Security, Access & Trust Closeout
A4: PPIQ-N001 | B4: Move the access token off localStorage to an httpOnly cookie | C4: N-P1 · Security, Access & Trust Closeout | D4: Track 2 — Hardening | E4: App Frontend | F4: Auth / Token Storage | G4: very important | H4: Current: the access token is persisted in localStorage, where any XSS can read it (Validation F4). Build: relocate the token to an httpOnly + SameSite cookie (or in-memory store with silent refresh) and remove every localStorage token read/write. | I4: 1) No localStorage token access remains in the bundle. 2) Auth survives a page reload via cookie/refresh. 3) Injected script cannot read the token. 4) Existing auth e2e stays green. | J4: Validation F4 | Vision 10.1 | K4: - | L4: Security | M4: 8 | N4: Not Started | O4: 0
A5: PPIQ-N002 | B5: Define & enforce the RBAC permission matrix | C5: N-P1 · Security, Access & Trust Closeout | D5: Track 2 — Hardening | E5: App Backend | F5: Access Control / RBAC | G5: critical | H5: Current: role/tenant primitives exist but no explicit permission matrix is enforced per endpoint/feature. Build: a permission catalog (resource x action), a central policy mapping roles to permissions, and authorization attributes on every endpoint group; deny by default. | I5: 1) A matrix test asserts each role's allowed/denied set on every endpoint group. 2) Default is deny. 3) The matrix is data-driven and documented (feeds N005). | J5: Vision (User/Role residual) | v3 3.8 | K5: - | L5: Feature | M5: 16 | N5: Not Started | O5: 0
A6: PPIQ-N003 | B6: Resolve license x role at the corner cases (single entitlement authority) | C6: N-P1 · Security, Access & Trust Closeout | D6: Track 2 — Hardening | E6: App Backend | F6: Entitlement Resolution | G6: very important | H6: Current: LicenseTier primitives are present but the interaction with roles is not centrally resolved or tested. Build: one Entitlement resolver = f(tier, role) -> capability set, read by both API and UI, with corner-case coverage (Enterprise-admin vs Pro-operator, etc.). | I6: 1) A single resolver authority exists. 2) UI hides/disables exactly what the API forbids. 3) Corner-case unit tests pass. | J6: Vision 4 | v3 3.8 | K6: PPIQ-N002 | L6: Feature | M6: 12 | N6: Not Started | O6: 0
A7: PPIQ-N004 | B7: Tenant-isolation integration tests across data, ML & assistant paths | C7: N-P1 · Security, Access & Trust Closeout | D7: Track 2 — Hardening | E7: App Backend | F7: Multi-tenancy | G7: critical | H7: Current: TenantId scaffolding exists but isolation is not proven by test. Build: integration tests proving a tenant can never read another tenant's dumps, mappings, findings, suggestions or knowledge-base chunks. | I7: 1) Cross-tenant access returns 403/empty at repo, query, ML-result and KB-retrieval layers. 2) Tests run in CI and gate regressions. | J7: v3 3.8 | Vision 10 | K7: - | L7: Test | M7: 10 | N7: Not Started | O7: 0
A8: PPIQ-N005 | B8: Author the 'User, Role & Access + Audit' doctrine section (the lone residual gap) | C8: N-P1 · Security, Access & Trust Closeout | D8: Track 2 — Hardening | E8: Documentation | F8: Canonical Spec | G8: very important | H8: Current: Vision v2.0 has no dedicated access-control section - the one heading the original draft left blank. Build: add the section (role catalog, RBAC matrix, license x role interaction, tenant-isolation model, immutable audit-log contract) to the canonical document. | I8: 1) Section added to Vision v2.0 and cross-referenced from v3. 2) It matches the implemented matrix (N002/N003). 3) Reviewed against the Improvement Analysis edit #1. | J8: Improvement Analysis 7 (edit 1) | K8: PPIQ-N002,PPIQ-N003,PPIQ-N004 | L8: Documentation | M8: 6 | N8: Not Started | O8: 0
A9: PPIQ-N006 | B9: Immutable audit-log coverage for every privileged action | C9: N-P1 · Security, Access & Trust Closeout | D9: Track 2 — Hardening | E9: App Backend | F9: Audit Log | G9: very important | H9: Current: audit-log immutability exists (script 096) but action coverage is incomplete. Build: append-only, tamper-evident entries for auth, config writes, mapping/materialize, job control, license/role changes and data exports, each with actor/tenant/before-after. | I9: 1) Each privileged action writes exactly one immutable entry. 2) An integration test enumerates the covered actions. 3) Entries are provably read-only. | J9: Vision 8/10 | v3 3.8 | K9: PPIQ-N002 | L9: Feature | M9: 8 | N9: Not Started | O9: 0
A10: PPIQ-N007 | B10: Fix the SQL syntax error seen during ordered-script application | C10: N-P1 · Security, Access & Trust Closeout | D10: Track 2 — Hardening | E10: Database | F10: Migration / Scripts | G10: very important | H10: Current: a syntax error surfaces while applying the ordered script set; root cause unconfirmed. Build: reproduce on a fresh DB, isolate the offending statement, fix it, and add the apply to the fail-on-error gate. | I10: 1) The full ordered set applies cleanly under ON_ERROR_STOP=1 on a fresh DB and a staging clone, BOM-free. 2) A CI step proves it. | J10: Validation | Vision 10.3 | K10: - | L10: Bug | M10: 5 | N10: Not Started | O10: 0
A11: N-P2 · The Value Model
A12: PPIQ-N008 | B12: Value/Impact computation engine (finding -> quantified impact) | C12: N-P2 · The Value Model | D12: Track 1 — Workflow | E12: App Backend | F12: Value Model | G12: critical | H12: Current: no code converts a finding into a monetary/operational figure - the architecture's biggest commercial lever (Validation F1). Build: a deterministic engine that, given a validated finding + tenant cost assumptions, computes a bounded impact (EUR/month from defect-rate delta, yield, downtime) with provenance and an explicit abstain path. | I12: 1) Returns a decomposed impact with every input cited. 2) Returns 'insufficient basis' instead of a guess when assumptions are missing. 3) Unit-tested on known vectors. | J12: Validation F1 | v3 5 | K12: - | L12: Feature | M12: 16 | N12: Not Started | O12: 0
A13: PPIQ-N009 | B13: Per-tenant cost-assumption configuration (inputs + demo defaults) | C13: N-P2 · The Value Model | D13: Track 1 — Workflow | E13: App Frontend | F13: Value Model | G13: very important | H13: Current: absent (0 code hits). Build: an admin surface + persisted, versioned model for cost inputs (cost/ton, scrap cost, downtime EUR/min, energy EUR/MWh, grade premiums), with realistic demo defaults, consumed by N008. | I13: 1) Assumptions are tenant-scoped, HMI-editable and versioned. 2) They feed the impact engine. 3) The demo tenant ships with realistic defaults. | J13: v3 5 | K13: PPIQ-N008 | L13: Feature | M13: 10 | N13: Not Started | O13: 0
A14: PPIQ-N010 | B14: ROI presentation contract (evidence-first, never overstated) | C14: N-P2 · The Value Model | D14: Track 1 — Workflow | E14: App Frontend | F14: Value Model | G14: very important | H14: Current: absent. Build: a presentation contract that renders impact as a ranged, evidence-linked figure with its assumption set and honesty caveats, in the suggestion feed and the assistant; forbidden from asserting a guaranteed saving. | I14: 1) Every impact figure shows inputs + range + drill-through. 2) Honesty-lint rejects 'guaranteed'/'will save'. 3) Snapshot tests cover the rendered contract. | J14: v3 5 | Vision 3 (honesty) | K14: PPIQ-N008,PPIQ-N009 | L14: Feature | M14: 8 | N14: Not Started | O14: 0
A15: N-P3 · Intelligence Core Completion
A16: PPIQ-N011 | B16: Add Spearman, mutual information & Lasso to the correlation compute engine | C16: N-P3 · Intelligence Core Completion | D16: Track 1 — Workflow | E16: App Backend | F16: Correlation Methods | G16: very important | H16: Current: Pearson, point-biserial and Cramer's V are implemented; Spearman, mutual information and Lasso are not (Validation F2). Build: implement Spearman (monotonic/ordinal), mutual information (non-linear) and Lasso multivariate screening behind the existing compute-engine interface, auto-selected by variable-pair type. | I16: 1) Each method computes correctly on golden vectors. 2) Method is auto-selected per variable-pair type. 3) Results persist with a method tag. | J16: Vision 3.2.1 | Validation F2 | K16: - | L16: Feature | M16: 16 | N16: Not Started | O16: 0
A17: PPIQ-N012 | B17: Add the missing validity machinery: VIF, bootstrap stability, confounding/stratification | C17: N-P3 · Intelligence Core Completion | D17: Track 1 — Workflow | E17: App Backend | F17: Statistical Validity | G17: very important | H17: Current: BH q-values, effect-size-first ranking, power and effective-n-by-heat exist; VIF, bootstrap stability and confounding/stratification checks do not. Build: variance-inflation screening, bootstrap stability flags and confounder stratification over the association results. | I17: 1) Each association carries a stability flag + VIF. 2) Stratified checks surface confounds. 3) Golden-dataset tests confirm spurious associations are demoted. | J17: Vision 3.2.2 | Validation F2 | K17: PPIQ-N011 | L17: Feature | M17: 14 | N17: Not Started | O17: 0
A18: PPIQ-N013 | B18: Per-job scheduling, backoff & MlReadiness governance gates | C18: N-P3 · Intelligence Core Completion | D18: Track 1 — Workflow | E18: App Backend | F18: ML Scheduling | G18: very important | H18: Current: per-source scheduling exists; ML-job readiness gating and backoff do not. Build: a readiness gate evaluated before each learning run (enough independent heats, freshness) with reschedule-on-not-ready and exponential backoff on failure. | I18: 1) A job refuses to run on insufficient/not-ready data and reschedules. 2) Backoff is observed on repeated failure. 3) Gate decisions are logged and visible in the Jobs Monitor. | J18: Vision 3.2.2 | K18: - | L18: Feature | M18: 10 | N18: Not Started | O18: 0
A19: PPIQ-N014 | B19: Persist the extended correlation result + wire it into the Jobs Monitor | C19: N-P3 · Intelligence Core Completion | D19: Track 1 — Workflow | E19: App Backend | F19: Results / Monitoring | G19: important | H19: Current: a base correlation result exists; extended fields and monitor integration are incomplete. Build: persist effect size, q-value, effective-n, stability, VIF and method per association, and surface each learning run's outcome/duration in the Jobs Monitor. | I19: 1) Extended columns are populated. 2) The Jobs Monitor shows last run/outcome/duration for every learning job. 3) The query is tested. | J19: Vision 2.2.6/3.2 | K19: PPIQ-N012,PPIQ-N013 | L19: Feature | M19: 8 | N19: Not Started | O19: 0
A20: PPIQ-N015 | B20: Golden-dataset test suite for the learning engine | C20: N-P3 · Intelligence Core Completion | D20: Track 1 — Workflow | E20: Backend Tests | F20: ML Tests | G20: very important | H20: Current: engine tests are partial. Build: fixture datasets with known injected associations (and known nulls) that assert recovery of true signals and rejection of spurious ones under FDR. | I20: 1) True associations are recovered with the correct method/effect. 2) Injected spurious signals are rejected. 3) The suite runs in CI and gates regressions. | J20: Vision 8 (results & math) | K20: PPIQ-N011,PPIQ-N012 | L20: Test | M20: 10 | N20: Not Started | O20: 0
A21: N-P4 · Risk Scorer Hardening
A22: PPIQ-N016 | B22: Risk-score calibration & reliability check | C22: N-P4 · Risk Scorer Hardening | D22: Track 1 — Workflow | E22: App Backend | F22: Risk Scorer | G22: important | H22: Current: the additive, decomposable scorer exists; calibration/reliability is absent (0 hits). Build: reliability-curve / Brier calibration on held-out data, surfaced alongside the score. | I22: 1) Calibration is computed and stored. 2) A miscalibrated model is flagged. 3) Tested on a synthetic labelled set. | J22: Vision 3.4 | K22: - | L22: Feature | M22: 10 | N22: Not Started | O22: 0
A23: PPIQ-N017 | B23: Complete the model registry: provenance & reproducibility | C23: N-P4 · Risk Scorer Hardening | D23: Track 1 — Workflow | E23: App Backend | F23: Model Registry | G23: important | H23: Current: registry scaffolding exists; provenance/repro linkage is incomplete. Build: link every persisted score to its inputs, feature snapshot and model version so a run is reproducible from the registry. | I23: 1) The score->inputs->version chain is queryable. 2) Re-running a registered version reproduces the score. 3) Integration-tested. | J23: Vision 3.4 | K23: PPIQ-N016 | L23: Feature | M23: 10 | N23: Not Started | O23: 0
A24: PPIQ-N018 | B24: Drift monitoring & champion/challenger promotion | C24: N-P4 · Risk Scorer Hardening | D24: Track 1 — Workflow | E24: App Backend | F24: Model Lifecycle | G24: important | H24: Current: absent (0 hits). Build: population-stability drift monitoring on features/outcomes and a champion/challenger promotion workflow gated on calibration + drift. | I24: 1) Drift is surfaced with a metric + threshold. 2) A challenger promotes only when it beats champion on calibration/stability. 3) Promotion is audited. | J24: Vision 3.4 | K24: PPIQ-N016,PPIQ-N017 | L24: Feature | M24: 12 | N24: Not Started | O24: 0
A25: N-P5 · Inspection -> Generated Pages
A26: PPIQ-N019 | B26: Inspection Job runner - on-demand analysis with progress | C26: N-P5 · Inspection -> Generated Pages | D26: Track 1 — Workflow | E26: App Backend | F26: Inspection Jobs | G26: very important | H26: Current: the inspection-job domain/endpoints are partial; the on-demand runner with progress is absent. Build: a runner that executes a selected defect/downtime/KPI investigation over a window, emitting a progress percentage. | I26: 1) A run streams progress and cancels cleanly. 2) It never hangs (global timeout). 3) It produces a structured result object. | J26: Vision 3.3 | K26: - | L26: Feature | M26: 12 | N26: Not Started | O26: 0
A27: PPIQ-N020 | B27: Auto-generate the analysis page from an inspection result (no hardcoding) | C27: N-P5 · Inspection -> Generated Pages | D27: Track 1 — Workflow | E27: App Frontend | F27: Generated Pages | G27: very important | H27: Current: absent. Build: from a run result, generate a page of widgets/charts showing the most influential parameters, persisted as a normal Page Definition. | I27: 1) The page is data-driven (no hardcoded layout). 2) It opens in the Correlation area as its own tab. 3) It is editable/savable like any page. | J27: Vision 3.3 | K27: PPIQ-N019 | L27: Feature | M27: 12 | N27: Not Started | O27: 0
A28: PPIQ-N021 | B28: Schedule inspection jobs periodically + Jobs Monitor integration | C28: N-P5 · Inspection -> Generated Pages | D28: Track 1 — Workflow | E28: App Backend | F28: Inspection Jobs | G28: important | H28: Current: absent. Build: let a saved inspection job run on a cadence or on demand, with status/duration reported in the Jobs Monitor. | I28: 1) Scheduled re-runs appear in the monitor. 2) 'Run now' works on demand. 3) Failures are visible and recoverable. | J28: Vision 3.3 | K28: PPIQ-N019 | L28: Feature | M28: 8 | N28: Not Started | O28: 0
A29: PPIQ-N022 | B29: E2E for the run -> generate -> save -> schedule loop | C29: N-P5 · Inspection -> Generated Pages | D29: Track 1 — Workflow | E29: Frontend Tests | F29: Inspection Tests | G29: important | H29: Current: absent. Build: an e2e that drives the full inspection lifecycle through the HMI. | I29: 1) The loop passes headless. 2) The generated page renders all widgets. 3) No 'could not be loaded' appears anywhere in the flow. | J29: Vision 8 | K29: PPIQ-N020,PPIQ-N021 | L29: Test | M29: 6 | N29: Not Started | O29: 0
A30: N-P6 · The AI Assistant
A31: PPIQ-N023 | B31: Suggestion engine - rule-based, evidence-linked, impact-ranked | C31: N-P6 · The AI Assistant | D31: Track 1 — Workflow | E31: App Backend | F31: Suggestions | G31: very important | H31: Current: prerequisites exist but the engine is absent. Build: a deterministic engine that turns validated findings (+ N008 impact) into ranked, evidence-linked recommendations, gated by tier. | I31: 1) Each suggestion links to its evidence + impact. 2) Ranking is by effect/impact, not p-value. 3) Nothing is emitted without a backing finding. | J31: Vision 3.5.1 | K31: PPIQ-N008,PPIQ-N012 | L31: Feature | M31: 12 | N31: Not Started | O31: 0
A32: PPIQ-N024 | B32: /api/suggestions endpoint + context filtering + license gating | C32: N-P6 · The AI Assistant | D32: Track 1 — Workflow | E32: App Backend | F32: Suggestions | G32: important | H32: Current: absent. Build: a read endpoint with area/defect/time filters, tenant-scoped and tier-gated. | I32: 1) Filters work. 2) Tenants are isolated. 3) Tier gating is enforced and contract-tested. | J32: Vision 3.5.1 | K32: PPIQ-N023,PPIQ-N003 | L32: Feature | M32: 6 | N32: Not Started | O32: 0
A33: PPIQ-N025 | B33: Suggestions & Recommendations page - the proactive feed | C33: N-P6 · The AI Assistant | D33: Track 1 — Workflow | E33: App Frontend | F33: Suggestions | G33: important | H33: Current: absent. Build: a feed UI with drill-through to evidence and the ROI presentation contract. | I33: 1) The feed renders ranked items with citations. 2) Drill-through opens the evidence. 3) Loading/empty/error states are real and recoverable. | J33: Vision 3.5.1 | K33: PPIQ-N024,PPIQ-N010 | L33: Feature | M33: 8 | N33: Not Started | O33: 0
A34: PPIQ-N026 | B34: Complete the knowledge-base ingestion pipeline (findings, cases, docs) | C34: N-P6 · The AI Assistant | D34: Track 1 — Workflow | E34: App Backend | F34: Assistant / KB | G34: important | H34: Current: pgvector + embedding provider exist; the ingestion pipeline is incomplete. Build: ingest findings, saved cases and domain docs into the vector + structured store with provenance, tenant-scoped. | I34: 1) Ingestion is idempotent and tenant-scoped. 2) Chunks carry source provenance. 3) Re-ingest updates cleanly. | J34: Vision 3.5.2 | K34: - | L34: Feature | M34: 10 | N34: Not Started | O34: 0
A35: PPIQ-N027 | B35: Complete the hybrid retrieval pipeline (semantic + structured filters) | C35: N-P6 · The AI Assistant | D35: Track 1 — Workflow | E35: App Backend | F35: Assistant / Retrieval | G35: important | H35: Current: partial. Build: combine semantic search with structured filters (area/defect/time) to select evidence for the agent. | I35: 1) Retrieval respects tenant + filters. 2) Relevance is validated on a fixture set. 3) Latency is bounded. | J35: Vision 3.5.2 | K35: PPIQ-N026 | L35: Feature | M35: 8 | N35: Not Started | O35: 0
A36: PPIQ-N028 | B36: Agent + typed-tool layer (findings, inspection, KPI, genealogy, compare) | C36: N-P6 · The AI Assistant | D36: Track 1 — Workflow | E36: App Backend | F36: Assistant / Agent | G36: very important | H36: Current: absent. Build: an agent that calls typed tools and phrases their structured results; it never computes or invents numbers. | I36: 1) Every figure in an answer traces to a tool result. 2) Tool calls are typed and audited. 3) No free-form math is performed by the model. | J36: Vision 3.5.2 | K36: PPIQ-N027 | L36: Feature | M36: 14 | N36: Not Started | O36: 0
A37: PPIQ-N029 | B37: Conversational assistant UI with citations + drill-through | C37: N-P6 · The AI Assistant | D37: Track 1 — Workflow | E37: App Frontend | F37: Assistant / UI | G37: important | H37: Current: absent. Build: a chat UI rendering answers with inline citations and drill-through to evidence. | I37: 1) Citations resolve to sources. 2) Drill-through works. 3) Loading/error states are real; no fabricated figure passes the grounding guard. | J37: Vision 3.5.2 | K37: PPIQ-N028 | L37: Feature | M37: 10 | N37: Not Started | O37: 0
A38: PPIQ-N030 | B38: Operator feedback loop (useful / acted / dismissed + outcomes) | C38: N-P6 · The AI Assistant | D38: Track 1 — Workflow | E38: App Backend | F38: Assistant / Feedback | G38: normal | H38: Current: absent. Build: capture operator feedback on suggestions/answers and feed it back into the knowledge base as 'experience'. | I38: 1) Feedback is persisted with its outcome. 2) The KB experience updates. 3) It is tenant-scoped and tested. | J38: Vision 3.5.2 | K38: PPIQ-N026,PPIQ-N029 | L38: Feature | M38: 6 | N38: Not Started | O38: 0
A39: PPIQ-N031 | B39: Assistant grounding & honesty-guardrail tests | C39: N-P6 · The AI Assistant | D39: Track 1 — Workflow | E39: Backend Tests | F39: Assistant Tests | G39: very important | H39: Current: absent. Build: tests that the agent never emits a number absent from a tool result/evidence and never uses forbidden vocabulary. | I39: 1) Grounding tests fail on any invented figure. 2) Forbidden-phrase assertions pass. 3) The group runs in CI. | J39: Vision 3 (honesty)/8 | K39: PPIQ-N028 | L39: Test | M39: 8 | N39: Not Started | O39: 0
A40: N-P7 · Workflow & HMI Completion
...

Sheet Phase Plan
A1: Phase Plan — execution order (counts & effort computed live)
A2: # | B2: Phase (execution order) | C2: Tasks | D2: Effort (hrs)
A3: 1 | B3: N-P1 · Security, Access & Trust Closeout | C3: =COUNTIF('v13 Backlog'!$C:$C,$B3) -> 7 | D3: =SUMIF('v13 Backlog'!$C:$C,$B3,'v13 Backlog'!$M:$M) -> 65
A4: 2 | B4: N-P2 · The Value Model | C4: =COUNTIF('v13 Backlog'!$C:$C,$B4) -> 3 | D4: =SUMIF('v13 Backlog'!$C:$C,$B4,'v13 Backlog'!$M:$M) -> 34
A5: 3 | B5: N-P3 · Intelligence Core Completion | C5: =COUNTIF('v13 Backlog'!$C:$C,$B5) -> 5 | D5: =SUMIF('v13 Backlog'!$C:$C,$B5,'v13 Backlog'!$M:$M) -> 58
A6: 4 | B6: N-P4 · Risk Scorer Hardening | C6: =COUNTIF('v13 Backlog'!$C:$C,$B6) -> 3 | D6: =SUMIF('v13 Backlog'!$C:$C,$B6,'v13 Backlog'!$M:$M) -> 32
A7: 5 | B7: N-P5 · Inspection -> Generated Pages | C7: =COUNTIF('v13 Backlog'!$C:$C,$B7) -> 4 | D7: =SUMIF('v13 Backlog'!$C:$C,$B7,'v13 Backlog'!$M:$M) -> 38
A8: 6 | B8: N-P6 · The AI Assistant | C8: =COUNTIF('v13 Backlog'!$C:$C,$B8) -> 9 | D8: =SUMIF('v13 Backlog'!$C:$C,$B8,'v13 Backlog'!$M:$M) -> 82
A9: 7 | B9: N-P7 · Workflow & HMI Completion | C9: =COUNTIF('v13 Backlog'!$C:$C,$B9) -> 6 | D9: =SUMIF('v13 Backlog'!$C:$C,$B9,'v13 Backlog'!$M:$M) -> 46
A10: 8 | B10: N-P8 · Presentation-Grade Hardening (Quality Bar) | C10: =COUNTIF('v13 Backlog'!$C:$C,$B10) -> 13 | D10: =SUMIF('v13 Backlog'!$C:$C,$B10,'v13 Backlog'!$M:$M) -> 109
A11: 9 | B11: N-P9 · Demo Build & Doctrine | C11: =COUNTIF('v13 Backlog'!$C:$C,$B11) -> 10 | D11: =SUMIF('v13 Backlog'!$C:$C,$B11,'v13 Backlog'!$M:$M) -> 68
A12: 10 | B12: N-P10 · Website (Pillar V) | C12: =COUNTIF('v13 Backlog'!$C:$C,$B12) -> 8 | D12: =SUMIF('v13 Backlog'!$C:$C,$B12,'v13 Backlog'!$M:$M) -> 52
A13: 11 | B13: N-P11 · Docs, Legal & Operations | C13: =COUNTIF('v13 Backlog'!$C:$C,$B13) -> 7 | D13: =SUMIF('v13 Backlog'!$C:$C,$B13,'v13 Backlog'!$M:$M) -> 36
B14: TOTAL | C14: =SUM(C3:C13) -> 75 | D14: =SUM(D3:D13) -> 620
B16: By Track
B17: Track | C17: Tasks | D17: Effort (hrs)
B18: Track 1 — Workflow | C18: =COUNTIF('v13 Backlog'!$D:$D,$B18) -> 30 | D18: =SUMIF('v13 Backlog'!$D:$D,$B18,'v13 Backlog'!$M:$M) -> 290
B19: Track 2 — Hardening | C19: =COUNTIF('v13 Backlog'!$D:$D,$B19) -> 27 | D19: =SUMIF('v13 Backlog'!$D:$D,$B19,'v13 Backlog'!$M:$M) -> 210
B20: Track 3 — Demo | C20: =COUNTIF('v13 Backlog'!$D:$D,$B20) -> 10 | D20: =SUMIF('v13 Backlog'!$D:$D,$B20,'v13 Backlog'!$M:$M) -> 68
B21: Track 4 — Website | C21: =COUNTIF('v13 Backlog'!$D:$D,$B21) -> 8 | D21: =SUMIF('v13 Backlog'!$D:$D,$B21,'v13 Backlog'!$M:$M) -> 52

Sheet Coverage Map
A1: Coverage Map — every Vision v2.0 area -> the v13 tasks that complete it
A2: Confirms nothing in the canonical target is unaddressed. 'Already built?' summarises what exists today (see the Excluded sheet).
A3: Vision v2.0 area | B3: What remains (the v13 work) | C3: v13 tasks | D3: Already built?
A4: 2.2.2 DB Link & credentials | B4: Behavioural connector tests + masked-credential proof | C4: N045 | D4: Core built
A5: 2.2.3 Two-stage / delta ingestion | B5: Schema-drift detection; resumability tests | C5: N032, N047 | D5: Engine built
A6: 2.2.4 Schema mapping engine | B6: Typed resolver errors (full UI design lives in v3 3.3) | C6: N033 | D6: Core + safe-SQL built
A7: 2.2.5 Genealogy spine | B7: Mapping-authored canonical spine, both directions | C7: N034 | D7: Partial join built
A8: 2.2.6 Jobs Monitor | B8: Extended result + learning-run visibility | C8: N014, N021 | D8: Monitor built
A9: 2.3 Page builder & widgets | B9: First-run wizard; heat-map widget; script grammar | C9: N035, N036, N037 | D9: Builder + script layer built
A10: 3.1 Feature store & outcomes | B10: (complete - no remaining work) | C10: - | D10: Built incl. cascade-downtime
A11: 3.2 Scheduled learning & methods | B11: Spearman/MI/Lasso; VIF/stability/confounding; gates; results; tests | C11: N011-N015 | D11: Pearson/PB/Cramer + FDR/effect/power built
A12: 3.3 Inspection -> generated pages | B12: Runner; auto-page generation; scheduling; e2e | C12: N019-N022 | D12: Investigate endpoint built
A13: 3.4 Risk scorer | B13: Calibration; registry provenance; drift/champion-challenger | C13: N016-N018 | D13: Additive decomposable scorer built
A14: 3.5.1 Proactive suggestions | B14: Engine; endpoint; proactive feed UI | C14: N023-N025 | D14: Prerequisites built
... A22: Value Model (commercial lever) | B22: Impact engine; cost config; ROI presentation contract | C22: N008-N010 | D22: Nothing built (0 code hits)

Sheet Excluded - Already Built
A1: Excluded from v13 — already built (the audit trail for 'no done tasks')
A2: These capabilities exist in the 31-May snapshot, so they are intentionally NOT in the backlog. Listed for transparency.
A3: Capability (excluded) | B3: Evidence / where it lives | C3: Prior ref
A4: Test foundation, coverage baseline & CI gate | B4: dotnet + vitest coverage; suite is red-on-regression and gated | C4: T300-T306
A5: Auth config-section prefix + bootstrap-collision guard | B5: StartupConfigurationValidator rejects DEV keys / default pw outside Dev | C5: T282
A6: Frontend auth retry backoff + attempt cap | B6: apiClient with bounded retry | C6: T280
A7: PostgreSQL public port closed + loopback audit | B7: 127.0.0.1 binding + external nmap scan guard | C7: T286 / T208
A8: Replace bootstrap admin in production | B8: disabled sentinel + real seeded admin | C8: T287
A9: Eight-source Compose definition (loopback-bound) | B9: docker-compose.demo-sources.yml | C9: T245
A10: SafeSqlValidator + typed resolver base | B10: SafeSqlValidator (CTE fix); SchemaViewResolver base | C10: T206
A11: Widget edit -> DB values + script-layer base | B11: widget builder binding | C11: T242
A12: Multi-grain feature store (heat/strand/coil/location) | B12: feature-store schema | C12: T209
A13: Metallurgical derived features | B13: FeatureEngineeringService | C13: T210
A14: Outcome catalog incl. cascade-downtime + KPI-as-view | B14: outcome definitions | C14: T211 / T293
... A23: Frontend resilience base | B23: global ErrorBoundary, Sonner toasts, apiClient timeouts/retry, skeleton loading | C23: prior session
