Workbook

Sheet Task List
A1: PlantProcess IQ — Phase-Grouped Task List (v9 · 31 May 2026 · test-foundation + deepened engineering plan)
A2: 103 tasks across 14 phases (adds Phase 0 — Test Foundation: 8 tasks). v9 deepens the plan into a rigorous engineering programme: a trustworthy, behaviour-true test suite is built FIRST (audit/repair/cover/gate every backend unit, frontend unit, integration, and e2e test, and convert behavioural validation scripts into real tests — see the Test Register sheet), then the feature/hardening phases proceed on a suite that gates regressions. Single authoritative Description + Validation per task; Status/Completion% retained; IDs stable; execution order = row order.
A4: Task ID | B4: Task Name | C4: Phase ID | D4: Severity | E4: Track | F4: Module | G4: Submodule | H4: Description | I4: Task Type | J4: Validation | K4: Status | L4: Completion % | M4: Effort (hrs)
A5: P00 — Test Foundation: Audit, Repair, Cover & Gate | 8 tasks | 67 hrs PRIORITY ZERO — the trust layer the rest of v9 stands on. You cannot harden, enhance, or ship confidently on a suite that does not reflect reality. This phase scans every backend unit, frontend unit, integration, and e2e test plus all validation scripts; deletes the no-ops and duplicates; repairs the stale/brittle ones so they assert REAL behaviour at the current status; adds tests for every uncovered critical area; converts behavioural validation scripts into real tests; and finally turns the trustworthy suite into a red-on-regression gate with a coverage ratchet. EXIT STATE (healthy): one command per stack runs a deterministic suite that mirrors real behaviour, coverage is measured and ratcheted, the suite gates CI, and the Test Register records every delete/modify/add decision.
A6: PPIQ-T300 | B6: Establish the test taxonomy, coverage baseline & CI reporting spine | C6: P00 | D6: critical | E6: Track 2 — Hardening | F6: Infrastructure | G6: Test Strategy / Coverage | H6: FOUNDATION for everything that follows. Before changing individual tests, stand up the measurement and reporting spine so 'tested' becomes verifiable, not asserted. WORK: (1) Define the test taxonomy and what each layer owns: Domain unit (pure logic, no IO), Application unit (services with mocked ports), Infrastructure integration (real Postgres via Testcontainers/compose, connectors, audit immutability), API integration (WebApplicationFactory + real DB, auth, endpoints), Frontend unit (Vitest: components/hooks/state/api-clients), Frontend e2e (Playwright: real flows), Visual + a11y (Playwright). (2) Turn on coverage collection on both stacks — .NET via coverlet/`--collect:"XPlat Code Coverage"` with a Cobertura report, frontend via Vitest V8 coverage — and publish both as CI artifacts with a coverage summary. (3) Establish a baseline number per layer and per critical module (auth, connectors, schema-mapping, delta-import, ML learning core, risk scorer, page builder) and record it as the Phase-0 starting point. (4) Make the whole suite runnable with one command per stack and wire both into Jenkins as reported (not yet gating) stages. | I6: Enhancement | J6: 1) `dotnet test` produces a Cobertura coverage report and `npm run test:coverage` produces a V8 report, both archived in CI. 2) A coverage summary table (per project + per critical module) is generated and stored as the Phase-0 baseline. 3) The taxonomy is documented (one paragraph per layer: what it owns, what it must NOT do). 4) One command runs each stack's full suite locally and in CI. | K6: Not Started | L6: 0 | M6: 6
A7: PPIQ-T301 | B7: Audit & triage every existing test against the real 31-May behaviour (the Test Register) | C7: P00 | D7: critical | E7: Track 2 — Hardening | F7: Infrastructure | G7: Test Audit / Triage | H7: Produce and execute the authoritative triage of all ~26 backend tests, ~17 frontend unit/integration tests, and ~35 e2e specs against the CURRENT application behaviour. The companion 'Test Register' sheet in this workbook is the line-by-line output of this task and its execution checklist. WORK: For each existing test, classify it as DELETE (obsolete, duplicated, or a no-op smoke), MODIFY (real intent but stale assertions, weak coverage, brittle selectors, or testing a mock instead of behaviour), or KEEP (already a strong, behaviour-true test). Specifically: remove the four `*TestEnvironmentTests` no-ops (`true.Should().BeTrue()`) once real coverage exists in their project; collapse overlapping phase-N e2e specs (phase1-*, phase2-*, phase56-*, phase78-*) that assert the same routes/flows into consolidated, behaviour-named specs; and upgrade thin specs (8–33 line placeholders such as phase02-data-lifecycle-contract, page-builder-v7, phase56-primary-flows, route-smoke) into real assertions. Each MODIFY entry states exactly what changes and why; each DELETE entry states what now covers it. | I7: Enhancement | J7: 1) Every existing test file has a recorded disposition (DELETE / MODIFY / KEEP) with a one-line rationale (see the Test Register). 2) All DELETE items are removed and the suite still builds and passes. 3) No remaining `true.Should().BeTrue()`-style no-op survives. 4) The count of overlapping phase-N e2e specs is reduced and the survivors are named by behaviour, not phase number. | K7: Not Started | L7: 0 | M7: 8
A8: PPIQ-T302 | B8: Backend unit coverage for uncovered Application/Domain logic | C8: P00 | D8: very important | E8: Track 2 — Hardening | F8: App Backend | G8: Unit Tests / Application & Domain | H8: Close the backend UNIT gaps for pure logic that today has no coverage, matching real behaviour as of 31-May. TARGET (uncovered or thin today): the additive RiskScoreService contribution decomposition (contributions sum exactly to the score; explanation shape); FeatureEngineeringService derived-feature math (cev, true_superheat, casting speed delta, residency, shift bucketing) on known inputs; QualityLabelBuilderService label derivation; MlReadinessService gate logic (ready vs under-powered thresholds); the SafeSql policy edge cases beyond what SafeSqlPolicyTests covers (CTE, nested subqueries, cross-tenant attempts); WidgetQueryExpressionService expression validation/safety; LicenseService tier-feature resolution corner cases. Use deterministic fixtures; no database (those belong to integration). | I8: New Feature | J8: 1) RiskScoreService has a unit test proving exact additive decomposition on a known vector. 2) FeatureEngineeringService derived features are asserted against hand-computed expected values. 3) MlReadinessService gate thresholds are covered both sides of the boundary. 4) New SafeSql cases (CTE/nested/cross-tenant) are rejected. 5) Coverage for the Application project rises measurably above the T300 baseline. | K8: Not Started | L8: 0 | M8: 10
A9: PPIQ-T303 | B9: Backend integration tests on real Postgres for data, ML, and security paths | C9: P00 | D9: very important | E9: Track 2 — Hardening | F9: App Backend | G9: Integration Tests / Postgres | H9: Add API + Infrastructure INTEGRATION tests that run against a real Postgres (Testcontainers or the demo compose) so the data lifecycle, the ML core, and security are proven end-to-end, not by source-text regex. TARGET: (1) ML learning core — apply 200_/201_/204_, run `ppiq_ml_seed_phase45_golden_dataset()` then `ppiq_ml_run_learning_job_v1`, and assert it RECOVERS the injected correlations with correct effect-size sign/magnitude, produces Benjamini-Hochberg q-values, and REJECTS spurious pairs under FDR (this replaces the static validate-v7-phase04-phase05 checks with behaviour). (2) Delta import — cold load then incremental, simulated mid-batch crash → resume with no duplicates, schema-drift detection. (3) Schema-mapping resolver — the three named errors (NoSuchView/NoSuchColumn/InvalidAggregateForType) and SafeSqlValidator blocking on generated join SQL, against a live schema. (4) Auth — login gate matrix (empty/bootstrap-collision/valid/role/bad-key) at the API. (5) Audit-log immutability already has a strong test — keep and extend with the new audit surfaces. | I9: New Feature | J9: 1) An integration test runs the ML learning job on the golden dataset and asserts recovery + FDR rejection (no regex on SQL text). 2) Delta-import crash/resume yields zero duplicates and a correct cursor. 3) Resolver returns the three typed errors and blocks malicious join SQL. 4) The auth gate matrix is asserted at the API with a real token. 5) These run in CI against a real Postgres. | K9: Not Started | L9: 0 | M9: 12
A10: PPIQ-T304 | B10: Frontend unit/component coverage for uncovered UI logic & Standard* contract | C10: P00 | D10: very important | E10: Track 2 — Hardening | F10: App Frontend | G10: Unit Tests / Vitest | H10: Close frontend UNIT gaps with Vitest, matching real component behaviour. Today only a handful of components/hooks are covered. TARGET: the apiClient retry/backoff + auth-failure mapping (T280/T281 behaviour — assert bounded attempts and that 401/403/500/network produce distinct outcomes); AuthContext bootstrap logic (no infinite re-login on failure); the LicenseContext tier gating; the full Standard* contract (StandardButton/Table/Tabs/Fields/Surface/DataFetchBoundary/ErrorBoundary — every variant and state in the UI Standards Reference, including the forbidden-phrase guard and the 'Refreshing X…' pattern); the widget-builder expression step validation; and the page-builder layout state reducer. Mock the network at the boundary; do not hit a real API. | I10: New Feature | J10: 1) apiClient tests prove retries are capped with backoff and that each HTTP status maps to its intended outcome. 2) AuthContext cannot enter an infinite re-login loop on a failing bootstrap. 3) Every Standard* component has variant+state coverage and a snapshot where appropriate. 4) The forbidden-phrase guard is unit-asserted. 5) Frontend coverage rises measurably above the T300 baseline. | K10: Not Started | L10: 0 | M10: 10
A11: PPIQ-T305 | B11: E2E coverage for the real critical journeys (consolidated, behaviour-named) | C11: P00 | D11: very important | E11: Track 2 — Hardening | F11: App Frontend | G11: E2E / Playwright | H11: Rebuild the e2e layer around the REAL critical journeys, consolidating the overlapping phase-N specs into durable, behaviour-named flows and adding the journeys that are missing. TARGET JOURNEYS (each from a clean login, no hardcoding): (a) Auth & shell — login as each persona, route-refresh survival, no fake 'connection failed'. (b) Data lifecycle — configure a DB link from the HMI → schedule a job → import → see data (the Track-3 Golden-Rule flow). (c) Page builder — create a page, drop+bind+script a widget, save, reload, it persists. (d) Inspection→analysis — run an inspection job and view its generated page (once P06 lands). (e) License toggle — switch Enterprise→Pro and watch a feature disappear. (f) Resilience — backend-outage handling shows retry UI, never a fake failure. Consolidate phase1-*/phase2-*/phase56-* duplicates into these. Keep auth-matrix, golden-path, dashboard-refresh-filter, hardening-matrix as the strong survivors and align them. | I11: New Feature | J11: 1) Each critical journey has exactly one authoritative, behaviour-named spec that runs green against the real app. 2) The data-lifecycle and page-builder journeys configure everything from the HMI (no hardcoded pages/data). 3) Overlapping phase-N specs are removed or merged; the e2e suite is smaller and clearer. 4) The suite runs in CI on chromium (and the responsive/multibrowser spec covers the rest). | K11: Not Started | L11: 0 | M11: 10
A12: PPIQ-T306 | B12: Convert behavioural validation scripts into real tests; keep structural ones as gates | C12: P00 | D12: important | E12: Track 2 — Hardening | F12: Infrastructure | G12: Validation → Test Migration | H12: Resolve the ~25 validation scripts (tools/validation/*, scripts/*.mjs, Frontend tools/*) into the test suite. The principle: a script that asserts BEHAVIOUR becomes a real test; a script that only checks file/structure stays a lightweight CI gate. WORK (see the Test Register for the per-script decision): (1) TRANSFER-TO-TEST the behavioural validators — e.g. validate-v7-phase04-phase05-acceptance (→ the ML integration test in T303), validate-t208-exposure (→ a deploy/network test or scripted scan), validate-api-client-policy / validate-standard-imports / validate-forbidden-copy / validate-no-console-in-src (→ Vitest+ESLint rules already partly exist; make them assertions), validate-sql-script-hygiene (→ an integration test that applies all scripts under ON_ERROR_STOP=1 on a fresh DB and asserts BOM-free + clean apply). (2) KEEP-AS-GATE the pure structure/acceptance file-existence scripts, but point each at the real test it now corresponds to so they stop being the sole source of truth. (3) RETIRE superseded per-phase acceptance scripts whose intent is fully covered by a real test. | I12: Enhancement | J12: 1) Every behavioural validator has either become a real test or is explicitly retired with its replacement named (Test Register). 2) The ML, exposure, and SQL-hygiene checks now run as real tests, not source-text regex. 3) Remaining validators are pure structure gates and are documented as such. 4) CI references the tests, not the scripts, for behavioural truth. | K12: Not Started | L12: 0 | M12: 6
A13: PPIQ-T307 | B13: Make the suite the gate: deterministic, fast, and red-on-regression | C13: P00 | D13: important | E13: Track 2 — Hardening | F13: Infrastructure | G13: CI / Test Gating | H13: Turn the now-trustworthy suite into the enforcement mechanism for the rest of v9, so later phases cannot silently regress. WORK: (1) Promote the reported stages from T300 to GATING — unit (both stacks) and the fast integration/e2e subset must pass for a green build; the heavy e2e/visual set runs nightly. (2) Stabilise flakiness: deterministic seeds, fixed Playwright waits (no arbitrary sleeps), Testcontainers lifecycle, and a quarantine lane for any genuinely flaky spec with an owner. (3) Set a coverage RATCHET (coverage may not drop below the T300 baseline; new critical modules require their own tests). (4) Document the contributor workflow: how to run, where tests live per layer, and the rule that a feature task is not Done until its tests are green. | I13: Enhancement | J13: 1) A failing unit/integration/fast-e2e test turns the build red and blocks merge. 2) The suite is deterministic across 3 consecutive CI runs (no flakes outside the quarantine lane). 3) Coverage cannot regress below the baseline (ratchet enforced). 4) The contributor testing workflow is documented and referenced from the UI-Standards onboarding. | K13: Not Started | L13: 0 | M13: 5
A14: P01 — Stabilize: Build-Green, Auth & Deploy Reliability | 14 tasks | 26 hrs FOUNDATION — highest priority and demo-protection. The app must build in CI, migrate cleanly, start reliably, log in deterministically, and expose nothing it shouldn't. This phase bundles the build-green hotfixes with EVERY auth/deploy/network bug surfaced during the login & deployment saga, so the whole reliability story lands together (not scattered across later phases). EXIT STATE (healthy): a green pipeline end-to-end; a fresh machine one-shots to a working admin login; the server has no public database port; and StartupConfigurationValidator blocks dev secrets under Production.
A15: PPIQ-T201 | B15: Fix Jenkins npm build failure (Node unavailable, exit 127) | C15: P01 | D15: critical | E15: Track 2 — Hardening | F15: Infrastructure | G15: CI / Build Agent | H15: ALREADY IN PLACE (30-May audit): Jenkinsfile runs UI gates inside node:20-alpine (npm ci + validate:phase5-phase6:strict); self-check check('PPIQ-T201',/node:20/). This capability is implemented — the task here is to CONFIRM it, not rebuild it. Reference scope / behaviour: The pipeline still fails at stage '2b. Phase 5/6 UI quality gates' with 'npm: not found' (exit 127): npm ci runs directly on `agent any` with no Node runtime. Run the UI gates inside a Node container (docker run --rm -v "$PWD":/app -w /app node:20-alpine sh -c 'npm ci && npm run validate:phase5-phase6:strict ...'), OR configure the Jenkins NodeJS tool ('node20') and wrap the stage in tools{ nodejs 'node20' }, OR install Node on the agent and ensure it is on the non-interactive PATH. Stages 3-5 must stop being skipped. | I15: Bug Fix | J15: Confirm (do NOT re-implement): 1) A full pipeline run reaches 'Build images' and 'Recreate containers' without the npm step failing. 2) `npm ci` and the validate/test:visual/test:a11y scripts run with a pinned Node 20. 3) A green build is produced end to end. 4) The fix is committed in the Jenkinsfile, not applied ad hoc on the agent. | K15: Done | L15: 1 | M15: 2
A16: PPIQ-T202 | B16: Reconcile migration 117 audit-table schema (still broken) | C16: P01 | D16: critical | E16: Track 2 — Hardening | F16: Database | G16: Migration / Widget Audit | H16: ALREADY IN PLACE (30-May audit): Script 117 (mod 30-May 16:18) now DROP TABLE IF EXISTS dashboard_widget_expression_audit then CREATE with created_at_utc + canonical EF columns + 2 indexes + verification SELECT. This capability is implemented — the task here is to CONFIRM it, not rebuild it. Reference scope / behaviour: Script 117 still uses CREATE TABLE IF NOT EXISTS for dashboard_widget_expression_audit with created_at_utc, but 113 already created that table with executed_at_utc — so IF NOT EXISTS is a no-op, created_at_utc never lands, and the index on it fails (silently, under ON_ERROR_STOP=0). The audit layer is on the stale schema. Replace 117's body with DROP TABLE IF EXISTS dashboard_widget_expression_audit; then CREATE TABLE with the EF-entity schema (id, dashboard_widget_definition_id, expression_version smallint, validation_status smallint, validation_message, query_expression, advanced_expression_json jsonb, created_at_utc) + the index. Make 113 and 117 not both CREATE the same table (113 becomes guard-only or canonical). Apply on the Hetzner staging clone. | I16: Bug Fix | J16: Confirm (do NOT re-implement): 1) Fresh Postgres 17 + ordered scripts apply with zero errors and the audit table has created_at_utc. 2) Re-apply on the staging clone is clean. 3) EF reads/writes against the audit table succeed (smallint enum + created_at_utc). 4) Exactly one migration CREATEs the table. | K16: Done | L16: 1 | M16: 2
A17: PPIQ-T203 | B17: Switch SQL migration runner to ON_ERROR_STOP=1 | C17: P01 | D17: very important | E17: Track 2 — Hardening | F17: Infrastructure | G17: CI / Migration Safety | H17: ALREADY IN PLACE (30-May audit): Jenkins 'Apply SQL scripts' stage uses psql -v ON_ERROR_STOP=1; self-check check('PPIQ-T203',/ON_ERROR_STOP=1/). PS verify scripts also use it. This capability is implemented — the task here is to CONFIRM it, not rebuild it. Reference scope / behaviour: The Jenkins 'Apply SQL scripts' stage runs psql with ON_ERROR_STOP=0, so a rolled-back migration (e.g. 117) reports success and the deploy proceeds onto a half-migrated schema. After T202 is fixed, change the runner to ON_ERROR_STOP=1 so any failing migration fails the build loudly. Audit the existing scripts first to ensure none rely on the permissive mode. | I17: Bug Fix | J17: Confirm (do NOT re-implement): 1) Runner uses ON_ERROR_STOP=1. 2) A deliberately broken script in a scratch branch turns the build red at the migration stage. 3) The full ordered script set still applies clean on a fresh DB and on staging. 4) No script depends on error-swallowing. | K17: Done | L17: 1 | M17: 1.5
A18: PPIQ-T288 | B18: Investigate the SQL syntax error seen during script application | C18: P01 | D18: normal | E18: Track 2 — Hardening | F18: Database | G18: Migration / Script Hygiene | H18: STARTING POINT (31-May audit — already built): 202_/203_ ML compute hotfix scripts added (the earlier compute stub/syntax issues addressed); BOM guard intent present. WHAT REMAINS — the actual work of this task: Confirm the full ordered script set applies clean under ON_ERROR_STOP=1 on fresh + staging; add the CI BOM guard if not yet enforced. FULL REFERENCE SPEC: A SQL syntax error was observed during one script-application run (flagged in the prior deploy session, separate from the 117 audit-table fix). Locate the offending statement, fix it, and ensure the full ordered script set applies cleanly under ON_ERROR_STOP=1 on a fresh DB and on the staging clone. Add the BOM-guard so re-introduced BOMs (recurred 3x) can't silently break a script again. | I18: Bug Fix | J18: 1) The specific syntax error is identified and fixed. 2) Full ordered scripts apply with zero errors on fresh + staging under ON_ERROR_STOP=1. 3) BOM guard in CI rejects any script with a UTF-8 BOM. 4) The previously BOM-stripped files (116 sql, vite.config.ts) are committed. | K18: Partial | L18: 0.6 | M18: 2
A19: PPIQ-T205 | B19: Verify standard-import ESLint block is an enforced Jenkins gate | C19: P01 | D19: important | E19: Track 2 — Hardening | F19: Infrastructure | G19: CI / Quality Gate | H19: ALREADY IN PLACE (30-May audit): validate-forbidden-copy + non-standard-import sweeps wired in Jenkins stage 2c; self-check asserts forbidden-phrase guard and Standard* enforcement; eslint config contains the rule. This capability is implemented — the task here is to CONFIRM it, not rebuild it. Reference scope / behaviour: Closes the residual of v4 PPIQ-T106. The forbidden-phrase sweep and auth-matrix are referenced in Jenkins stage 2c, but confirm the non-standard-import rule (no native <button>/<input>/<select>/<table>/<textarea> in src/pages|features; no import from src/hardening/*) actually fails the build, not just warns. Wire pnpm/npm lint as a failing stage with a clear offender list and canonical-replacement hint; add the pre-commit hook. | I19: Enhancement | J19: Confirm (do NOT re-implement): 1) A native <button> in src/pages/* fails the build naming the file + replacement. 2) An import from src/hardening/* fails lint. 3) Stage runs on every push. 4) Pre-commit blocks locally. | K19: Done | L19: 0.9 | M19: 1.5
A20: PPIQ-T282 | B20: Auth config-section prefix + bootstrap-collision: lock in & guard | C20: P01 | D20: important | E20: Track 2 — Hardening | F20: App Backend | G20: Auth / Configuration | H20: ALREADY IN PLACE (31-May audit): StartupConfigurationValidator.cs (435L) validates PlantProcess:Auth binding, REJECTS legacy Auth:* keys with a fix hint, checks SigningKey>=32, Issuer/Audience, and bootstrap config. This capability is implemented — CONFIRM it, do not rebuild. Reference scope / behaviour: WORK: add a startup self-check (no secret leakage) that logs once: the section it bound from, the resolved Users count, whether SigningKey is present and >=32 chars, and whether any Users[].Password equals BootstrapAdminPassword (WARN loudly if so). This converts the two silent failure modes into a loud, one-line startup signal. | I20: Bug Fix | J20: Confirm (do NOT re-implement): Confirm the startup self-check log line and the bootstrap-collision warning fire on a real boot. | K20: Done | L20: 1 | M20: 2
A21: PPIQ-T280 | B21: Frontend auth-failure retry storm: add backoff + attempt cap | C21: P01 | D21: very important | E21: Track 2 — Hardening | F21: App Frontend | G21: Auth / AuthContext | H21: ALREADY IN PLACE (31-May audit): apiClient: AUTH_RETRY_BACKOFF_MS=[0,500,1500], maxAttempts cap, retryable-only; comment '// PPIQ-T280: auth-failure retry storm capped with backoff'. This capability is implemented — CONFIRM it, do not rebuild. Reference scope / behaviour: AuthContext.tsx auto-logs-in on mount with VITE_SMOKE_* and registers a window 'plantprocess:auth-failure' listener that calls bootstrap() again. apiClient.dispatchAuthFailure fires that event on EVERY non-2xx. When the auto-login itself returns 401/403, the listener re-triggers the failing login, producing an unbounded POST /auth/login storm (observed: thousands of identical requests flooding the API log) and a stuck 'Backend connection failed' screen. Add an attempt cap + exponential backoff, and do NOT let a failure of the bootstrap login itself re-dispatch auth-failure (guard against self-retrigger). | I21: Bug Fix | J21: Confirm (do NOT re-implement): Confirm a failing auto-login produces <=3 attempts then stops (no /auth/login storm) via test. | K21: Done | L21: 0.9 | M21: 3
A22: PPIQ-T281 | B22: Frontend mislabels all non-2xx + network errors as 'Backend connection failed' | C22: P01 | D22: very important | E22: Track 2 — Hardening | F22: App Frontend | G22: Auth / Error Surfacing | H22: STARTING POINT (31-May audit — already built): apiClient maps 401/403 to a typed auth-failure event distinct from network; status carried through. Full per-status user-facing copy not fully confirmed. WHAT REMAINS — the actual work of this task: Confirm 401 vs 403 vs 500 vs network each render a DISTINCT message in the login/bootstrap UI. FULL REFERENCE SPEC: The login/bootstrap path renders one generic 'Cannot reach the backend API' screen for 401 (wrong creds), 403 (bootstrap blocked), 500 (server/config) and true network failures alike. During the login saga this hid the real cause for hours: backend returned 401/403/500 in sequence and the UI showed the identical red screen each time. Surface the real status: 401 -> invalid credentials, 403 -> bootstrap admin disabled / use a real admin, 500 -> show Problem detail, network/abort (status 0) -> unreachable. This is the founder's Vision §2 'never show a fake failure' rule applied to auth. | I22: Bug Fix | J22: 1) 401 shows an invalid-credentials message distinct from a network-unreachable message. 2) 403 shows the bootstrap-disabled explanation. 3) 500 surfaces the backend Problem detail. 4) Only a true fetch/abort error shows 'cannot reach backend'. 5) Covered by tests mapping status->message. | K22: Partial | L22: 0.6 | M22: 2.5
A23: PPIQ-T285 | B23: Frontend VITE_SMOKE_PASSWORD must equal backend admin password (env contract) | C23: P01 | D23: important | E23: Track 2 — Hardening | F23: App Frontend | G23: Auth / Env Contract | H23: ALREADY IN PLACE (31-May audit): Auth-matrix + smoke use PPIQ_SMOKE_PASSWORD/PPIQ_ADMIN_PASSWORD env contract; .env docs updated; CI passes creds through. This capability is implemented — CONFIRM it, do not rebuild. Reference scope / behaviour: Because the app auto-logs-in as admin using VITE_SMOKE_PASSWORD (.env.local, highest Vite precedence), a mismatch between that value and the backend Users[0] admin password causes a permanent 401 + the connection-failed screen even when the backend is correct. Add a documented env contract and a dev-time guard: a tiny check (script or startup console.warn) that flags when the configured smoke password is the literal placeholder/empty, and document that .env.local VITE_SMOKE_PASSWORD must match the backend admin password. Longer term (post-demo) replace silent auto-login with an explicit login form fallback when bootstrap fails. | I23: Bug Fix | J23: Confirm (do NOT re-implement): Confirm the dev-time guard warns on empty/placeholder VITE_SMOKE_PASSWORD; optional manual-login fallback on bootstrap 401. | K23: Done | L23: 0.85 | M23: 1.5
A24: PPIQ-T283 | B24: SQL apply NOTICE-abort bug in dev-bootstrap.ps1 (idempotent re-run fails) | C24: P01 | D24: important | E24: Track 2 — Hardening | F24: Infrastructure | G24: Dev Bootstrap / Migration | H24: ALREADY IN PLACE (31-May audit): tools/phase23/fix-legacy-auth-config-files.cjs migrates stale Auth:* config; StartupConfigurationValidator blocks the legacy keys going forward. This capability is implemented — CONFIRM it, do not rebuild. Reference scope / behaviour: dev-bootstrap.ps1 Invoke-PsqlFile runs psql with 2>&1 while $ErrorActionPreference='Stop', so a benign psql NOTICE (e.g. 'relation already exists, skipping' from idempotent script 050) is treated as a terminating error and aborts the whole bootstrap on a second run. Fix: set local client_min_messages=warning for the psql invocation and use a local $ErrorActionPreference='Continue' (or -StopOnSqlError opt-in) so NOTICEs don't abort. Also correct the script's user-secrets paths to the PlantProcess:Auth prefix (incl. SigningKey) so a fresh machine truly one-shots login. | I24: Bug Fix | J24: Confirm (do NOT re-implement): Confirm dev-bootstrap.ps1 idempotent re-run (no NOTICE-abort) end-to-end on a clean machine. | K24: Done | L24: 0.9 | M24: 2
A25: PPIQ-T284 | B25: Kill-by-PORT not by process name in dev/runbook scripts | C25: P01 | D25: important | E25: Track 2 — Hardening | F25: Infrastructure | G25: Dev Tooling / Runbook | H25: ALREADY IN PLACE (31-May audit): tools/dev/Stop-PPIQ-Port.ps1 + Show-PPIQ-PortOwner.ps1 free :5063/:5173 by OwningProcess (Get-NetTCPConnection) and report the new listener. This capability is implemented — CONFIRM it, do not rebuild. Reference scope / behaviour: Stop/relaunch scripts filtered Get-CimInstance for Name='dotnet.exe' matching PlantProcess.Api. But 'dotnet run' builds an apphost and the process actually listening on :5063 is PlantProcess.Api.exe (a child), so the filter never killed the real listener — every config change 'didn't take' because a stale server kept answering on the port. Standardize all dev/runbook scripts to free the port by OwningProcess (Get-NetTCPConnection -LocalPort) and verify the new listener's StartTime, so a restart provably replaces the process. | I25: Bug Fix | J25: Confirm (do NOT re-implement): Confirm both scripts print the fresh PID+StartTime after a restart. | K25: Done | L25: 1 | M25: 1.5
A26: PPIQ-T286 | B26: Verify PostgreSQL public port is closed on the live server (deploy regression) | C26: P01 | D26: very important | E26: Track 2 — Hardening | F26: Infrastructure | G26: Deployment / Network | H26: ALREADY IN PLACE (31-May audit): Infrastructure/deploy/verify-server-exposure.sh + rotate-postgres-password.sh exist; compose keeps Postgres off 0.0.0.0; README documents nmap proof. This capability is implemented — CONFIRM it, do not rebuild. Reference scope / behaviour: During deployment the server's PostgreSQL port was publicly exposed (the DB container published 5432 to the host/internet). Confirm the live Hetzner stack binds Postgres to the internal Docker network only (no host port publish, or bound to 127.0.0.1), rotate the DB password if it was exposed, and capture an external scan proving 5432 is not reachable from the internet. Distinct from T208 (loopback audit of ALL services) — this is the specific, already-observed Postgres exposure. | I26: Bug Fix | J26: Confirm (do NOT re-implement): Run verify-server-exposure.sh against the live host and attach the scan output. | K26: Done | L26: 0.9 | M26: 1.5
... A28: PPIQ-T208 | B28: Finish loopback-binding audit for all infra services + external scan proof | C28: P01 | D28: important | E28: Track 2 — Hardening | F28: Infrastructure | G28: Docker Compose / Network Exposure | H28: ALREADY IN PLACE (31-May audit): tools/validation/validate-t208-exposure.cjs + Infrastructure/deploy/README.md documents 'nmap -Pn 178.105.152.180' loopback proof; demo compose internal-only. This capability is implemented — CONFIRM it, do not rebuild. Reference scope / behaviour: Closes residual of v4 PPIQ-T105 (only Postgres proven on 127.0.0.1). Audit redis, seq, jaeger, grafana, prometheus, jenkins, workers in docker-compose.demo.yml; bind each published port to 127.0.0.1 unless intentionally public (Caddy 80/443; Jenkins :9090 behind basicauth). Prove with an external nmap and document each decision in Infrastructure/deploy/README.md. | I28: Bug Fix | J28: Confirm (do NOT re-implement): Attach the actual external scan result; confirm only 80/443 reachable. | K28: Done | L28: 0.85 | M28: 1.5
A29: P02 — Data Lifecycle: Sources, Ingestion, Mapping & Genealogy | 8 tasks | 41 hrs The generic data-in backbone AND the substrate the whole demo runs on. Stand up the eight realistic source systems, split the coherent dataset across them, harden the mapping resolver/joins, build the heat->ladle->tundish->strand->slab->coil genealogy spine via the mapping engine (no hardcoding), then verify every connector against the live sources and make delta-import resumable. EXIT STATE (healthy): from the HMI you can connect to and import from all eight sources, map them into the generic schema, and resolve any coil back to its melt/cast conditions and forward to its defects/QA.
A30: PPIQ-T245 | B30: docker-compose.demo-sources.yml — eight source systems (loopback-bound) | C30: P02 | D30: very important | E30: Track 3 — Demo | F30: Infrastructure | G30: Demo Sources / Compose | H30: ALREADY IN PLACE (31-May audit): docker-compose.demo-sources.yml (151L): meltshop-postgres, caster-oracle, hsm-oracle, pkl-mssql, downtime-mysql, parsytec-mysql + per-source init SQL under Infrastructure/demo-sources/*. This capability is implemented — CONFIRM it, do not rebuild. Reference scope / behaviour: Author docker-compose.demo-sources.yml standing up the eight source systems from the Vision: Postgres MeltShop (EAF/LF), Oracle Caster, Oracle HSM, MSSQL PKL, Excel Yard, MySQL Downtime, MySQL Parsytec surface-inspection, and Excel QA. Every service is bound to loopback / the internal Docker network only (consistent with the network-hardening in P01) and seeded with realistic schemas matching the Vision's table descriptions so the app must connect to genuinely heterogeneous sources. | I30: New Feature | J30: Confirm (do NOT re-implement): Confirm all services come up healthy and none publish to 0.0.0.0; add the remaining Excel (Yard/QA) sources or document them as file drops. | K30: Done | L30: 0.9 | M30: 6
A31: PPIQ-T246 | B31: Split the existing coherent dataset across the eight source systems | C31: P02 | D31: very important | E31: Track 3 — Demo | F31: Database | G31: Demo Sources / Seed Distribution | H31: STARTING POINT (31-May audit — already built): Per-source init/001_schema_seed.sql under Infrastructure/demo-sources/* + synthetic_inspection_source_insert.sql (6601L) splitting inspection data into the source shape. WHAT REMAINS — the actual work of this task: Finish splitting ALL of the coherent dataset across the 8 sources so it must be re-joined via the mapping engine; verify row coherence across sources. FULL REFERENCE SPEC: The single-DB seed already produces vision-scale volumes (630 heats, 5,670 slabs/coils, ~40k HSM measurements, ~17k QA results, ~210 downtime events — 100k+ rows). The remaining work is distributing this SAME coherent, genealogy-linked data across the eight separate source containers (per their native structures) so the demo is configured LIVE from the HMI per the Track-3 golden rule. Preserve end-to-end genealogy across systems. | I31: Enhancement | J31: 1) Each source container is seeded with its slice in its native structure. 2) Material ADV_COIL4002 traces end-to-end across every system incl. a downtime and a QA sample. 3) Re-seeding is idempotent. 4) Total volume preserved (100k+ rows). | K31: Partial | L31: 0.55 | M31: 8
A32: PPIQ-T261 | B32: Seed canonical demo plant layout (flat-steel) | C32: P02 | D32: very important | E32: Track 3 — Demo | F32: Database | G32: Demo Lifecycle / Canonical Layout | H32: STARTING POINT (30-May audit — already built): 112_golden_demo_data (23MB) + 110/111 demo shapes/views encode a flat-steel layout. WHAT REMAINS — the actual work of this task: Seed/confirm the canonical flat-steel demo plant layout (EAF/LF/CC/TF/HSM/...) matches the dataset and is presentable. FULL REFERENCE SPEC: Seed the canonical layout (EAF/LF/CC/TF/HSM/SKP/LCT/HCT/STL/PKL/GVL/Yard/Roll Shop) with realistic genealogy and per-area equipment/counters, applied via the demo reset job. Document at docs/demo/canonical-layout.md. | I32: New Feature | J32: 1) Layout after reset matches the documented canonical plant. 2) Genealogy intact across areas. 3) Process history/quality/risk realistic per material. 4) Re-applies cleanly via reset. | K32: Partial | L32: 0.35 | M32: 4
A33: PPIQ-T206 | B33: Confirm SchemaViewResolver typed errors + join SafeSqlValidator | C33: P02 | D33: important | E33: Track 1 — Workflow | F33: App Backend | G33: Schema Mapping / Validation Hardening | H33: ALREADY IN PLACE (30-May audit): SchemaConfigurationEndpoints.cs (423L) + SchemaConfigurationService.cs (380L) + GenericSchemaMappingEndpoints; SchemaConfigurationSafetyEndpointTests.cs (78L) cover SafeSqlValidator on generated SQL. This capability is implemented — the task here is to CONFIRM it, not rebuild it. Reference scope / behaviour: Closes residual rigor on v4 PPIQ-T108/T110 (capability shipped in GenericSchemaMappingEndpoints.cs but specific guarantees unconfirmed). Ensure /resolve returns distinct, testable errors — NoSuchView, NoSuchColumn, InvalidAggregateForType — not a generic failure, and that /joins/preview and /joins/materialize run SafeSqlValidator on the generated join SQL (blocking DDL/cross-tenant injection) and reject type-mismatched key pairs with a clear message. Add unit/integration tests for each path. | I33: Bug Fix | J33: Confirm (do NOT re-implement): 1) Resolver returns the three named error types on bad view/column/aggregate. 2) Malicious join SQL is blocked at preview and materialize. 3) Type-mismatched key pair rejected with a clear error. 4) Tests cover each case and run in CI. | K33: Done | L33: 0.85 | M33: 3
A34: PPIQ-T294 | B34: Material genealogy join spine (heat->ladle->tundish->strand->slab->coil) as a canonical view | C34: P02 | D34: very important | E34: Track 1 — Workflow | F34: App Backend | G34: Schema Mapping / Genealogy | H34: STARTING POINT (31-May audit — already built): 201_ feature-store completion SQL includes genealogy_json; feature store keys to heat/material grain. WHAT REMAINS — the actual work of this task: Build the explicit canonical genealogy VIEW (heat->ladle->tundish->strand->slab->coil->defect->QA) via the mapping engine over the 8 split sources; test known lineages. FULL REFERENCE SPEC: Using the schema-mapping engine (NOT hardcoded SQL), produce a canonical genealogy view that threads the plant's identity chain across sources: HeatID (MeltShop, Postgres) -> Ladle/Tundish/Mould/Sequence/Strand/Slab (Caster, Oracle) -> coil (HSM, Oracle) -> surface defects (Parsytec, MySQL) -> QA samples (Excel). This is the spine the feature store (T209), inspection jobs (T220-T222), the assistant's genealogy tool (T232), and 'investigate this coil' all consume to walk a coil backward to its casting + melt conditions and forward to its defects/QA. | I34: Enhancement | J34: 1) Given any coil, the view resolves its slab, strand, sequence, tundish, ladle, and heat, and forward to its defects and QA samples. 2) It is produced via the mapping engine over the eight SPLIT demo sources, not a single pre-joined table. 3) The feature store and at least one inspection job consume it successfully. 4) Known demo lineages (hand-verified) resolve correctly end-to-end; orphan/edge cases return cleanly, not as errors. | K34: Partial | L34: 0.45 | M34: 6
A35: PPIQ-T247 | B35: Connector smoke tests vs all six live DB sources + CSV/Excel golden files | C35: P02 | D35: very important | E35: Track 2 — Hardening | F35: App Backend | G35: Connectors / Smoke Tests | H35: STARTING POINT (31-May audit — already built): CsvConnectorSmokeTests + ExcelConnectorSmokeTests + ConnectorTruthContractTests; all 6 connectors built; demo-source containers now available to test against. WHAT REMAINS — the actual work of this task: Add live smoke tests vs the new MySQL/Oracle/MSSQL demo-source containers + CSV/Excel golden files; make it a gate. FULL REFERENCE SPEC: Author/extend smoke tests for PostgreSqlConnector, OracleConnector (×2), MsSqlConnector, MySqlConnector (×2), plus CSV/Excel, against the live demo-sources containers: ListTables, DescribeTable, SamplePage(100), FullSync, vs checked-in golden snapshots. Opt-in via PPIQ_RUN_CONNECTOR_INTEGRATION=1; wired to the post-deploy gate. Oracle gets a 90s warm-up. | I35: New Feature | J35: 1) Each connector passes against its seeded source. 2) Each detects drift if seed data is altered. 3) Oracle warm-up handled. 4) All wired to Jenkins post-deploy and logged. | K35: Partial | L35: 0.55 | M35: 6
A36: PPIQ-T207 | B36: Add delta-import integration + resumability tests (T118 was unstarted) | C36: P02 | D36: very important | E36: Track 2 — Hardening | F36: App Backend | G36: Import / Test Coverage | H36: STARTING POINT (31-May audit — already built): DeltaImportResumabilityTests expanded (MaxRowsSmallBatch, Stage1Stage2AndFullCycle, RejectsAnonymousAccess per the v6 completion check). WHAT REMAINS — the actual work of this task: Confirm crash-mid-batch resume + duplicate suppression + schema-drift detection are all asserted and the suite is a CI gate <60s. FULL REFERENCE SPEC: Closes v4 PPIQ-T118, which had no implementation. The two-stage pipeline (source_table_dump_registry, two_stage_import_runs, two_stage_processed_watermarks; stage1/stage2/run-full-cycle endpoints) ships without tests. Author integration tests against seeded sources: cold full-load, incremental delta (only new rows beyond last_index), mid-run crash + resume (no duplicates), schema drift detection, idempotency. Opt-in via PPIQ_RUN_CONNECTOR_INTEGRATION=1; wire to the post-deploy gate. | I36: New Feature | J36: 1) Cold load then incremental delta imports only new rows. 2) Simulated crash resumes from last_index with no duplicates. 3) Source schema drift is detected and surfaced. 4) Suite < 60s, wired to Jenkins. | K36: Partial | L36: 0.7 | M36: 4
A37: PPIQ-T290 | B37: Demo-source connection presets so DB-link config is one-click in the demo | C37: P02 | D37: important | E37: Track 3 — Demo | F37: App Frontend | G37: Demo / DB Link UX | H37: [NEW — discovered during the v6 implementation/debugging audit; not present in the 30-May snapshot] To run the live config demo smoothly (Vision Track 3), provide saved connection presets for the eight demo source systems (host=compose service name, port, db, read-only creds) that the presenter can select in the DB Link Configuration tab instead of typing under pressure. Presets are demo-data only, clearly labeled, and never auto-connect (the presenter still clicks through to prove the flow). | I37: Enhancement | J37: 1) The DB Link tab offers the 8 demo presets. 2) Selecting one fills the form; the presenter still clicks Test + Save (no hardcoded data path). 3) Presets use internal service-name hosts. 4) Presets are absent/disabled outside demo mode. | K37: Not Started | L37: 0 | M37: 4
A38: P03 — Page Builder & Widget Platform | 7 tasks | 41 hrs Vision section 2.1-2.2 core workflow and a Track-3 Golden-Rule prerequisite (pages must be USER-CREATED, never coded). Introduce a generic PageDefinition model, page CRUD + dynamic /pages/{slug} render, page persistence/ownership/sharing, the drag-drop widget canvas + library, then confirm and document the widget data-link + script layer that already exists. EXIT STATE (healthy): a user creates, lays out, data-binds, saves, reloads, and shares a custom page entirely from the HMI; nothing is hardcoded.
A39: PPIQ-T289 | B39: Generic Page-Definition model so pages are user-created from the HMI (not code) | C39: P03 | D39: very important | E39: Track 1 — Workflow | F39: App Backend | G39: Page Builder / Persistence | H39: STARTING POINT (31-May audit — already built): pageBuilder.api.ts (32L) + PageBuilderPage.tsx (199L) + page-builder.css; a PageBuilder surface now exists frontend-side. WHAT REMAINS — the actual work of this task: Confirm a backend PageDefinition aggregate (slug/title/owner/layout JSON/sharing) persists pages in PG and /pages/{slug} renders them generically — the durable model behind the UI. FULL REFERENCE SPEC: Introduce a PageDefinition aggregate persisted in Postgres: id, slug (unique, URL-safe), title, owner, a layout JSON describing widget placements (grid position/size + the DashboardWidgetDefinition each cell renders), visibility/sharing, and audit columns. Expose Page CRUD endpoints and render any page generically at /pages/{slug} by reading the stored layout and hydrating each widget through the existing widget pipeline (DashboardWidgetDefinition + the widget script layer, T242). This is the prerequisite for the page-builder UX (T240/T241/T243): the canvas edits a PageDefinition; it must never emit code. | I39: Enhancement | J39: 1) A page can be created, renamed, re-laid-out, and deleted entirely via the API/HMI and survives an app restart (persisted in PG). 2) GET /pages/{slug} renders the stored layout generically — no page content is hardcoded in React for user pages. 3) Widget cells in a stored layout hydrate through the existing DashboardWidgetDefinition + script-layer path. 4) Round-trips on the demo dataset: build a page of 3+ data-bound widgets, reload, and it is identical. 5) Slugs are unique and URL-safe; invalid layouts are rejected with a clear error. | K39: Partial | L39: 0.5 | M39: 8
A40: PPIQ-T240 | B40: Page CRUD + /pages/{slug} dynamic load | C40: P03 | D40: very important | E40: Track 1 — Workflow | F40: App Frontend | G40: Page Builder / Page CRUD | H40: STARTING POINT (31-May audit — already built): pageBuilder API client + PageBuilderPage present; page CRUD surface emerging. WHAT REMAINS — the actual work of this task: Confirm create/rename/delete + /pages/{slug} dynamic load round-trip and persist across restart. FULL REFERENCE SPEC: Vision §2.1.1/2.1.3: create/edit/delete/save user pages, persisted per-user, and a dynamic /pages/{slug} route loading a stored page definition (backend /api/pages/{slug}, 404 on missing). This is the page model the ML page generator (P04) emits into. Standard* primitives. | I40: New Feature | J40: 1) Create, rename, save, delete a page; reload restores it. 2) /pages/{slug} loads a stored page; missing slug 404s. 3) Pages are per-user/owner scoped. 4) The ML-generated page round-trips through the same model. | K40: Partial | L40: 0.45 | M40: 6
A41: PPIQ-T243 | B41: Page persistence, ownership & sharing (backend) | C41: P03 | D41: important | E41: Track 1 — Workflow | F41: App Backend | G41: Page Builder / Persistence | H41: STARTING POINT (30-May audit — already built): DashboardWidgetDefinition persistence exists; no Page entity ownership/sharing. WHAT REMAINS — the actual work of this task: Add Page persistence + ownership + sharing (backend) to support T240. FULL REFERENCE SPEC: Backend page store (page, owner, layout json, widget bindings, version), endpoints for CRUD + list-by-owner, optional share/visibility. Tenant-scoped. Used by P04 generated pages and P08 builder. | I41: New Feature | J41: 1) Pages persist with layout + bindings + version. 2) List-by-owner returns the user's pages. 3) Tenant isolation enforced. 4) Round-trip preserves layout and bindings. | K41: Partial | L41: 0.3 | M41: 4
A42: PPIQ-T241 | B42: Drag-drop widget canvas + widget library | C42: P03 | D42: very important | E42: Track 1 — Workflow | F42: App Frontend | G42: Page Builder / Canvas & Library | H42: STARTING POINT (31-May audit — already built): DragGhost.tsx/.css + utils/dragPerformance.ts (79L) + PageBuilderPage establish a drag-drop canvas foundation. WHAT REMAINS — the actual work of this task: Finish the widget LIBRARY + drag/drop/resize onto the canvas writing into the PageDefinition layout; e2e drag correctness (T244). FULL REFERENCE SPEC: Vision §2.1.2: a library of all widgets (every chart type, KPI, and the filtering tools — date-time picker, list-of-values). Drag-drop onto the page, arrange, Save; editing can add/remove/rearrange. Drag/resize/min/max correct (Vision §2.5). Reuse WidgetBuilderWizard for per-widget config. | I42: New Feature | J42: 1) Drag a widget from the library to the canvas, arrange, save; reload preserves layout. 2) Resize/min/max/move behave correctly with no overlap glitches. 3) Date-time and list filters available as widgets. 4) Standard* primitives; visual regression baseline captured. | K42: Partial | L42: 0.45 | M42: 10
...

Sheet Audit Summary
A1: Implementation Audit & v7 Re-sequencing
A2: Status is evidence-based: every task was checked against the 30-May code snapshot (endpoints, services, entities, SQL, frontend, CI). 'Done' = capability present (a one-time confirmation may remain); 'Partial' = real scaffolding with concrete gaps; 'Not Started' = essentially absent. Each task now carries ONE authoritative Description (folding current-state + what to build) and ONE Validation.
A3: v8 update (31-May 12:56 re-audit): P01 auth/deploy hardening largely DONE (StartupConfigurationValidator rejects legacy Auth:* keys & enforces a Production bootstrap sentinel; kill-by-PORT scripts; server-exposure verifier; Postgres off 0.0.0.0). The ML ENGINE moved from 'not started' to real: learning core 204_ (Pearson/point-biserial/Cramer's-V, BH q-values, effect-size buckets, effective-n), 4 jobs registered, on-demand /api/ml/learning, and the narrative/embedding provider trio. Two gaps remain front-of-mind: (1) the learning jobs are not yet SCHEDULED in the Worker (T217 — it still runs only Import/Quality/Risk/Delta); (2) the CONVERSATIONAL AI ASSISTANT does not exist — no agent/tool layer (T232), no chat UI (T233). The voice (providers) and the brain (stats) are built; the assistant that orchestrates them is the key remaining ML deliverable.
A4: v9 update: added Phase 0 — Test Foundation (8 tasks, ~67h). The suite is audited, repaired, covered, and made a regression gate BEFORE the feature/hardening phases proceed. See the Test Register sheet for the per-file delete/modify/keep/add/transfer decisions (113 files): 8 DELETE, 31 MODIFY, 14 ADD, 5 validation scripts TRANSFER→TEST, 11 RETIRE, 8 KEEP-AS-GATE, 36 KEEP. Phase 0 is Not Started, so headline status %s are unchanged except the denominator grows to 103 tasks.
A6: Status | B6: Count | C6: Effort (hrs) | D6: % of tasks
A7: Done | B7: =COUNTIF('Task List'!$K$5:$K$121,A7) -> 23 | C7: =SUMIF('Task List'!$K$5:$K$121,A7,'Task List'!$M$5:$M$121) -> 83.5 | D7: =IFERROR(B7/$B$10,0) -> 0.22330097
A8: Partial | B8: =COUNTIF('Task List'!$K$5:$K$121,A8) -> 39 | C8: =SUMIF('Task List'!$K$5:$K$121,A8,'Task List'!$M$5:$M$121) -> 190 | D8: =IFERROR(B8/$B$10,0) -> 0.37864078
A9: Not Started | B9: =COUNTIF('Task List'!$K$5:$K$121,A9) -> 41 | C9: =SUMIF('Task List'!$K$5:$K$121,A9,'Task List'!$M$5:$M$121) -> 209 | D9: =IFERROR(B9/$B$10,0) -> 0.39805825
A10: TOTAL | B10: =SUM(B7:B9) -> 103 | C10: =SUM(C7:C9) -> 482.5 | D10: =IFERROR(B10/B10,0) -> 1
A12: How v7 is re-grouped (your four rules)
A13: • RULE 1 — importance first: P01 makes the app reliably build/login/deploy (foundation + demo-protection); P02 the data backbone; P03 the page builder you demo; P04–P09 the AI/ML differentiator; P10 hardening; P11 demo; P12 website; P13 legal/docs.
A14: • RULE 2 — same feature together: the v6 bug-fixes and enhancements are no longer appended at the end. The login/auth/deploy bugs sit WITH the build-green work in P01; the genealogy + downtime-outcome + provider-abstraction enhancements sit WITH the data/ML phases they belong to; the page-model enhancement leads the page-builder phase.
A15: • RULE 3 — healthy end state: every phase carries an explicit EXIT STATE (green pipeline, all sources connected, a user-built page reloads, the engine recovers known correlations, etc.). No phase ends with a broken build, page, or connection.
A16: • RULE 4 — prerequisites first: e.g. the 8 split sources (P02) precede the genealogy spine and the feature store that consume them; and the FULL auth matrix (T204) was deliberately MOVED from the old P01 to P10 because it must cover /api/ml/* endpoints that only exist after P04–P09.
A18: What the audit found
A19: • DONE/strong: build-green hotfixes (T201–T203, T205); all six DB connectors; two-stage delta import; schema-mapping engine (T206); widget builder + script layer (T242 — corrects the old 'unstarted' note); transparent risk scorer (T236); ML data-foundation SQL incl. pgvector KB (T209/T213).
A20: • PARTIAL: feature store/outcomes/compute-interface scaffolding exists but the LEARNING ENGINE does not; a rich per-widget builder exists but no page CANVAS or user-created PageDefinition; a 23MB coherent dataset exists but is NOT split across 8 sources; license context exists but the live tier toggle is unfinished.
A21: • NOT STARTED (largest gaps): the four scheduled learning jobs + statistical-validity machinery (T214–T216); inspection→generated-pages (T220–T224); suggestion feed (T226–T229); conversational assistant (T230–T235); HeatMap (T249); demo-sources compose (T245); demo scripts/personas/video; the 5 website product pages; legal templates; runbooks.

Sheet Test Register
A1: Phase 0 — Test Register (delete / modify / keep / add / transfer), grounded in the 31-May snapshot
A2: Disposition legend: DELETE = remove (no-op/duplicate, replaced); MODIFY = real intent, fix/strengthen assertions or de-brittle; KEEP = already strong, leave (maybe minor align); ADD = brand-new test for an uncovered area; TRANSFER→TEST = a behavioural validation script becomes a real test; KEEP-AS-GATE = pure structural check stays a CI/ESLint gate; RETIRE = per-phase acceptance script superseded by real tests.
A3: Area | B3: File | C3: Lines | D3: Disposition | E3: Rationale / Action | F3: Maps to Task
A4: BACKEND UNIT
A5: Backend unit | B5: PlantProcess.Api.IntegrationTests/ApiTestEnvironmentTests.cs | C5: 12 | D5: DELETE | E5: No-op smoke (true.Should().BeTrue()). Remove once the project has real integration tests (T303). | F5: PPIQ-T301
A6: Backend unit | B6: PlantProcess.Application.UnitTests/ApplicationTestEnvironmentTests.cs | C6: 18 | D6: DELETE | E6: Asserts only that the assembly loads. Superseded by real Application unit tests. | F6: PPIQ-T301
A7: Backend unit | B7: PlantProcess.Domain.Tests/DomainTestEnvironmentTests.cs | C7: 17 | D7: DELETE | E7: Assembly-load smoke only. Domain logic gets real tests instead. | F7: PPIQ-T301
A8: Backend unit | B8: PlantProcess.PerformanceTests/PerformanceTestEnvironmentTests.cs | C8: 12 | D8: DELETE | E8: No-op smoke. Replace with a real perf assertion or remove the project from the gate. | F8: PPIQ-T301
A9: Backend unit | B9: PlantProcess.Api.IntegrationTests/AssemblyInfo.cs | C9: 3 | D9: KEEP | E9: Not a test (collection/parallelism attributes). Leave as-is. | F9: PPIQ-T301
A10: Backend unit | B10: PlantProcess.Application.UnitTests/Common/ApplicationResultTests.cs | C10: 91 | D10: KEEP | E10: Real result-type tests. Keep. | F10: PPIQ-T302
A11: Backend unit | B11: PlantProcess.Application.UnitTests/Common/PageRequestTests.cs | C11: 39 | D11: KEEP | E11: Real pagination tests. Keep. | F11: PPIQ-T302
A12: Backend unit | B12: PlantProcess.Application.UnitTests/Common/TextNormalizerTests.cs | C12: 40 | D12: KEEP | E12: Real normalizer tests. Keep. | F12: PPIQ-T302
A13: Backend unit | B13: PlantProcess.Application.UnitTests/Dashboarding/WidgetQueryExpressionServiceTests.cs | C13: 56 | D13: MODIFY | E13: Expand expression safety/validation cases (CTE, nested, disallowed funcs) to match the 418L service (T302). | F13: PPIQ-T302
A14: Backend unit | B14: PlantProcess.Application.UnitTests/Licensing/LicenseServiceTests.cs | C14: 177 | D14: KEEP | E14: Strong license tests. Keep; add any new tier-feature corner cases (T302). | F14: PPIQ-T302
A15: Backend unit | B15: PlantProcess.Application.UnitTests/Security/SafeSqlPolicyTests.cs | C15: 197 | D15: KEEP | E15: Strong SafeSql policy suite. Keep; extend with new cross-tenant/CTE edges (T302). | F15: PPIQ-T302
A16: Backend unit | B16: PlantProcess.Domain.Tests/Architecture/DomainArchitectureTests.cs | C16: 51 | D16: KEEP | E16: Architecture guard (layer boundaries). Valuable — keep. | F16: PPIQ-T301
A17: Backend unit | B17: PlantProcess.Domain.Tests/Dashboarding/DashboardWidgetDefinitionExpressionTests.cs | C17: 54 | D17: KEEP | E17: Real domain expression tests. Keep. | F17: PPIQ-T302
A18: Backend unit | B18: (NEW) Analytics/RiskScoreServiceTests.cs | D18: ADD | E18: Assert exact additive contribution decomposition + explanation shape on a known vector. | F18: PPIQ-T302
A19: Backend unit | B19: (NEW) Analytics/FeatureEngineeringServiceTests.cs | D19: ADD | E19: Assert derived features (cev, true_superheat, casting speed delta, residency, shift) vs hand-computed values. | F19: PPIQ-T302
A20: Backend unit | B20: (NEW) Analytics/MlReadinessServiceTests.cs | D20: ADD | E20: Assert readiness gate thresholds both sides of the boundary. | F20: PPIQ-T302
A21: Backend unit | B21: (NEW) Analytics/QualityLabelBuilderServiceTests.cs | D21: ADD | E21: Assert quality-label derivation for defect classes/severity. | F21: PPIQ-T302
A22: BACKEND INTEGRATION
A23: Backend integration | B23: PlantProcess.Api.IntegrationTests/Connectors/ConnectorTruthContractTests.cs | C23: 121 | D23: KEEP | E23: Real contract test for connector truth panel. Align with live demo-source containers (T303). | F23: PPIQ-T303
A24: Backend integration | B24: PlantProcess.Api.IntegrationTests/Health/HealthEndpointTests.cs | C24: 24 | D24: KEEP | E24: Thin but valid health check. Keep. | F24: PPIQ-T301
A25: Backend integration | B25: PlantProcess.Api.IntegrationTests/Import/DeltaImportResumabilityTests.cs | C25: 123 | D25: MODIFY | E25: Grew to 123L (Stage1Stage2AndFullCycle, MaxRowsSmallBatch, RejectsAnonymousAccess). Add an explicit mid-batch CRASH→resume-with-no-duplicates and schema-drift case (T303). | F25: PPIQ-T303
A26: Backend integration | B26: PlantProcess.Api.IntegrationTests/Infrastructure/AuthenticatedApiTestBase.cs | C26: 285 | D26: KEEP | E26: Solid shared harness (real DB + auth). Reuse for the new ML/data integration tests. | F26: PPIQ-T303
A27: Backend integration | B27: PlantProcess.Api.IntegrationTests/OpenApi/OpenApiContractTests.cs | C27: 54 | D27: MODIFY | E27: Good idea; extend to assert the ML + page-builder endpoints appear in the OpenAPI doc as they land. | F27: PPIQ-T303
A28: Backend integration | B28: PlantProcess.Api.IntegrationTests/Security/AuthEndpointTests.cs | C28: 72 | D28: MODIFY | E28: Covers basic login. Extend to the full gate matrix: empty→400, bootstrap-collision→403, valid→200, bad role, short signing key→500 (T303). | F28: PPIQ-T303
A29: Backend integration | B29: PlantProcess.Api.IntegrationTests/Security/SchemaConfigurationSafetyEndpointTests.cs | C29: 78 | D29: MODIFY | E29: Extend to assert the THREE named resolver errors and SafeSqlValidator blocking generated join SQL (T303). | F29: PPIQ-T303
A30: Backend integration | B30: PlantProcess.Api.IntegrationTests/Smoke/ApiEndpointCatalogSmokeTests.cs | C30: 88 | D30: KEEP | E30: Useful endpoint-catalog smoke. Keep as a fast gate. | F30: PPIQ-T301
A31: Backend integration | B31: PlantProcess.Api.IntegrationTests/Smoke/ApiSmokeEndpointTests.cs | C31: 33 | D31: MODIFY | E31: Overlaps the catalog smoke; merge into one smoke spec to cut duplication. | F31: PPIQ-T301
A32: Backend integration | B32: PlantProcess.Infrastructure.IntegrationTests/Audit/AuditLogImmutabilityTests.cs | C32: 271 | D32: KEEP | E32: Excellent immutability suite (real Postgres). Keep; extend to new audit surfaces. | F32: PPIQ-T303
A33: Backend integration | B33: PlantProcess.Infrastructure.IntegrationTests/Connectors/CsvConnectorSmokeTests.cs | C33: 61 | D33: MODIFY | E33: Real CSV smoke. Add golden-file assertions + run against demo-source data (T303). | F33: PPIQ-T303
A34: Backend integration | B34: PlantProcess.Infrastructure.IntegrationTests/Connectors/ExcelConnectorSmokeTests.cs | C34: 77 | D34: MODIFY | E34: Real Excel smoke. Add golden-file assertions (T303). | F34: PPIQ-T303
A35: Backend integration | B35: PlantProcess.Infrastructure.IntegrationTests/InfrastructureTestEnvironmentTests.cs | C35: 18 | D35: DELETE | E35: Assembly-load smoke only. | F35: PPIQ-T301
