Workbook

Sheet Current Authority
A1: PPIQ BACKLOG v2.24.0 — Industrial Integration authority 16Sep2026
A2: Authority | B2: Current value | C2: As of | D2: Meaning
A3: Functional Design | B3: v4.11.0 | C3: 2026-09-16 | D3: Owner-approved Industrial Integration Contract integrated into Chapters 1–6: stable field/layout identity, Time/Value-change/Trigger-counter policies, continuous acquisition sessions with finite accepted batches, logical Dump Store, source-data lifecycle/capacity truth. Existing closed work remains historical evidence.
A4: Execution Backlog | B4: v2.24.0 | C4: 2026-09-16 | D4: Meaningful authority revision: adds T-268..T-275 and amends affected OPC/design acceptance. No closed task is reopened; expanded industrial-integration scope is separately owned.
A5: Integrated Chapter 3/4 visuals | B5: v4.11.0 target contract; illustrated regeneration pending T-265/T-266 | C5: 2026-09-16 | D5: Functional contract is authoritative now; T-265/T-266 still own derived visual/prototype/illustrated synchronization and do not receive runtime credit.
A6: Release 1 | B6: M2 — approx. one month from owner planning checkpoint | C6: Owner planning basis | D6: No new absolute delivery date.
A7: Release 2 | B7: M3 — 45 days after M2 completion | C7: Owner planning basis | D7: 45 days after M2 completion; prior approved release allocation retained.
A8: Rows and retirements | B8: 187 active; T-105→T-104; T-111→T-110/T-155/T-159 | C8: Adds T-268 through T-275 | D8: Eight new bounded industrial-integration execution owners. No existing task retired or reopened by this design revision.
A9: T-099 closure | B9: ca02b40ea1b69050a45cb35a3e1d64f15b1f66af | C9: Final14Sep terminal transcript inspected15Sep | D9: CLOSED GREEN/COMMITTED; exact transcript corroborated. DefinitionKind known-red remains; not release-wideGREEN.
A10: T-262 evidence | B10: CONTRACT GREEN COMMIT86e1b677; INTEGRATION UNVERIFIED | C10: Evidence from12Sep; reviewed15Sep | D10: Producer declaration is committed with backend24/24, catalogue8/8, content39/39 and authoring404/404; parent36de9370 (short). Live definition-store integration is explicitly not executed. Current row asks for needed integration closure: retain In Progress pending that disposition, but withdraw the false 'no accepted SHA/run supplied' statement. No producer rewrite. Pasted text(20260912-074928).txt | lines1229-1243; T-262 GREEN committed86e1b677212195f191697ecdca7e9441b3dbde33; parent36de9370; live definition-store integration explicitly unexecuted. Later 14-Sep coordination explicitly allocates live definition-store Gate 0 to T-261 Runner 2. Reconcile that integration gate separately; no producer rewrite.
A11: Planning estimates | B11: Existing estimates preserved; T-268..T-275 intentionally unestimated | C11: 2026-09-16 | D11: New scope is not zero hours. Source-level preflight is required before LOW/BASE/HIGH or P80 is accepted; historical OPC estimates are not silently reused for expanded v4.11.0 scope.
A12: Current task table | B12: Backlog!A1:BB188 | C12: 187 task rows | D12: Dependency validation reads the saved v2.24.0 task rows. New tasks are excluded from hour totals until explicitly estimated.
A13: Derived views | B13: Worker Tracks / Dependency Graph / Capability Map / Release Plan / dashboards | C13: v2.24.0 | D13: Formula ranges are extended through Backlog row 188. New task rows are appended to Worker Tracks and Dependency Graph.
... A31: Controlled book | B31: 12 document families / 14 physical files | C31: Owner direction — 2026-09-14 | D31: PPIQ_Definition.md registers the allowed files. The Backlog holds coverage, acceptance, validation and handoffs; no new status/JSON/README/atlas files.

Sheet Backlog
A1: Task Id | B1: Milestone Id | C1: Phase Id | D1: Task Name | E1: Module | F1: Sub-module | G1: Priority | H1: Task Description | I1: Task Validation | J1: Hours | K1: Status | L1: AI Agent Owner | M1: Depends On (IDs only) | N1: Must Precede (IDs only) | O1: Delivery Target | P1: Release Criticality | Q1: AI Execution Class | R1: AI Guarded Time P80 (h) | S1: AI Sequence Wave | T1: AI Start / Dependency Gate | U1: File / Subsystem Lock | V1: No-Rework Handoff Ruling | W1: Product Track | X1: Tech-Lead Ruling | Y1: Commit String | Z1: Commit Date | AA1: Primary Capability ID | AB1: Primary Capability Name | AC1: Secondary Capability IDs | AD1: Capability Contribution | AE1: Completeness Dimensions Targeted | AF1: Capability Requirement Class | AG1: Release Scope | AH1: Capability Closure Effect | AI1: Capability Evidence | AJ1: Estimate Basis | AK1: Design Package | AL1: UI Companion Reference | AM1: Usable scope estimate (1/0) | AN1: Contract-ready predecessors (not completion) | AO1: Evidence State | AP1: Closure Evidence Basis | AQ1: Parent Commit | AR1: Estimate Status | AS1: Usable planning hours | AT1: Usable planning P80 h | AU1: Source review coverage | AV1: Proposed remaining LOW h | AW1: Proposed remaining BASE h | AX1: Proposed remaining HIGH h | AY1: Remaining estimate confidence | AZ1: Remaining estimate basis | BA1: Source locations | BB1: Source as-of / evidence boundary
A2: T-086 | B2: M2 | C2: P1 | D2: Freeze the legacy Fleet v2 controlled regression oracle | E2: Testing | F2: Emulated sources | G2: Critical | H2: Freeze and certify the existing Fleet v2 dataset only as a legacy discrete-manufacturing regression oracle with predeclared known answers/negative controls. It is not the canonical product vocabulary, not the generic M2 fixture authority and not the source of customer schema semantics. T-208 owns new generic controlled fixtures, including the continuous-process known-answer pack. | I2: Fleet v2 is immutable and its declared phenomena/negative controls are reproducible. An architecture check proves no generic runtime/Layer-B/registry contract derives vocabulary or universal grain from Fleet. T-208 can run independently with neutral/continuous fixtures. | J2: 8 | K2: Done | L2: Worker 1 | M2: T-201 | N2: T-087; T-088; T-131 | O2: M2: ~1 month from owner planning checkpoint; exact date not committed | P2: Release 1 MUST | Q2: Integration/E2E/certification | R2: 2.72 | S2: M2-P1 | T2: CLOSED BASELINE — no new start gate and no re-execution implied. Preserve accepted closure and clean owned scope; reopen only on a concrete, separately recorded regression. Downstream consumes the frozen contract. | U2: Own canonical DB/backend/security/API/infra. No W2-owned UI/admin task files and no W3 ML/Assistant runtime. | V2: Commit before downstream consumer starts; consumer must use the contract, not redesign producer-owned semantics. | W2: Product Foundation & Release Truth | X2: M2 P1 — Product Foundation & Release Truth. Release 1 is genuine early production / first-week customer work. | Y2: 77a8ea4f — T-086: freeze the legacy regression oracle and gate generic surfaces against its vocabulary | Z2: 46259 | AA2: L8.8 | AB2: C1–C4 performance certification and golden-journey release gate | AD2: Validate | AE2: D5 | AF2: Core | AG2: R1 | AH2: Advances | AI2: =IF(Y2="","",Y2) -> 77a8ea4f — T-086: freeze the legacy regression oracle and gate generic surfaces against its vocabulary | AJ2: Inherited baseline estimate | AK2: v4.10.3 | AL2: Chapters 3/4 v4.10.3 — MD + illustrated Word; UI Coverage / UI Controls in this workbook | AM2: =IF(AND(ISNUMBER(J2),OR(AR2="INHERITED ESTIMATE",AR2="CONFIRMED ESTIMATE")),1,0) -> 1 | AO2: Recorded closed — inherited evidence | AP2: Inherited v2.22.0 intended record; no new runtime certification in this repair. | AR2: INHERITED ESTIMATE | AS2: =IF(AM2=1,J2,"") -> 8 | AT2: =IF(AND(AM2=1,ISNUMBER(R2)),R2,"") -> 2.72 | AU2: =IFERROR(INDEX('Source Review'!$B$2:$B$52,MATCH($A2,'Source Review'!$A$2:$A$52,0)),"NOT SOURCE-REVIEWED IN THIS PASS") -> NOT SOURCE-REVIEWED IN THIS PASS | AV2: =IFERROR(INDEX('Source Review'!$F$2:$F$52,MATCH($A2,'Source Review'!$A$2:$A$52,0)),"") | AW2: =IFERROR(INDEX('Source Review'!$G$2:$G$52,MATCH($A2,'Source Review'!$A$2:$A$52,0)),"") | AX2: =IFERROR(INDEX('Source Review'!$H$2:$H$52,MATCH($A2,'Source Review'!$A$2:$A$52,0)),"") | AY2: =IF(COUNTIF('Source Review'!$A$2:$A$52,$A2)>0,"UNCONFIRMED REVIEW ESTIMATE - not P80 or elapsed","NOT ESTIMATED IN THIS PASS") -> NOT ESTIMATED IN THIS PASS | AZ2: =IFERROR(INDEX('Source Review'!$I$2:$I$52,MATCH($A2,'Source Review'!$A$2:$A$52,0)),"") | BA2: =IFERROR(INDEX('Source Review'!$E$2:$E$52,MATCH($A2,'Source Review'!$A$2:$A$52,0)),"") | BB2: =IF(COUNTIF('Source Review'!$A$2:$A$52,$A2)>0,"14-Sep-2026 snapshot; later closure evidence separate; no live HEAD verification","")
A3: T-087 | B3: M2 | C3: P1 | D3: Physical three-schema migration | E3: Database | F3: Schema | G3: Critical | H3: The measured database carries twelve schemas with 162 tables in public, of which 108 use a ppiq_ name prefix, while the ruled schemas ppiq_plant and ppiq_meta exist and hold zero tables. Migrate to the three ruled schemas: ppiq_staging, ppiq_plant, ppiq_meta. The staging rename is already prepared, because the canvas reads its schema from the configuration key Prep:StagingSchema rather than a literal. | I3: Rule 2 is provable in one query on a fresh database. All application tests pass. The canvas catalogue lists tables from the renamed schema with only a configuration change. AND THE BENCHMARK SURVIVES THE MOVE: the phenomenon and benchmark harness frozen in T-086 is re-run UNCHANGED after the schema migration and produces identical results. A migration that silently alters the reference dataset destroys every comparison made against it. | J3: 12 | K3: Done | L3: Worker 1 | M3: T-086; T-088 | N3: T-089; T-099; T-102; T-112; T-114; T-128; T-196; T-233; T-251; T-252 | O3: M2: ~1 month from owner planning checkpoint; exact date not committed | P3: Release 1 MUST | Q3: DB/schema/migration | R3: 2.325 | S3: M2-P1 | T3: CLOSED BASELINE — no new start gate and no re-execution implied. Preserve accepted closure and clean owned scope; reopen only on a concrete, separately recorded regression. Downstream consumes the frozen contract. | U3: Own canonical DB/backend/security/API/infra. No W2-owned UI/admin task files and no W3 ML/Assistant runtime. | V3: Commit before downstream consumer starts; consumer must use the contract, not redesign producer-owned semantics. | W3: Product Foundation & Release Truth | X3: M2 P1 — Product Foundation & Release Truth. Release 1 is genuine early production / first-week customer work. | Y3: e7d82f078d7dfa4c1ca4ec6e88d0dbc7e1ecd6ba — subject not recovered | Z3: 46262 | AA3: L2.1 | AB3: Three-schema platform and placement law | AC3: L5.7 | AD3: Converge | AE3: D4; D5 | AF3: Core | AG3: R1 | AH3: Advances | AI3: =IF(Y3="","",Y3) -> e7d82f078d7dfa4c1ca4ec6e88d0dbc7e1ecd6ba — subject not recovered | AJ3: Inherited baseline estimate | AK3: v4.10.3 | AL3: Chapters 3/4 v4.10.3 — MD + illustrated Word; UI Coverage / UI Controls in this workbook | AM3: =IF(AND(ISNUMBER(J3),OR(AR3="INHERITED ESTIMATE",AR3="CONFIRMED ESTIMATE")),1,0) -> 1 | AO3: Recorded closed — inherited evidence | AP3: Inherited v2.22.0 intended record; no new runtime certification in this repair. | AR3: INHERITED ESTIMATE | AS3: =IF(AM3=1,J3,"") -> 12 | AT3: =IF(AND(AM3=1,ISNUMBER(R3)),R3,"") -> 2.325 | AU3: =IFERROR(INDEX('Source Review'!$B$2:$B$52,MATCH($A3,'Source Review'!$A$2:$A$52,0)),"NOT SOURCE-REVIEWED IN THIS PASS") -> NOT SOURCE-REVIEWED IN THIS PASS | AV3: =IFERROR(INDEX('Source Review'!$F$2:$F$52,MATCH($A3,'Source Review'!$A$2:$A$52,0)),"") | AW3: =IFERROR(INDEX('Source Review'!$G$2:$G$52,MATCH($A3,'Source Review'!$A$2:$A$52,0)),"") | AX3: =IFERROR(INDEX('Source Review'!$H$2:$H$52,MATCH($A3,'Source Review'!$A$2:$A$52,0)),"") | AY3: =IF(COUNTIF('Source Review'!$A$2:$A$52,$A3)>0,"UNCONFIRMED REVIEW ESTIMATE - not P80 or elapsed","NOT ESTIMATED IN THIS PASS") -> NOT ESTIMATED IN THIS PASS | AZ3: =IFERROR(INDEX('Source Review'!$I$2:$I$52,MATCH($A3,'Source Review'!$A$2:$A$52,0)),"") | BA3: =IFERROR(INDEX('Source Review'!$E$2:$E$52,MATCH($A3,'Source Review'!$A$2:$A$52,0)),"") | BB3: =IF(COUNTIF('Source Review'!$A$2:$A$52,$A3)>0,"14-Sep-2026 snapshot; later closure evidence separate; no live HEAD verification","")
A4: T-088 | B4: M2 | C4: P1 | D4: Canonical migration order and legacy script archival | E4: Database | F4: Schema | G4: Very Important | H4: Backend/database/scripts contains hotfix, repair, phase and drift-correction scripts accumulated over months, including cases where two scripts created the same table. Define one canonical ordered migration path, archive superseded scripts, and add a truth gate that no two scripts create the same table. | I4: A fresh database builds from the canonical path with no manual step. The truth gate fails if a duplicate CREATE TABLE is introduced. | J4: 12 | K4: Done | L4: Worker 1 | M4: T-086 | N4: T-087; T-089; T-112; T-128; T-251; T-252; T-256; T-260 | O4: M2: ~1 month from owner planning checkpoint; exact date not committed | P4: Release 1 MUST | Q4: DB/schema/migration | R4: 2.325 | S4: M2-P1 | T4: CLOSED BASELINE — no new start gate and no re-execution implied. Preserve accepted closure and clean owned scope; reopen only on a concrete, separately recorded regression. Downstream consumes the frozen contract. | U4: Own canonical DB/backend/security/API/infra. No W2-owned UI/admin task files and no W3 ML/Assistant runtime. | V4: Commit before downstream consumer starts; consumer must use the contract, not redesign producer-owned semantics. | W4: Product Foundation & Release Truth | X4: M2 P1 — Product Foundation & Release Truth. Release 1 is genuine early production / first-week customer work. | Y4: 6a62c9d6 — Establish canonical database migration authority | Z4: 46260 | AA4: L8.1 | AB4: Fresh install and upgrade authority | AC4: L5.7; L2.1 | AD4: Converge | AE4: D4; D5 | AF4: Core | AG4: R1 | AH4: Advances | AI4: =IF(Y4="","",Y4) -> 6a62c9d6 — Establish canonical database migration authority | AJ4: Inherited baseline estimate | AK4: v4.10.3 | AL4: Chapters 3/4 v4.10.3 — MD + illustrated Word; UI Coverage / UI Controls in this workbook | AM4: =IF(AND(ISNUMBER(J4),OR(AR4="INHERITED ESTIMATE",AR4="CONFIRMED ESTIMATE")),1,0) -> 1 | AO4: Recorded closed — inherited evidence | AP4: Inherited v2.22.0 intended record; no new runtime certification in this repair. | AR4: INHERITED ESTIMATE | AS4: =IF(AM4=1,J4,"") -> 12 | AT4: =IF(AND(AM4=1,ISNUMBER(R4)),R4,"") -> 2.325 | AU4: =IFERROR(INDEX('Source Review'!$B$2:$B$52,MATCH($A4,'Source Review'!$A$2:$A$52,0)),"NOT SOURCE-REVIEWED IN THIS PASS") -> NOT SOURCE-REVIEWED IN THIS PASS | AV4: =IFERROR(INDEX('Source Review'!$F$2:$F$52,MATCH($A4,'Source Review'!$A$2:$A$52,0)),"") | AW4: =IFERROR(INDEX('Source Review'!$G$2:$G$52,MATCH($A4,'Source Review'!$A$2:$A$52,0)),"") | AX4: =IFERROR(INDEX('Source Review'!$H$2:$H$52,MATCH($A4,'Source Review'!$A$2:$A$52,0)),"") | AY4: =IF(COUNTIF('Source Review'!$A$2:$A$52,$A4)>0,"UNCONFIRMED REVIEW ESTIMATE - not P80 or elapsed","NOT ESTIMATED IN THIS PASS") -> NOT ESTIMATED IN THIS PASS | AZ4: =IFERROR(INDEX('Source Review'!$I$2:$I$52,MATCH($A4,'Source Review'!$A$2:$A$52,0)),"") | BA4: =IFERROR(INDEX('Source Review'!$E$2:$E$52,MATCH($A4,'Source Review'!$A$2:$A$52,0)),"") | BB4: =IF(COUNTIF('Source Review'!$A$2:$A$52,$A4)>0,"14-Sep-2026 snapshot; later closure evidence separate; no live HEAD verification","")
A5: T-089 | B5: M2 | C5: P1 | D5: definition_store, definition_versions and definition_dependencies | E5: Database | F5: Definition store | G5: Critical | H5: Create the tables specified in Chapter 3 4.5.11 with immutable versions and a dependency graph, plus a trigger that rejects a dependency cycle. | I5: Integration tests: create, version, publish, and reject a cycle. Version rows must be immutable, proved by an update attempt that fails. | J5: 12 | K5: Done | L5: Worker 1 | M5: T-087; T-088 | N5: T-090; T-092; T-095; T-099; T-106; T-114; T-128; T-183; T-243; T-244 | O5: M2: ~1 month from owner planning checkpoint; exact date not committed | P5: Release 1 MUST | Q5: DB/schema/migration | R5: 2.325 | S5: M2-P1 | T5: CLOSED BASELINE — no new start gate and no re-execution implied. Preserve accepted closure and clean owned scope; reopen only on a concrete, separately recorded regression. Downstream consumes the frozen contract. | U5: Own canonical DB/backend/security/API/infra. No W2-owned UI/admin task files and no W3 ML/Assistant runtime. | V5: Commit before downstream consumer starts; consumer must use the contract, not redesign producer-owned semantics. | W5: Product Foundation & Release Truth | X5: M2 P1 — Product Foundation & Release Truth. Release 1 is genuine early production / first-week customer work. | Y5: 0fd79e5e3516cdfd0ab5a73a02e16638fd02693a — subject not recovered | AA5: L2.5 | AB5: Unified definition store and immutable target/version governance | AC5: L5.6 | AD5: Build | AE5: D4; D5 | AF5: Core | AG5: R1 | AH5: Advances | AI5: =IF(Y5="","",Y5) -> 0fd79e5e3516cdfd0ab5a73a02e16638fd02693a — subject not recovered | AJ5: Inherited baseline estimate | AK5: v4.10.3 | AL5: Chapters 3/4 v4.10.3 — MD + illustrated Word; UI Coverage / UI Controls in this workbook | AM5: =IF(AND(ISNUMBER(J5),OR(AR5="INHERITED ESTIMATE",AR5="CONFIRMED ESTIMATE")),1,0) -> 1 | AO5: Recorded closed — inherited evidence | AP5: Inherited v2.22.0 intended record; no new runtime certification in this repair. | AR5: INHERITED ESTIMATE | AS5: =IF(AM5=1,J5,"") -> 12 | AT5: =IF(AND(AM5=1,ISNUMBER(R5)),R5,"") -> 2.325 | AU5: =IFERROR(INDEX('Source Review'!$B$2:$B$52,MATCH($A5,'Source Review'!$A$2:$A$52,0)),"NOT SOURCE-REVIEWED IN THIS PASS") -> NOT SOURCE-REVIEWED IN THIS PASS | AV5: =IFERROR(INDEX('Source Review'!$F$2:$F$52,MATCH($A5,'Source Review'!$A$2:$A$52,0)),"") | AW5: =IFERROR(INDEX('Source Review'!$G$2:$G$52,MATCH($A5,'Source Review'!$A$2:$A$52,0)),"") | AX5: =IFERROR(INDEX('Source Review'!$H$2:$H$52,MATCH($A5,'Source Review'!$A$2:$A$52,0)),"") | AY5: =IF(COUNTIF('Source Review'!$A$2:$A$52,$A5)>0,"UNCONFIRMED REVIEW ESTIMATE - not P80 or elapsed","NOT ESTIMATED IN THIS PASS") -> NOT ESTIMATED IN THIS PASS | AZ5: =IFERROR(INDEX('Source Review'!$I$2:$I$52,MATCH($A5,'Source Review'!$A$2:$A$52,0)),"") | BA5: =IFERROR(INDEX('Source Review'!$E$2:$E$52,MATCH($A5,'Source Review'!$A$2:$A$52,0)),"") | BB5: =IF(COUNTIF('Source Review'!$A$2:$A$52,$A5)>0,"14-Sep-2026 snapshot; later closure evidence separate; no live HEAD verification","")
A6: T-090 | B6: M2 | C6: P1 | D6: Move all five definition kinds onto the store | E6: Backend | F6: Definition store | G6: Critical | H6: Replace the M1 compatibility adapter behind IDefinitionService with the real implementation for all five purposes: S1 Transformation, S2 Pages and widgets and filters and master items, S3 Analysis, S4 Model, S5 Log rule. The old per-artifact tables become a compatibility projection and then are retired. v2.10.1 OUTCOME SEMANTICS BINDING. As part of canonical definition convergence, bind the already-frozen SM-06 OutcomeDefinition to the canonical immutable versioned definition authority; do not design a second outcome authority. The canonical binding preserves outcome_code, outcome_type, class_taxonomy_ref, ordinal_rank_map, grain_code, detection_position_code, detection_timestamp_field, direction, unit_code, censoring_policy and definition/version identity. Any legacy ml_outcome_definitions representation may remain only as a compatibility projection during convergence and must not remain an independent semantic authority. | I6: The M1 integration test written against IDefinitionService must pass unchanged, since it references no table name. That is the proof that the visible contract did not move. Publish an SM-06 OutcomeDefinition and resolve it back by exact immutable version. Changing detection_position_code, detection_timestamp_field, grain, taxonomy, ordinal map, direction, unit or censoring policy creates a new definition version rather than silently mutating published meaning. If a compatibility outcome representation remains during convergence, prove it resolves to the same canonical definition/version and cannot diverge into a second authority. | J6: 12 | K6: Done | L6: Worker 1 | M6: T-089 | N6: T-091; T-092; T-095; T-099; T-104; T-106; T-114; T-128; T-134; T-147; T-183; T-195; T-210; T-221; T-228; T-231; T-232; T-233; T-235; T-239; T-243; T-244 | O6: M2: ~1 month from owner planning checkpoint; exact date not committed | P6: Release 1 MUST | Q6: Backend/domain contract | R6: 1.8 | S6: M2-P1 | T6: CLOSED BASELINE — no new start gate and no re-execution implied. Preserve accepted closure and clean owned scope; reopen only on a concrete, separately recorded regression. Downstream consumes the frozen contract. | U6: Own canonical DB/backend/security/API/infra. No W2-owned UI/admin task files and no W3 ML/Assistant runtime. | V6: Downstream consumers wait for the committed T-090 authority. Handover/progress notes do not substitute for closure; the pack must apply, build, test, replay and commit on the user machine. | W6: Product Foundation & Release Truth | X6: CENTRAL 30-Aug-2026: canonical definition convergence remains full scope. Deliver the standard executable PowerShell pack; no Task-ID-less changes. | Y6: a6399d9c — subject not recovered | AA6: L5.6 | AB6: Unified definition-store semantics | AC6: L2.5 | AD6: Converge | AE6: D3; D4; D5 | AF6: Core | AG6: R1 | AH6: Advances | AI6: =IF(Y6="","",Y6) -> a6399d9c — subject not recovered | AJ6: Inherited baseline estimate | AK6: v4.10.3 | AL6: Chapters 3/4 v4.10.3 — MD + illustrated Word; UI Coverage / UI Controls in this workbook | AM6: =IF(AND(ISNUMBER(J6),OR(AR6="INHERITED ESTIMATE",AR6="CONFIRMED ESTIMATE")),1,0) -> 1 | AO6: Recorded closed — inherited evidence | AP6: Inherited v2.22.0 intended record; no new runtime certification in this repair. | AR6: INHERITED ESTIMATE | AS6: =IF(AM6=1,J6,"") -> 12 | AT6: =IF(AND(AM6=1,ISNUMBER(R6)),R6,"") -> 1.8 | AU6: =IFERROR(INDEX('Source Review'!$B$2:$B$52,MATCH($A6,'Source Review'!$A$2:$A$52,0)),"NOT SOURCE-REVIEWED IN THIS PASS") -> NOT SOURCE-REVIEWED IN THIS PASS | AV6: =IFERROR(INDEX('Source Review'!$F$2:$F$52,MATCH($A6,'Source Review'!$A$2:$A$52,0)),"") | AW6: =IFERROR(INDEX('Source Review'!$G$2:$G$52,MATCH($A6,'Source Review'!$A$2:$A$52,0)),"") | AX6: =IFERROR(INDEX('Source Review'!$H$2:$H$52,MATCH($A6,'Source Review'!$A$2:$A$52,0)),"") | AY6: =IF(COUNTIF('Source Review'!$A$2:$A$52,$A6)>0,"UNCONFIRMED REVIEW ESTIMATE - not P80 or elapsed","NOT ESTIMATED IN THIS PASS") -> NOT ESTIMATED IN THIS PASS | AZ6: =IFERROR(INDEX('Source Review'!$I$2:$I$52,MATCH($A6,'Source Review'!$A$2:$A$52,0)),"") | BA6: =IFERROR(INDEX('Source Review'!$E$2:$E$52,MATCH($A6,'Source Review'!$A$2:$A$52,0)),"") | BB6: =IF(COUNTIF('Source Review'!$A$2:$A$52,$A6)>0,"14-Sep-2026 snapshot; later closure evidence separate; no live HEAD verification","")
A7: T-091 | B7: M2 | C7: P1 | D7: Impact preview, export and import | E7: Backend | F7: Definition store | G7: Very Important | H7: Add dependency impact preview before a publish, and export and import of a definition with its dependencies, per Chapter 3 4.5.11. | I7: Publish a change to a definition three others depend on and confirm the preview lists all three before the publish is confirmed. Export and reimport into an empty database and confirm equality. | J7: 12 | K7: Done | L7: Worker 1 | M7: T-090 | N7: T-128; T-183 | O7: M2: ~1 month from owner planning checkpoint; exact date not committed | P7: Release 1 MUST | Q7: Backend/domain contract | R7: 1.8 | S7: M2-P1 | T7: CLOSED BASELINE — no new start gate and no re-execution implied. Preserve accepted closure and clean owned scope; reopen only on a concrete, separately recorded regression. Downstream consumes the frozen contract. | U7: Own canonical DB/backend/security/API/infra. No W2-owned UI/admin task files and no W3 ML/Assistant runtime. | V7: Commit before downstream consumer starts; consumer must use the contract, not redesign producer-owned semantics. | W7: Product Foundation & Release Truth | X7: M2 P1 — Product Foundation & Release Truth. Release 1 is genuine early production / first-week customer work. | Y7: c6d64289 — subject not recovered | AA7: L5.6 | AB7: Unified definition-store semantics | AC7: L2.5 | AD7: Build | AE7: D3; D5 | AF7: Core | AG7: R1 | AH7: Advances | AI7: =IF(Y7="","",Y7) -> c6d64289 — subject not recovered | AJ7: Inherited baseline estimate | AK7: v4.10.3 | AL7: Chapters 3/4 v4.10.3 — MD + illustrated Word; UI Coverage / UI Controls in this workbook | AM7: =IF(AND(ISNUMBER(J7),OR(AR7="INHERITED ESTIMATE",AR7="CONFIRMED ESTIMATE")),1,0) -> 1 | AO7: Recorded closed — inherited evidence | AP7: Inherited v2.22.0 intended record; no new runtime certification in this repair. | AR7: INHERITED ESTIMATE | AS7: =IF(AM7=1,J7,"") -> 12 | AT7: =IF(AND(AM7=1,ISNUMBER(R7)),R7,"") -> 1.8 | AU7: =IFERROR(INDEX('Source Review'!$B$2:$B$52,MATCH($A7,'Source Review'!$A$2:$A$52,0)),"NOT SOURCE-REVIEWED IN THIS PASS") -> NOT SOURCE-REVIEWED IN THIS PASS | AV7: =IFERROR(INDEX('Source Review'!$F$2:$F$52,MATCH($A7,'Source Review'!$A$2:$A$52,0)),"") | AW7: =IFERROR(INDEX('Source Review'!$G$2:$G$52,MATCH($A7,'Source Review'!$A$2:$A$52,0)),"") | AX7: =IFERROR(INDEX('Source Review'!$H$2:$H$52,MATCH($A7,'Source Review'!$A$2:$A$52,0)),"") | AY7: =IF(COUNTIF('Source Review'!$A$2:$A$52,$A7)>0,"UNCONFIRMED REVIEW ESTIMATE - not P80 or elapsed","NOT ESTIMATED IN THIS PASS") -> NOT ESTIMATED IN THIS PASS | AZ7: =IFERROR(INDEX('Source Review'!$I$2:$I$52,MATCH($A7,'Source Review'!$A$2:$A$52,0)),"") | BA7: =IFERROR(INDEX('Source Review'!$E$2:$E$52,MATCH($A7,'Source Review'!$A$2:$A$52,0)),"") | BB7: =IF(COUNTIF('Source Review'!$A$2:$A$52,$A7)>0,"14-Sep-2026 snapshot; later closure evidence separate; no live HEAD verification","")
A8: T-092 | B8: M2 | C8: P1 | D8: Registry authority: dimensions and measures as rows | E8: Backend | F8: Registry | G8: Critical | H8: Replace compiled dimension/measure catalogues with canonical registry projections over published definition versions. Registry rows must support customer-defined dimensions/measures without rebuild, plus analysis-grain metadata, signal/aggregation semantics and reference-derived measure roles. It remains a projection/serving authority, not a competing mutable definition store. | I8: Using the same binary, add a customer-shaped dimension and measure through definitions/registry data only and use them in an authored widget. No C#/React/product-SQL edit. Registry exposes declared grain and aggregation/reference metadata and rejects unresolved semantics. | J8: 12 | K8: Done | L8: Worker 1 | M8: T-089; T-090; T-210; T-231 | N8: T-093; T-094; T-128; T-183; T-212; T-215; T-228; T-237; T-247 | O8: M2: ~1 month from owner planning checkpoint; exact date not committed | P8: Release 1 MUST | Q8: Backend/domain contract | R8: 1.8 | S8: M2-P1 | T8: CLOSED BASELINE — no new start gate and no re-execution implied. Preserve accepted closure and clean owned scope; reopen only on a concrete, separately recorded regression. Downstream consumes the frozen contract. | U8: Own canonical DB/backend/security/API/infra. No W2-owned UI/admin task files and no W3 ML/Assistant runtime. | V8: Commit before downstream consumer starts; consumer must use the contract, not redesign producer-owned semantics. | W8: Product Foundation & Release Truth | X8: M2 P1 — Product Foundation & Release Truth. Release 1 is genuine early production / first-week customer work. | Y8: ab2962a4; 7cad36e4 — registry authority closure commits | Z8: 46267 | AA8: L3.9 | AB8: Master items, bookmarks and saved views | AC8: L5.1 | AD8: Build | AE8: D1; D3; D5 | AF8: Core | AG8: R1 | AH8: Advances | AI8: =IF(Y8="","",Y8) -> ab2962a4; 7cad36e4 — registry authority closure commits | AJ8: Inherited baseline estimate | AK8: v4.10.3 | AL8: Chapters 3/4 v4.10.3 — MD + illustrated Word; UI Coverage / UI Controls in this workbook | AM8: =IF(AND(ISNUMBER(J8),OR(AR8="INHERITED ESTIMATE",AR8="CONFIRMED ESTIMATE")),1,0) -> 1 | AO8: Recorded closed — inherited evidence | AP8: Inherited v2.22.0 intended record; no new runtime certification in this repair. | AR8: INHERITED ESTIMATE | AS8: =IF(AM8=1,J8,"") -> 12 | AT8: =IF(AND(AM8=1,ISNUMBER(R8)),R8,"") -> 1.8 | AU8: =IFERROR(INDEX('Source Review'!$B$2:$B$52,MATCH($A8,'Source Review'!$A$2:$A$52,0)),"NOT SOURCE-REVIEWED IN THIS PASS") -> NOT SOURCE-REVIEWED IN THIS PASS | AV8: =IFERROR(INDEX('Source Review'!$F$2:$F$52,MATCH($A8,'Source Review'!$A$2:$A$52,0)),"") | AW8: =IFERROR(INDEX('Source Review'!$G$2:$G$52,MATCH($A8,'Source Review'!$A$2:$A$52,0)),"") | AX8: =IFERROR(INDEX('Source Review'!$H$2:$H$52,MATCH($A8,'Source Review'!$A$2:$A$52,0)),"") | AY8: =IF(COUNTIF('Source Review'!$A$2:$A$52,$A8)>0,"UNCONFIRMED REVIEW ESTIMATE - not P80 or elapsed","NOT ESTIMATED IN THIS PASS") -> NOT ESTIMATED IN THIS PASS | AZ8: =IFERROR(INDEX('Source Review'!$I$2:$I$52,MATCH($A8,'Source Review'!$A$2:$A$52,0)),"") | BA8: =IFERROR(INDEX('Source Review'!$E$2:$E$52,MATCH($A8,'Source Review'!$A$2:$A$52,0)),"") | BB8: =IF(COUNTIF('Source Review'!$A$2:$A$52,$A8)>0,"14-Sep-2026 snapshot; later closure evidence separate; no live HEAD verification","")
A9: T-093 | B9: M2 | C9: P1 | D9: Plant-vocabulary sweep, part 1: build the term list and the architecture test | E9: Backend | F9: Registry | G9: Very Important | H9: Rule 1 needs an enforcement mechanism before the sweep, or the sweep is a one-off. Create a registry-held list of plant terms (the term list is itself DATA, never a compiled constant) and an architecture test that fails the build when any listed term appears in product code outside registry data, seed content or test fixtures. Seed the list from the dimension names already found compiled into DashboardWidgetQuerySafetyRegistry: ProductFamily, GradeOrRecipe, ShiftCode, DefectType, RiskClass. | I9: Add a term to the list and confirm the build goes red on an existing violation, then goes green once that violation is fixed. Confirm removing a term from the list does not require a code change. | J9: 6 | K9: Done | L9: Worker 1 | M9: T-092; T-206 | N9: T-094; T-128; T-183 | O9: M2: ~1 month from owner planning checkpoint; exact date not committed | P9: Release 1 MUST | Q9: Backend/domain contract | R9: 0.9 | S9: M2-P1 | T9: CLOSED BASELINE — no new start gate and no re-execution implied. Preserve accepted closure and clean owned scope; reopen only on a concrete, separately recorded regression. Downstream consumes the frozen contract. | U9: Own canonical DB/backend/security/API/infra. No W2-owned UI/admin task files and no W3 ML/Assistant runtime. | V9: Commit before downstream consumer starts; consumer must use the contract, not redesign producer-owned semantics. | W9: Product Foundation & Release Truth | X9: M2 P1 — Product Foundation & Release Truth. Release 1 is genuine early production / first-week customer work. | Y9: 4e2e0f654b93ceed2ecdfbce4d3c1768550b3079 — T-093 govern plant vocabulary as data-driven genericity debt | Z9: 46268 | AA9: L5.1 | AB9: Canonical entity catalogue | AD9: Build | AE9: D3; D5 | AF9: Core | AG9: R1 | AH9: Advances | AI9: =IF(Y9="","",Y9) -> 4e2e0f654b93ceed2ecdfbce4d3c1768550b3079 — T-093 govern plant vocabulary as data-driven genericity debt | AJ9: Inherited baseline estimate | AK9: v4.10.3 | AL9: Chapters 3/4 v4.10.3 — MD + illustrated Word; UI Coverage / UI Controls in this workbook | AM9: =IF(AND(ISNUMBER(J9),OR(AR9="INHERITED ESTIMATE",AR9="CONFIRMED ESTIMATE")),1,0) -> 1 | AO9: Recorded closed — inherited evidence | AP9: Inherited v2.22.0 intended record; no new runtime certification in this repair. | AR9: INHERITED ESTIMATE | AS9: =IF(AM9=1,J9,"") -> 6 | AT9: =IF(AND(AM9=1,ISNUMBER(R9)),R9,"") -> 0.9 | AU9: =IFERROR(INDEX('Source Review'!$B$2:$B$52,MATCH($A9,'Source Review'!$A$2:$A$52,0)),"NOT SOURCE-REVIEWED IN THIS PASS") -> NOT SOURCE-REVIEWED IN THIS PASS | AV9: =IFERROR(INDEX('Source Review'!$F$2:$F$52,MATCH($A9,'Source Review'!$A$2:$A$52,0)),"") | AW9: =IFERROR(INDEX('Source Review'!$G$2:$G$52,MATCH($A9,'Source Review'!$A$2:$A$52,0)),"") | AX9: =IFERROR(INDEX('Source Review'!$H$2:$H$52,MATCH($A9,'Source Review'!$A$2:$A$52,0)),"") | AY9: =IF(COUNTIF('Source Review'!$A$2:$A$52,$A9)>0,"UNCONFIRMED REVIEW ESTIMATE - not P80 or elapsed","NOT ESTIMATED IN THIS PASS") -> NOT ESTIMATED IN THIS PASS | AZ9: =IFERROR(INDEX('Source Review'!$I$2:$I$52,MATCH($A9,'Source Review'!$A$2:$A$52,0)),"") | BA9: =IFERROR(INDEX('Source Review'!$E$2:$E$52,MATCH($A9,'Source Review'!$A$2:$A$52,0)),"") | BB9: =IF(COUNTIF('Source Review'!$A$2:$A$52,$A9)>0,"14-Sep-2026 snapshot; later closure evidence separate; no live HEAD verification","")
A10: T-094 | B10: M2 | C10: P1 | D10: Plant-vocabulary sweep, part 2: remove hardcoded universal grain and industry vocabulary | E10: Backend | F10: Registry | G10: Very Important | H10: Clear generic-runtime/demo-vocabulary violations without replacing one industry noun with another. Complete the declared-dimension execution path on BOTH runtime wire surfaces: (A) persisted widget execution via DashboardWidgetFiltersDto/declared keyed dimensions and (B) workspace/global dashboard query execution via DashboardQueryDto and the overview/quality/risk/data-quality/materials routes. Remove fixed universal grain/industry vocabulary from DashboardReferenceDataDto and the frontend consumers by resolving published registry definitions, canonical members and governed Analysis Subject/relationship authority. The target contract is definition/registry member -> relationship/path resolution -> Analysis Subject -> typed refusal; the current direct single-reference resolver is an interim implementation until T-095/T-096 path authority lands. No presentation vocabulary becomes product authority. | I10: Using the same binary, author a foreign/customer-shaped dimension and prove it filters both a persisted widget and the workspace/global route surface through the same published definition/member identity. Both surfaces must return the same typed refusal when the dimension is undeclared, inactive, unmapped, has no subject path, or becomes ambiguous. No compiled fallback to defectType/riskClass/shiftCode or a universal material grain. Frontend consumers use the keyed contract. Wave-C genericity arithmetic remains exact: every known fingerprint is retired or explicitly lawful; unknown=0. | J10: 24 | K10: Done | L10: Worker 1 | M10: T-092; T-093; T-209 | N10: T-095; T-128; T-183; T-196; T-253; T-256; T-258 | O10: M2: ~1 month from owner planning checkpoint; exact date not committed | P10: Release 1 MUST | Q10: Backend/domain contract | R10: 3.6 | S10: M2-P1 | T10: CLOSED BASELINE — no new start gate and no re-execution implied. Preserve accepted closure and clean owned scope; reopen only on a concrete, separately recorded regression. Downstream consumes the frozen contract. | U10: Own canonical DB/backend/security/API/infra. No W2-owned UI/admin task files and no W3 ML/Assistant runtime. | V10: Commit before downstream consumer starts; consumer must use the contract, not redesign producer-owned semantics. | W10: Product Foundation & Release Truth | X10: CENTRAL 04-Sep-2026: T-094 remains open. Scope is formally amended from one wire to both declared-dimension execution surfaces. No new task is created while T-094 is open; after closure any new surface requires a new Task ID. | Y10: 377aabdffb27d651d30537ce5228ee4afe268526; 6ab97ee2; e74ecd1c; 5a967f1b0ab45961c8b8a880bb4fdec53a783134 — final: T-094 close keyed declared-dimension cutover and genericity reconciliation | Z10: 46272 | AA10: L5.1 | AB10: Canonical entity catalogue | AC10: L5.3 | AD10: Build | AE10: D1; D3; D5 | AF10: Core | AG10: R1 | AH10: Advances | AI10: =IF(Y10="","",Y10) -> 377aabdffb27d651d30537ce5228ee4afe268526; 6ab97ee2; e74ecd1c; 5a967f1b0ab45961c8b8a880bb4fdec53a783134 — final: T-094 close keyed declared-dimension cutover and genericity reconciliation | AJ10: Inherited baseline estimate | AK10: v4.10.3 | AL10: Chapters 3/4 v4.10.3 — MD + illustrated Word; UI Coverage / UI Controls in this workbook | AM10: =IF(AND(ISNUMBER(J10),OR(AR10="INHERITED ESTIMATE",AR10="CONFIRMED ESTIMATE")),1,0) -> 1 | AO10: Recorded closed — inherited evidence | AP10: Inherited v2.22.0 intended record; no new runtime certification in this repair. | AR10: INHERITED ESTIMATE | AS10: =IF(AM10=1,J10,"") -> 24 | AT10: =IF(AND(AM10=1,ISNUMBER(R10)),R10,"") -> 3.6 | AU10: =IFERROR(INDEX('Source Review'!$B$2:$B$52,MATCH($A10,'Source Review'!$A$2:$A$52,0)),"NOT SOURCE-REVIEWED IN THIS PASS") -> NOT SOURCE-REVIEWED IN THIS PASS | AV10: =IFERROR(INDEX('Source Review'!$F$2:$F$52,MATCH($A10,'Source Review'!$A$2:$A$52,0)),"") | AW10: =IFERROR(INDEX('Source Review'!$G$2:$G$52,MATCH($A10,'Source Review'!$A$2:$A$52,0)),"") | AX10: =IFERROR(INDEX('Source Review'!$H$2:$H$52,MATCH($A10,'Source Review'!$A$2:$A$52,0)),"") | AY10: =IF(COUNTIF('Source Review'!$A$2:$A$52,$A10)>0,"UNCONFIRMED REVIEW ESTIMATE - not P80 or elapsed","NOT ESTIMATED IN THIS PASS") -> NOT ESTIMATED IN THIS PASS | AZ10: =IFERROR(INDEX('Source Review'!$I$2:$I$52,MATCH($A10,'Source Review'!$A$2:$A$52,0)),"") | BA10: =IFERROR(INDEX('Source Review'!$E$2:$E$52,MATCH($A10,'Source Review'!$A$2:$A$52,0)),"") | BB10: =IF(COUNTIF('Source Review'!$A$2:$A$52,$A10)>0,"14-Sep-2026 snapshot; later closure evidence separate; no live HEAD verification","")
A11: T-201 | B11: M2 | C11: P1 | D11: Freeze the successful M1 presentation baseline and transfer programme authority to M2 | E11: Programme | F11: Release baseline | G11: Critical | H11: Resolve the shared dirty tree, keep/revert the associative change on evidence, commit exact owned files, tag/freeze the successful presentation baseline, and formally stop presentation-only feature/page/data work. Remaining generic defects move to M2-P0 owners rather than being completed as M1 content. | I11: Clean index and explicit foreign-file inventory; immutable release/tag or equivalent frozen artifact; presentation profile still launches; one ledger lists every unclosed M1 item as frozen, superseded, or consumed by a named M2 task. No customer-demo-only task remains on the September critical path. | J11: 4 | K11: Done | L11: Worker 1 | N11: T-086; T-202; T-203; T-204; T-205; T-206; T-207; T-208; T-213; T-241 | O11: M2: ~1 month from owner planning checkpoint; exact date not committed | P11: Release 1 MUST | Q11: Release / governance | R11: 1.5 | S11: M2-P1 | T11: CLOSED BASELINE — no new start gate and no re-execution implied. Preserve accepted closure and clean owned scope; reopen only on a concrete, separately recorded regression. Downstream consumes the frozen contract. | U11: Git/worktree ownership + release/tag only. | V11: After commit/tag, all workers consume the frozen baseline; nobody reopens M1 presentation scope without a proven regression. | W11: Product Foundation & Release Truth | X11: M2 P1 — Product Foundation & Release Truth. Release 1 is genuine early production / first-week customer work. | Y11: BASELINE HEAD 7da9d46ed29545f1c4f4686fa82c117c08b9fc86; TAG m1-presentation-baseline-2026-08-21 — no task commit; tag is closure artifact | Z11: 46258 | AA11: L8.8 | AB11: C1–C4 performance certification and golden-journey release gate | AD11: Validate | AE11: D1; D5 | AF11: Core | AG11: R1 | AH11: Advances | AI11: =IF(Y11="","",Y11) -> BASELINE HEAD 7da9d46ed29545f1c4f4686fa82c117c08b9fc86; TAG m1-presentation-baseline-2026-08-21 — no task commit; tag is closure artifact | AJ11: Inherited baseline estimate | AK11: v4.10.3 | AL11: Chapters 3/4 v4.10.3 — MD + illustrated Word; UI Coverage / UI Controls in this workbook | AM11: =IF(AND(ISNUMBER(J11),OR(AR11="INHERITED ESTIMATE",AR11="CONFIRMED ESTIMATE")),1,0) -> 1 | AO11: Recorded closed — inherited evidence | AP11: Inherited v2.22.0 intended record; no new runtime certification in this repair. | AR11: INHERITED ESTIMATE | AS11: =IF(AM11=1,J11,"") -> 4 | AT11: =IF(AND(AM11=1,ISNUMBER(R11)),R11,"") -> 1.5 | AU11: =IFERROR(INDEX('Source Review'!$B$2:$B$52,MATCH($A11,'Source Review'!$A$2:$A$52,0)),"NOT SOURCE-REVIEWED IN THIS PASS") -> NOT SOURCE-REVIEWED IN THIS PASS | AV11: =IFERROR(INDEX('Source Review'!$F$2:$F$52,MATCH($A11,'Source Review'!$A$2:$A$52,0)),"") | AW11: =IFERROR(INDEX('Source Review'!$G$2:$G$52,MATCH($A11,'Source Review'!$A$2:$A$52,0)),"") | AX11: =IFERROR(INDEX('Source Review'!$H$2:$H$52,MATCH($A11,'Source Review'!$A$2:$A$52,0)),"") | AY11: =IF(COUNTIF('Source Review'!$A$2:$A$52,$A11)>0,"UNCONFIRMED REVIEW ESTIMATE - not P80 or elapsed","NOT ESTIMATED IN THIS PASS") -> NOT ESTIMATED IN THIS PASS | AZ11: =IFERROR(INDEX('Source Review'!$I$2:$I$52,MATCH($A11,'Source Review'!$A$2:$A$52,0)),"") | BA11: =IFERROR(INDEX('Source Review'!$E$2:$E$52,MATCH($A11,'Source Review'!$A$2:$A$52,0)),"") | BB11: =IF(COUNTIF('Source Review'!$A$2:$A$52,$A11)>0,"14-Sep-2026 snapshot; later closure evidence separate; no live HEAD verification","")
A12: T-202 | B12: M2 | C12: P1 | D12: Persisted page/widget definition replay gate | E12: Quality | F12: Release Truth | G12: Critical | H12: Enumerate every active customer-facing page/widget definition from the real database and execute its actual query contract against the release API/database. Validate declared terminal semantics, row/population evidence and compatibility. This gate tests the product as persisted, not merely source-code paths. | I12: Every active persisted widget executes with 2xx plus Populated/Empty/Blocked/Refused as documented; unexpected 4xx/5xx is a failure. Deliberately corrupt one dimension/measure combination and prove the gate fails. Restore and prove green. Emit machine-readable report naming definition/page/widget. | J12: 10 | K12: Done | L12: Worker 2 | M12: T-201 | N12: T-212; T-248 | O12: M2: ~1 month from owner planning checkpoint; exact date not committed | P12: Release 1 MUST | Q12: E2E / integration gate | R12: 4 | S12: M2-P1 | T12: CLOSED BASELINE — no new start gate and no re-execution implied. Preserve accepted closure and clean owned scope; reopen only on a concrete, separately recorded regression. Downstream consumes the frozen contract. | U12: Frontend E2E + dashboard query test harness; no canonical schema edits. | V12: T-150 later consumes this gate; it does not redesign it. | W12: Product Foundation & Release Truth | X12: M2 P1 — Product Foundation & Release Truth. Release 1 is genuine early production / first-week customer work. | Y12: ad37c324 — Add persisted definition replay gate for release truth | Z12: 46259 | AA12: L8.8 | AB12: C1–C4 performance certification and golden-journey release gate | AC12: L3.1; L3.4 | AD12: Validate | AE12: D2; D5 | AF12: Core | AG12: R1 | AH12: Advances | AI12: =IF(Y12="","",Y12) -> ad37c324 — Add persisted definition replay gate for release truth | AJ12: Inherited baseline estimate | AK12: v4.10.3 | AL12: Chapters 3/4 v4.10.3 — MD + illustrated Word; UI Coverage / UI Controls in this workbook | AM12: =IF(AND(ISNUMBER(J12),OR(AR12="INHERITED ESTIMATE",AR12="CONFIRMED ESTIMATE")),1,0) -> 1 | AO12: Recorded closed — inherited evidence | AP12: Inherited v2.22.0 intended record; no new runtime certification in this repair. | AR12: INHERITED ESTIMATE | AS12: =IF(AM12=1,J12,"") -> 10 | AT12: =IF(AND(AM12=1,ISNUMBER(R12)),R12,"") -> 4 | AU12: =IFERROR(INDEX('Source Review'!$B$2:$B$52,MATCH($A12,'Source Review'!$A$2:$A$52,0)),"NOT SOURCE-REVIEWED IN THIS PASS") -> NOT SOURCE-REVIEWED IN THIS PASS | AV12: =IFERROR(INDEX('Source Review'!$F$2:$F$52,MATCH($A12,'Source Review'!$A$2:$A$52,0)),"") | AW12: =IFERROR(INDEX('Source Review'!$G$2:$G$52,MATCH($A12,'Source Review'!$A$2:$A$52,0)),"") | AX12: =IFERROR(INDEX('Source Review'!$H$2:$H$52,MATCH($A12,'Source Review'!$A$2:$A$52,0)),"") | AY12: =IF(COUNTIF('Source Review'!$A$2:$A$52,$A12)>0,"UNCONFIRMED REVIEW ESTIMATE - not P80 or elapsed","NOT ESTIMATED IN THIS PASS") -> NOT ESTIMATED IN THIS PASS | AZ12: =IFERROR(INDEX('Source Review'!$I$2:$I$52,MATCH($A12,'Source Review'!$A$2:$A$52,0)),"") | BA12: =IFERROR(INDEX('Source Review'!$E$2:$E$52,MATCH($A12,'Source Review'!$A$2:$A$52,0)),"") | BB12: =IF(COUNTIF('Source Review'!$A$2:$A$52,$A12)>0,"14-Sep-2026 snapshot; later closure evidence separate; no live HEAD verification","")
A13: T-203 | B13: M2 | C13: P1 | D13: Customer-route network, console and widget-state invariant | E13: Quality | F13: Release Truth | G13: Critical | H13: For every customer-reachable route, navigate and settle against the real API; fail on unexpected HTTP >=400, failed required request, uncaught JS exception, unhandled console error, error toast, or widget Failed state. Record route/request/widget evidence. | I13: Inject one failing API response and one uncaught render error and prove the route gate fails for the named cause. With faults removed, every customer route settles with zero unexpected network/console/widget failures. | J13: 10 | K13: Done | L13: Worker 2 | M13: T-201 | N13: T-222; T-248 | O13: M2: ~1 month from owner planning checkpoint; exact date not committed | P13: Release 1 MUST | Q13: Playwright / session | R13: 4 | S13: M2-P1 | T13: CLOSED BASELINE — no new start gate and no re-execution implied. Preserve accepted closure and clean owned scope; reopen only on a concrete, separately recorded regression. Downstream consumes the frozen contract. | U13: Frontend E2E/session harness. | V13: All later customer-facing feature tasks must add their route to this gate before close. | W13: Product Foundation & Release Truth | X13: M2 P1 — Product Foundation & Release Truth. Release 1 is genuine early production / first-week customer work. | Y13: cd1a450e — Add customer route invariant gate with durable evidence | Z13: 46259 | AA13: L8.8 | AB13: C1–C4 performance certification and golden-journey release gate | AC13: L6.7 | AD13: Validate | AE13: D2; D5 | AF13: Core | AG13: R1 | AH13: Advances | AI13: =IF(Y13="","",Y13) -> cd1a450e — Add customer route invariant gate with durable evidence | AJ13: Inherited baseline estimate | AK13: v4.10.3 | AL13: Chapters 3/4 v4.10.3 — MD + illustrated Word; UI Coverage / UI Controls in this workbook | AM13: =IF(AND(ISNUMBER(J13),OR(AR13="INHERITED ESTIMATE",AR13="CONFIRMED ESTIMATE")),1,0) -> 1 | AO13: Recorded closed — inherited evidence | AP13: Inherited v2.22.0 intended record; no new runtime certification in this repair. | AR13: INHERITED ESTIMATE | AS13: =IF(AM13=1,J13,"") -> 10 | AT13: =IF(AND(AM13=1,ISNUMBER(R13)),R13,"") -> 4 | AU13: =IFERROR(INDEX('Source Review'!$B$2:$B$52,MATCH($A13,'Source Review'!$A$2:$A$52,0)),"NOT SOURCE-REVIEWED IN THIS PASS") -> NOT SOURCE-REVIEWED IN THIS PASS | AV13: =IFERROR(INDEX('Source Review'!$F$2:$F$52,MATCH($A13,'Source Review'!$A$2:$A$52,0)),"") | AW13: =IFERROR(INDEX('Source Review'!$G$2:$G$52,MATCH($A13,'Source Review'!$A$2:$A$52,0)),"") | AX13: =IFERROR(INDEX('Source Review'!$H$2:$H$52,MATCH($A13,'Source Review'!$A$2:$A$52,0)),"") | AY13: =IF(COUNTIF('Source Review'!$A$2:$A$52,$A13)>0,"UNCONFIRMED REVIEW ESTIMATE - not P80 or elapsed","NOT ESTIMATED IN THIS PASS") -> NOT ESTIMATED IN THIS PASS | AZ13: =IFERROR(INDEX('Source Review'!$I$2:$I$52,MATCH($A13,'Source Review'!$A$2:$A$52,0)),"") | BA13: =IFERROR(INDEX('Source Review'!$E$2:$E$52,MATCH($A13,'Source Review'!$A$2:$A$52,0)),"") | BB13: =IF(COUNTIF('Source Review'!$A$2:$A$52,$A13)>0,"14-Sep-2026 snapshot; later closure evidence separate; no live HEAD verification","")
A14: T-204 | B14: M2 | C14: P1 | D14: Associative cross-filter state-machine certification | E14: Frontend | F14: Associative BI | G14: Critical | H14: Replace click-smoke acceptance with a state-machine proof: capture widgets A/B/C, click X in A, assert selection state, assert B/C re-query with X, assert returned populations and visible results change, clear X and assert restoration. Execute across interactive renderer families. | I14: Bar, line, scatter, heatmap, table-row and interactive KPI families each prove selection propagation, dependent request mutation, population/result change, and restoration. A deliberate broken dependency-array/bridge falsification must fail the test. | J14: 10 | K14: Done | L14: Worker 2 | M14: T-201 | N14: T-222; T-248 | O14: M2: ~1 month from owner planning checkpoint; exact date not committed | P14: Release 1 MUST | Q14: Frontend behavioural E2E | R14: 4.25 | S14: M2-P1 | T14: CLOSED BASELINE — no new start gate and no re-execution implied. Preserve accepted closure and clean owned scope; reopen only on a concrete, separately recorded regression. Downstream consumes the frozen contract. | U14: AssociativeContext/filter bridge + E2E tests; no unrelated chart redesign. | V14: This task supersedes using browser walking as the acceptance of cross-filtering. | W14: Product Foundation & Release Truth | X14: M2 P1 — Product Foundation & Release Truth. Release 1 is genuine early production / first-week customer work. | Y14: c6491e2d — closure-state HEAD; exact task commit subject not independently recovered | Z14: 46265 | AA14: L3.2 | AB14: Associative engine and selection strip | AD14: Validate | AE14: D2; D5 | AF14: Core | AG14: R1 | AH14: Advances | AI14: =IF(Y14="","",Y14) -> c6491e2d — closure-state HEAD; exact task commit subject not independently recovered | AJ14: Inherited baseline estimate | AK14: v4.10.3 | AL14: Chapters 3/4 v4.10.3 — MD + illustrated Word; UI Coverage / UI Controls in this workbook | AM14: =IF(AND(ISNUMBER(J14),OR(AR14="INHERITED ESTIMATE",AR14="CONFIRMED ESTIMATE")),1,0) -> 1 | AO14: Recorded closed — inherited evidence | AP14: Inherited v2.22.0 intended record; no new runtime certification in this repair. | AR14: INHERITED ESTIMATE | AS14: =IF(AM14=1,J14,"") -> 10 | AT14: =IF(AND(AM14=1,ISNUMBER(R14)),R14,"") -> 4.25 | AU14: =IFERROR(INDEX('Source Review'!$B$2:$B$52,MATCH($A14,'Source Review'!$A$2:$A$52,0)),"NOT SOURCE-REVIEWED IN THIS PASS") -> NOT SOURCE-REVIEWED IN THIS PASS | AV14: =IFERROR(INDEX('Source Review'!$F$2:$F$52,MATCH($A14,'Source Review'!$A$2:$A$52,0)),"") | AW14: =IFERROR(INDEX('Source Review'!$G$2:$G$52,MATCH($A14,'Source Review'!$A$2:$A$52,0)),"") | AX14: =IFERROR(INDEX('Source Review'!$H$2:$H$52,MATCH($A14,'Source Review'!$A$2:$A$52,0)),"") | AY14: =IF(COUNTIF('Source Review'!$A$2:$A$52,$A14)>0,"UNCONFIRMED REVIEW ESTIMATE - not P80 or elapsed","NOT ESTIMATED IN THIS PASS") -> NOT ESTIMATED IN THIS PASS | AZ14: =IFERROR(INDEX('Source Review'!$I$2:$I$52,MATCH($A14,'Source Review'!$A$2:$A$52,0)),"") | BA14: =IFERROR(INDEX('Source Review'!$E$2:$E$52,MATCH($A14,'Source Review'!$A$2:$A$52,0)),"") | BB14: =IF(COUNTIF('Source Review'!$A$2:$A$52,$A14)>0,"14-Sep-2026 snapshot; later closure evidence separate; no live HEAD verification","")
A15: T-205 | B15: M2 | C15: P1 | D15: Frontend global suite termination and machine-readable gate | E15: Frontend | F15: Test infrastructure | G15: Very Important | H15: Make the global frontend unit/component suite terminate deterministically, produce a machine-readable result, and fail the pipeline on non-termination, timeout, skipped mandatory tests or leaked handles. | I15: Run the full suite twice from clean processes under the declared timeout; both terminate with identical pass/fail/skip counts and machine-readable output. Inject a leaked handle/non-terminating test and prove the gate goes red. | J15: 8 | K15: Done | L15: Worker 2 | M15: T-201 | N15: T-150; T-248; T-250; T-255; T-257 | O15: M2: ~1 month from owner planning checkpoint; exact date not committed | P15: Release 1 MUST | Q15: Frontend test infrastructure | R15: 3.2 | S15: M2-P1 | T15: CLOSED BASELINE — no new start gate and no re-execution implied. Preserve accepted closure and clean owned scope; reopen only on a concrete, separately recorded regression. Downstream consumes the frozen contract. | U15: Frontend test runner/config only. | V15: T-205 remains closed. Deterministic suite-truth mutations are owned by T-250; do not amend or reopen T-205 for product/test corrections. | W15: Product Foundation & Release Truth | X15: CENTRAL 30-Aug-2026: T-205 CLOSED GREEN at b7fcc890. The gate correctly reports suite truth; bounded corrections are a separate explicit task. | Y15: b7fcc890 — Gate the frontend suite on deterministic termination and machine-readable evidence | Z15: 46264 | AA15: L8.2 | AB15: Test architecture with disposable isolated databases | AD15: Validate | AE15: D2; D5 | AF15: Core | AG15: R1 | AH15: Advances | AI15: =IF(Y15="","",Y15) -> b7fcc890 — Gate the frontend suite on deterministic termination and machine-readable evidence | AJ15: Inherited baseline estimate | AK15: v4.10.3 | AL15: Chapters 3/4 v4.10.3 — MD + illustrated Word; UI Coverage / UI Controls in this workbook | AM15: =IF(AND(ISNUMBER(J15),OR(AR15="INHERITED ESTIMATE",AR15="CONFIRMED ESTIMATE")),1,0) -> 1 | AO15: Recorded closed — inherited evidence | AP15: Inherited v2.22.0 intended record; no new runtime certification in this repair. | AR15: INHERITED ESTIMATE | AS15: =IF(AM15=1,J15,"") -> 8 | AT15: =IF(AND(AM15=1,ISNUMBER(R15)),R15,"") -> 3.2 | AU15: =IFERROR(INDEX('Source Review'!$B$2:$B$52,MATCH($A15,'Source Review'!$A$2:$A$52,0)),"NOT SOURCE-REVIEWED IN THIS PASS") -> NOT SOURCE-REVIEWED IN THIS PASS | AV15: =IFERROR(INDEX('Source Review'!$F$2:$F$52,MATCH($A15,'Source Review'!$A$2:$A$52,0)),"") | AW15: =IFERROR(INDEX('Source Review'!$G$2:$G$52,MATCH($A15,'Source Review'!$A$2:$A$52,0)),"") | AX15: =IFERROR(INDEX('Source Review'!$H$2:$H$52,MATCH($A15,'Source Review'!$A$2:$A$52,0)),"") | AY15: =IF(COUNTIF('Source Review'!$A$2:$A$52,$A15)>0,"UNCONFIRMED REVIEW ESTIMATE - not P80 or elapsed","NOT ESTIMATED IN THIS PASS") -> NOT ESTIMATED IN THIS PASS | AZ15: =IFERROR(INDEX('Source Review'!$I$2:$I$52,MATCH($A15,'Source Review'!$A$2:$A$52,0)),"") | BA15: =IFERROR(INDEX('Source Review'!$E$2:$E$52,MATCH($A15,'Source Review'!$A$2:$A$52,0)),"") | BB15: =IF(COUNTIF('Source Review'!$A$2:$A$52,$A15)>0,"14-Sep-2026 snapshot; later closure evidence separate; no live HEAD verification","")
A16: T-206 | B16: M2 | C16: P1 | D16: Scope-aware genericity architecture gate | E16: Architecture | F16: Genericity | G16: Critical | H16: Create a scope-aware architecture test that forbids customer/demo/industry vocabulary and compiled customer dimension/grain authorities inside generic runtime/engine/API contracts while allowing that vocabulary in explicitly classified fixtures, mappings and documentation. Include detection of compiled dimension arrays and implicit grain defaults. | I16: Falsify the gate with a generic-runtime 'coil' fallback, a compiled customer dimension, and an industry-specific class; each fails. The same terms in approved fixture paths remain allowed. Gate consumes configured path/authority classes, not a naive whole-repo negative text scan. | J16: 8 | K16: Done | L16: Worker 3 | M16: T-201 | N16: T-093; T-213 | O16: M2: ~1 month from owner planning checkpoint; exact date not committed | P16: Release 1 MUST | Q16: Architecture/test | R16: 2 | S16: M2-P1 | T16: CLOSED BASELINE — no new start gate and no re-execution implied. Preserve accepted closure and clean owned scope; reopen only on a concrete, separately recorded regression. Downstream consumes the frozen contract. | U16: Architecture/genericity tests only; no W1 schema or W2 UI mutation. | V16: Violations are routed to the owning task/file; Worker 3 does not fix foreign files. | W16: Product Foundation & Release Truth | X16: M2 P1 — Product Foundation & Release Truth. Release 1 is genuine early production / first-week customer work. | Y16: Not recovered from reviewed sessions | AA16: L5.1 | AB16: Canonical entity catalogue | AD16: Validate | AE16: D1; D5 | AF16: Core | AG16: R1 | AH16: Advances | AI16: =IF(Y16="","",Y16) -> Not recovered from reviewed sessions | AJ16: Inherited baseline estimate | AK16: v4.10.3 | AL16: Chapters 3/4 v4.10.3 — MD + illustrated Word; UI Coverage / UI Controls in this workbook | AM16: =IF(AND(ISNUMBER(J16),OR(AR16="INHERITED ESTIMATE",AR16="CONFIRMED ESTIMATE")),1,0) -> 1 | AO16: Recorded closed — inherited evidence | AP16: Inherited v2.22.0 intended record; no new runtime certification in this repair. | AR16: INHERITED ESTIMATE | AS16: =IF(AM16=1,J16,"") -> 8 | AT16: =IF(AND(AM16=1,ISNUMBER(R16)),R16,"") -> 2 | AU16: =IFERROR(INDEX('Source Review'!$B$2:$B$52,MATCH($A16,'Source Review'!$A$2:$A$52,0)),"NOT SOURCE-REVIEWED IN THIS PASS") -> NOT SOURCE-REVIEWED IN THIS PASS | AV16: =IFERROR(INDEX('Source Review'!$F$2:$F$52,MATCH($A16,'Source Review'!$A$2:$A$52,0)),"") | AW16: =IFERROR(INDEX('Source Review'!$G$2:$G$52,MATCH($A16,'Source Review'!$A$2:$A$52,0)),"") | AX16: =IFERROR(INDEX('Source Review'!$H$2:$H$52,MATCH($A16,'Source Review'!$A$2:$A$52,0)),"") | AY16: =IF(COUNTIF('Source Review'!$A$2:$A$52,$A16)>0,"UNCONFIRMED REVIEW ESTIMATE - not P80 or elapsed","NOT ESTIMATED IN THIS PASS") -> NOT ESTIMATED IN THIS PASS | AZ16: =IFERROR(INDEX('Source Review'!$I$2:$I$52,MATCH($A16,'Source Review'!$A$2:$A$52,0)),"") | BA16: =IFERROR(INDEX('Source Review'!$E$2:$E$52,MATCH($A16,'Source Review'!$A$2:$A$52,0)),"") | BB16: =IF(COUNTIF('Source Review'!$A$2:$A$52,$A16)>0,"14-Sep-2026 snapshot; later closure evidence separate; no live HEAD verification","")
