Workbook

Sheet Current Authority
A1: PPIQ BACKLOG v2.24.0 — v4.11.1 execution authority | 17Sep2026
A2: Authority | B2: Current value | C2: As of | D2: Meaning
A3: Functional Design | B3: v4.11.1 | C3: 2026-09-17 | D3: Integrated across Chapters 1–6; current functional authority.
A4: Execution Backlog | B4: v2.24.0 | C4: 2026-09-17 | D4: In-place status/evidence/dependency/acceptance reconciliation; no new task family.
A5: Integrated Chapter 3/4 visuals | B5: v4.11.1 functional authority; illustrated regeneration pending T-265/T-266 | C5: 2026-09-17 | D5: Markdown page/runtime contracts are current. Missing illustrated DOCX derivatives do not block implementation workers.
A6: Release 1 | B6: M2 — approx. one month from owner planning checkpoint | C6: Owner planning basis | D6: No new absolute delivery date.
A7: Release 2 | B7: M3 — 45 days after M2 completion | C7: Owner planning basis | D7: 45 days after M2 completion; prior approved release allocation retained.
A8: Rows and retirements | B8: 187 active; T-105→T-104; T-111→T-110/T-155/T-159 | C8: Adds T-268 through T-275 | D8: Eight new bounded industrial-integration execution owners. No existing task retired or reopened by this design revision.
A9: T-099 closure | B9: ca02b40ea1b69050a45cb35a3e1d64f15b1f66af | C9: Final14Sep terminal transcript inspected15Sep | D9: CLOSED GREEN/COMMITTED; exact transcript corroborated. DefinitionKind known-red remains; not release-wideGREEN.
A10: T-262 closure | B10: CLOSED GREEN / COMMITTED | C10: 2026-09-16 | D10: Final live definition-store closure db0b0f84ec721f8adff1da14d4a62762200a22d6; producer 86e1b677... and 33aca26a... are ancestors.
A11: Planning estimates | B11: Industrial source preflight GREEN; T-268..T-275 estimate calibration pending | C11: 2026-09-17 | D11: Estimate calibration is not a start gate. No delivery forecast is asserted until estimates are accepted.
A12: Current task table | B12: Backlog!A1:BB188 | C12: 187 task rows | D12: Dependency validation reads the saved v2.24.0 task rows. New tasks are excluded from hour totals until explicitly estimated.
A13: Derived views | B13: Worker Tracks / Dependency Graph / Capability Map / Release Plan / dashboards | C13: v2.24.0 | D13: Formula ranges are extended through Backlog row 188. New task rows are appended to Worker Tracks and Dependency Graph.
... A31: Controlled book | B31: 12 document families / 14 physical files | C31: Owner direction — 2026-09-14 | D31: PPIQ_Definition.md registers the allowed files. The Backlog holds coverage, acceptance, validation and handoffs; no new status/JSON/README/atlas files.

Sheet Backlog
A1: Task Id | B1: Milestone Id | C1: Phase Id | D1: Task Name | E1: Module | F1: Sub-module | G1: Priority | H1: Task Description | I1: Task Validation | J1: Hours | K1: Status | L1: AI Agent Owner | M1: Depends On (IDs only) | N1: Must Precede (IDs only) | O1: Delivery Target | P1: Release Criticality | Q1: AI Execution Class | R1: AI Guarded Time P80 (h) | S1: AI Sequence Wave | T1: AI Start / Dependency Gate | U1: File / Subsystem Lock | V1: No-Rework Handoff Ruling | W1: Product Track | X1: Tech-Lead Ruling | Y1: Commit String | Z1: Commit Date | AA1: Primary Capability ID | AB1: Primary Capability Name | AC1: Secondary Capability IDs | AD1: Capability Contribution | AE1: Completeness Dimensions Targeted | AF1: Capability Requirement Class | AG1: Release Scope | AH1: Capability Closure Effect | AI1: Capability Evidence | AJ1: Estimate Basis | AK1: Design Package | AL1: UI Companion Reference | AM1: Usable scope estimate (1/0) | AN1: Contract-ready predecessors (not completion) | AO1: Evidence State | AP1: Closure Evidence Basis | AQ1: Parent Commit | AR1: Estimate Status | AS1: Usable planning hours | AT1: Usable planning P80 h | AU1: Source review coverage | AV1: Proposed remaining LOW h | AW1: Proposed remaining BASE h | AX1: Proposed remaining HIGH h | AY1: Remaining estimate confidence | AZ1: Remaining estimate basis | BA1: Source locations | BB1: Source as-of / evidence boundary
A2: T-086 | B2: M2 | C2: P1 | D2: Freeze the legacy Fleet v2 controlled regression oracle | E2: Testing | F2: Emulated sources | G2: Critical | H2: Freeze and certify the existing Fleet v2 dataset only as a legacy discrete-manufacturing regression oracle with predeclared known answers/negative controls. It is not the canonical product vocabulary, not the generic M2 fixture authority and not the source of customer schema semantics. T-208 owns new generic controlled fixtures, including the continuous-process known-answer pack. | I2: Fleet v2 is immutable and its declared phenomena/negative controls are reproducible. An architecture check proves no generic runtime/Layer-B/registry contract derives vocabulary or universal grain from Fleet. T-208 can run independently with neutral/continuous fixtures. | J2: 8 | K2: Done | L2: Worker 1 | M2: T-201 | N2: T-087; T-088; T-131 | O2: M2: ~1 month from owner planning checkpoint; exact date not committed | P2: Release 1 MUST | Q2: Integration/E2E/certification | R2: 2.72 | S2: M2-P1 | T2: CLOSED BASELINE — no new start gate and no re-execution implied. Preserve accepted closure and clean owned scope; reopen only on a concrete, separately recorded regression. Downstream consumes the frozen contract. | U2: Own canonical DB/backend/security/API/infra. No W2-owned UI/admin task files and no W3 ML/Assistant runtime. | V2: Commit before downstream consumer starts; consumer must use the contract, not redesign producer-owned semantics. | W2: Product Foundation & Release Truth | X2: M2 P1 — Product Foundation & Release Truth. Release 1 is genuine early production / first-week customer work. | Y2: 77a8ea4f — T-086: freeze the legacy regression oracle and gate generic surfaces against its vocabulary | Z2: 46259 | AA2: L8.8 | AB2: C1–C4 performance certification and golden-journey release gate | AD2: Validate | AE2: D5 | AF2: Core | AG2: R1 | AH2: Advances | AI2: =IF(Y2="","",Y2) -> 77a8ea4f — T-086: freeze the legacy regression oracle and gate generic surfaces against its vocabulary | AJ2: Inherited baseline estimate | AK2: v4.11.1 | AL2: Chapters 3/4 v4.10.3 — MD + illustrated Word; UI Coverage / UI Controls in this workbook | AM2: =IF(AND(ISNUMBER(J2),OR(AR2="INHERITED ESTIMATE",AR2="CONFIRMED ESTIMATE")),1,0) -> 1 | AO2: Recorded closed — inherited evidence | AP2: Inherited v2.22.0 intended record; no new runtime certification in this repair. | AR2: INHERITED ESTIMATE | AS2: =IF(AM2=1,J2,"") -> 8 | AT2: =IF(AND(AM2=1,ISNUMBER(R2)),R2,"") -> 2.72 | AU2: NOT SOURCE-REVIEWED IN THIS PASS | AY2: NOT ESTIMATED IN THIS PASS
A3: T-087 | B3: M2 | C3: P1 | D3: Physical three-schema migration | E3: Database | F3: Schema | G3: Critical | H3: The measured database carries twelve schemas with 162 tables in public, of which 108 use a ppiq_ name prefix, while the ruled schemas ppiq_plant and ppiq_meta exist and hold zero tables. Migrate to the three ruled schemas: ppiq_staging, ppiq_plant, ppiq_meta. The staging rename is already prepared, because the canvas reads its schema from the configuration key Prep:StagingSchema rather than a literal. | I3: Rule 2 is provable in one query on a fresh database. All application tests pass. The canvas catalogue lists tables from the renamed schema with only a configuration change. AND THE BENCHMARK SURVIVES THE MOVE: the phenomenon and benchmark harness frozen in T-086 is re-run UNCHANGED after the schema migration and produces identical results. A migration that silently alters the reference dataset destroys every comparison made against it. | J3: 12 | K3: Done | L3: Worker 1 | M3: T-086; T-088 | N3: T-089; T-099; T-102; T-112; T-114; T-128; T-196; T-233; T-251; T-252; T-272 | O3: M2: ~1 month from owner planning checkpoint; exact date not committed | P3: Release 1 MUST | Q3: DB/schema/migration | R3: 2.325 | S3: M2-P1 | T3: CLOSED BASELINE — no new start gate and no re-execution implied. Preserve accepted closure and clean owned scope; reopen only on a concrete, separately recorded regression. Downstream consumes the frozen contract. | U3: Own canonical DB/backend/security/API/infra. No W2-owned UI/admin task files and no W3 ML/Assistant runtime. | V3: Commit before downstream consumer starts; consumer must use the contract, not redesign producer-owned semantics. | W3: Product Foundation & Release Truth | X3: M2 P1 — Product Foundation & Release Truth. Release 1 is genuine early production / first-week customer work. | Y3: e7d82f078d7dfa4c1ca4ec6e88d0dbc7e1ecd6ba — subject not recovered | Z3: 46262 | AA3: L2.1 | AB3: Three-schema platform and placement law | AC3: L5.7 | AD3: Converge | AE3: D4; D5 | AF3: Core | AG3: R1 | AH3: Advances | AI3: =IF(Y3="","",Y3) -> e7d82f078d7dfa4c1ca4ec6e88d0dbc7e1ecd6ba — subject not recovered | AJ3: Inherited baseline estimate | AK3: v4.11.1 | AL3: Chapters 3/4 v4.10.3 — MD + illustrated Word; UI Coverage / UI Controls in this workbook | AM3: =IF(AND(ISNUMBER(J3),OR(AR3="INHERITED ESTIMATE",AR3="CONFIRMED ESTIMATE")),1,0) -> 1 | AO3: Recorded closed — inherited evidence | AP3: Inherited v2.22.0 intended record; no new runtime certification in this repair. | AR3: INHERITED ESTIMATE | AS3: =IF(AM3=1,J3,"") -> 12 | AT3: =IF(AND(AM3=1,ISNUMBER(R3)),R3,"") -> 2.325 | AU3: NOT SOURCE-REVIEWED IN THIS PASS | AY3: NOT ESTIMATED IN THIS PASS
A4: T-088 | B4: M2 | C4: P1 | D4: Canonical migration order and legacy script archival | E4: Database | F4: Schema | G4: Very Important | H4: Backend/database/scripts contains hotfix, repair, phase and drift-correction scripts accumulated over months, including cases where two scripts created the same table. Define one canonical ordered migration path, archive superseded scripts, and add a truth gate that no two scripts create the same table. | I4: A fresh database builds from the canonical path with no manual step. The truth gate fails if a duplicate CREATE TABLE is introduced. | J4: 12 | K4: Done | L4: Worker 1 | M4: T-086 | N4: T-087; T-089; T-112; T-128; T-251; T-252; T-256; T-260; T-272 | O4: M2: ~1 month from owner planning checkpoint; exact date not committed | P4: Release 1 MUST | Q4: DB/schema/migration | R4: 2.325 | S4: M2-P1 | T4: CLOSED BASELINE — no new start gate and no re-execution implied. Preserve accepted closure and clean owned scope; reopen only on a concrete, separately recorded regression. Downstream consumes the frozen contract. | U4: Own canonical DB/backend/security/API/infra. No W2-owned UI/admin task files and no W3 ML/Assistant runtime. | V4: Commit before downstream consumer starts; consumer must use the contract, not redesign producer-owned semantics. | W4: Product Foundation & Release Truth | X4: M2 P1 — Product Foundation & Release Truth. Release 1 is genuine early production / first-week customer work. | Y4: 6a62c9d6 — Establish canonical database migration authority | Z4: 46260 | AA4: L8.1 | AB4: Fresh install and upgrade authority | AC4: L5.7; L2.1 | AD4: Converge | AE4: D4; D5 | AF4: Core | AG4: R1 | AH4: Advances | AI4: =IF(Y4="","",Y4) -> 6a62c9d6 — Establish canonical database migration authority | AJ4: Inherited baseline estimate | AK4: v4.11.1 | AL4: Chapters 3/4 v4.10.3 — MD + illustrated Word; UI Coverage / UI Controls in this workbook | AM4: =IF(AND(ISNUMBER(J4),OR(AR4="INHERITED ESTIMATE",AR4="CONFIRMED ESTIMATE")),1,0) -> 1 | AO4: Recorded closed — inherited evidence | AP4: Inherited v2.22.0 intended record; no new runtime certification in this repair. | AR4: INHERITED ESTIMATE | AS4: =IF(AM4=1,J4,"") -> 12 | AT4: =IF(AND(AM4=1,ISNUMBER(R4)),R4,"") -> 2.325 | AU4: NOT SOURCE-REVIEWED IN THIS PASS | AY4: NOT ESTIMATED IN THIS PASS
A5: T-089 | B5: M2 | C5: P1 | D5: definition_store, definition_versions and definition_dependencies | E5: Database | F5: Definition store | G5: Critical | H5: Create the tables specified in Chapter 3 4.5.11 with immutable versions and a dependency graph, plus a trigger that rejects a dependency cycle. | I5: Integration tests: create, version, publish, and reject a cycle. Version rows must be immutable, proved by an update attempt that fails. | J5: 12 | K5: Done | L5: Worker 1 | M5: T-087; T-088 | N5: T-090; T-092; T-095; T-099; T-106; T-114; T-128; T-183; T-243; T-244 | O5: M2: ~1 month from owner planning checkpoint; exact date not committed | P5: Release 1 MUST | Q5: DB/schema/migration | R5: 2.325 | S5: M2-P1 | T5: CLOSED BASELINE — no new start gate and no re-execution implied. Preserve accepted closure and clean owned scope; reopen only on a concrete, separately recorded regression. Downstream consumes the frozen contract. | U5: Own canonical DB/backend/security/API/infra. No W2-owned UI/admin task files and no W3 ML/Assistant runtime. | V5: Commit before downstream consumer starts; consumer must use the contract, not redesign producer-owned semantics. | W5: Product Foundation & Release Truth | X5: M2 P1 — Product Foundation & Release Truth. Release 1 is genuine early production / first-week customer work. | Y5: 0fd79e5e3516cdfd0ab5a73a02e16638fd02693a — subject not recovered | AA5: L2.5 | AB5: Unified definition store and immutable target/version governance | AC5: L5.6 | AD5: Build | AE5: D4; D5 | AF5: Core | AG5: R1 | AH5: Advances | AI5: =IF(Y5="","",Y5) -> 0fd79e5e3516cdfd0ab5a73a02e16638fd02693a — subject not recovered | AJ5: Inherited baseline estimate | AK5: v4.11.1 | AL5: Chapters 3/4 v4.10.3 — MD + illustrated Word; UI Coverage / UI Controls in this workbook | AM5: =IF(AND(ISNUMBER(J5),OR(AR5="INHERITED ESTIMATE",AR5="CONFIRMED ESTIMATE")),1,0) -> 1 | AO5: Recorded closed — inherited evidence | AP5: Inherited v2.22.0 intended record; no new runtime certification in this repair. | AR5: INHERITED ESTIMATE | AS5: =IF(AM5=1,J5,"") -> 12 | AT5: =IF(AND(AM5=1,ISNUMBER(R5)),R5,"") -> 2.325 | AU5: NOT SOURCE-REVIEWED IN THIS PASS | AY5: NOT ESTIMATED IN THIS PASS
A6: T-090 | B6: M2 | C6: P1 | D6: Move all five definition kinds onto the store | E6: Backend | F6: Definition store | G6: Critical | H6: Replace the M1 compatibility adapter behind IDefinitionService with the real implementation for all five purposes: S1 Transformation, S2 Pages and widgets and filters and master items, S3 Analysis, S4 Model, S5 Log rule. The old per-artifact tables become a compatibility projection and then are retired. v2.10.1 OUTCOME SEMANTICS BINDING. As part of canonical definition convergence, bind the already-frozen SM-06 OutcomeDefinition to the canonical immutable versioned definition authority; do not design a second outcome authority. The canonical binding preserves outcome_code, outcome_type, class_taxonomy_ref, ordinal_rank_map, grain_code, detection_position_code, detection_timestamp_field, direction, unit_code, censoring_policy and definition/version identity. Any legacy ml_outcome_definitions representation may remain only as a compatibility projection during convergence and must not remain an independent semantic authority. | I6: The M1 integration test written against IDefinitionService must pass unchanged, since it references no table name. That is the proof that the visible contract did not move. Publish an SM-06 OutcomeDefinition and resolve it back by exact immutable version. Changing detection_position_code, detection_timestamp_field, grain, taxonomy, ordinal map, direction, unit or censoring policy creates a new definition version rather than silently mutating published meaning. If a compatibility outcome representation remains during convergence, prove it resolves to the same canonical definition/version and cannot diverge into a second authority. | J6: 12 | K6: Done | L6: Worker 1 | M6: T-089 | N6: T-091; T-092; T-095; T-099; T-104; T-106; T-114; T-128; T-134; T-147; T-183; T-195; T-210; T-221; T-228; T-231; T-232; T-233; T-235; T-239; T-243; T-244 | O6: M2: ~1 month from owner planning checkpoint; exact date not committed | P6: Release 1 MUST | Q6: Backend/domain contract | R6: 1.8 | S6: M2-P1 | T6: CLOSED BASELINE — no new start gate and no re-execution implied. Preserve accepted closure and clean owned scope; reopen only on a concrete, separately recorded regression. Downstream consumes the frozen contract. | U6: Own canonical DB/backend/security/API/infra. No W2-owned UI/admin task files and no W3 ML/Assistant runtime. | V6: Downstream consumers wait for the committed T-090 authority. Handover/progress notes do not substitute for closure; the pack must apply, build, test, replay and commit on the user machine. | W6: Product Foundation & Release Truth | X6: CENTRAL 30-Aug-2026: canonical definition convergence remains full scope. Deliver the standard executable PowerShell pack; no Task-ID-less changes. | Y6: a6399d9c — subject not recovered | AA6: L5.6 | AB6: Unified definition-store semantics | AC6: L2.5 | AD6: Converge | AE6: D3; D4; D5 | AF6: Core | AG6: R1 | AH6: Advances | AI6: =IF(Y6="","",Y6) -> a6399d9c — subject not recovered | AJ6: Inherited baseline estimate | AK6: v4.11.1 | AL6: Chapters 3/4 v4.10.3 — MD + illustrated Word; UI Coverage / UI Controls in this workbook | AM6: =IF(AND(ISNUMBER(J6),OR(AR6="INHERITED ESTIMATE",AR6="CONFIRMED ESTIMATE")),1,0) -> 1 | AO6: Recorded closed — inherited evidence | AP6: Inherited v2.22.0 intended record; no new runtime certification in this repair. | AR6: INHERITED ESTIMATE | AS6: =IF(AM6=1,J6,"") -> 12 | AT6: =IF(AND(AM6=1,ISNUMBER(R6)),R6,"") -> 1.8 | AU6: NOT SOURCE-REVIEWED IN THIS PASS | AY6: NOT ESTIMATED IN THIS PASS
A7: T-091 | B7: M2 | C7: P1 | D7: Impact preview, export and import | E7: Backend | F7: Definition store | G7: Very Important | H7: Add dependency impact preview before a publish, and export and import of a definition with its dependencies, per Chapter 3 4.5.11. | I7: Publish a change to a definition three others depend on and confirm the preview lists all three before the publish is confirmed. Export and reimport into an empty database and confirm equality. | J7: 12 | K7: Done | L7: Worker 1 | M7: T-090 | N7: T-128; T-183 | O7: M2: ~1 month from owner planning checkpoint; exact date not committed | P7: Release 1 MUST | Q7: Backend/domain contract | R7: 1.8 | S7: M2-P1 | T7: CLOSED BASELINE — no new start gate and no re-execution implied. Preserve accepted closure and clean owned scope; reopen only on a concrete, separately recorded regression. Downstream consumes the frozen contract. | U7: Own canonical DB/backend/security/API/infra. No W2-owned UI/admin task files and no W3 ML/Assistant runtime. | V7: Commit before downstream consumer starts; consumer must use the contract, not redesign producer-owned semantics. | W7: Product Foundation & Release Truth | X7: M2 P1 — Product Foundation & Release Truth. Release 1 is genuine early production / first-week customer work. | Y7: c6d64289 — subject not recovered | AA7: L5.6 | AB7: Unified definition-store semantics | AC7: L2.5 | AD7: Build | AE7: D3; D5 | AF7: Core | AG7: R1 | AH7: Advances | AI7: =IF(Y7="","",Y7) -> c6d64289 — subject not recovered | AJ7: Inherited baseline estimate | AK7: v4.11.1 | AL7: Chapters 3/4 v4.10.3 — MD + illustrated Word; UI Coverage / UI Controls in this workbook | AM7: =IF(AND(ISNUMBER(J7),OR(AR7="INHERITED ESTIMATE",AR7="CONFIRMED ESTIMATE")),1,0) -> 1 | AO7: Recorded closed — inherited evidence | AP7: Inherited v2.22.0 intended record; no new runtime certification in this repair. | AR7: INHERITED ESTIMATE | AS7: =IF(AM7=1,J7,"") -> 12 | AT7: =IF(AND(AM7=1,ISNUMBER(R7)),R7,"") -> 1.8 | AU7: NOT SOURCE-REVIEWED IN THIS PASS | AY7: NOT ESTIMATED IN THIS PASS
A8: T-092 | B8: M2 | C8: P1 | D8: Registry authority: dimensions and measures as rows | E8: Backend | F8: Registry | G8: Critical | H8: Replace compiled dimension/measure catalogues with canonical registry projections over published definition versions. Registry rows must support customer-defined dimensions/measures without rebuild, plus analysis-grain metadata, signal/aggregation semantics and reference-derived measure roles. It remains a projection/serving authority, not a competing mutable definition store. | I8: Using the same binary, add a customer-shaped dimension and measure through definitions/registry data only and use them in an authored widget. No C#/React/product-SQL edit. Registry exposes declared grain and aggregation/reference metadata and rejects unresolved semantics. | J8: 12 | K8: Done | L8: Worker 1 | M8: T-089; T-090; T-210; T-231 | N8: T-093; T-094; T-128; T-183; T-212; T-215; T-228; T-237; T-247 | O8: M2: ~1 month from owner planning checkpoint; exact date not committed | P8: Release 1 MUST | Q8: Backend/domain contract | R8: 1.8 | S8: M2-P1 | T8: CLOSED BASELINE — no new start gate and no re-execution implied. Preserve accepted closure and clean owned scope; reopen only on a concrete, separately recorded regression. Downstream consumes the frozen contract. | U8: Own canonical DB/backend/security/API/infra. No W2-owned UI/admin task files and no W3 ML/Assistant runtime. | V8: Commit before downstream consumer starts; consumer must use the contract, not redesign producer-owned semantics. | W8: Product Foundation & Release Truth | X8: M2 P1 — Product Foundation & Release Truth. Release 1 is genuine early production / first-week customer work. | Y8: ab2962a4; 7cad36e4 — registry authority closure commits | Z8: 46267 | AA8: L3.9 | AB8: Master items, bookmarks and saved views | AC8: L5.1 | AD8: Build | AE8: D1; D3; D5 | AF8: Core | AG8: R1 | AH8: Advances | AI8: =IF(Y8="","",Y8) -> ab2962a4; 7cad36e4 — registry authority closure commits | AJ8: Inherited baseline estimate | AK8: v4.11.1 | AL8: Chapters 3/4 v4.10.3 — MD + illustrated Word; UI Coverage / UI Controls in this workbook | AM8: =IF(AND(ISNUMBER(J8),OR(AR8="INHERITED ESTIMATE",AR8="CONFIRMED ESTIMATE")),1,0) -> 1 | AO8: Recorded closed — inherited evidence | AP8: Inherited v2.22.0 intended record; no new runtime certification in this repair. | AR8: INHERITED ESTIMATE | AS8: =IF(AM8=1,J8,"") -> 12 | AT8: =IF(AND(AM8=1,ISNUMBER(R8)),R8,"") -> 1.8 | AU8: NOT SOURCE-REVIEWED IN THIS PASS | AY8: NOT ESTIMATED IN THIS PASS
A9: T-093 | B9: M2 | C9: P1 | D9: Plant-vocabulary sweep, part 1: build the term list and the architecture test | E9: Backend | F9: Registry | G9: Very Important | H9: Rule 1 needs an enforcement mechanism before the sweep, or the sweep is a one-off. Create a registry-held list of plant terms (the term list is itself DATA, never a compiled constant) and an architecture test that fails the build when any listed term appears in product code outside registry data, seed content or test fixtures. Seed the list from the dimension names already found compiled into DashboardWidgetQuerySafetyRegistry: ProductFamily, GradeOrRecipe, ShiftCode, DefectType, RiskClass. | I9: Add a term to the list and confirm the build goes red on an existing violation, then goes green once that violation is fixed. Confirm removing a term from the list does not require a code change. | J9: 6 | K9: Done | L9: Worker 1 | M9: T-092; T-206 | N9: T-094; T-128; T-183 | O9: M2: ~1 month from owner planning checkpoint; exact date not committed | P9: Release 1 MUST | Q9: Backend/domain contract | R9: 0.9 | S9: M2-P1 | T9: CLOSED BASELINE — no new start gate and no re-execution implied. Preserve accepted closure and clean owned scope; reopen only on a concrete, separately recorded regression. Downstream consumes the frozen contract. | U9: Own canonical DB/backend/security/API/infra. No W2-owned UI/admin task files and no W3 ML/Assistant runtime. | V9: Commit before downstream consumer starts; consumer must use the contract, not redesign producer-owned semantics. | W9: Product Foundation & Release Truth | X9: M2 P1 — Product Foundation & Release Truth. Release 1 is genuine early production / first-week customer work. | Y9: 4e2e0f654b93ceed2ecdfbce4d3c1768550b3079 — T-093 govern plant vocabulary as data-driven genericity debt | Z9: 46268 | AA9: L5.1 | AB9: Canonical entity catalogue | AD9: Build | AE9: D3; D5 | AF9: Core | AG9: R1 | AH9: Advances | AI9: =IF(Y9="","",Y9) -> 4e2e0f654b93ceed2ecdfbce4d3c1768550b3079 — T-093 govern plant vocabulary as data-driven genericity debt | AJ9: Inherited baseline estimate | AK9: v4.11.1 | AL9: Chapters 3/4 v4.10.3 — MD + illustrated Word; UI Coverage / UI Controls in this workbook | AM9: =IF(AND(ISNUMBER(J9),OR(AR9="INHERITED ESTIMATE",AR9="CONFIRMED ESTIMATE")),1,0) -> 1 | AO9: Recorded closed — inherited evidence | AP9: Inherited v2.22.0 intended record; no new runtime certification in this repair. | AR9: INHERITED ESTIMATE | AS9: =IF(AM9=1,J9,"") -> 6 | AT9: =IF(AND(AM9=1,ISNUMBER(R9)),R9,"") -> 0.9 | AU9: NOT SOURCE-REVIEWED IN THIS PASS | AY9: NOT ESTIMATED IN THIS PASS
A10: T-094 | B10: M2 | C10: P1 | D10: Plant-vocabulary sweep, part 2: remove hardcoded universal grain and industry vocabulary | E10: Backend | F10: Registry | G10: Very Important | H10: Clear generic-runtime/demo-vocabulary violations without replacing one industry noun with another. Complete the declared-dimension execution path on BOTH runtime wire surfaces: (A) persisted widget execution via DashboardWidgetFiltersDto/declared keyed dimensions and (B) workspace/global dashboard query execution via DashboardQueryDto and the overview/quality/risk/data-quality/materials routes. Remove fixed universal grain/industry vocabulary from DashboardReferenceDataDto and the frontend consumers by resolving published registry definitions, canonical members and governed Analysis Subject/relationship authority. The target contract is definition/registry member -> relationship/path resolution -> Analysis Subject -> typed refusal; the current direct single-reference resolver is an interim implementation until T-095/T-096 path authority lands. No presentation vocabulary becomes product authority. | I10: Using the same binary, author a foreign/customer-shaped dimension and prove it filters both a persisted widget and the workspace/global route surface through the same published definition/member identity. Both surfaces must return the same typed refusal when the dimension is undeclared, inactive, unmapped, has no subject path, or becomes ambiguous. No compiled fallback to defectType/riskClass/shiftCode or a universal material grain. Frontend consumers use the keyed contract. Wave-C genericity arithmetic remains exact: every known fingerprint is retired or explicitly lawful; unknown=0. | J10: 24 | K10: Done | L10: Worker 1 | M10: T-092; T-093; T-209 | N10: T-095; T-128; T-183; T-196; T-253; T-256; T-258 | O10: M2: ~1 month from owner planning checkpoint; exact date not committed | P10: Release 1 MUST | Q10: Backend/domain contract | R10: 3.6 | S10: M2-P1 | T10: CLOSED BASELINE — no new start gate and no re-execution implied. Preserve accepted closure and clean owned scope; reopen only on a concrete, separately recorded regression. Downstream consumes the frozen contract. | U10: Own canonical DB/backend/security/API/infra. No W2-owned UI/admin task files and no W3 ML/Assistant runtime. | V10: Commit before downstream consumer starts; consumer must use the contract, not redesign producer-owned semantics. | W10: Product Foundation & Release Truth | X10: CENTRAL 04-Sep-2026: T-094 remains open. Scope is formally amended from one wire to both declared-dimension execution surfaces. No new task is created while T-094 is open; after closure any new surface requires a new Task ID. | Y10: 377aabdffb27d651d30537ce5228ee4afe268526; 6ab97ee2; e74ecd1c; 5a967f1b0ab45961c8b8a880bb4fdec53a783134 — final: T-094 close keyed declared-dimension cutover and genericity reconciliation | Z10: 46272 | AA10: L5.1 | AB10: Canonical entity catalogue | AC10: L5.3 | AD10: Build | AE10: D1; D3; D5 | AF10: Core | AG10: R1 | AH10: Advances | AI10: =IF(Y10="","",Y10) -> 377aabdffb27d651d30537ce5228ee4afe268526; 6ab97ee2; e74ecd1c; 5a967f1b0ab45961c8b8a880bb4fdec53a783134 — final: T-094 close keyed declared-dimension cutover and genericity reconciliation | AJ10: Inherited baseline estimate | AK10: v4.11.1 | AL10: Chapters 3/4 v4.10.3 — MD + illustrated Word; UI Coverage / UI Controls in this workbook | AM10: =IF(AND(ISNUMBER(J10),OR(AR10="INHERITED ESTIMATE",AR10="CONFIRMED ESTIMATE")),1,0) -> 1 | AO10: Recorded closed — inherited evidence | AP10: Inherited v2.22.0 intended record; no new runtime certification in this repair. | AR10: INHERITED ESTIMATE | AS10: =IF(AM10=1,J10,"") -> 24 | AT10: =IF(AND(AM10=1,ISNUMBER(R10)),R10,"") -> 3.6 | AU10: NOT SOURCE-REVIEWED IN THIS PASS | AY10: NOT ESTIMATED IN THIS PASS
A11: T-095 | B11: M2 | C11: P2 | D11: Relationship members, cardinality, grain conversion and preferred paths | E11: Backend | F11: Relationship model | G11: Critical | H11: Extend the M1 slice to the full model in Chapter 3 4.5.10: members, cardinality, grain conversion between related entities, preferred path selection when more than one path exists, and published versions. v2.10.2 CONVERGENCE CORRECTION — T-095 does not merely 'extend' M1 physical tables. It converges the M1 relationship service/compatibility persistence onto the canonical Chapter 3 4.5.10 tables after definition_store exists, including source_definition_id/version, grain conversion, preferred paths, ambiguity/validation state and retirement semantics, while keeping the M1 external contract stable. | I11: Declare two paths between the same pair of entities, mark one preferred, and confirm the resolver chooses it. Change the preference and confirm the resolution changes with no other edit. | J11: 12 | K11: Done | L11: Worker 1 | M11: T-057; T-089; T-090; T-094 | N11: T-096; T-098; T-102; T-103; T-104; T-107; T-109; T-114; T-128; T-134; T-183; T-196; T-221 | O11: M2: ~1 month from owner planning checkpoint; exact date not committed | P11: Release 1 MUST | Q11: Backend/domain contract | R11: 1.8 | S11: M2-P2 | T11: CLOSED BASELINE — no new start gate and no re-execution implied. Preserve accepted closure and clean owned scope; reopen only on a concrete, separately recorded regression. Downstream consumes the frozen contract. | U11: Own canonical DB/backend/security/API/infra. No W2-owned UI/admin task files and no W3 ML/Assistant runtime. | V11: Commit before downstream consumer starts; consumer must use the contract, not redesign producer-owned semantics. | W11: Day-1 Data Workbench — DB Link, Canvas, Jobs & OPC | X11: M2 P2 — Day-1 Data Workbench — DB Link, Canvas, Jobs & OPC. Release 1 is genuine early production / first-week customer work. | Y11: 554d1ac02af122fdeb7ca54b1dd35bac0c76f23e — subject not recovered | Z11: 46272 | AA11: L5.2 | AB11: Permanent relationship model | AD11: Build | AE11: D1; D3; D5 | AF11: Core | AG11: R1 | AH11: Advances | AI11: =IF(Y11="","",Y11) -> 554d1ac02af122fdeb7ca54b1dd35bac0c76f23e — subject not recovered | AJ11: Inherited baseline estimate | AK11: v4.11.1 | AL11: Chapters 3/4 v4.10.3 — MD + illustrated Word; UI Coverage / UI Controls in this workbook | AM11: =IF(AND(ISNUMBER(J11),OR(AR11="INHERITED ESTIMATE",AR11="CONFIRMED ESTIMATE")),1,0) -> 1 | AO11: Recorded closed — inherited evidence | AP11: Inherited v2.22.0 intended record; no new runtime certification in this repair. | AR11: INHERITED ESTIMATE | AS11: =IF(AM11=1,J11,"") -> 12 | AT11: =IF(AND(AM11=1,ISNUMBER(R11)),R11,"") -> 1.8 | AU11: SOURCE CORROBORATES CLOSED FOUNDATION | AV11: 0 | AW11: 0 | AX11: 0 | AY11: UNCONFIRMED REVIEW ESTIMATE - not P80 or elapsed | AZ11: Closed original scope; zero remaining here does not certify downstream Canvas integration. | BA11: Backend/PlantProcess.Application/Relationships/RelationshipService.cs:145-217 — PublishAsync Backend/PlantProcess.Application/Relationships/RelationshipService.cs:218-260 — ValidateDeclaration | BB11: 14-Sep-2026 snapshot; later closure evidence separate; no live HEAD verification
A12: T-096 | B12: M2 | C12: P2 | D12: Path resolver, part 1: resolver core and the first eight consumers | E12: Backend | F12: Relationship model | G12: Critical | H12: Chapter 2 3.15.4 names sixteen consumers of the relationship model. Build the resolver core, then route the first eight through it: canonical projection, page and widget queries, associative filtering, drill-down, drill-through, genealogy, statistics and correlation. | I12: A regression test per consumer asserting it resolves through the published model, and refuses with a named reason when the relationship is unpublished. Eight tests, no exceptions. | J12: 8 | K12: Done | L12: Worker 1 | M12: T-095 | N12: T-097; T-098; T-107; T-109; T-128; T-134; T-183; T-221 | O12: M2: ~1 month from owner planning checkpoint; exact date not committed | P12: Release 1 MUST | Q12: Backend/domain contract | R12: 1.2 | S12: M2-P2 | T12: CLOSED BASELINE — no new start gate and no re-execution implied. Preserve accepted closure and clean owned scope; reopen only on a concrete, separately recorded regression. Downstream consumes the frozen contract. | U12: Own canonical DB/backend/security/API/infra. No W2-owned UI/admin task files and no W3 ML/Assistant runtime. | V12: Commit before downstream consumer starts; consumer must use the contract, not redesign producer-owned semantics. | W12: Day-1 Data Workbench — DB Link, Canvas, Jobs & OPC | X12: M2 P2 — Day-1 Data Workbench — DB Link, Canvas, Jobs & OPC. Release 1 is genuine early production / first-week customer work. | Y12: de243027073fc5e492d65e9f9845255342517510 — T-096 relationship resolver consumer convergence | Z12: 46273 | AA12: L5.2 | AB12: Permanent relationship model | AD12: Build | AE12: D3; D5 | AF12: Core | AG12: R1 | AH12: Advances | AI12: =IF(Y12="","",Y12) -> de243027073fc5e492d65e9f9845255342517510 — T-096 relationship resolver consumer convergence | AJ12: Inherited baseline estimate | AK12: v4.11.1 | AL12: Chapters 3/4 v4.10.3 — MD + illustrated Word; UI Coverage / UI Controls in this workbook | AM12: =IF(AND(ISNUMBER(J12),OR(AR12="INHERITED ESTIMATE",AR12="CONFIRMED ESTIMATE")),1,0) -> 1 | AO12: Recorded closed — inherited evidence | AP12: Inherited v2.22.0 intended record; no new runtime certification in this repair. | AR12: INHERITED ESTIMATE | AS12: =IF(AM12=1,J12,"") -> 8 | AT12: =IF(AND(AM12=1,ISNUMBER(R12)),R12,"") -> 1.2 | AU12: SOURCE CORROBORATES CLOSED FOUNDATION | AV12: 0 | AW12: 0 | AX12: 0 | AY12: UNCONFIRMED REVIEW ESTIMATE - not P80 or elapsed | AZ12: Original resolver/convergence closure retained; no rebuilding cost. | BA12: Backend/PlantProcess.Application/Relationships/RelationshipResolver.cs:34-113 — ResolveAsync Backend/tests/PlantProcess.Architecture.Tests/RelationshipConsumerBarrierTests.cs:55-96 — ConsumerFamilies | BB12: 14-Sep-2026 snapshot; later closure evidence separate; no live HEAD verification
A13: T-097 | B13: M2 | C13: P2 | D13: Path resolver, part 2: the remaining eight consumers and the regression suite | E13: Backend | F13: Relationship model | G13: Critical | H13: Route the remaining eight through the resolver: feature engineering, model training, prediction, practice learning, remediation search, value calculation, assistant retrieval and evidence. Some of these are built in Release 2; add the resolver seam now so they cannot be written against an ad-hoc join later. | I13: Eight further regression tests. For consumers whose engine arrives in Release 2, the test asserts the seam exists and refuses when unpublished, which is what stops a later shortcut. | J13: 6 | K13: Done | L13: Worker 1 | M13: T-096 | N13: T-098; T-107; T-109; T-128; T-183 | O13: M2: ~1 month from owner planning checkpoint; exact date not committed | P13: Release 1 MUST | Q13: Backend/domain contract | R13: 0.9 | S13: M2-P2 | T13: CLOSED BASELINE — no new start gate and no re-execution implied. Preserve accepted closure and clean owned scope; reopen only on a concrete, separately recorded regression. Downstream consumes the frozen contract. | U13: Own canonical DB/backend/security/API/infra. No W2-owned UI/admin task files and no W3 ML/Assistant runtime. | V13: Commit before downstream consumer starts; consumer must use the contract, not redesign producer-owned semantics. | W13: Day-1 Data Workbench — DB Link, Canvas, Jobs & OPC | X13: M2 P2 — Day-1 Data Workbench — DB Link, Canvas, Jobs & OPC. Release 1 is genuine early production / first-week customer work. | Y13: 95220d1804493f8e7b80347fe3ed4de24741f9ec — T-097 relationship consumer barrier across all sixteen families | Z13: 46273 | AA13: L5.2 | AB13: Permanent relationship model | AD13: Build | AE13: D3; D5 | AF13: Core | AG13: R1 | AH13: Advances | AI13: =IF(Y13="","",Y13) -> 95220d1804493f8e7b80347fe3ed4de24741f9ec — T-097 relationship consumer barrier across all sixteen families | AJ13: Inherited baseline estimate | AK13: v4.11.1 | AL13: Chapters 3/4 v4.10.3 — MD + illustrated Word; UI Coverage / UI Controls in this workbook | AM13: =IF(AND(ISNUMBER(J13),OR(AR13="INHERITED ESTIMATE",AR13="CONFIRMED ESTIMATE")),1,0) -> 1 | AO13: Recorded closed — inherited evidence | AP13: Inherited v2.22.0 intended record; no new runtime certification in this repair. | AR13: INHERITED ESTIMATE | AS13: =IF(AM13=1,J13,"") -> 6 | AT13: =IF(AND(AM13=1,ISNUMBER(R13)),R13,"") -> 0.9 | AU13: SOURCE CORROBORATES CLOSED GUARD | AV13: 0 | AW13: 0 | AX13: 0 | AY13: UNCONFIRMED REVIEW ESTIMATE - not P80 or elapsed | AZ13: No remaining original implementation; avoid counting unwired later engines against this completed guard. | BA13: Backend/tests/PlantProcess.Architecture.Tests/RelationshipConsumerBarrierTests.cs:12-44 — barrier semantics Backend/tests/PlantProcess.Architecture.Tests/RelationshipConsumerBarrierTests.cs:55-114 — consumer and forbidden-authority inventory | BB13: 14-Sep-2026 snapshot; later closure evidence separate; no live HEAD verification
A14: T-098 | B14: M2 | C14: P2 | D14: Relationship Browser page and path evidence | E14: Frontend | F14: Relationship model | G14: Very Important | H14: Build the C6 Relationship Browser from Chapter 3 4.4 with the ten-field page contract, showing declared relationships, their members, their paths and the evidence for each path. v2.10.2 CONTINUITY CORRECTION — complete the existing T-060 /relationships page in place. Do not create a second C6 surface. Preserve the route, layout and M1 control contract while replacing/extending the hidden relationship authority and path evidence. | I14: Open a relationship and confirm its members, cardinality and path are shown with evidence. Confirm an unpublished relationship is visibly distinct from a published one. Run the M1 C6 continuity snapshot before/after canonical cutover and prove no visible-contract regression. | J14: 12 | K14: Not Started | L14: Worker 2 | M14: T-095; T-096; T-097 | N14: T-107; T-109; T-128; T-183 | O14: M2: ~1 month from owner planning checkpoint; exact date not committed | P14: Release 1 MUST | Q14: Frontend/UI feature | R14: 2 | S14: M2-P2 | T14: Use the accepted M1 regression baseline; require empty index and clean owned paths, preserving unrelated user work. Then: T-060 M1 C6 surface + T-095 + T-096 + T-097. | U14: Own named UI/admin task end-to-end only after producer APIs/security are committed. | V14: Commit before downstream consumer starts; consumer must use the contract, not redesign producer-owned semantics. | W14: Day-1 Data Workbench — DB Link, Canvas, Jobs & OPC | X14: M2 P2 — Day-1 Data Workbench — DB Link, Canvas, Jobs & OPC. Release 1 is genuine early production / first-week customer work. | AA14: L5.2 | AB14: Permanent relationship model | AD14: Build | AE14: D1; D2; D5 | AF14: Core | AG14: R1 | AH14: Advances | AI14: =IF(Y14="","",Y14) | AJ14: Inherited baseline estimate | AK14: v4.11.1 | AL14: Chapters 3/4 v4.10.3 — MD + illustrated Word; UI Coverage / UI Controls in this workbook v2.23.0 — Use T-265 C6 relationship list/detail/member/cardinality/path-validation handoffs. Trace every applicable Chapter 3 control to a reachable UI variant and keep resolver behavior under its existing authority. | AM14: =IF(AND(ISNUMBER(J14),OR(AR14="INHERITED ESTIMATE",AR14="CONFIRMED ESTIMATE")),1,0) -> 1 | AO14: Not started — no completion claimed | AP14: Inherited v2.22.0 intended record; no new runtime certification in this repair. | AR14: INHERITED ESTIMATE | AS14: =IF(AM14=1,J14,"") -> 12 | AT14: =IF(AND(AM14=1,ISNUMBER(R14)),R14,"") -> 2 | AU14: REUSABLE BACKEND PRESENT; CANONICAL UI NOT LOCATED | AV14: 6 | AW14: 9 | AX14: 14 | AY14: UNCONFIRMED REVIEW ESTIMATE - not P80 or elapsed | AZ14: UI 4/6/9 + contract/negative tests 1/2/3 + targeted closure 1/1/2. Reuse all relationship producer work. | BA14: Backend/PlantProcess.Api/Endpoints/Relationships/RelationshipEndpoints.cs:21-92 — MapRelationshipEndpoints Backend/PlantProcess.Application/Relationships/RelationshipResolver.cs:62-113 — path results | BB14: 14-Sep-2026 snapshot; later closure evidence separate; no live HEAD verification
A15: T-099 | B15: M2 | C15: P2 | D15: Quarantine, part 1: the table, the reprocess API and the first eight PV classes | E15: Backend | F15: Quarantine | G15: Critical | H15: Chapter 3 4.5.14 specifies quarantine with fifteen typed PV codes. A repository search for projection_quarantine returns zero hits, so this does not exist. Build the table with its columns, the reprocess endpoint, and the first eight validation classes so a bad row is quarantined under a named code instead of corrupting the canonical layer or failing the whole batch. | I15: Craft one malformed input per implemented class and assert each is quarantined under the correct code, while the good rows in the same batch still project. | J15: 8 | K15: Done | L15: Worker 1 | M15: T-087; T-089; T-090 | N15: T-100; T-101; T-104; T-107; T-108; T-109; T-114; T-128; T-183; T-261 | O15: M2: ~1 month from owner planning checkpoint; exact date not committed | P15: Release 1 MUST | Q15: Backend/domain contract | R15: 1.2 | S15: M2-P2 | T15: CLOSED BASELINE — no new start gate and no re-execution implied. Preserve accepted closure and clean owned scope; reopen only on a concrete, separately recorded regression. Downstream consumes the frozen contract. | U15: Own canonical DB/backend/security/API/infra. No W2-owned UI/admin task files and no W3 ML/Assistant runtime. | V15: Commit before downstream consumer starts; consumer must use the contract, not redesign producer-owned semantics. | W15: Day-1 Data Workbench — DB Link, Canvas, Jobs & OPC | X15: M2 P2 — Day-1 Data Workbench — DB Link, Canvas, Jobs & OPC. Release 1 is genuine early production / first-week customer work. v2.22.1 — CLOSED GREEN / COMMITTED at ca02b40ea1b69050a45cb35a3e1d64f15b1f66af (parent 86e1b677212195f191697ecdca7e9441b3dbde33). Preserve this closure unless a concrete later regression is demonstrated. Gate O has one exact inherited DefinitionKind RED and canonical replay limitations remain; this is not Release-wide GREEN. | Y15: ca02b40ea1b69050a45cb35a3e1d64f15b1f66af | AA15: L2.3 | AB15: Canonical projection with validation, quarantine and reprocessing | AD15: Build | AE15: D3; D4; D5 | AF15: Core | AG15: R1 | AH15: Advances | AI15: =IF(Y15="","",Y15) -> ca02b40ea1b69050a45cb35a3e1d64f15b1f66af | AJ15: Inherited baseline estimate | AK15: v4.11.1 | AL15: Chapters 3/4 v4.10.3 — MD + illustrated Word; UI Coverage / UI Controls in this workbook | AM15: =IF(AND(ISNUMBER(J15),OR(AR15="INHERITED ESTIMATE",AR15="CONFIRMED ESTIMATE")),1,0) -> 1 | AO15: CLOSED GREEN / COMMITTED — FINAL TRANSCRIPT CORROBORATED | AP15: Final executed terminal transcript corroborates the owner-reported closure: 49/49 live,5/5 catalogue,19/19 owned;6/6 disposable DBs dropped;0survivors. GateO900=899passed+1exact inheritedDefinitionKindRED. Exact staging and one semantic commit proven. No live rerun performed in this review; no release-wideGREEN. Pasted text(20260914-134548).txt | lines430-450; final gatesQ/R; COMMITca02b40ea1b69050a45cb35a3e1d64f15b1f66af; PARENT86e1b677212195f191697ecdca7e9441b3dbde33; live49/49, catalogue5/5, owned19/19; not release-wideGREEN. | AQ15: 86e1b677212195f191697ecdca7e9441b3dbde33 | AR15: INHERITED ESTIMATE | AS15: =IF(AM15=1,J15,"") -> 8 | AT15: =IF(AND(AM15=1,ISNUMBER(R15)),R15,"") -> 1.2 | AU15: CLOSED SCOPE PRESERVED; SOURCE CORROBORATES | AV15: 0 | AW15: 0 | AX15: 0 | AY15: UNCONFIRMED REVIEW ESTIMATE - not P80 or elapsed | AZ15: T-099 CLOSED GREEN at ca02b40e; its inherited DefinitionKind RED is not a reason to budget a rewrite. | BA15: Backend/PlantProcess.Application/Integration/Services/Mapping/MappingRowProjector.cs:141-181 — MapMaterialUnitAsync Backend/PlantProcess.Api/Endpoints/Quarantine/QuarantineEndpoints.cs:8-33 — bounded reprocess surface Backend/database/scripts/841_genealogy_edge_weight_guard_topology_parity.sql:3-20 — narrow topology correction | BB15: 14-Sep-2026 snapshot; later closure evidence separate; no live HEAD verification
A16: T-100 | B16: M2 | C16: P2 | D16: Quarantine, part 2: the remaining seven PV classes and per-class tests | E16: Backend | F16: Quarantine | G16: Critical | H16: Implement the remaining seven validation classes and give every class its own test fixture, so the class set is provably complete against Chapter 3 4.5.14 rather than approximately complete. | I16: Distinct governed validation codes and fixture coverage must equal PV01..PV15 exactly. At least 15 classification fixtures; additional regression fixtures for an existing code are allowed. The completeness ratchet fails for an unproved enum member, not for duplicate display names or extra same-code tests. Live PostgreSQL proof executes every PV class; PV15 quarantine→cross-batch reference arrival→bounded reprocess passes; PV13 .60+.40=1.00 must not be quarantined. Exact live constraint, canonical migration order, disposable cleanup and exact single-commit closure required. | J16: 6 | K16: Done | L16: Worker 1 | M16: T-099 | N16: T-101; T-107; T-109; T-128; T-183; T-261 | O16: M2: ~1 month from owner planning checkpoint; exact date not committed | P16: Release 1 MUST | Q16: Backend/domain contract | R16: 0.9 | S16: M2-P2 | T16: RUNNER-1 CANDIDATE IS PRESENT; DO NOT RERUN RUNNER 1 or require a clean owned tree relative to HEAD. Resume from the exact handoff/postimages. Resume v1.0.1 is issued; success is not yet reported. Validate HEAD against the handoff and all owned postimage hashes before continuing. Expected parent supplied for closure is 4e0f1219ddbac3163bafe7ce510b62520683a77c; do not substitute the older T-099-only HEAD. If the exact gates fail, stop and report without manual resets, cleanup of unrelated work, or a fresh mutation pack. Worker 1/CENTRAL retains the execution lock through T-100 final commit; Worker 2 remains held. | U16: Worker 1 is the recorded execution owner; CENTRAL-assisted delivery. Preserve the existing T-100 candidate and unrelated dirty work. Exclusive shared repository mutation lock until T-100 is committed. | V16: Release Worker 2 only after T-100 final commit SHA and closure evidence. The successor consumes PROJECTION_* declaration, PV01..PV15 row-validation and JOB_EXEC_* runtime boundaries without duplication. | W16: Day-1 Data Workbench — DB Link, Canvas, Jobs & OPC | X16: M2 P2 — Day-1 Data Workbench — DB Link, Canvas, Jobs & OPC. Release 1 is genuine early production / first-week customer work. | Y16: e7ebc56341c371ce7b617585dce7f42d9a255f61 — T-100 complete remaining projection quarantine validation classes | Z16: 2026-09-15 | AA16: L2.3 | AB16: Canonical projection with validation, quarantine and reprocessing | AD16: Build | AE16: D3; D5 | AF16: Core | AG16: R1 | AH16: Advances | AI16: =IF(Y16="","",Y16) -> e7ebc56341c371ce7b617585dce7f42d9a255f61 — T-100 complete remaining projection quarantine validation classes | AJ16: SUPERSEDED: prior remaining LOW/BASE/HIGH 6/10/16 h included validators and unit tests now reported complete. Do not charge that implementation again. Closure-only remaining effort (harness recovery, live certification, cleanup, commit proof) is UNCONFIRMED, not zero; no invented elapsed time or calibrated P80. Preserve J/R as historical scope values, excluded from usable totals. | AK16: v4.11.1 | AL16: Chapters 3/4 v4.10.3 — MD + illustrated Word; UI Coverage / UI Controls in this workbook | AM16: =IF(AND(ISNUMBER(J16),OR(AR16="INHERITED ESTIMATE",AR16="CONFIRMED ESTIMATE")),1,0) -> 0 | AO16: CLOSED GREEN / COMMITTED | AP16: Final closure e7ebc56341c371ce7b617585dce7f42d9a255f61 supersedes the earlier Runner-1/live-harness-blocked state. Preserve closure absent a concrete regression. | AR16: CLOSED | AS16: =IF(AM16=1,J16,"") | AT16: =IF(AND(AM16=1,ISNUMBER(R16)),R16,"") | AU16: RUNNER 1 GREEN REPORTED / DB BUILD PASSED / LIVE HARNESS BLOCKED / UNCOMMITTED | AV16: UNCONFIRMED | AW16: UNCONFIRMED | AX16: UNCONFIRMED | AY16: UNCONFIRMED — closure-only remaining effort; prior 6/10/16 h superseded | AZ16: SUPERSEDED: prior remaining LOW/BASE/HIGH 6/10/16 h included validators and unit tests now reported complete. Do not charge that implementation again. Closure-only remaining effort (harness recovery, live certification, cleanup, commit proof) is UNCONFIRMED, not zero; no invented elapsed time or calibrated P80. Preserve J/R as historical scope values, excluded from usable totals. | BA16: Backend/PlantProcess.Api/Endpoints/Quarantine/QuarantineEndpoints.cs:8-13 — ownership Backend/PlantProcess.Application/Integration/Services/Mapping/MappingRowProjector.cs:630-690 — existing validation pattern Latest owner-supplied conversation update, received 15-Sep-2026; runner/host logs and script bytes were not independently inspected in this workbook update. This supersedes the earlier 14-Sep source-only T-100 estimate, not the frozen Design. USER-REPORTED: Runner1_1.0.5 SHA256 75B6C7DE78E0A677701BFEDF1EC70D4D1499C8168193B35D503CF26DF76DC7AA; Runner2_1.0.0 SHA256 9C29E607B52114DE680131A0FDE0F840D7CC56D3642FA09F73FD2AB5A7B3D493; Resume-ProjectionQuarantineCompletion_1.0.1.ps1 SHA256 5F6668258E8CAC517793B825AF712C8D8C9355F8CE9C0C69FBC5CAFCBDCB80E6. Names/hashes recorded as supplied, NOT locally verified. Script hashes are not commit IDs. | BB16: 14-Sep snapshot supplemented by latest 15-Sep user-reported runner progress; no current-HEAD or runner-byte verification
A17: T-101 | B17: M2 | C17: P2 | D17: Quarantine retry, reprocess and Mapping Health completion | E17: Frontend | F17: Quarantine | G17: Very Important | H17: Complete the C2 Mapping Health page against Chapter 3 4.4 C2: issues grouped by code, example rows, and Reprocess after the mapping is corrected. The M1 version delivered the shape; this delivers the full class set and the retry semantics. v2.22.0 — Quarantine inspection API/UI and schema-drift enforcement. Keep one drift event authority and reuse current schemas/compatibility safely. v2.22.1 — Own the M2 B4 Importing monitoring surface as well as C2 quarantine/Mapping Health: show each real batch status, failure code/reason, progress/counts, last committed cursor and its watermark range; drill into durable batch/run evidence. Use the existing canonical import/job contracts. T-106 owns terminal-status truth; T-108 owns durable cursor/replay; T-125 owns operational metrics/API observability. No second status or cursor authority and no advanced M3 recovery UI is introduced. | I17: Quarantine rows under three different codes, correct one mapping, reprocess, and confirm only the affected rows clear. The M1 continuity snapshot of this page must still match. v2.22.0 — GET quarantine list/detail filtered by code, dataset and batch with staging lineage/correction hint; tenant denial; remove mapped source object/field -> typed execution refusal and persisted C2 event; corrected reprocess uses declared version and records outcome. v2.22.1 — Drive B4 against a successful batch, a failed batch and a capped/partial batch; displayed outcome, counts, error and last committed cursor equal the canonical response after reload. A failed batch is never green; a retry/correction links to the same durable evidence. Tenant denial and empty/loading/failure states are asserted. Consume frozen T-106/T-108/T-125 response contracts for parallel UI work; final live integration is certified by T-247/T-150, not by a mock-only result. | J17: 12 | K17: Not Started | L17: Worker 2 | M17: T-099; T-100 | N17: T-107; T-109; T-128; T-183 | O17: M2: ~1 month from owner planning checkpoint; exact date not committed | P17: Release 1 MUST | Q17: Frontend/UI feature | R17: 2 | S17: M2-P2 | T17: GATE PROSE INCOMPLETE — original text ends with an ellipsis. Do not infer omitted conditions. Column M lists completion prerequisites; AN/Contract Handoffs lists contract-only prerequisites. Full task acceptance in column I still applies. Recover the omitted prose before claiming this gate fully reconciled. Preserved original fragment: Use the accepted M1 regression baseline; require empty index and clean owned paths, preserving unrelated user work. Then: T-061 final M1 API/page contract + T-099 + T-100 canonical quarantine impleme... | U17: Own named UI/admin task end-to-end only after producer APIs/security are committed. | V17: Commit before downstream consumer starts; consumer must use the contract, not redesign producer-owned semantics. | W17: Day-1 Data Workbench — DB Link, Canvas, Jobs & OPC | X17: M2 P2 — Day-1 Data Workbench — DB Link, Canvas, Jobs & OPC. Release 1 is genuine early production / first-week customer work. | AA17: L2.3 | AB17: Canonical projection with validation, quarantine and reprocessing | AC17: L1.6; L1.2; L1.7 | AD17: Build | AE17: D2; D5 | AF17: Core | AG17: R1 | AH17: Advances | AI17: =IF(Y17="","",Y17) | AJ17: RE-ESTIMATE REQUIRED — J/R retain the prior-scope figures for traceability; excluded from usable planning totals. New full-scope and remaining-work estimates are not supplied. | AK17: v4.11.1 | AL17: Chapters 3/4 v4.10.3 — MD + illustrated Word; UI Coverage / UI Controls in this workbook v2.23.0 — T-265 owns B4/C2/C3 visual depth. Implement its applicable batch outcome/error/committed cursor and catalogue-driven quarantine list/detail/refusal/reprocess states under the existing T-101 scope; all row actions and counts use canonical tenant-scoped payloads. Do not limit the renderer to eight PV codes. | AM17: =IF(AND(ISNUMBER(J17),OR(AR17="INHERITED ESTIMATE",AR17="CONFIRMED ESTIMATE")),1,0) -> 0 | AO17: Not started — no completion claimed | AP17: Inherited v2.22.0 intended record; no new runtime certification in this repair. | AR17: RE-ESTIMATE REQUIRED | AS17: =IF(AM17=1,J17,"") | AT17: =IF(AND(AM17=1,ISNUMBER(R17)),R17,"") | AU17: PARTIAL REUSE; CURRENT EXPANDED SCOPE OPEN | AV17: 12 | AW17: 18 | AX17: 28 | AY17: UNCONFIRMED REVIEW ESTIMATE - not P80 or elapsed | AZ17: Read API/filter/detail 3/4/6 + B4/C2/C3 UI 4/6/10 + drift/retry integration 3/5/8 + tests/closure 2/3/4. | BA17: Backend/PlantProcess.Api/Endpoints/Quarantine/QuarantineEndpoints.cs:8-33 — MapQuarantineEndpoints Backend/PlantProcess.Application/Integration/Services/Staging/StagingRecordService.cs:85-110 — durable staging identity | BB17: 14-Sep-2026 snapshot; later closure evidence separate; no live HEAD verification
A18: T-102 | B18: M2 | C18: P2 | D18: Identity resolution across sources | E18: Backend | F18: Genealogy | G18: Very Important | H18: Harden material identity resolution using material_aliases so the same physical material arriving under two different source identifiers becomes one canonical unit. The schema already supports this: material_units carries a unique key on (site_id, material_code) plus a filtered unique on (source_system, source_record_id), which makes projection idempotent without forbidding rows that have no source identity. | I18: Import the same material under two different source identifiers and confirm one canonical unit results with both aliases recorded. Re-run the import and confirm no duplicate appears. | J18: 8 | K18: Not Started | L18: Worker 1 | M18: T-087; T-095 | N18: T-103; T-107; T-109; T-128; T-183 | O18: M2: ~1 month from owner planning checkpoint; exact date not committed | P18: Release 1 MUST | Q18: Backend/domain contract | R18: 1.2 | S18: M2-P2 | T18: Use the accepted M1 regression baseline; require empty index and clean owned paths, preserving unrelated user work. Then: T-087 canonical plant schema + T-095 relationship/material identity authority. | U18: Own canonical DB/backend/security/API/infra. No W2-owned UI/admin task files and no W3 ML/Assistant runtime. | V18: Commit before downstream consumer starts; consumer must use the contract, not redesign producer-owned semantics. | W18: Day-1 Data Workbench — DB Link, Canvas, Jobs & OPC | X18: M2 P2 — Day-1 Data Workbench — DB Link, Canvas, Jobs & OPC. Release 1 is genuine early production / first-week customer work. | AA18: L2.4 | AB18: Genealogy resolution and attribution | AD18: Build | AE18: D3; D5 | AF18: Core | AG18: R1 | AH18: Advances | AI18: =IF(Y18="","",Y18) | AJ18: Inherited baseline estimate | AK18: v4.11.1 | AL18: Chapters 3/4 v4.10.3 — MD + illustrated Word; UI Coverage / UI Controls in this workbook | AM18: =IF(AND(ISNUMBER(J18),OR(AR18="INHERITED ESTIMATE",AR18="CONFIRMED ESTIMATE")),1,0) -> 1 | AO18: Not started — no completion claimed | AP18: Inherited v2.22.0 intended record; no new runtime certification in this repair. | AR18: INHERITED ESTIMATE | AS18: =IF(AM18=1,J18,"") -> 8 | AT18: =IF(AND(AM18=1,ISNUMBER(R18)),R18,"") -> 1.2 | AU18: EXISTING ALIAS FOUNDATION; IDENTITY-SAFETY GAP | AV18: 4 | AW18: 7 | AX18: 12 | AY18: UNCONFIRMED REVIEW ESTIMATE - not P80 or elapsed | AZ18: Scope-safe lookup/merge 2/4/7 + ambiguity/idempotency tests 1/2/4 + closure 1/1/1. | BA18: Backend/PlantProcess.Application/Integration/Services/Mapping/MappingRowProjector.cs:244-264 — MapMaterialAliasAsync Backend/PlantProcess.Application/Integration/Services/Mapping/MappingRowProjector.cs:721-744 — ResolveMaterialIdAsync Backend/PlantProcess.Infrastructure/Persistence/Configurations/Materials/MaterialAliasConfiguration.cs:27-36 — composite unique Backend/PlantProcess.Infrastructure/Persistence/Configurations/Materials/MaterialUnitConfiguration.cs:43-47 — site/source uniqueness | BB18: 14-Sep-2026 snapshot; later closure evidence separate; no live HEAD verification
