Workbook

Sheet Read Me
A1: PlantProcess IQ - Product Backlog v13
A3: WHAT v13 CHANGES (03-Jul-2026, supersedes v12)
A4: 1. NEW TARGET COLUMN: every task carries a meeting target - done / 8-Jul (technical evaluation) / 14-Jul (V2 completion) / post-deal. The 8-Jul meeting (sales + technical engineer) is the V2 AUDIENCE arriving six days early; the backlog is re-cut around it.
A5: 2. SESSION LEDGER RECORDED AS DONE ROWS (V1-31..V1-34): website content refresh; header nav styling drift fix; BOM hygiene test backup exclusion; the Administrator consolidation that mounted the four orphaned journey tabs and gated PPIQ-T### codes + DEMO/DEVELOPMENT badges. Each carries its machine-verified evidence.
A6: 3. GOLDEN-RULE ERADICATION TASKS (V1-35..V1-39): the 03-Jul audit found real demo MACHINERY inside the product (hardcoded scenario fixtures, DemoModeContext, /demo-lifecycle, demo-reset in-app, "Demo Plant") plus generic code trapped in demo-named files, plus a too-narrow CI guard. All violations of the no-demo-code golden rule, now backloged for removal/rename/gating with a strengthened CI gate.
A7: 4. JOB GOVERNANCE (V2-30..V2-33, from the 03-Jul journey spec): interval floors DB-Link 2min / Loading 3min / Engine 20min / AI+ML 60min (config-driven, backend-enforced); per-type max-parallelism + per-SOURCE single-scan lock + start jitter; Loading no-op fast path via watermark compare; Run-now that respects the guards. V1-41 ships the minimum stuck-run reaper for 8-Jul (347 zombie Running rows are live evidence).
A8: 5. STAGE-2 RESHAPED (V2-28): Karim-locked - one Loading job PER MAPPING VIEW with its own watermark, generic projector consumes SchemaViewDefinition, the IF/ELSIF ladder dies, the 8 demo sources become seed mappings. Open decision inside the row: edit-a-mapping reprojection policy (full vs forward-only).
A9: 6. STALE ROWS CORRECTED: V1-09 genealogy foundation is VERIFIED-PRESENT (29-Jun live DB check), not a rebuild; V1-14 action-matrix reopened because the admin surface changed on 03-Jul; V1-17..V1-23 remaining hours reduced to the live-verification effort now that the UI is wired.
A11: HOW TO READ A TASK (unchanged from v12): Description = what a junior/mid dev does, where, and how. Validation/Acceptance = hard, falsifiable checks. Many acceptances demand LIVE HMI behaviour on the demo dataset (code present + tested is not done until proven live).
A13: THE 8-JUL BAR: the engineer clicks every button and questions every value. Ship the 7-step journey live end-to-end, zero dead buttons, no internal codes, no demo machinery behavior, honest states in Jobs Monitor, correlation producing real results, and an assistant that is either verified live or framed honestly. Numbers-fully-justified (Value Engine, universal provenance, generic projector) completes by 14-Jul; for 8-Jul the honesty answer (population + method + abstain) is the shield.

Sheet Backlog
A1: PlantProcess IQ - Product Backlog v13 . 8-Jul technical evaluation re-cut + golden-rule eradication + job governance
A2: Task ID | B2: Version | C2: Phase | D2: Task Name | E2: Persona(s) | F2: Sub-criterion lifted | G2: Gate | H2: Track | I2: Module | J2: Severity | K2: Status | L2: % done | M2: Target | N2: Description (junior-dev-actionable) | O2: Validation / Acceptance (hard, reproducible) | P2: Task Type | Q2: Effort (h) | R2: Remaining (h) | S2: Prereq | T2: Lineage
A3: V1-01 | B3: V1 | C3: V1-P1 Stable environment (nothing breaks) | D3: Local dev reproducibility: EF-first + PGCLIENTENCODING + design-time factory (MERGED) | E3: A1,A4 | F3: A1-2, A1-10 | G3: G9 | H3: Environment | I3: Infra | J3: Critical | K3: MOSTLY-DONE | L3: 0.8 | M3: 14-Jul | N3: MERGES old V1-01+V1-02 and the LOCAL residue of V1-03. The SERVER path is already green (the pipeline runs EF in a sibling before the numbered SQL, handles encoding, and uses ConnectionStrings__PlantProcessDb). Remaining is LOCAL-only and small: (a) fold `dotnet ef database update` into the start of `ppiq.ps1 migrate`/`demo`; (b) export PGCLIENTENCODING=UTF8 before every psql in ppiq.ps1; (c) rewrite PlantProcessDesignTimeDbContextFactory to read ConnectionStrings__PlantProcessDb -> PLANTPROCESS_DESIGNTIME_CONNECTION_STRING -> PLANTPROCESS_DB with an honest error; (d) converge the LOCAL compose remnants (delete duplicate demo-sources fleet + Infrastructure/deploy/docker-compose.demo.yml). Commit so the two session env-vars are no longer needed locally. | O3: From a clean LOCAL DB, `ppiq.ps1 demo` provisions one-shot (EF schema -> SQL decoration -> app on :5063) with ZERO hand-set env vars, twice. grep finds no duplicate demo compose. Evidence: clean-run terminal log + grep. | P3: refactor | Q3: 6 | R3: 1.2 | S3: - | T3: V1-01
A4: V1-02 | B4: V1 | C4: V1-P1 Stable environment (nothing breaks) | D4: Delete env/profiles/local.env (leaks plantprocess123) + rotate | E4: A1,A2 | F4: A2-5 | G4: G12 | H4: Environment | I4: Security | J4: Critical | K4: NEW | L4: 0.1 | M4: 14-Jul | N4: Remove env/profiles/local.env (it carries IsBootstrapAdmin=true and the literal plantprocess123) and rotate any key that ever touched it. Keep only deploy/compose/.env.dev (container-local creds) and the git-ignored server /var/lib/ppiq-preserve/.env. Also strip the stale 4-user set from appsettings.Development.json so it stops shadowing the canonical five locally. | O4: grep finds zero `plantprocess123` and zero `IsBootstrapAdmin=true` in the repo; the startup guard still passes; a bare `dotnet run` shows the canonical five users. Evidence: grep output + boot log. | P4: hardening | Q4: 3 | R4: 2.7 | S4: - | T4: V1-02
A5: V1-03 | B5: V1 | C5: V1-P1 Stable environment (nothing breaks) | D5: Commit LOCAL test config — fix the clean-machine failures (server suite already green) | E5: A1 | F5: A1-2 | G5: G9 | H5: Testing | I5: Testing | J5: Critical | K5: PARTIAL | L5: 0.4 | M5: 14-Jul | N5: The SERVER pipeline already runs the backend (~567) and frontend (202) suites green. The remaining gap is the LOCAL clean-machine path: author committed appsettings.Test.json (DSN + 64-char signing key + a real admin + PPIQ_FORCE_EXTERNAL_API_TEST_HOST) and wire Do-Test so WebApplicationFactory boots the host and finds the DB without per-run env vars. This was the documented cause of the local 83 reds. | O5: `ppiq.ps1 test` exits 0 TWICE on a fresh LOCAL checkout (no hand-set vars). Evidence: two consecutive green run logs. | P5: hardening | Q5: 5 | R5: 3 | S5: V1-01 | T5: V1-03
A6: V1-04 | B6: V1 | C6: V1-P1 Stable environment (nothing breaks) | D6: Persistent infra Caddyfile + correct route targets [NEW 26-Jun] | E6: A2,A4 | F6: A4-9 | G6: G9 | H6: Infra | I6: Infra | J6: Very important | K6: NEW | L6: 0 | M6: 14-Jul | N6: NEW from the 26-Jun session. The live infra Caddyfile is an orphaned inode (host bind source deleted) with STALE targets (plantprocess-app-web, plantprocess-website) that don't match the real containers (plantprocess-web, plantprocess-api); app.* still serves 200 but it's fragile and hot-reloads are non-persistent. Re-establish a persistent host-bound Caddyfile in the infra project with CORRECT targets, so routes survive a Caddy recreate. Do NOT recreate ppiq-caddy until this lands. | O6: After recreating ppiq-caddy, app.*/api.*/website.* all route to the correct live containers; the Caddyfile is host-bound and survives a restart. Evidence: docker exec cat + curl matrix. | P6: hardening | Q6: 6 | R6: 6 | S6: - | T6: V2-13
A7: V1-05 | B7: V1 | C7: V1-P1 Stable environment (nothing breaks) | D7: Harden .env<->Postgres-volume password coupling + provisioning resilience [NEW 26-Jun] | E7: A4 | F7: A4-9 | G7: G9 | H7: Infra | I7: Infra | J7: Important | K7: NEW | L7: 0 | M7: 14-Jul | N7: NEW from the 26-Jun session. Two small hardenings: (1) make ensure-runtime-env.sh PRESERVE POSTGRES_PASSWORD across a stale-key regeneration (today a regen rotates it and diverges from the existing Postgres volume -> 28P01); document the rule that /var/lib/ppiq-preserve/.env must not be deleted, and if it is, the volume must be wiped in the same step. (2) Wrap FirstRunProvisioningHostedService provisioning in try/catch so a provisioning failure logs but never crashes the API at startup. | O7: A simulated stale-key regen keeps the same POSTGRES_PASSWORD and the API still connects; an induced provisioning error is logged and the API still starts. Evidence: regen log + fault-injection test. | P7: hardening | Q7: 5 | R7: 5 | S7: - | T7: V2-14
A8: V1-06 | B8: V1 | C8: V1-P1 Stable environment (nothing breaks) | D8: Spamhaus / outbound-mail relay remediation (relay + SPF/DKIM/PTR + block 25) | E8: A4, A6 | F8: A6.10 CTA/lead capture | G8: G9 | H8: hardening | I8: Infra | J8: Very important | K8: NEW | L8: 0 | M8: 14-Jul | N8: The Hetzner/Spamhaus abuse notice (23 Jun) requires lead-capture email to stop sending direct on port 25. Route all outbound mail (the website lead-capture, V5OutboundLeadSystemEndpoints) through an authenticated transactional relay on 587/465, publish SPF and DKIM DNS records for plantprocessiq.com, set a valid PTR/reverse-DNS for the sending IP, and block outbound port 25 at the firewall. Relay host/port/credentials live in env/secret config, never hardcoded. Confirm delisting with a PUBLIC Spamhaus checker, not Hetzner's resolvers. | O8: A lead submitted on the live site is delivered to the inbox via the 587/465 relay (headers show the relay, not direct 25); `dig TXT` shows valid SPF + DKIM for plantprocessiq.com; the sending IP has a matching PTR; outbound 25 is closed (egress test); a public Spamhaus lookup shows the IP/domain not listed. | P8: hardening | Q8: 5 | R8: 5 | T8: (new)
A9: V1-07 | B9: V1 | C9: V1-P1 Stable environment (nothing breaks) | D9: Phase gate: clean checkout boots seeded + green twice + SERVER deploy green | E9: A1,A4 | F9: A1-2, A1-9 | G9: G9 | H9: Environment | I9: Deploy | J9: Critical | K9: NEW | L9: 0.3 | M9: 14-Jul | N9: End-of-phase regression. LOCAL: clean clone -> `ppiq.ps1 reset && ppiq.ps1 demo` boots the seeded stack; `ppiq.ps1 test` green twice; genealogy walk resolves; capture the `seed exit=0` line. SERVER: confirm `git push` -> Jenkins `plantprocessiq-deploy` reaches PIPELINE GREEN (already true at build #96; the gate is to keep it green after the foundation/test work lands). Seals V1-P1 as deployable in both environments. | O9: All LOCAL gates pass on a fresh machine, scripted, with seed exit=0; the SERVER pipeline is green on the same commit. Evidence: one combined run log + the green Jenkins build. | P9: verification | Q9: 4 | R9: 2.8 | S9: V1-01, V1-03, V1-04 | T9: V1-07
A10: V1-08 | B10: V1 | C10: V1-P1 Stable environment (nothing breaks) | D10: Wire website CTA to a real inbox (CODE DONE — commit + SMTP + relay) | E10: A6 | F10: A6-10 | G10: G8 | H10: Web | I10: Web | J10: Very important | K10: MOSTLY-DONE | L10: 0.65 | M10: 14-Jul | N10: Per the handover the lead-email CODE is DONE and builds clean (V5OutboundLeadSystemEndpoints.cs TrySendLeadEmailAsync; env PlantProcess__Lead__Smtp__*; form POSTs to /api/v5/outbound/leads). Remaining: COMMIT it; supply live SMTP env; do a real-send test. IMPORTANT: route via an authenticated transactional relay (587/465) with SPF+DKIM+PTR and outbound port 25 blocked - never send from the VPS IP (Hetzner/Spamhaus notice). (Hardened backend + e2e assert is the separate V2 task.) | O10: A test submit lands in your inbox/DB via the relay; Spamhaus web-checker shows the IP not listing. Evidence: the received lead + checker screenshot + commit hash. | P10: feature | Q10: 4 | R10: 1.4 | S10: - | T10: V1-18
A11: V1-09 | B11: V1 | C11: V1-P2 The 7-step journey walk (end-to-end, no dead end) | D11: Rebuild mapping/genealogy/safe-SQL foundation (demo-minimum, model-first) [P0 — biggest real gap] | E11: A3,A4 | F11: A3-5, A4-2, A4-6 | G11: G2 | H11: Workflow | I11: Database | J11: Critical | K11: VERIFIED-PRESENT | L11: 0.9 | M11: done | N11: STALE-REBUILD FRAMING CORRECTED (29-Jun live DB check on ppiq_app): the foundation EXISTS and WORKS - ppiq_walk_genealogy (self + both heats for C-0044170 with viaEdgeId provenance), ppiq_resolve_material_by_business_key, ppiq_resolve_safe_sql, ppiq_v5_blended_attribution_for_child (0.70/0.30 across H-3361/H-3362), ppiq_golden_thread, plus ppiq_business_key_definitions / canonical_business_keys / canonical_genealogy_edges / canonical_material_units / genealogy_edges. Remaining: only canonical_mapping_versions (mapping-lifecycle versioning) is absent - defer to V2 (generic projector task); write the one-paragraph verification note into the docs. | O11: SELECT ppiq_walk_genealogy(tenant, 'C-0044170', 'both', 6) returns both heats with provenance; blended attribution returns 0.70/0.30; note committed. No rebuild performed.' | P11: feature | Q11: 4 | R11: 0.5 | S11: V1-01 | T11: V1-04
A12: V1-10 | B12: V1 | C12: V1-P2 The 7-step journey walk (end-to-end, no dead end) | D12: Verify genealogy both directions on C-0044170 live | E12: A3 | F12: A3-5 | G12: G2 | H12: Workflow | I12: FrontEnd | J12: Critical | K12: PARTIAL | L12: 0.85 | M12: 8-Jul | N12: With the foundation rebuilt, walk C-0044170 coil->melt and melt->coils in the running HMI, confirming the Material Investigation evidence panel renders both directions on the customer's own keys. | O12: Recorded walk: both directions resolve on the demo data, no stall. Evidence: clip in the dry-run. | P12: verification | Q12: 2 | R12: 0.3 | S12: V1-04 | T12: V1-05
A13: V1-11 | B13: V1 | C13: V1-P2 The 7-step journey walk (end-to-end, no dead end) | D13: Verify transition-coil weighted attribution (70/30) live | E13: A3 | F13: A3-8 | G13: G15 | H13: Workflow | I13: FrontEnd | J13: Very important | K13: PARTIAL | L13: 0.8 | M13: 8-Jul | N13: Confirm a casting-transition coil reports weighted (e.g. 70/30) attribution across two heats (H-3361/H-3362) with the population/exclusions shown, never a single fabricated heat. The backend test is already green; the live HMI clip is owed. | O13: A transition coil renders weighted provenance + stated population live. Evidence: clip. | P13: verification | Q13: 2 | R13: 0.4 | S13: V1-04 | T13: V1-06
A14: V1-12 | B14: V1 | C14: V1-P2 The 7-step journey walk (end-to-end, no dead end) | D14: App boots under Playwright (no early webServer exit) | E14: A1 | F14: A1-2 | G14: G9 | H14: Testing | I14: Testing | J14: Critical | K14: PARTIAL | L14: 0.55 | M14: 14-Jul | N14: Fix playwright config so webServer starts the API+web and waits for :5063/:5173 instead of exiting early; run at least one real spec against the booted app. | O14: `ppiq.ps1 e2e` starts the app and runs >=1 spec to green. Evidence: Playwright HTML report. | P14: hardening | Q14: 5 | R14: 2.2 | S14: V1-01 | T14: V1-08
A15: V1-13 | B15: V1 | C15: V1-P2 The 7-step journey walk (end-to-end, no dead end) | D15: One-click readiness check passes live | E15: A4 | F15: A4-7 | G15: G7 | H15: Workflow | I15: Backend | J15: Critical | K15: PARTIAL | L15: 0.5 | M15: 8-Jul | N15: Make the readiness surface return green (sources healthy, counts match, jobs ready) in one call on the seeded stack. | O15: Readiness endpoint returns all-green on the demo data, shown live. Evidence: screenshot + clip. | P15: feature | Q15: 5 | R15: 2.5 | S15: V1-04 | T15: V1-09
A16: V1-14 | B16: V1 | C16: V1-P2 The 7-step journey walk (end-to-end, no dead end) | D16: Verify every demo-path button live (click-through) + commit the action-matrix | E16: A3 | F16: A3-1, A3-3 | G16: G6 | H16: Workflow | I16: FrontEnd | J16: Critical | K16: PARTIAL | L16: 0.4 | M16: 8-Jul | N16: The action-matrix was green against the OLD admin surface (Connector Truth | Import Jobs | Tier Override). 03-Jul the Administrator was consolidated to six tabs (DB Configuration | Schema Configuration | Importing Data | Jobs Monitor | Connector Truth | License), so phase9ActionMatrix.ts + phase9-action-matrix.spec.ts must be updated to enumerate the NEW admin controls (every button in all six tabs), then the full click-through re-recorded. | O16: The action-matrix files are committed; every button on the 9-step script performs its action live; 0 unhandled rejections on the path. Evidence: recorded run + commit hash. | P16: verification | Q16: 3 | R16: 3 | S16: V1-04 | T16: V1-10
A17: V1-15 | B17: V1 | C17: V1-P2 The 7-step journey walk (end-to-end, no dead end) | D17: Demo-path robustness fault gate - no crash from user/license/docker/DB | E17: A3, A4 | F17: A3.2 e2e no crash · A4.9 operational resilience | G17: G6 | H17: demo | I17: Testing | J17: Critical | K17: NEW | L17: 0 | M17: 8-Jul | N17: Guarantee the demo path never crashes from any cause a Procurement viewer could trigger. Enumerate the fault classes - bad login, a role/tier-gated control clicked, a license expiry/grace state, a Jenkins/Docker restart mid-session, a transient DB connection drop (the orphan-stack / conn-key / SigningKey issues) - and make each degrade gracefully (typed error, retry, or read-only banner) instead of a white screen, unhandled 500, or dead UI. Add an error boundary on every demo route and health/retry on the API client. This is enforcement, not a one-off fix. | O17: Inducing each fault (kill the API container, expire the license, drop the DB connection, click a gated control as a low-tier role) produces a graceful message and the app recovers when the fault clears - zero white screens, zero uncaught 500s reaching the user, zero frozen buttons. A checklist enumerates every fault class and its observed graceful behaviour. | P17: test | Q17: 6 | R17: 6 | T17: (new)
A18: V1-16 | B18: V1 | C18: V1-P2 The 7-step journey walk (end-to-end, no dead end) | D18: Record the clean dry-run video (insurance) — Karim-owned | E18: A3,A5 | F18: A3-2 | G18: G7 | H18: Demo | I18: Docs | J18: Critical | K18: NEW | L18: 0 | M18: 8-Jul | N18: Per the handover this CANNOT be AI-done. Record an MP4 of the full 9-step walk on the seeded stack against the live server demo URL (app.178.105.152.180.sslip.io) logged in as sysadmin - the pilot acceptance artifact and the backup if live ever fails. Blocks the demo-reel cut. | O18: MP4 exists; no dead click; matches the script. Evidence: the file. | P18: content | Q18: 3 | R18: 3 | S18: V1-10 | T18: V1-11
A19: V1-17 | B19: V1 | C19: V1-P2 The 7-step journey walk (end-to-end, no dead end) | D19: J1 - Auto-login lands on a working home (sysadmin, no login page) | E19: A4, A3 | F19: A2.4 token/session | G19: G12 | H19: workflow | I19: FrontEnd | J19: Important | K19: PARTIAL | L19: 0.7 | M19: 8-Jul | N19: Verify + harden step 1: the app auto-authenticates as the permanent sysadmin (FirstRunProvisioning SOU support account) and lands directly on a populated, navigable home - no login page in V1. No 401, no blank screen, no console error on first load. The auto-login uses the real auth/session machinery (signed token + __Host- cookie), not a bypass. | O19: A cold load of the demo URL reaches a working authenticated home as sysadmin with the nav visible and at least one populated panel; no login prompt appears; the browser console shows no errors; the session is a real signed token (verifiable in the cookie), not a stub. | P19: test | Q19: 2 | R19: 0.6 | T19: (new)
A20: V1-18 | B20: V1 | C20: V1-P2 The 7-step journey walk (end-to-end, no dead end) | D20: J2 - Connect + select the demo data source(s) via the DB Configuration tab | E20: A4, A3 | F20: A4.1 source onboarding HMI | G20: G1 | H20: workflow | I20: FrontEnd | J20: Critical | K20: PARTIAL | L20: 0.6 | M20: 8-Jul | N20: UI now mounted (03-Jul consolidation) - remaining is the LIVE walk: register a source, test-connect (incl. against a stopped container -> typed error), table picker populates from live source metadata. PRIOR SCOPE: Verify + harden step 2: the DB Configuration tab (AdminDbConfigurationTab.tsx, 1126 lines) lets the user register/select one, two, or all 8 demo sources, run a connection test, and choose which tables to import. Confirm the tab invokes the connector/registry backend (ConnectorAdminEndpoints -> ppiq_register_dump_source / ProvisionBaseline) and shows a clear success/failure state. Fix any dead control, any test button that does nothing, any table-picker that does not populate. The 6 connectors (Csv/Excel/MySql/Oracle/Postgres/historian) already exist - this is wiring + UX verification. | O20: From the HMI: select a demo source, run the connection test and see a green result; choose tables and see them registered (verify via SELECT * FROM source_table_dump_registry); repeat for two and for all eight; every control does something (no dead button); a deliberately bad connection shows a typed error, not a crash. | P20: test | Q20: 4 | R20: 1 | T20: (new)
A21: V1-19 | B21: V1 | C21: V1-P2 The 7-step journey walk (end-to-end, no dead end) | D21: J3 - Run Stage-1 import to staging + see it in Jobs Monitor + job log | E21: A4, A3 | F21: A4.4 Jobs Monitor | G21: G1 | H21: workflow | I21: FrontEnd | J21: Critical | K21: PARTIAL | L21: 0.5 | M21: 8-Jul | N21: Scheduling UI now reachable via Importing Data tab - remaining is the live Stage-1 run + incremental second-run proof (watermark tail-only). PRIOR SCOPE: Verify + harden step 3: trigger Stage-1 (ppiq_run_stage1_delta_import) from the Importing Data tab; confirm the dump/staging tables fill, the Jobs Monitor tab (AdminJobsMonitorTab 350) + TwoStageImportMonitorPanel (376) show last-run status/duration/rows, and the job log records the run. Confirm incremental behaviour: a second run imports only the new tail (two_stage_processed_watermarks / last-index comparison), not the whole table. | O21: A Stage-1 run populates staging (row count > 0 in the dump tables); the Jobs Monitor shows the run with status, rows, duration; a second immediate run imports 0 or only-new rows (watermark proven); the job log has an Info entry; a forced failure (bad source) shows an Error entry in the monitor and the log. | P21: test | Q21: 4 | R21: 1.5 | T21: (new)
A22: V1-20 | B22: V1 | C22: V1-P2 The 7-step journey walk (end-to-end, no dead end) | D22: J4 - No-code Mapper UI loads the demo staging schema and previews/joins/filters | E22: A4, A3 | F22: A3.4 widget/mapping config | G22: G2 | H22: workflow | I22: FrontEnd | J22: Critical | K22: PARTIAL | L22: 0.5 | M22: 8-Jul | N22: Verify + harden step 4: the Schema Configuration tab (AdminSchemaConfigurationTab.implementation.generated 955) + CanonicalSchemaMappingPanel (514) + V5NoCodeMapperPage must read the real demo STAGING schema (tables + columns from the dump), let the user define a view/join/filter, preview rows, and validate via SafeSqlValidator/SqlAllowlistProvider. This is the verify-needed seam: confirm the UI binds to live staging metadata, not a placeholder. Fix any panel that loads empty. | O22: On the demo staging data the mapper lists the actual source tables and columns; defining a view previews real rows; a join across two dump tables previews correctly; a malformed SQL is rejected by safe-SQL with a typed error (not a 500); no dead control on the tab. | P22: test | Q22: 6 | R22: 2.5 | T22: (new)
A23: V1-21 | B23: V1 | C23: V1-P2 The 7-step journey walk (end-to-end, no dead end) | D23: J5 - Run Stage-2 canonical refresh + monitor + log (TEMP demo shapes - V1 ONLY) | E23: A4, A3 | F23: A4.4 Jobs Monitor | G23: G2 | H23: workflow | I23: FrontEnd | J23: Critical | K23: PARTIAL | L23: 0.5 | M23: 8-Jul | N23: GENERIC-ONLY RED LINE: the hardcoded demo-shape projection used here is a TEMPORARY V1-ONLY measure to hit 1 Jul and MUST be eradicated in V2 (see the V2 generic-projector task). | O23: nan | P23: test | Q23: 4 | R23: 2 | T23: (new)
A24: V1-22 | B24: V1 | C24: V1-P2 The 7-step journey walk (end-to-end, no dead end) | D24: J6 - Build/open a dashboard + widget bound to the freshly-imported canonical data | E24: A4, A3 | F24: A3.1 zero dead buttons | G24: G3 | H24: workflow | I24: FrontEnd | J24: Critical | K24: PARTIAL | L24: 0.4 | M24: 8-Jul | N24: Verify + harden step 6: on the now-populated canonical data, create a page (PageBuilderPage.implementation 435), drag a widget (WidgetBuilder wizard - data/filter/preview steps), bind it to a canonical view via the widget script layer (WidgetScriptSqlCompiler 240), and save. CRITICAL seam-6 check: confirm widgets read the canonical_* views that Stage-2 populates - NOT pre-seeded tables - so a live re-import visibly changes the widget. Use DashboardGridLayout (552-state) for drag-drop persistence. | O24: A newly created page+widget renders rows that came through the import; re-running the import and refreshing visibly changes the widget's numbers (proving it reads canonical views, not seed); save+reload persists the page and layout; no dead button in the page/widget builder; the widget's query passes the safe-SQL compiler. | P24: test | Q24: 6 | R24: 3 | T24: (new)
A25: V1-23 | B25: V1 | C25: V1-P2 The 7-step journey walk (end-to-end, no dead end) | D25: J7 - Run a correlation / inspection + read grounded results on the imported data | E25: A4, A3 | F25: A3.7 correlation honest | G25: G4 | H25: workflow | I25: FrontEnd | J25: Critical | K25: PARTIAL | L25: 0.5 | M25: 8-Jul | N25: Verify + harden step 7: from Advanced Analysis (AdvancedAnalysisPage 214) + Inspection Jobs (InspectionJobsPage 88), configure an inspection (a defect/downtime/KPI + a duration window), run it on the imported canonical data using the already-built engines (CorrelationService 564 + AdvancedCorrelationComputeService 390), and read a grounded suspected-contributor result. The GroundedAssistantPage (129) must explain it with citations and render no uncited number (GroundingService). Wire the engines to the imported demo data live. | O25: An inspection job runs on imported data and returns a suspected contributor with population + method shown (Spearman/MI/etc., q-value, bootstrap stability); the grounded assistant explains it citing evidence handles and renders no uncited number; clicking a number opens its provenance; results match the demo expectation (the defect linked to its superheat driver). | P25: test | Q25: 5 | R25: 2.5 | T25: (new)
A26: V1-24 | B26: V1 | C26: V1-P2 The 7-step journey walk (end-to-end, no dead end) | D26: J-WALK - End-to-end journey walk under induced faults (the no-dead-end gate) | E26: A4, A3 | F26: A3.2 e2e no crash | G26: G6 | H26: workflow | I26: Testing | J26: Critical | K26: NEW | L26: 0 | M26: 8-Jul | N26: The actual V1 test: walk all 7 steps as ONE continuous flow on a clean demo stack (source -> staging -> map -> canonical -> dashboard -> analysis), then induce the fault classes (bad login, role/tier gate, container restart, DB blip) at each step. Enumerate EVERY break, dead button, and crash in ONE pass (preventive-maintenance mandate - do not fix one runtime error at a time) and fix each at source. This gate is the no-dead-end guarantee for the Procurement demo. | O26: The full source-to-analysis walk completes with zero dead buttons, zero white screens, zero uncaught 500s reaching the user; each induced fault degrades gracefully and the stack recovers when it clears; ppiq e2e and the dead-button scanner are both clean; a recorded walk shows no dead click. | P26: test | Q26: 6 | R26: 6 | T26: (new)
A27: V1-25 | B27: V1 | C27: V1-P3 Presentation pack (deck, ROI, video) | D27: Finalize the 9-step demo script (DELIVERED — fill 2 placeholders) | E27: A5 | F27: C5 | G27: G7 | H27: Demo | I27: Docs | J27: Very important | K27: MOSTLY-DONE | L27: 0.8 | M27: 8-Jul | N27: Per the handover the script PlantProcess-IQ-Live-Demo-Script.md is DELIVERED (connect->map->build page->...). Remaining: fill the 2 placeholders (roadmap specifics + your real per-plant price) and rehearse it cold once, including the surprise-question answers (incl. the new 'do you ship a customer-usable admin?' -> no; only the sysadmin support account, customer admin added at commissioning). | O27: You run it cold once end-to-end with the placeholders filled. Evidence: the script doc + a rehearsal note. | P27: content | Q27: 2 | R27: 0.4 | S27: V1-11 | T27: V1-12
A28: V1-26 | B28: V1 | C28: V1-P3 Presentation pack (deck, ROI, video) | D28: Finalize the ROI model + slide (DELIVERED — fill real price) | E28: A5 | F28: A5-1, A5-7 | G28: G5 | H28: Web | I28: Docs | J28: Very important | K28: MOSTLY-DONE | L28: 0.8 | M28: 8-Jul | N28: Per the handover PlantProcess-IQ-ROI-Model.xlsx + PlantProcess-IQ-ROI-Slide.pptx are DELIVERED (base case EUR 480,000/yr vs a EUR 300k placeholder price; labelled projected-not-proven). Remaining: replace the placeholder price with your real per-plant price and re-verify the figure still exceeds it. Also fits the 07-editions-and-licensing doc (which carries [[PER_PLANT_ACV_RANGE]]). | O28: The model + slide carry a defensible EUR/yr number against your real price, assumptions stated, tied to the demo finding. Evidence: the files. | P28: content | Q28: 4 | R28: 0.8 | S28: - | T28: V1-13
A29: V1-27 | B29: V1 | C29: V1-P3 Presentation pack (deck, ROI, video) | D29: Finalize the founder credibility pack (DELIVERED as 09-founder doc — fill background) | E29: A5 | F29: A5-10 | G29: - | H29: Web | I29: Docs | J29: Very important | K29: MOSTLY-DONE | L29: 0.8 | M29: 8-Jul | N29: The customer doc 09-founder-and-company.md is DELIVERED and on-brand. Remaining: fill [[YEARS]] and [[BACKGROUND_DETAIL]] (your 14 yrs PSI Metals / SMS / EzzSteel, named plants/processes), [[COMPANY_LOCATION]], [[CONTACT_NAME_AND_EMAIL]], [[WEBSITE_URL]]; optionally produce the one-slide version placed before the offer slide. | O29: The doc (and optional slide) has your named plants + contact filled; on-brand. Evidence: the file. | P29: content | Q29: 2 | R29: 0.4 | S29: - | T29: V1-14
A30: V1-28 | B30: V1 | C30: V1-P3 Presentation pack (deck, ROI, video) | D30: Technical annex to the 1-Jul deck (engineer/CEO audience: architecture, stats methods, security) | E30: A5,A6 | F30: A6-1 | G30: G8 | H30: Web | I30: Docs | J30: Very important | K30: NEW | L30: 0 | M30: 8-Jul | N30: The 22-slide procurement deck exists (1-Jul). For 8-Jul add a short technical annex: architecture/topology slide (read-only, OT-safe, two-stage pipeline), statistics discipline slide (methods, FDR, readiness gates, abstain), security slide (Argon2id, signed license, RBAC, no-egress AI), and the honest-status slide (implemented vs validation-ongoing, per capability with data volumes). Fix contact placeholders (email/phone) from slide 22. | O30: Rehearsed once; <=12 slides; on-brand. Evidence: the file. | P30: content | Q30: 3 | R30: 3 | S30: - | T30: V1-15
A31: V1-29 | B31: V1 | C31: V1-P3 Presentation pack (deck, ROI, video) | D31: Finalize the pilot offer (DELIVERED as 08-pilot doc — fill price/customer) | E31: A5 | F31: A5-7 | G31: - | H31: Web | I31: Docs | J31: Very important | K31: MOSTLY-DONE | L31: 0.8 | M31: 8-Jul | N31: The customer doc 08-pilot-offer.md is DELIVERED (read-only, time-boxed, fee-credited-on-conversion; scope/success/commercials tables). Remaining: fill [[PILOT_FEE]] (lean EUR30k for the first), [[CONVERSION_TARGET]] (the EUR120k/yr figure), [[CUSTOMER_NAME]], [[PILOT_DURATION]], and the source/target-question specifics per prospect. | O31: One offer with the price + conversion figure + ask filled for a named prospect. Evidence: the file. | P31: content | Q31: 2 | R31: 0.4 | S31: - | T31: V1-16
A32: V1-30 | B32: V1 | C32: V1-P3 Presentation pack (deck, ROI, video) | D32: Cut the 2-3 minute demo video (blueprint delivered) | E32: A6 | F32: A6-10 | G32: G8 | H32: Web | I32: Docs | J32: Important | K32: NEW | L32: 0 | M32: 14-Jul | N32: Per the handover the cut sheet PlantProcess-IQ-Demo-Reel-CutSheet.md is DELIVERED (2:45 EDL + VO + export + 'no dead click' QC). The MP4 render is yours and depends on the V1-13 recording. | O32: 2-3 min MP4; no dead click. Evidence: the file. | P32: content | Q32: 3 | R32: 3 | S32: V1-11 | T32: V1-17
A33: V1-31 | B33: V1 | C33: V1-P3 Presentation pack (deck, ROI, video) | D33: DONE 03-Jul: Website content refresh (aim/features/value-chain/pricing/diagram) | E33: A6 | F33: A6-6, A6-7 | G33: G14 | H33: Web | I33: Web | J33: Critical | K33: DONE | L33: 1 | M33: done | N33: Rewrote phase1WebsiteProof.ts + App.tsx + PricingLicenseMatrix + Showcase: canonical-tagline hero, How-It-Works 6-step pipeline, Beyond-BI differentiator (correlation/suggestions/grounded AI, "implemented, validation ongoing"), Proven-At-Scale (11,997/1,993/5,688/6), pricing rebuilt to locked deposit+subscription (Standard 12k+6k / Pro Plus 28k+14k Recommended / Enterprise 50k+25k), connector truth updated (PG/MSSQL/MySQL/Oracle run live in demo env). Content validator updated in the same change. | O33: validate-website-content.mjs PASS (80 checks incl. new tier/value-chain/AI-honesty needles); check-tagline PASS; tsc+vite build PASS on target machine 03-Jul 11:12. | P33: modification | Q33: 5 | R33: 0 | T33: NEW 03-Jul
A34: V1-32 | B34: V1 | C34: V1-P3 Presentation pack (deck, ROI, video) | D34: DONE 03-Jul: Header nav styling drift fix (.site-nav never styled) | E34: A6 | F34: A6-8 | G34: G14 | H34: Web | I34: Web | J34: Very important | K34: DONE | L34: 1 | M34: done | N34: Root cause: markup uses .site-nav/.phase10-nav but only .nav-links was ever styled -> raw underlined links, brand text inline. Appended nav-polish CSS (pill links, hover, cyan active, brand column stack, sticky border) to phase10.css, idempotent marker. | O34: Header renders spaced pill links with active page highlighted; validators green; applied 03-Jul. | P34: bug fix | Q34: 2 | R34: 0 | T34: NEW 03-Jul
A35: V1-33 | B35: V1 | C35: V1-P1 Stable environment (nothing breaks) | D35: DONE 03-Jul: BOM hygiene test excludes deploy\.ppiq-backups (+ stray BOM stripped) | E35: A1 | F35: A1-2 | G35: G9 | H35: Testing | I35: Backend | J35: Very important | K35: DONE | L35: 1 | M35: done | N35: Utf8NoBomRepositoryHygieneTests skip-list lacked .ppiq-backups, so ANY backup of a .sql/.json broke the suite (conflicts with backup-before-edit mandate). Added StartsWith deploy\.ppiq-backups + Contains \.ppiq-backups mirroring the existing pattern; stripped the BOM from stage2_fn_dump.sql. | O35: dotnet test --filter Utf8NoBomRepositoryHygieneTests PASS; full suite no longer fails on backups. | P35: bug fix | Q35: 1 | R35: 0 | T35: NEW 03-Jul
A36: V1-34 | B36: V1 | C36: V1-P2 The 7-step journey walk (end-to-end, no dead end) | D36: DONE 03-Jul: Consolidated Administrator - journey tabs wired; internal codes + env badges gated | E36: A3,A4 | F36: A4-1, A3-1 | G36: G6 | H36: Workflow | I36: FrontEnd | J36: Critical | K36: DONE | L36: 1 | M36: done | N36: Root cause of "Test Journey not implemented": three competing admin surfaces; the routed one was the shallow demo-orchestration page while DbConfigurationTab (1150), SchemaConfigurationTab (955), ImportingDataTab, JobsMonitorTab were mounted nowhere. AdminPageContent now mounts all four + Connector Truth + honest read-only License card. PageShell task eyebrows render only under VITE_SHOW_TASK_CODES=1; AppLayout DEVELOPMENT/DEMO/tier badges only under VITE_SHOW_ENVIRONMENT_BADGES=1 (data-* attrs preserved for e2e). | O36: tsc clean, vite build clean, vitest 202/202 PASS on target machine 03-Jul 13:05; /admin shows six tabs; no PPIQ-T### or DEMO/DEVELOPMENT badges visible. | P36: bug fix | Q36: 6 | R36: 0 | T36: NEW 03-Jul; unblocks V1-18..V1-24
A37: V1-35 | B37: V1 | C37: V1-P3 Product truth & golden rule (03-Jul findings) | D37: Demo-layer eradication A: remove demo MACHINERY from the app (golden rule) | E37: A1,A3 | F37: A1-6 | G37: G6 | H37: Hardening | I37: FrontEnd | J37: Critical | K37: NEW | L37: 0 | M37: 8-Jul | N37: Per the golden rule (no demo code/page/path/mode in the product, demo = external emulated sources only): remove src/demo/plantProcessDemoScenario* (hardcoded fake scenario fixtures consumed by DemoModeContext + LockedFeatureOverlay - fabricated state in the product), remove state/DemoModeContext (unwire from App.tsx + AppLayout), components/demo/* (EnvironmentBanner/ModeControl/ReadinessPanel/LifecycleKpiStrip), the /demo-lifecycle route + DemoLifecyclePage, api/demo/*. Demo-RESET moves OUT of the app into tools/ (PowerShell + compose script that resets the emulation source containers + re-seeds) - Karim decision pending: default = delete-from-app. LockedFeatureOverlay must read real license state, never scenario fixtures. | O37: grep -ri "demoScenario|DemoModeContext|demo-lifecycle" src/ returns ONLY the architecture test; tsc+build+vitest green; LockedFeatureOverlay renders from LicenseContext live; tools/reset-emulation-sources.ps1 resets + reseeds the fleet. | P37: refactor | Q37: 8 | R37: 8 | S37: V1-34 | T37: NEW 03-Jul audit
A38: V1-36 | B38: V1 | C38: V1-P3 Product truth & golden rule (03-Jul findings) | D38: Demo-layer eradication B: rename generic code trapped in demo-named files | E38: A1 | F38: A1-4 | G38: G6 | H38: Hardening | I38: FrontEnd | J38: Very important | K38: NEW | L38: 0 | M38: 14-Jul | N38: Class-1 renames with all references updated: DemoAnalyticsPages(.implementation) -> PlatformOpsPages; DemoAnalyticsWorkflowTruthPage -> ConnectorTruthPage; demo-analytics.css -> platform-ops.css; api/demo-analytics/demoAnalytics.api.ts -> split generic Suggestions/DynamicPage endpoints into platformOps.api.ts; Phase10LicenseDemoPage -> CommercialLicenseShowcasePage (also kills a phase code). Naming Golden Rule applies; customer must never see "demo" in a route, title, or bundle chunk name. | O38: No file/route/component in src/ contains "demo" except the architecture test + allowlist; bundle chunk names contain no Demo*; tsc+build+vitest green; /admin Connector Truth tab unchanged visually. | P38: refactor | Q38: 6 | R38: 6 | S38: V1-35 | T38: NEW 03-Jul audit; feeds V2-24
A39: V1-37 | B39: V1 | C39: V1-P3 Product truth & golden rule (03-Jul findings) | D39: Strengthened NO-DEMO-CODE CI gate (the guard that failed) | E39: A1 | F39: A1-2 | G39: G6 | H39: Hardening | I39: Testing | J39: Very important | K39: NEW | L39: 0 | M39: 14-Jul | N39: noHardcodedDemoPages.test.ts passed while the whole demo layer existed - its rule is too narrow. Rewrite as a real gate: FAIL if any file/symbol/route under src/ matches (?i)demo (allowlist: the test itself + an explicit documented list, empty after V1-35/36); FAIL on fixture datasets imported by product components. Wire into vitest architecture suite + the repo guard script so CI blocks regressions. | O39: Introduce a dummy src/pages/DemoFoo.tsx -> vitest fails with a clear message; remove it -> green. Gate runs in the Jenkins frontend stage. | P39: test | Q39: 3 | R39: 3 | S39: V1-36 | T39: NEW 03-Jul
A40: V1-38 | B40: V1 | C40: V1-P3 Product truth & golden rule (03-Jul findings) | D40: Plant display name from configuration (kill hardcoded "Demo Plant") | E40: A1,A6 | F40: A1-6 | G40: G6 | H40: Workflow | I40: FrontEnd | J40: Important | K40: NEW | L40: 0 | M40: 8-Jul | N40: AppLayout hardcodes "Demo Plant" in the plant strip. Plant/site display name must come from configuration (site/tenant record in ppiq_meta via an existing overview endpoint, fallback to a neutral default like the tenant name). Generic for mineral-water/cars/food installs. | O40: Change the site name in DB/config -> sidebar shows it after reload; grep "Demo Plant" in src/ returns nothing. | P40: modification | Q40: 3 | R40: 3 | T40: NEW 03-Jul
...

Sheet Version Summary
A1: Version Summary v13
A2: Version | B2: Tasks | C2: Scope (h) | D2: Remaining (h)
A3: V1 | B3: =COUNTIF(Backlog!B3:B126,A3) -> 43 | C3: =SUMIF(Backlog!B3:B126,A3,Backlog!Q3:Q126) -> 176 | D3: =SUMIF(Backlog!B3:B126,A3,Backlog!R3:R126) -> 113.1
A4: V2 | B4: =COUNTIF(Backlog!B3:B126,A4) -> 33 | C4: =SUMIF(Backlog!B3:B126,A4,Backlog!Q3:Q126) -> 290 | D4: =SUMIF(Backlog!B3:B126,A4,Backlog!R3:R126) -> 220.9
A5: V3 | B5: =COUNTIF(Backlog!B3:B126,A5) -> 23 | C5: =SUMIF(Backlog!B3:B126,A5,Backlog!Q3:Q126) -> 188 | D5: =SUMIF(Backlog!B3:B126,A5,Backlog!R3:R126) -> 175.1
A6: V4 | B6: =COUNTIF(Backlog!B3:B126,A6) -> 25 | C6: =SUMIF(Backlog!B3:B126,A6,Backlog!Q3:Q126) -> 222 | D6: =SUMIF(Backlog!B3:B126,A6,Backlog!R3:R126) -> 218.1
A7: TOTAL | B7: =B3+B4+B5+B6 -> 124 | C7: =C3+C4+C5+C6 -> 876 | D7: =D3+D4+D5+D6 -> 727.2
A9: By meeting target
A10: Target | B10: Tasks | C10: Remaining (h)
A11: done | B11: =COUNTIF(Backlog!M3:M126,A11) -> 5 | C11: =SUMIF(Backlog!M3:M126,A11,Backlog!R3:R126) -> 0.5
A12: 8-Jul | B12: =COUNTIF(Backlog!M3:M126,A12) -> 26 | C12: =SUMIF(Backlog!M3:M126,A12,Backlog!R3:R126) -> 71.3
A13: 14-Jul | B13: =COUNTIF(Backlog!M3:M126,A13) -> 42 | C13: =SUMIF(Backlog!M3:M126,A13,Backlog!R3:R126) -> 253.8
A14: 14-Jul (honest framing ready for 8-Jul) | B14: =COUNTIF(Backlog!M3:M126,A14) -> 3 | C14: =SUMIF(Backlog!M3:M126,A14,Backlog!R3:R126) -> 8.4
A15: post-deal | B15: =COUNTIF(Backlog!M3:M126,A15) -> 48 | C15: =SUMIF(Backlog!M3:M126,A15,Backlog!R3:R126) -> 393.2
