Workbook

Sheet Current Authority
A1: PPIQ Backlog v2.19.0 — Two-Release Production + Database Authority Convergence
A3: Authority | B3: Current value | C3: Date | D3: Meaning
A4: Master Design | B4: v4.10.1 | C4: 2026-09-04 | D4: Six design chapters only
A5: Execution Backlog | B5: v2.19.0 | C5: 2026-09-04 | D5: This workbook only
A6: Release 1 | B6: M2 — 30 Sep 2026 | D6: Early production / customer first-week ready
A7: Release 2 | B7: M3 — 30 Oct 2026 | D7: Heavy production / more users / more data
A8: Phase vocabulary | B8: P1 · P2 · P3 · P4 · P5 | D8: No alternative milestone/phase codes are current authority
A9: Mirror law | B9: 100% traceability required | D9: Every design requirement maps to backlog acceptance; every task maps to design
A10: Historical work | B10: Archive only | D10: Prior M1/Fleet-specific work is evidence, not current execution scope
A11: Latest revision | B11: T-094 scope reconciled; release gate generated; DB catalogue/isolation tasks added | C11: 2026-09-04 | D11: Canvas/OPC schedule contradictions removed; T-150 now gates every Release-1 MUST row; physical database zero-unknown authority introduced.

Sheet Backlog
A1: Task Id | B1: Milestone Id | C1: Phase Id | D1: Task Name | E1: Module | F1: Sub-module | G1: Priority | H1: Task Description | I1: Task Validation | J1: Hours | K1: Status | L1: AI Agent Owner | M1: Depends On (IDs only) | N1: Must Precede (IDs only) | O1: Delivery Target | P1: Release Criticality | Q1: AI Execution Class | R1: AI Guarded Time P80 (h) | S1: AI Sequence Wave | T1: AI Start / Dependency Gate | U1: File / Subsystem Lock | V1: No-Rework Handoff Ruling | W1: Product Track | X1: Tech-Lead Ruling
A2: T-086 | B2: M2 | C2: P1 | D2: Freeze the legacy Fleet v2 controlled regression oracle | E2: Testing | F2: Emulated sources | G2: Critical | H2: Freeze and certify the existing Fleet v2 dataset only as a legacy discrete-manufacturing regression oracle with predeclared known answers/negative controls. It is not the canonical product vocabulary, not the generic M2 fixture authority and not the source of customer schema semantics. T-208 owns new generic controlled fixtures, including the continuous-process known-answer pack. | I2: Fleet v2 is immutable and its declared phenomena/negative controls are reproducible. An architecture check proves no generic runtime/Layer-B/registry contract derives vocabulary or universal grain from Fleet. T-208 can run independently with neutral/continuous fixtures. | J2: 8 | K2: Done | L2: Worker 1 | M2: T-201 | N2: T-087; T-088; T-131 | O2: 2026-09-30 Release 1 | P2: Release 1 MUST | Q2: Integration/E2E/certification | R2: 2.72 | S2: M2-P1 | T2: WAIT for Presentation RC freeze/tag + clean index/worktree. Then: Release 1 dependency order | U2: Own canonical DB/backend/security/API/infra. No W2-owned UI/admin task files and no W3 ML/Assistant runtime. | V2: Commit before downstream consumer starts; consumer must use the contract, not redesign producer-owned semantics. | W2: Product Foundation & Release Truth | X2: M2 P1 — Product Foundation & Release Truth. Release 1 is genuine early production / first-week customer work.
A3: T-087 | B3: M2 | C3: P1 | D3: Physical three-schema migration | E3: Database | F3: Schema | G3: Critical | H3: The measured database carries twelve schemas with 162 tables in public, of which 108 use a ppiq_ name prefix, while the ruled schemas ppiq_plant and ppiq_meta exist and hold zero tables. Migrate to the three ruled schemas: ppiq_staging, ppiq_plant, ppiq_meta. The staging rename is already prepared, because the canvas reads its schema from the configuration key Prep:StagingSchema rather than a literal. | I3: Rule 2 is provable in one query on a fresh database. All application tests pass. The canvas catalogue lists tables from the renamed schema with only a configuration change. AND THE BENCHMARK SURVIVES THE MOVE: the phenomenon and benchmark harness frozen in T-086 is re-run UNCHANGED after the schema migration and produces identical results. A migration that silently alters the reference dataset destroys every comparison made against it. | J3: 12 | K3: Done | L3: Worker 1 | M3: T-086; T-088 | N3: T-061; T-089; T-099; T-102; T-112; T-114; T-128; T-196; T-233 | O3: 2026-09-30 Release 1 | P3: Release 1 MUST | Q3: DB/schema/migration | R3: 2.325 | S3: M2-P1 | T3: WAIT for Presentation RC freeze/tag + clean index/worktree. Then: T-086 + T-088 canonical migration order/runner/truth gate established FIRST. | U3: Own canonical DB/backend/security/API/infra. No W2-owned UI/admin task files and no W3 ML/Assistant runtime. | V3: Commit before downstream consumer starts; consumer must use the contract, not redesign producer-owned semantics. | W3: Product Foundation & Release Truth | X3: M2 P1 — Product Foundation & Release Truth. Release 1 is genuine early production / first-week customer work.
A4: T-088 | B4: M2 | C4: P1 | D4: Canonical migration order and legacy script archival | E4: Database | F4: Schema | G4: Very Important | H4: Backend/database/scripts contains hotfix, repair, phase and drift-correction scripts accumulated over months, including cases where two scripts created the same table. Define one canonical ordered migration path, archive superseded scripts, and add a truth gate that no two scripts create the same table. | I4: A fresh database builds from the canonical path with no manual step. The truth gate fails if a duplicate CREATE TABLE is introduced. | J4: 12 | K4: Done | L4: Worker 1 | M4: T-086 | N4: T-087; T-089; T-112; T-128 | O4: 2026-09-30 Release 1 | P4: Release 1 MUST | Q4: DB/schema/migration | R4: 2.325 | S4: M2-P1 | T4: WAIT for Presentation RC freeze/tag + clean index/worktree. Then: T-086 frozen M2 reference dataset; define canonical migration order before T-... | U4: Own canonical DB/backend/security/API/infra. No W2-owned UI/admin task files and no W3 ML/Assistant runtime. | V4: Commit before downstream consumer starts; consumer must use the contract, not redesign producer-owned semantics. | W4: Product Foundation & Release Truth | X4: M2 P1 — Product Foundation & Release Truth. Release 1 is genuine early production / first-week customer work.
A5: T-089 | B5: M2 | C5: P1 | D5: definition_store, definition_versions and definition_dependencies | E5: Database | F5: Definition store | G5: Critical | H5: Create the tables specified in Chapter 3 4.5.11 with immutable versions and a dependency graph, plus a trigger that rejects a dependency cycle. | I5: Integration tests: create, version, publish, and reject a cycle. Version rows must be immutable, proved by an update attempt that fails. | J5: 12 | K5: Done | L5: Worker 1 | M5: T-087; T-088 | N5: T-061; T-090; T-092; T-095; T-099; T-106; T-114; T-128; T-183; T-243; T-244 | O5: 2026-09-30 Release 1 | P5: Release 1 MUST | Q5: DB/schema/migration | R5: 2.325 | S5: M2-P1 | T5: WAIT for Presentation RC freeze/tag + clean index/worktree. Then: T-087 + T-088 canonical three-schema/migration authority green. | U5: Own canonical DB/backend/security/API/infra. No W2-owned UI/admin task files and no W3 ML/Assistant runtime. | V5: Commit before downstream consumer starts; consumer must use the contract, not redesign producer-owned semantics. | W5: Product Foundation & Release Truth | X5: M2 P1 — Product Foundation & Release Truth. Release 1 is genuine early production / first-week customer work.
A6: T-090 | B6: M2 | C6: P1 | D6: Move all five definition kinds onto the store | E6: Backend | F6: Definition store | G6: Critical | H6: Replace the M1 compatibility adapter behind IDefinitionService with the real implementation for all five purposes: S1 Transformation, S2 Pages and widgets and filters and master items, S3 Analysis, S4 Model, S5 Log rule. The old per-artifact tables become a compatibility projection and then are retired. v2.10.1 OUTCOME SEMANTICS BINDING. As part of canonical definition convergence, bind the already-frozen SM-06 OutcomeDefinition to the canonical immutable versioned definition authority; do not design a second outcome authority. The canonical binding preserves outcome_code, outcome_type, class_taxonomy_ref, ordinal_rank_map, grain_code, detection_position_code, detection_timestamp_field, direction, unit_code, censoring_policy and definition/version identity. Any legacy ml_outcome_definitions representation may remain only as a compatibility projection during convergence and must not remain an independent semantic authority. | I6: The M1 integration test written against IDefinitionService must pass unchanged, since it references no table name. That is the proof that the visible contract did not move. Publish an SM-06 OutcomeDefinition and resolve it back by exact immutable version. Changing detection_position_code, detection_timestamp_field, grain, taxonomy, ordinal map, direction, unit or censoring policy creates a new definition version rather than silently mutating published meaning. If a compatibility outcome representation remains during convergence, prove it resolves to the same canonical definition/version and cannot diverge into a second authority. | J6: 12 | K6: Done | L6: Worker 1 | M6: T-089 | N6: T-061; T-091; T-092; T-095; T-099; T-104; T-106; T-114; T-128; T-134; T-147; T-183; T-195; T-210; T-221; T-228; T-231; T-232; T-233; T-235; T-239; T-243; T-244 | O6: 2026-09-30 Release 1 | P6: Release 1 MUST | Q6: Backend/domain contract | R6: 1.8 | S6: M2-P1 | T6: IN PROGRESS — T-089 complete. Full T-090 remains one task and one final commit. Worker 1 must deliver one self-contained standard PowerShell apply pack; no scope split and no manual .cs/SQL installation. | U6: Own canonical DB/backend/security/API/infra. No W2-owned UI/admin task files and no W3 ML/Assistant runtime. | V6: Downstream consumers wait for the committed T-090 authority. Handover/progress notes do not substitute for closure; the pack must apply, build, test, replay and commit on the user machine. | W6: Product Foundation & Release Truth | X6: CENTRAL 30-Aug-2026: canonical definition convergence remains full scope. Deliver the standard executable PowerShell pack; no Task-ID-less changes.
A7: T-091 | B7: M2 | C7: P1 | D7: Impact preview, export and import | E7: Backend | F7: Definition store | G7: Very Important | H7: Add dependency impact preview before a publish, and export and import of a definition with its dependencies, per Chapter 3 4.5.11. | I7: Publish a change to a definition three others depend on and confirm the preview lists all three before the publish is confirmed. Export and reimport into an empty database and confirm equality. | J7: 12 | K7: Done | L7: Worker 1 | M7: T-090 | N7: T-128; T-183 | O7: 2026-09-30 Release 1 | P7: Release 1 MUST | Q7: Backend/domain contract | R7: 1.8 | S7: M2-P1 | T7: WAIT for Presentation RC freeze/tag + clean index/worktree. Then: T-090 all definition kinds bound to the canonical store. | U7: Own canonical DB/backend/security/API/infra. No W2-owned UI/admin task files and no W3 ML/Assistant runtime. | V7: Commit before downstream consumer starts; consumer must use the contract, not redesign producer-owned semantics. | W7: Product Foundation & Release Truth | X7: M2 P1 — Product Foundation & Release Truth. Release 1 is genuine early production / first-week customer work.
A8: T-092 | B8: M2 | C8: P1 | D8: Registry authority: dimensions and measures as rows | E8: Backend | F8: Registry | G8: Critical | H8: Replace compiled dimension/measure catalogues with canonical registry projections over published definition versions. Registry rows must support customer-defined dimensions/measures without rebuild, plus analysis-grain metadata, signal/aggregation semantics and reference-derived measure roles. It remains a projection/serving authority, not a competing mutable definition store. | I8: Using the same binary, add a customer-shaped dimension and measure through definitions/registry data only and use them in an authored widget. No C#/React/product-SQL edit. Registry exposes declared grain and aggregation/reference metadata and rejects unresolved semantics. | J8: 12 | K8: Done | L8: Worker 1 | M8: T-089; T-090; T-210; T-231 | N8: T-093; T-094; T-128; T-183; T-212; T-215; T-228; T-237; T-247 | O8: 2026-09-30 Release 1 | P8: Release 1 MUST | Q8: Backend/domain contract | R8: 1.8 | S8: M2-P1 | T8: WAIT for Presentation RC freeze/tag + clean index/worktree. Then: T-089 + T-090 canonical definition authority. | U8: Own canonical DB/backend/security/API/infra. No W2-owned UI/admin task files and no W3 ML/Assistant runtime. | V8: Commit before downstream consumer starts; consumer must use the contract, not redesign producer-owned semantics. | W8: Product Foundation & Release Truth | X8: M2 P1 — Product Foundation & Release Truth. Release 1 is genuine early production / first-week customer work.
A9: T-093 | B9: M2 | C9: P1 | D9: Plant-vocabulary sweep, part 1: build the term list and the architecture test | E9: Backend | F9: Registry | G9: Very Important | H9: Rule 1 needs an enforcement mechanism before the sweep, or the sweep is a one-off. Create a registry-held list of plant terms (the term list is itself DATA, never a compiled constant) and an architecture test that fails the build when any listed term appears in product code outside registry data, seed content or test fixtures. Seed the list from the dimension names already found compiled into DashboardWidgetQuerySafetyRegistry: ProductFamily, GradeOrRecipe, ShiftCode, DefectType, RiskClass. | I9: Add a term to the list and confirm the build goes red on an existing violation, then goes green once that violation is fixed. Confirm removing a term from the list does not require a code change. | J9: 6 | K9: Done | L9: Worker 1 | M9: T-092; T-206 | N9: T-094; T-128; T-183 | O9: 2026-09-30 Release 1 | P9: Release 1 MUST | Q9: Backend/domain contract | R9: 0.9 | S9: M2-P1 | T9: WAIT for Presentation RC freeze/tag + clean index/worktree. Then: T-092 registry/definition authority available; architecture term list is comm... | U9: Own canonical DB/backend/security/API/infra. No W2-owned UI/admin task files and no W3 ML/Assistant runtime. | V9: Commit before downstream consumer starts; consumer must use the contract, not redesign producer-owned semantics. | W9: Product Foundation & Release Truth | X9: M2 P1 — Product Foundation & Release Truth. Release 1 is genuine early production / first-week customer work.
A10: T-094 | B10: M2 | C10: P1 | D10: Plant-vocabulary sweep, part 2: remove hardcoded universal grain and industry vocabulary | E10: Backend | F10: Registry | G10: Very Important | H10: Clear generic-runtime/demo-vocabulary violations without replacing one industry noun with another. Complete the declared-dimension execution path on BOTH runtime wire surfaces: (A) persisted widget execution via DashboardWidgetFiltersDto/declared keyed dimensions and (B) workspace/global dashboard query execution via DashboardQueryDto and the overview/quality/risk/data-quality/materials routes. Remove fixed universal grain/industry vocabulary from DashboardReferenceDataDto and the frontend consumers by resolving published registry definitions, canonical members and governed Analysis Subject/relationship authority. The target contract is definition/registry member -> relationship/path resolution -> Analysis Subject -> typed refusal; the current direct single-reference resolver is an interim implementation until T-095/T-096 path authority lands. No presentation vocabulary becomes product authority. | I10: Using the same binary, author a foreign/customer-shaped dimension and prove it filters both a persisted widget and the workspace/global route surface through the same published definition/member identity. Both surfaces must return the same typed refusal when the dimension is undeclared, inactive, unmapped, has no subject path, or becomes ambiguous. No compiled fallback to defectType/riskClass/shiftCode or a universal material grain. Frontend consumers use the keyed contract. Wave-C genericity arithmetic remains exact: every known fingerprint is retired or explicitly lawful; unknown=0. | J10: 24 | K10: Done | L10: Worker 1 | M10: T-092; T-093; T-209 | N10: T-095; T-128; T-183; T-196 | O10: 2026-09-30 Release 1 | P10: Release 1 MUST | Q10: Backend/domain contract | R10: 3.6 | S10: M2-P1 | T10: IN PROGRESS — T-092/T-093/T-209 authorities are green. Three part-commits exist but no closure. Finish the second wire, frontend consumers and Wave-C proof under the same T-094 scope; do not reopen after closure. | U10: Own canonical DB/backend/security/API/infra. No W2-owned UI/admin task files and no W3 ML/Assistant runtime. | V10: Commit before downstream consumer starts; consumer must use the contract, not redesign producer-owned semantics. | W10: Product Foundation & Release Truth | X10: CENTRAL 04-Sep-2026: T-094 remains open. Scope is formally amended from one wire to both declared-dimension execution surfaces. No new task is created while T-094 is open; after closure any new surface requires a new Task ID.
A11: T-201 | B11: M2 | C11: P1 | D11: Freeze the successful M1 presentation baseline and transfer programme authority to M2 | E11: Programme | F11: Release baseline | G11: Critical | H11: Resolve the shared dirty tree, keep/revert the associative change on evidence, commit exact owned files, tag/freeze the successful presentation baseline, and formally stop presentation-only feature/page/data work. Remaining generic defects move to M2-P0 owners rather than being completed as M1 content. | I11: Clean index and explicit foreign-file inventory; immutable release/tag or equivalent frozen artifact; presentation profile still launches; one ledger lists every unclosed M1 item as frozen, superseded, or consumed by a named M2 task. No customer-demo-only task remains on the September critical path. | J11: 4 | K11: Done | L11: Worker 1 | N11: T-086; T-202; T-203; T-204; T-205; T-206; T-207; T-208; T-213; T-241 | O11: 2026-09-30 Release 1 | P11: Release 1 MUST | Q11: Release / governance | R11: 1.5 | S11: M2-P1 | T11: Start immediately. No later M2 mutating work begins on the shared tree before this close. | U11: Git/worktree ownership + release/tag only. | V11: After commit/tag, all workers consume the frozen baseline; nobody reopens M1 presentation scope without a proven regression. | W11: Product Foundation & Release Truth | X11: M2 P1 — Product Foundation & Release Truth. Release 1 is genuine early production / first-week customer work.
A12: T-202 | B12: M2 | C12: P1 | D12: Persisted page/widget definition replay gate | E12: Quality | F12: Release Truth | G12: Critical | H12: Enumerate every active customer-facing page/widget definition from the real database and execute its actual query contract against the release API/database. Validate declared terminal semantics, row/population evidence and compatibility. This gate tests the product as persisted, not merely source-code paths. | I12: Every active persisted widget executes with 2xx plus Populated/Empty/Blocked/Refused as documented; unexpected 4xx/5xx is a failure. Deliberately corrupt one dimension/measure combination and prove the gate fails. Restore and prove green. Emit machine-readable report naming definition/page/widget. | J12: 10 | K12: Done | L12: Worker 2 | M12: T-201 | N12: T-150; T-212 | O12: 2026-09-30 Release 1 | P12: Release 1 MUST | Q12: E2E / integration gate | R12: 4 | S12: M2-P1 | T12: T-201 committed/frozen baseline. | U12: Frontend E2E + dashboard query test harness; no canonical schema edits. | V12: T-150 later consumes this gate; it does not redesign it. | W12: Product Foundation & Release Truth | X12: M2 P1 — Product Foundation & Release Truth. Release 1 is genuine early production / first-week customer work.
A13: T-203 | B13: M2 | C13: P1 | D13: Customer-route network, console and widget-state invariant | E13: Quality | F13: Release Truth | G13: Critical | H13: For every customer-reachable route, navigate and settle against the real API; fail on unexpected HTTP >=400, failed required request, uncaught JS exception, unhandled console error, error toast, or widget Failed state. Record route/request/widget evidence. | I13: Inject one failing API response and one uncaught render error and prove the route gate fails for the named cause. With faults removed, every customer route settles with zero unexpected network/console/widget failures. | J13: 10 | K13: Done | L13: Worker 2 | M13: T-201 | N13: T-150; T-222 | O13: 2026-09-30 Release 1 | P13: Release 1 MUST | Q13: Playwright / session | R13: 4 | S13: M2-P1 | T13: T-201; may run in parallel with T-202 on non-overlapping test files. | U13: Frontend E2E/session harness. | V13: All later customer-facing feature tasks must add their route to this gate before close. | W13: Product Foundation & Release Truth | X13: M2 P1 — Product Foundation & Release Truth. Release 1 is genuine early production / first-week customer work.
A14: T-204 | B14: M2 | C14: P1 | D14: Associative cross-filter state-machine certification | E14: Frontend | F14: Associative BI | G14: Critical | H14: Replace click-smoke acceptance with a state-machine proof: capture widgets A/B/C, click X in A, assert selection state, assert B/C re-query with X, assert returned populations and visible results change, clear X and assert restoration. Execute across interactive renderer families. | I14: Bar, line, scatter, heatmap, table-row and interactive KPI families each prove selection propagation, dependent request mutation, population/result change, and restoration. A deliberate broken dependency-array/bridge falsification must fail the test. | J14: 10 | K14: Done | L14: Worker 2 | M14: T-201 | N14: T-150; T-222 | O14: 2026-09-30 Release 1 | P14: Release 1 MUST | Q14: Frontend behavioural E2E | R14: 4.25 | S14: M2-P1 | T14: T-201; resolve current associative ownership first. | U14: AssociativeContext/filter bridge + E2E tests; no unrelated chart redesign. | V14: This task supersedes using browser walking as the acceptance of cross-filtering. | W14: Product Foundation & Release Truth | X14: M2 P1 — Product Foundation & Release Truth. Release 1 is genuine early production / first-week customer work.
A15: T-205 | B15: M2 | C15: P1 | D15: Frontend global suite termination and machine-readable gate | E15: Frontend | F15: Test infrastructure | G15: Very Important | H15: Make the global frontend unit/component suite terminate deterministically, produce a machine-readable result, and fail the pipeline on non-termination, timeout, skipped mandatory tests or leaked handles. | I15: Run the full suite twice from clean processes under the declared timeout; both terminate with identical pass/fail/skip counts and machine-readable output. Inject a leaked handle/non-terminating test and prove the gate goes red. | J15: 8 | K15: Done | L15: Worker 2 | M15: T-201 | N15: T-150; T-250 | O15: 2026-09-30 Release 1 | P15: Release 1 MUST | Q15: Frontend test infrastructure | R15: 3.2 | S15: M2-P1 | T15: CLOSED GREEN 2026-08-30 at b7fcc890. Infrastructure gate certified. Do not rerun full T-205 Certify unless the T-205 gate/validator/watchdog/reaper/evidence contract itself changes. | U15: Frontend test runner/config only. | V15: T-205 remains closed. Deterministic suite-truth mutations are owned by T-250; do not amend or reopen T-205 for product/test corrections. | W15: Product Foundation & Release Truth | X15: CENTRAL 30-Aug-2026: T-205 CLOSED GREEN at b7fcc890. The gate correctly reports suite truth; bounded corrections are a separate explicit task.
A16: T-206 | B16: M2 | C16: P1 | D16: Scope-aware genericity architecture gate | E16: Architecture | F16: Genericity | G16: Critical | H16: Create a scope-aware architecture test that forbids customer/demo/industry vocabulary and compiled customer dimension/grain authorities inside generic runtime/engine/API contracts while allowing that vocabulary in explicitly classified fixtures, mappings and documentation. Include detection of compiled dimension arrays and implicit grain defaults. | I16: Falsify the gate with a generic-runtime 'coil' fallback, a compiled customer dimension, and an industry-specific class; each fails. The same terms in approved fixture paths remain allowed. Gate consumes configured path/authority classes, not a naive whole-repo negative text scan. | J16: 8 | K16: Done | L16: Worker 3 | M16: T-201 | N16: T-093; T-150; T-213 | O16: 2026-09-30 Release 1 | P16: Release 1 MUST | Q16: Architecture/test | R16: 2 | S16: M2-P1 | T16: T-201. Isolated architecture test files only until each product owner consumes findings. | U16: Architecture/genericity tests only; no W1 schema or W2 UI mutation. | V16: Violations are routed to the owning task/file; Worker 3 does not fix foreign files. | W16: Product Foundation & Release Truth | X16: M2 P1 — Product Foundation & Release Truth. Release 1 is genuine early production / first-week customer work.
A17: T-208 | B17: M2 | C17: P1 | D17: Generic controlled validation fixture authority and continuous-process known-answer pack | E17: Quality | F17: Test data | G17: Critical | H17: Create the dataset-neutral controlled fixture authority separate from product vocabulary. Keep Fleet v2 as legacy discrete regression oracle only; continuous-process fixture includes irregular analog samples, state intervals, counters, alarms, process windows, independent manual/business records, PLUS a declared transition/stabilisation event and conflicting multi-objective practice vectors with predeclared known answers. | I17: Fixture manifests are machine-readable, immutable by version, inaccessible as planted truth to runtime, and include SampleMean vs TimeWeightedMean, StateDuration, Delta, interval overlap, transition/stabilisation regime truth, a pooled-vs-steady-state confounding case, a known Pareto frontier, negative controls and refusal cases. Product code contains no fixture vocabulary. | J17: 10 | K17: Done | L17: Worker 3 | M17: T-201 | N17: T-150; T-209; T-211; T-216; T-217; T-218; T-234; T-238 | O17: 2026-09-30 Release 1 | P17: Release 1 MUST | Q17: Test fixture / kernel | R17: 2.5 | S17: M2-P1 | T17: T-201. May run in parallel with T-206; no production DB migration/DI. | U17: New generic fixture/test assets only. | V17: T-211/T-217/T-219 consume this fixture; they never read planted expected answers at runtime. | W17: Product Foundation & Release Truth | X17: M2 P1 — Product Foundation & Release Truth. Release 1 is genuine early production / first-week customer work.
A18: T-209 | B18: M2 | C18: P1 | D18: Analysis Subject and Grain contract + schema-independent resolution kernel | E18: Architecture / Analytics Engine | F18: Generic subject/grain contract | G18: Critical | H18: Freeze the generic AnalysisSubject/GrainDefinition contract and a schema-independent resolver/kernel. It defines subject kinds, grain identity, time-window semantics, typed GR01 refusal and the rule that no analytical result requires a material identifier. No production migration, DI registration or canonical table edit in this task. | I18: Known-answer tests resolve discrete, equipment-window and flow-interval subjects; missing grain refuses GR01; no industry noun/material-only assumption appears in the public contract. Runs without production DB access. | J18: 6 | K18: Done | L18: Worker 3 | M18: T-208 | N18: T-094; T-210; T-214; T-231; T-234 | O18: 2026-09-30 Release 1 | P18: Release 1 MUST | Q18: Kernel/contract | R18: 1.5 | S18: M2-P1 | T18: T-208 only; no production DB dependency. | U18: New generic contract/kernel/tests only. | V18: T-231 persists this contract; downstream consumers bind to contract, not table shape. | W18: Product Foundation & Release Truth | X18: M2 P1 — Product Foundation & Release Truth. Release 1 is genuine early production / first-week customer work.
A19: T-210 | B19: M2 | C19: P1 | D19: Canonical signal and aggregation semantics authority | E19: Backend | F19: Semantic measurement authority | G19: Critical | H19: Extend parameter definitions and KPI bindings with signal_kind, aggregation_kind, interpolation, weight basis, maximum gap, quality policy, counter-reset and time basis. Remove any silent DEFAULT 'Average'. Store grammar as product-owned enums/registry; customer parameters select it. | I19: Create Analog/State/Counter definitions and prove no aggregate can execute from data_type alone. Parameter or KPI binding may declare a valid method; absent semantics returns AG01. Invalid method for signal returns AG02. Fresh DB/replay green and no default Average in canonical schema. | J19: 12 | K19: Done | L19: Worker 1 | M19: T-090; T-209 | N19: T-092; T-128; T-211; T-212; T-242 | O19: 2026-09-30 Release 1 | P19: Release 1 MUST | Q19: DB/schema authority | R19: 5.1 | S19: M2-P1 | T19: T-209 + T-090. Complete before T-092 exposes measures and before T-211 integration. | U19: Parameter definitions/KPI bindings/migrations/definition contract. | V19: T-211 executes exactly this contract; no second aggregation registry. | W19: Product Foundation & Release Truth | X19: M2 P1 — Product Foundation & Release Truth. Release 1 is genuine early production / first-week customer work.
A20: T-216 | B20: M2 | C20: P1 | D20: Source Time Authority contract and timestamp-semantics kernel | E20: Architecture / Analytics Engine | F20: Temporal authority contract | G20: Critical | H20: Freeze the per-source time contract: timezone, timestamp basis/origin, DST policy, clock reference, observed skew, maximum tolerated skew, and source/server/ingest timestamp semantics. No production persistence in this task. | I20: Known-answer contract tests distinguish source/server/ingest timestamps and prove skew beyond tolerance yields TemporalUncertain rather than conflict. Runs without production DB access. | J20: 5 | K20: Done | L20: Worker 3 | M20: T-208 | N20: T-200; T-217; T-233 | O20: 2026-09-30 Release 1 | P20: Release 1 MUST | Q20: Kernel/contract | R20: 1.25 | S20: M2-P1 | T20: T-208 fixture; no canonical DB dependency. | U20: Temporal contract/tests only. | V20: T-233 persists source-time authority; T-217 consumes contract without waiting for persistence. | W20: Product Foundation & Release Truth | X20: M2 P1 — Product Foundation & Release Truth. Release 1 is genuine early production / first-week customer work.
A21: T-231 | B21: M2 | C21: P1 | D21: Persist Analysis Subject and Grain authority in canonical definition store | E21: Backend / Database | F21: Canonical subject/grain persistence | G21: Critical | H21: Persist the frozen T-209 AnalysisSubject/GrainDefinition contract through canonical definitions and analysis_subjects/grain-definition tables. This task owns migration, tenant-safe keys, version binding and canonical APIs only; it does not redesign the contract. | I21: Fresh migration/replay green. Persist discrete, equipment-window and flow-interval grains; same binary resolves all via API. GR01 preserved. Tenant isolation and definition-version replay pass. | J21: 6 | K21: Done | L21: Worker 1 | M21: T-090; T-209 | N21: T-092; T-128; T-139; T-232; T-235 | O21: 2026-09-30 Release 1 | P21: Release 1 MUST | Q21: DB/schema authority | R21: 2.55 | S21: M2-P1 | T21: T-090 + committed T-209 contract. | U21: analysis_subjects/grain definitions + API/migrations. | V21: T-092/T-128/T-139/T-213 consume committed persistence; they do not invent subject identity. | W21: Product Foundation & Release Truth | X21: M2 P1 — Product Foundation & Release Truth. Release 1 is genuine early production / first-week customer work.
A22: T-095 | B22: M2 | C22: P2 | D22: Relationship members, cardinality, grain conversion and preferred paths | E22: Backend | F22: Relationship model | G22: Critical | H22: Extend the M1 slice to the full model in Chapter 3 4.5.10: members, cardinality, grain conversion between related entities, preferred path selection when more than one path exists, and published versions. v2.10.2 CONVERGENCE CORRECTION — T-095 does not merely 'extend' M1 physical tables. It converges the M1 relationship service/compatibility persistence onto the canonical Chapter 3 4.5.10 tables after definition_store exists, including source_definition_id/version, grain conversion, preferred paths, ambiguity/validation state and retirement semantics, while keeping the M1 external contract stable. | I22: Declare two paths between the same pair of entities, mark one preferred, and confirm the resolver chooses it. Change the preference and confirm the resolution changes with no other edit. | J22: 12 | K22: In Progress | L22: Worker 1 | M22: T-057; T-089; T-090; T-094 | N22: T-096; T-098; T-102; T-103; T-104; T-107; T-109; T-114; T-128; T-134; T-183; T-196; T-221 | O22: 2026-09-30 Release 1 | P22: Release 1 MUST | Q22: Backend/domain contract | R22: 1.8 | S22: M2-P2 | T22: WAIT for Presentation RC freeze/tag + clean index/worktree. Then: T-057 M1 relationship contract + T-089 + T-090 + T-094. | U22: Own canonical DB/backend/security/API/infra. No W2-owned UI/admin task files and no W3 ML/Assistant runtime. | V22: Commit before downstream consumer starts; consumer must use the contract, not redesign producer-owned semantics. | W22: Day-1 Data Workbench — DB Link, Canvas, Jobs & OPC | X22: M2 P2 — Day-1 Data Workbench — DB Link, Canvas, Jobs & OPC. Release 1 is genuine early production / first-week customer work.
A23: T-096 | B23: M2 | C23: P2 | D23: Path resolver, part 1: resolver core and the first eight consumers | E23: Backend | F23: Relationship model | G23: Critical | H23: Chapter 2 3.15.4 names sixteen consumers of the relationship model. Build the resolver core, then route the first eight through it: canonical projection, page and widget queries, associative filtering, drill-down, drill-through, genealogy, statistics and correlation. | I23: A regression test per consumer asserting it resolves through the published model, and refuses with a named reason when the relationship is unpublished. Eight tests, no exceptions. | J23: 8 | K23: In Progress | L23: Worker 1 | M23: T-095 | N23: T-097; T-098; T-107; T-109; T-128; T-134; T-183; T-221 | O23: 2026-09-30 Release 1 | P23: Release 1 MUST | Q23: Backend/domain contract | R23: 1.2 | S23: M2-P2 | T23: WAIT for Presentation RC freeze/tag + clean index/worktree. Then: T-095 canonical relationship publication/model complete. | U23: Own canonical DB/backend/security/API/infra. No W2-owned UI/admin task files and no W3 ML/Assistant runtime. | V23: Commit before downstream consumer starts; consumer must use the contract, not redesign producer-owned semantics. | W23: Day-1 Data Workbench — DB Link, Canvas, Jobs & OPC | X23: M2 P2 — Day-1 Data Workbench — DB Link, Canvas, Jobs & OPC. Release 1 is genuine early production / first-week customer work.
... A34: T-107 | B34: M2 | C34: P2 | D34: Dual-predicate admission control and the three ML execution lanes | E34: Backend | F34: Jobs | G34: Critical | H34: Replace the old single weighted-pool assumption with the frozen resource contract. Each lane has max_concurrency and resource_capacity; admission requires both running_count < max_concurrency and sum(compute_weight)+candidate <= resource_capacity. The logical ml class resolves to ml.training, ml.batch_scoring and ml.online_scoring. Online capacity is hard-reserved and unavailable to training or batch. Keep this platform-level scheduler generic; Worker 3 supplies the ML job classes and later integration tests, but this task must not wire any new AI runtime into the M1 presentation path. v2.10.2 MEASUREMENT RULING — this task implements the configurable dual-predicate admission mechanism and three-lane isolation. Test values may prove satisfiability, but no max_concurrency/resource_capacity/reserved fraction is a production-selected value here. Site values remain benchmark outputs owned by T-155/T-159. | I34: Prove a declared job can be admitted under a satisfiable configuration and a too-heavy job is refused by name. Saturate training and batch and prove an online-scoring job still admits inside its reservation. Prove batch never enters the online lane and the same compute_weight is never used as a concurrency count. Existing import/projection/analysis/report behaviour remains green. The acceptance report labels resource values as TEST_CONFIGURATION unless they come from the named production/site benchmark manifest. No code default is presented as the final capacity decision. | J34: 12 | K34: Not Started | L34: Worker 3 | M34: T-095; T-096; T-097; T-098; T-099; T-100; T-101; T-102; T-103; T-104; T-105; T-106 | N34: T-122; T-141; T-187; T-192 | O34: 2026-09-30 Release 1 | P34: Release 1 MUST | Q34: Backend/domain contract | R34: 1.8 | S34: M2-P2 | T34: WAIT for Presentation RC freeze/tag + clean index/worktree. Then: T-106 canonical job contract + T-095..T-105 canonical data/relationship path;... | U34: Own T-106/T-107/T-109 only after W1 producer contracts; no schema authority rewrites. | V34: Commit before downstream consumer starts; consumer must use the contract, not redesign producer-owned semantics. | W34: Day-1 Data Workbench — DB Link, Canvas, Jobs & OPC | X34: M2 P2 — Day-1 Data Workbench — DB Link, Canvas, Jobs & OPC. Release 1 is genuine early production / first-week customer work.
A35: T-108 | B35: M2 | C35: P2 | D35: stage_watermarks and delta-scoped projection | E35: Backend | F35: Delta propagation | G35: Critical | H35: Today only import is incremental. Chapter 4 5.3.9 requires every downstream stage to be delta-scoped. Add the stage_watermarks table and make canonical projection delta-scoped against it. The arithmetic that justifies this: a naive full scan for one Pro-tier customer is 481 TB per day, while delta-scoped is 5 to 20 GB, a ratio of 24,000 to 1. | I35: Change one source row and confirm projection processes a bounded delta rather than a full scan, evidenced by rows-scanned telemetry. | J35: 8 | K35: Not Started | L35: Worker 1 | N35: T-109 | O35: 2026-09-30 Release 1 | P35: Release 1 MUST | Q35: Backend/domain contract | R35: 1.2 | S35: M2-P2 | T35: WAIT for Presentation RC freeze/tag + clean index/worktree. Then: Release 1 dependency order | U35: Own canonical DB/backend/security/API/infra. No W2-owned UI/admin task files and no W3 ML/Assistant runtime. | V35: Commit before downstream consumer starts; consumer must use the contract, not redesign producer-owned semantics. | W35: Day-1 Data Workbench — DB Link, Canvas, Jobs & OPC | X35: M2 P2 — Day-1 Data Workbench — DB Link, Canvas, Jobs & OPC. Release 1 is genuine early production / first-week customer work.
A36: T-109 | B36: M2 | C36: P2 | D36: Delta-scoped feature refresh and analysis, with telemetry and ML hand-off | E36: Backend | F36: Delta propagation | G36: Critical | H36: Extend the stage-watermark mechanism into the canonical feature refresh and analysis path. The task owns delta discovery, dirty-feature identification and telemetry only; training must never read feature_store directly. Expose a bounded changed-population contract that Worker 3's Snapshot Materialiser consumes later. Do not add temporary M1/presentation schema dependencies. | I36: Insert one bounded delta and prove only affected feature rows and analyses are recomputed. Record rows scanned, rows changed and Scan Amplification. Assert no training/encoding component is reachable from this task and the output contract contains no customer table name. | J36: 6 | K36: Not Started | L36: Worker 3 | M36: T-095; T-096; T-097; T-098; T-099; T-100; T-101; T-102; T-103; T-104; T-105; T-108 | N36: T-136; T-187 | O36: 2026-09-30 Release 1 | P36: Release 1 MUST | Q36: Backend/domain contract | R36: 0.9 | S36: M2-P2 | T36: WAIT for Presentation RC freeze/tag + clean index/worktree. Then: T-095..T-105; T-108 | U36: Own T-106/T-107/T-109 only after W1 producer contracts; no schema authority rewrites. | V36: Commit before downstream consumer starts; consumer must use the contract, not redesign producer-owned semantics. | W36: Day-1 Data Workbench — DB Link, Canvas, Jobs & OPC | X36: M2 P2 — Day-1 Data Workbench — DB Link, Canvas, Jobs & OPC. Release 1 is genuine early production / first-week customer work.
A37: T-110 | B37: M2 | C37: P2 | D37: Chunk manifests, checkpoint, resume and deterministic merge | E37: Backend | F37: Delta propagation | G37: Critical | H37: Implement Chapter 4 5.3.9.6a: bounded chunks with receipts, checkpoint and resume after interruption, and a deterministic merge so a resumed run produces the same result as an uninterrupted one. | I37: Kill a running job at 60 percent, restart it, and confirm the final result is byte-identical to an uninterrupted run over the same input. | J37: 12 | K37: Not Started | L37: Worker 1 | O37: 2026-09-30 Release 1 | P37: Release 1 MUST | Q37: Backend/domain contract | R37: 1.8 | S37: M2-P2 | T37: WAIT for Presentation RC freeze/tag + clean index/worktree. Then: Release 1 dependency order | U37: Own canonical DB/backend/security/API/infra. No W2-owned UI/admin task files and no W3 ML/Assistant runtime. | V37: Commit before downstream consumer starts; consumer must use the contract, not redesign producer-owned semantics. | W37: Day-1 Data Workbench — DB Link, Canvas, Jobs & OPC | X37: M2 P2 — Day-1 Data Workbench — DB Link, Canvas, Jobs & OPC. Release 1 is genuine early production / first-week customer work.
A38: T-111 | B38: M2 | C38: P2 | D38: Scan budget and the Scan Amplification metric | E38: Infrastructure | F38: Monitoring | G38: Very Important | H38: Add scan admission and the Scan Amplification Ratio from Chapter 6 6.1.12.2a, with a baseline and a regression gate that fails the build when amplification rises beyond the baseline. | I38: Record a baseline, then deliberately remove a delta scope and confirm the gate goes red. Restore and confirm green. | J38: 12 | K38: Not Started | L38: Worker 1 | O38: 2026-09-30 Release 1 | P38: Release 1 MUST | Q38: Infrastructure/deployment | R38: 3.2 | S38: M2-P2 | T38: WAIT for Presentation RC freeze/tag + clean index/worktree. Then: Release 1 dependency order | U38: Own canonical DB/backend/security/API/infra. No W2-owned UI/admin task files and no W3 ML/Assistant runtime. | V38: Commit before downstream consumer starts; consumer must use the contract, not redesign producer-owned semantics. | W38: Day-1 Data Workbench — DB Link, Canvas, Jobs & OPC | X38: M2 P2 — Day-1 Data Workbench — DB Link, Canvas, Jobs & OPC. Release 1 is genuine early production / first-week customer work.
A39: T-207 | B39: M2 | C39: P2 | D39: Connector capability truth: stop advertising unimplemented browse/read/subscription | E39: Acquisition | F39: Connector truth | G39: Critical | H39: Make connector capability metadata executable truth. Current OPC/historian configuration validation or deterministic sample generation must not advertise live browse/bounded-read/subscription unless the connector build executes and tests that operation. | I39: Against the current implementation, unsupported browse/read/subscription report false/unavailable and attempts return typed OT01 rather than fabricated data. Add a contract test that makes any future advertised capability fail until an executable implementation passes. | J39: 6 | K39: Done | L39: Worker 1 | M39: T-201 | N39: T-150; T-224 | O39: 2026-09-30 Release 1 | P39: Release 1 MUST | Q39: Backend contract | R39: 2.25 | S39: M2-P2 | T39: T-201. Does not implement production OPC; truth-corrects the current connector contract only. | U39: Connector metadata/API contract and tests. | V39: T-224..T-226 later may flip capabilities to true only by passing this contract. | W39: Day-1 Data Workbench — DB Link, Canvas, Jobs & OPC | X39: M2 P2 — Day-1 Data Workbench — DB Link, Canvas, Jobs & OPC. Release 1 is genuine early production / first-week customer work.
A40: T-212 | B40: M2 | C40: P2 | D40: Integrate aggregation semantics into Layer-A widget/query execution | E40: Backend/Frontend | F40: Dashboard query semantics | G40: Critical | H40: Make dashboard/query aggregation resolve the canonical KPI/parameter semantics and certified kernel/database implementation. Remove raw-cap-before-aggregate and implicit average fallbacks in all customer-facing measures touched by this contract. | I40: Persisted-definition replay on discrete and continuous fixtures proves exact known answers; no raw row limit is applied before aggregate; AG01/AG02 render typed Blocked/Refused rather than API 500. Query plan performs bounded server-side aggregation. | J40: 10 | K40: Not Started | L40: Worker 2 | M40: T-202; T-210; T-211; T-092; T-234; T-235; T-236 | O40: 2026-09-30 Release 1 | P40: Release 1 MUST | Q40: Cross-layer integration | R40: 5.1428571 | S40: M2-P2 | T40: T-202 + T-210/T-211 + T-092 + committed T-234/T-235/T-236. | U40: Dashboard query service/executor + focused frontend state mapping. | V40: Consumes W1 semantics and W3 kernel; no independent aggregation rules. | W40: Day-1 Data Workbench — DB Link, Canvas, Jobs & OPC | X40: M2 P2 — Day-1 Data Workbench — DB Link, Canvas, Jobs & OPC. Release 1 is genuine early production / first-week customer work.
A41: T-213 | B41: M2 | C41: P2 | D41: Customer Data Intake and Capability Assessment authority | E41: Onboarding | F41: Customer data assessment | G41: Critical | H41: Create a versioned assessment workflow/report for an unknown customer: source inventory, entity/equipment map, time model, identity/join strategy, parameter catalogue, KPI candidates, references, aggregation gaps, data quality, historical coverage, reconciliation/ML eligibility, OT trial requirements and missing information. The intake MUST also capture same-calendar-window manual vs machine history availability, transition/changeover definitions and stabilisation rules, sequence/campaign boundaries, setup/preparation evidence, and customer objective sets/trade-off preferences. Accepted results become normal definitions/mappings; the assessment is not a second authority. | I41: Run against one foreign/customer-shaped fixture and produce a complete report with explicit UNKNOWN/MISSING states, including regime-context readiness and multi-objective readiness. Same-window reconciliation evidence is separately reported. No product-code change is made for customer vocabulary. Re-run after one new source/field creates a new assessment version and diff. | J41: 8 | K41: Done | L41: Worker 2 | M41: T-201; T-206 | N41: T-227; T-247 | O41: 2026-09-30 Release 1 | P41: Release 1 MUST | Q41: Backend / product workflow | R41: 3.2 | S41: M2-P2 | T41: External gate: customer data structure received (expected 2-Sep-2026) + T-201/T-206 green. | U41: Onboarding assessment service/report; no customer-specific schema code. | V41: Mappings/definitions become canonical through existing authorities; report does not become a shadow registry. | W41: Day-1 Data Workbench — DB Link, Canvas, Jobs & OPC | X41: M2 P2 — Day-1 Data Workbench — DB Link, Canvas, Jobs & OPC. Release 1 is genuine early production / first-week customer work.
A42: T-224 | B42: M2 | C42: P2 | D42: Production OPC UA edge runtime: endpoint security, certificates and session lifecycle | E42: Acquisition | F42: OPC UA edge | G42: Critical | H42: Implement real OPC UA client runtime inside the customer-side collector boundary: endpoint discovery/selection, security policy negotiation, application certificate/trust management, authenticated session lifecycle and read-only enforcement. Core never gains plant-network credentials/routes. | I42: Against a real SDK test server, establish trusted and rejected sessions, rotate trust, reconnect after server restart and prove no write/control verb/path exists. Capability metadata remains false until this task and downstream browse/subscription tasks pass. | J42: 12 | K42: Not Started | L42: Worker 1 | M42: T-207 | N42: T-153; T-225 | O42: 2026-09-30 Release 1 | P42: Release 1 MUST | Q42: External/site + backend | R42: 7.2 | S42: M2-P2 | T42: Release 1 MUST — start after T-207 connector-truth authority. Site/customer OT certification may require customer access, but the executable production OPC UA runtime itself cannot be deferred past M2. | U42: Customer-side edge agent/OPC adapter only. | V42: T-225 consumes session adapter; site certification remains T-153/T-227-like acceptance, not hidden in code. | W42: Day-1 Data Workbench — DB Link, Canvas, Jobs & OPC | X42: CENTRAL 04-Sep-2026: remove the contradictory 'after 30-Sep demo' gate. M2 is genuine early production and its P2 outcome includes real read-only OPC UA runtime.
A43: T-225 | B43: M2 | C43: P2 | D43: Production OPC UA edge runtime: browse, tag registration, subscription and monitored items | E43: Acquisition | F43: OPC UA edge | G43: Critical | H43: Implement namespace browse, tag selection/registration, subscriptions/monitored items, sampling/publishing interval and deadband configuration behind generic collector contracts. | I43: Browse a test namespace, register N tags, subscribe, receive changed values and prove disconnect/reconnect resumes without fabricated deterministic samples. Read-only operations only. `supportsTagBrowse`/`supportsSubscription` become true only after these executed tests. | J43: 12 | K43: Not Started | L43: Worker 1 | M43: T-224 | N43: T-153; T-226 | O43: 2026-09-30 Release 1 | P43: Release 1 MUST | Q43: External/site + backend | R43: 7.2 | S43: M2-P2 | T43: T-224. | U43: Edge OPC adapter + tag registry integration. | V43: T-226 consumes typed acquired values; no core API direct OPC connection. | W43: Day-1 Data Workbench — DB Link, Canvas, Jobs & OPC | X43: M2 P2 — Day-1 Data Workbench — DB Link, Canvas, Jobs & OPC. Release 1 is genuine early production / first-week customer work.
A44: T-226 | B44: M2 | C44: P2 | D44: Production OPC UA edge runtime: quality/timestamps, recovery and spool-to-canonical proof | E44: Acquisition | F44: OPC UA edge | G44: Critical | H44: Preserve OPC StatusCode/quality plus source/server timestamps, integrate reconnect/sequence-loss handling and existing store-and-forward spool, map acquired values into canonical observations under Source Time Authority. | I44: Good/bad/uncertain quality and source-vs-server timestamp cases land correctly; network interruption queues locally and resumes idempotently; duplicate replay does not duplicate canonical observations; customer-core direction remains one-way. | J44: 12 | K44: Not Started | L44: Worker 1 | M44: T-225; T-233 | N44: T-153 | O44: 2026-09-30 Release 1 | P44: Release 1 MUST | Q44: External/site + backend | R44: 7.2 | S44: M2-P2 | T44: T-225 + T-216 Source Time Authority. | U44: Edge spool/acquisition mapper + canonical ingest contract. | V44: T-153 real-source connector certification consumes this implementation; do not call implementation itself site-certified. | W44: Day-1 Data Workbench — DB Link, Canvas, Jobs & OPC | X44: M2 P2 — Day-1 Data Workbench — DB Link, Canvas, Jobs & OPC. Release 1 is genuine early production / first-week customer work.
A45: T-232 | B45: M2 | C45: P2 | D45: Persist Performance Reference authority and projections | E45: Backend / Database | F45: Reference persistence | G45: Critical | H45: Persist the frozen T-214 Performance Reference contract, including declared standards/targets/envelopes, deterministic scope precedence, effective dating, directionality, provenance and projections from existing specifications/operating limits. No second reference authority. | I45: Migration/replay green; Global/Site/Equipment reference precedence and effective-date replay pass; equal-authority ambiguity remains RF01; existing specification/limit projections resolve through one read authority. | J45: 6 | K45: Not Started | L45: Worker 1 | M45: T-090; T-231; T-214 | N45: T-215 | O45: 2026-09-30 Release 1 | P45: Release 1 MUST | Q45: DB/schema authority | R45: 2.55 | S45: M2-P2 | T45: T-090 + T-231 + committed T-214 contract. | U45: performance reference tables/projections/API. | V45: T-215 consumes persistence; no local reference math. | W45: Day-1 Data Workbench — DB Link, Canvas, Jobs & OPC | X45: M2 P2 — Day-1 Data Workbench — DB Link, Canvas, Jobs & OPC. Release 1 is genuine early production / first-week customer work.
A46: T-233 | B46: M2 | C46: P2 | D46: Persist Source Time Authority and observation timestamp provenance | E46: Backend / Database | F46: Temporal authority persistence | G46: Critical | H46: Persist the frozen T-216 Source Time Authority contract per source/site and preserve source/server/ingest timestamp provenance on observations. Own migrations, tenant-safe keys and canonical read API; no settings UI and no alignment algorithm here. | I46: Two sources with different declared timestamp origins and known skew persist/replay correctly; source/server/ingest timestamps survive ingestion; tenant isolation passes; the API exposes exactly the T-216 contract. | J46: 5 | K46: Not Started | L46: Worker 1 | M46: T-087; T-090; T-216 | N46: T-221; T-226 | O46: 2026-09-30 Release 1 | P46: Release 1 MUST | Q46: DB/schema authority | R46: 2.125 | S46: M2-P2 | T46: T-087 + T-090 + committed T-216 contract. | U46: source_time_authorities/observation timestamp provenance/API. | V46: T-221/T-226 consume canonical persistence; T-217 kernel does not wait. | W46: Day-1 Data Workbench — DB Link, Canvas, Jobs & OPC | X46: M2 P2 — Day-1 Data Workbench — DB Link, Canvas, Jobs & OPC. Release 1 is genuine early production / first-week customer work.
A47: T-235 | B47: M2 | C47: P2 | D47: Persist transition/stabilisation authority and regime context | E47: Backend / Database | F47: Process regime persistence | G47: Critical | H47: Persist process_transition_definitions and process_transition_events plus effective-dated stabilisation policy, provenance and query API under the canonical definition/tenant authority. Do not model changeover as downtime by default; overlap is allowed and explicit. | I47: Fresh migration/replay green. A customer-authored transition definition and event round-trip with scope/from-to context/stabilisation rule; no shipped industry values. Querying an interval returns exact transition/stabilisation overlaps and evidence. | J47: 8 | K47: Not Started | L47: Worker 1 | M47: T-090; T-231; T-234 | N47: T-164; T-212; T-237 | O47: 2026-09-30 Release 1 | P47: Release 1 MUST | Q47: DB/schema authority | R47: 3.4 | S47: M2-P2 | T47: T-090 + T-231 + committed T-234 contract. | U47: process transition tables/API/migrations. | V47: T-237/customer onboarding consume committed persistence; do not redesign contract. | W47: Day-1 Data Workbench — DB Link, Canvas, Jobs & OPC | X47: M2 P2 — Day-1 Data Workbench — DB Link, Canvas, Jobs & OPC. Release 1 is genuine early production / first-week customer work.
A48: T-241 | B48: M2 | C48: P2 | D48: Canvas executable block contract, typed ports and graph validation | E48: Frontend | F48: No-code authoring | G48: Important | H48: Generalise the typed-port and graph semantics already proven in the M1 SharedAuthoringShell/VisualJoinCanvas slice into the production canvas contract. Reuse the existing shell and ports; do not create a second canvas. Define executable block kinds, typed input/output ports, required-port rules, graph validation and genericity constraints. No block or port may carry industry vocabulary. | I48: Architecture test proves one shared canvas contract. Typed-port known answers pass; an unconnected required port returns a typed refusal; incompatible ports refuse before execution; no industry noun/default grain appears in the generic block contract. | J48: 10 | K48: Done | L48: Worker 2 | M48: T-032; T-201 | N48: T-242; T-243 | O48: 2026-09-30 Release 1 | P48: Release 1 MUST | Q48: Post-Sep product completion | S48: M2-P2 | T48: CLOSED — Release-1 Canvas prerequisite. Preserve evidence; do not reopen absent contradictory regression evidence. | U48: Frontend shared authoring shell, canvas graph/ports only. | V48: Reuse M1 SharedAuthoringShell and existing typed-port assets. No second canvas component. | W48: Day-1 Data Workbench — DB Link, Canvas, Jobs & OPC | X48: M2 P2 — Day-1 Data Workbench — DB Link, Canvas, Jobs & OPC. Release 1 is genuine early production / first-week customer work.
A49: T-242 | B49: M2 | C49: P2 | D49: Canvas production block library: relational, arithmetic, logic, window and governed aggregate | E49: Frontend | F49: No-code authoring | G49: Important | H49: Complete the executable block library behind the existing catalogue: source/filter/join, arithmetic, comparison, boolean logic, branch/window and governed aggregate blocks. Aggregate blocks resolve the canonical aggregation semantics authority and never default to Average. Include production arithmetic/comparison/Boolean blocks, IF/ELSE, ForEach, RepeatN and WhileBounded. WhileBounded requires max_iterations, runtime budget and cancellation; unbounded loops cannot publish. | I49: Every executable block has deterministic known-answer and type-mismatch tests. Aggregate blocks consume the canonical aggregation contract and refuse AG01 when semantics are undeclared. Unsupported catalogue entries remain visibly unavailable rather than silently no-op. Known-answer graphs prove +,-,*,/, comparisons, AND/OR/NOT, IF/ELSE, ForEach, RepeatN and bounded While. A graph with no finite loop bound refuses validation. | J49: 16 | K49: In Progress | L49: Worker 2 | M49: T-241; T-210 | N49: T-243 | O49: 2026-09-30 Release 1 | P49: Release 1 MUST | Q49: Post-Sep product completion | S49: M2-P2 | T49: Release 1 MUST — execute after T-241 and T-210; must close before T-243/T-247. | U49: Canvas block registry and executable block nodes. | V49: Do not duplicate analytics kernels; blocks call governed Layer-A/Layer-B contracts. | W49: Day-1 Data Workbench — DB Link, Canvas, Jobs & OPC | X49: CENTRAL 04-Sep-2026: remove 'After 30-Sep MUST lane'. A Release-1-MUST task cannot be scheduled after its own release date.
A50: T-243 | B50: M2 | C50: P2 | D50: Canvas persistence, immutable versioning and reopen/edit round-trip | E50: Frontend | F50: No-code authoring | G50: Important | H50: Persist the shared canvas graph through the unified definition_store/definition_versions authority. Save block positions, typed connections, parameters and purpose; reopen and edit a published/draft version under the existing lifecycle. No canvas-specific shadow store. | I50: Create/save/reopen/edit round-trip preserves semantic graph content; version history is immutable; rollback selects an existing version; no second definition lifecycle/table is introduced. | J50: 12 | K50: In Progress | L50: Worker 2 | M50: T-241; T-242; T-089; T-090 | N50: T-245; T-246 | O50: 2026-09-30 Release 1 | P50: Release 1 MUST | Q50: Post-Sep product completion | S50: M2-P2 | T50: Release 1 MUST — execute after T-241/T-242 and canonical definition-store authority; must close before T-245/T-247. | U50: Frontend canvas persistence + definition-store client contracts. | V50: No canvas-specific persistence schema. | W50: Day-1 Data Workbench — DB Link, Canvas, Jobs & OPC | X50: CENTRAL 04-Sep-2026: remove 'After 30-Sep MUST lane'. A Release-1-MUST task cannot be scheduled after its own release date.
...

Sheet Release Plan
A1: Release Roadmap — Only M2 and M3
A3: Release | B3: Date | C3: Phase | D3: Phase name | E3: Task count | F3: Nominal open h | G3: AI P80 open h | H3: Primary customer outcome | I3: Exit condition | J3: Owner pressure | L3: M2 open tasks | M3: =COUNTIFS(Backlog!$B:$B,"M2",Backlog!$K:$K,"<>Done") -> 53 | N3: M2 nominal h | O3: =SUMIFS(Backlog!$J:$J,Backlog!$B:$B,"M2",Backlog!$K:$K,"<>Done") -> 522 | P3: M2 AI P80 h | Q3: =SUMIFS(Backlog!$R:$R,Backlog!$B:$B,"M2",Backlog!$K:$K,"<>Done") -> 119.63119
