Workbook

Sheet Backlog
A1: Task Id | B1: Milestone Id | C1: Phase Id | D1: Task Name | E1: Module | F1: Sub-module | G1: Priority | H1: Task Description | I1: Task Validation | J1: Hours | K1: Status | L1: Recommended Owner | M1: Worker 3 Parallel Label | N1: Worker 3 Boundary / Scope | O1: Depends On / Release Gate | P1: v2.10.2 Change | Q1: Verified Live State | R1: Evidence / Commit | S1: Design Review Verdict | T1: Design / Concept Finding | U1: Tech-Lead Ruling | V1: Revised Dependency / Gate | W1: Parallel / Booster Ruling | X1: Rework Risk | Y1: Review Authority / Date | Z1: Product Track | AA1: Delivery Target | AB1: Release Criticality | AC1: Concept Alignment Ruling | AD1: Deadline Risk | AE1: AI Agent Owner | AF1: AI Agent Lane | AG1: AI Execution Class | AH1: AI Speed Factor (x) | AI1: P80 Guard Multiplier | AJ1: AI Active Time P50 (h) | AK1: AI Guarded Time P80 (h) | AL1: AI Sequence Wave | AM1: AI Start / Dependency Gate | AN1: File / Subsystem Lock | AO1: No-Rework Handoff Ruling
A2: T-001 | B2: M1 | C2: M1-P1 | D2: Build the six-beat Design Traceability Matrix | E2: Documentation | F2: Design contract | G2: Critical | H2: Create docs/m1/M1_Traceability_Matrix.md. One row per screen that will be opened in the customer presentation. Columns: Screen, Route, Chapter 2 journey step (J4..J15), Chapter 3 page contract id (A1..F9 / G1..G6), Chapter 4 behaviour section (5.1..5.7), Chapter 5 tutorial step, Current implementation file, Classification. Classification is one of KEEP (matches final design), MODIFY (visible surface needs change), TEMP-ADAPTER (visible surface is final but persistence behind it is temporary and M2 replaces it), NEW. Get the route list from Frontend/PlantProcess.Web/src/App.tsx, which currently declares 69 route paths. Chapter 3 section 4.4 lists the target 40 route pages plus 6 shell components; every presentation screen must map to one of them. | I2: The matrix has zero rows where the Chapter 3 column is blank. Walk the list with the App.tsx route table open: every route you intend to open in the room appears, and no route outside the list is reachable from the demo navigation. Reviewed and signed off before any other M1 task starts. | J2: 8 | K2: Done | L2: Completed / no assignment | M2: CLOSED | N2: No new work. Preserve evidence and do not reopen unless a regression proves it. | O2: — | P2: CARRIED v2.9.2 | Q2: Done — backlog-claimed; closure evidence not reloaded in this pass | S2: No new contradiction identified in this pass | V2: — | W2: CLOSED | X2: Low / not newly identified | Y2: Deep design reconciliation 16-Aug-2026; Chapter 3/4 + Layer-B architecture + latest source/audit evidence | Z2: Track 1 — Presentation / Demo | AA2: 2026-08-20 Presentation RC | AB2: M1 Contract | AC2: Presentation-visible contract. Prepared Fleet v2 topology is allowed; no fake product behaviour and no production-only scope. | AD2: Closed | AE2: CLOSED | AF2: Closed / evidence preserved | AG2: Closed | AH2: 0 | AI2: 0 | AJ2: =IF($K2="Done",0,MAX(0.25,$J2/$AH2)) -> 0 | AK2: =IF($K2="Done",0,$AJ2*$AI2) -> 0 | AL2: CLOSED | AM2: Closed — do not reopen without contradictory regression evidence. | AN2: No active lock. | AO2: None — preserve evidence.
A3: T-002 | B3: M1 | C3: M1-P1 | D3: Audit every presented route and control against the Chapter 3 page inventory | E3: Frontend | F3: Design contract | G3: Critical | H3: CORRECTED IN v2.1. The v2.0 validation only forbade phase-token routes, which was too narrow - and the code proves it was also unnecessary, because every to: value in AppLayout.tsx is already canonical and the legacy /phase8, /phase9 and /phase15 paths are Navigate reverse redirects that no navigation entry points at. The real task is wider. Compare EVERY presented route, EVERY JourneyRail stage and EVERY navigation entry against the Chapter 3 4.4 canonical inventory of 40 route pages plus 6 shell components. For each, record the Chapter 3 contract id or record it as out-of-inventory. An out-of-inventory surface that is opened in the room is a frozen contract nobody chose. Note that PPIQ-T12 (navigationContract.test.ts) already ships from this task's own applied pack and covers the token rule; the audit below extends it, it does not repeat it. | I3: A table with one row per presented route, per JourneyRail stage and per navigation entry, each carrying a Chapter 3 contract id or an explicit out-of-inventory decision. Zero rows left undecided. Cross-check the JourneyRail stage list against Chapter 2 3.3.1 J1 to J15 - a stage that names a journey step the design does not have is a defect. | J3: 8 | K3: Done | L3: Completed / no assignment | M3: CLOSED | N3: No new work. Preserve evidence and do not reopen unless a regression proves it. | O3: — | P3: CARRIED v2.9.2 | Q3: Done — backlog-claimed; closure evidence not reloaded in this pass | S3: No new contradiction identified in this pass | V3: — | W3: CLOSED | X3: Low / not newly identified | Y3: Deep design reconciliation 16-Aug-2026; Chapter 3/4 + Layer-B architecture + latest source/audit evidence | Z3: Track 1 — Presentation / Demo | AA3: 2026-08-20 Presentation RC | AB3: M1 Contract | AC3: Presentation-visible contract. Prepared Fleet v2 topology is allowed; no fake product behaviour and no production-only scope. | AD3: Closed | AE3: CLOSED | AF3: Closed / evidence preserved | AG3: Closed | AH3: 0 | AI3: 0 | AJ3: =IF($K3="Done",0,MAX(0.25,$J3/$AH3)) -> 0 | AK3: =IF($K3="Done",0,$AJ3*$AI3) -> 0 | AL3: CLOSED | AM3: Closed — do not reopen without contradictory regression evidence. | AN3: No active lock. | AO3: None — preserve evidence.
A4: T-003 | B4: M1 | C4: M1-P1 | D4: Lock the presentation profile as a data profile, not a branch | E4: Infrastructure | F4: Environments | G4: Critical | H4: Chapter 6 forbids environment branches: the same artifact moves across environments. Confirm scripts/run/start-api.ps1 keeps its ValidateSet local/test/server/presentation and that the only difference between profiles is env/profiles/*.env. Fix the duplicated ConnectionStrings__PlantProcessDb declaration that appears twice (lines 18 and 19) in both local.env and presentation.env. Add a top-of-file comment to start-api.ps1 stating that the default is `local` and that the presentation must be launched with -Profile presentation. | I4: Run `.\scripts\run\start-api.ps1 -Profile presentation` and hit GET /api/ml/foundation/readiness. It must report outcome_values around 195,221 and correlation_results around 320, which proves the API is on ppiq_presentation. Repeat with -Profile local and confirm the numbers differ. Record both outputs in the evidence folder. | J4: 4 | K4: Done | L4: Completed / no assignment | M4: CLOSED | N4: No new work. Preserve evidence and do not reopen unless a regression proves it. | O4: — | P4: CARRIED v2.9.2 | Q4: Done — backlog-claimed; closure evidence not reloaded in this pass | S4: No new contradiction identified in this pass | V4: — | W4: CLOSED | X4: Low / not newly identified | Y4: Deep design reconciliation 16-Aug-2026; Chapter 3/4 + Layer-B architecture + latest source/audit evidence | Z4: Track 1 — Presentation / Demo | AA4: 2026-08-20 Presentation RC | AB4: M1 Contract | AC4: Presentation is a profile/release artifact, NOT a long-lived code branch. Freeze with immutable tag/release + presentation profile/database. | AD4: Closed | AE4: CLOSED | AF4: Closed / evidence preserved | AG4: Closed | AH4: 0 | AI4: 0 | AJ4: =IF($K4="Done",0,MAX(0.25,$J4/$AH4)) -> 0 | AK4: =IF($K4="Done",0,$AJ4*$AI4) -> 0 | AL4: CLOSED | AM4: Closed — do not reopen without contradictory regression evidence. | AN4: No active lock. | AO4: None — preserve evidence.
A5: T-004 | B5: M1 | C5: M1-P1 | D5: Create the M1 acceptance checklist and evidence folder | E5: Documentation | F5: Quality | G5: Important | H5: Create docs/m1/ACCEPTANCE.md holding the UI/UX Golden Gate as a checklist applied per screen: Standard* components where one exists, no raw local styling, primary Electric Blue, selection Electric Cyan, secondary Corporate Blue, warning and refusal Amber, destructive Hot Red, muted Muted Steel, inline-start/inline-end never left/right, keyboard path, RTL mirror, all seven states (Empty, Loading, Populated, Filtered-empty, Blocked, Refused, Failed), widget failure isolation, registry-driven customer vocabulary, no number without evidence. Create docs/m1/evidence/ for screenshots and command output. | I5: Every screen in the traceability matrix has a checklist instance in the folder. A screen is not Green until every line is ticked with an evidence file name beside it. | J5: 4 | K5: Done | L5: Completed / no assignment | M5: CLOSED | N5: No new work. Preserve evidence and do not reopen unless a regression proves it. | O5: — | P5: CARRIED v2.9.2 | Q5: Done — backlog-claimed; closure evidence not reloaded in this pass | S5: No new contradiction identified in this pass | V5: — | W5: CLOSED | X5: Low / not newly identified | Y5: Deep design reconciliation 16-Aug-2026; Chapter 3/4 + Layer-B architecture + latest source/audit evidence | Z5: Track 1 — Presentation / Demo | AA5: 2026-08-20 Presentation RC | AB5: M1 Contract | AC5: Presentation-visible contract. Prepared Fleet v2 topology is allowed; no fake product behaviour and no production-only scope. | AD5: Closed | AE5: CLOSED | AF5: Closed / evidence preserved | AG5: Closed | AH5: 0 | AI5: 0 | AJ5: =IF($K5="Done",0,MAX(0.25,$J5/$AH5)) -> 0 | AK5: =IF($K5="Done",0,$AJ5*$AI5) -> 0 | AL5: CLOSED | AM5: Closed — do not reopen without contradictory regression evidence. | AN5: No active lock. | AO5: None — preserve evidence.
A6: T-005 | B6: M1 | C6: M1-P1 | D6: Rebuild ppiq_presentation into scratch and diff against live | E6: Database | F6: Presentation data | G6: Critical | H6: scripts/demo/Rebuild-PresentationDb.ps1 rebuilds the demo database in one command, but it restores from deploy/.ppiq-snapshots/ppiq_app_20260713_203359.dump, a 13 July snapshot. Every correction made against the live presentation database between 14 and 27 July survives a rebuild only if it became one of the script's steps. Run the script with -TargetDb ppiq_presentation_scratch (the script's guard requires the name to contain 'presentation'), then produce a diff: object list (tables, views, functions, triggers, indexes) and row count per table, scratch versus live. | I6: Produce docs/m1/evidence/presentation_db_diff.txt. Acceptance is either an empty diff, or a written list of every difference. Do not proceed to the next task until that list exists, and never run the rebuild against the live database before it does. | J6: 6 | K6: Done | L6: Completed / no assignment | M6: CLOSED | N6: No new work. Preserve evidence and do not reopen unless a regression proves it. | O6: — | P6: CARRIED v2.9.2 | Q6: Done — backlog-claimed; closure evidence not reloaded in this pass | S6: No new contradiction identified in this pass | V6: — | W6: CLOSED | X6: Low / not newly identified | Y6: Deep design reconciliation 16-Aug-2026; Chapter 3/4 + Layer-B architecture + latest source/audit evidence | Z6: Track 1 — Presentation / Demo | AA6: 2026-08-20 Presentation RC | AB6: M1 Contract | AC6: Presentation-visible contract. Prepared Fleet v2 topology is allowed; no fake product behaviour and no production-only scope. | AD6: Closed | AE6: CLOSED | AF6: Closed / evidence preserved | AG6: Closed | AH6: 0 | AI6: 0 | AJ6: =IF($K6="Done",0,MAX(0.25,$J6/$AH6)) -> 0 | AK6: =IF($K6="Done",0,$AJ6*$AI6) -> 0 | AL6: CLOSED | AM6: Closed — do not reopen without contradictory regression evidence. | AN6: No active lock. | AO6: None — preserve evidence.
A7: T-006 | B7: M1 | C7: M1-P1 | D7: Convert every diff finding into a seed or migration script | E7: Database | F7: Presentation data | G7: Critical | H7: For each row of the diff from the previous task, decide: is this a product fix (goes to Backend/database/scripts as a numbered migration) or presentation data (goes to scripts/demo as a seed step)? The governing law is that presentation DATA may be presentation-only but presentation FIXES may never be. Add each item in the correct place and re-run the rebuild. | I7: Re-run Rebuild-PresentationDb.ps1 into a fresh scratch database and re-run the diff. It must now be empty. That output is the proof that no fix exists only as data. | J7: 8 | K7: Done | L7: Completed / no assignment | M7: CLOSED | N7: No new work. Preserve evidence and do not reopen unless a regression proves it. | O7: — | P7: CARRIED v2.9.2 | Q7: Done — backlog-claimed; closure evidence not reloaded in this pass | S7: No new contradiction identified in this pass | V7: — | W7: CLOSED | X7: Low / not newly identified | Y7: Deep design reconciliation 16-Aug-2026; Chapter 3/4 + Layer-B architecture + latest source/audit evidence | Z7: Track 1 — Presentation / Demo | AA7: 2026-08-20 Presentation RC | AB7: M1 Contract | AC7: Presentation-visible contract. Prepared Fleet v2 topology is allowed; no fake product behaviour and no production-only scope. | AD7: Closed | AE7: CLOSED | AF7: Closed / evidence preserved | AG7: Closed | AH7: 0 | AI7: 0 | AJ7: =IF($K7="Done",0,MAX(0.25,$J7/$AH7)) -> 0 | AK7: =IF($K7="Done",0,$AJ7*$AI7) -> 0 | AL7: CLOSED | AM7: Closed — do not reopen without contradictory regression evidence. | AN7: No active lock. | AO7: None — preserve evidence.
A8: T-007 | B8: M1 | C8: M1-P1 | D8: Presentation Phenomena and Widget Coverage Matrix, part 1: inventory and the 36-chart blueprint | E8: Documentation | F8: Presentation data | G8: Critical | H8: REOPENED IN v2.5 - source truth changed after runtime measurement. The artifacts stand, but they were written against FLEET_RELATIONS.md, and measurement proved that document describes a larger, richer emulation than the one staged: 630 heats not 1,802, 5,670 coils not 18,661, 1,987 defects not 34,312, SIX defect codes not twenty, and THREE chemistry elements at one station not twelve at three. This task does not restart, and it does NOT stay half-open until the fleet is rebuilt - a task that closes twenty tasks later violates both the ordering law and the no-PARTIAL rule. It closes HERE as a PRE-GENERATION SPECIFICATION: the measured current inventory plus the 36-chart blueprint. Post-generation re-measurement and final certification belong to the phenomenon-proof task in M1-P1b, which cites this task by name so the link is machine-checked from that end. REWRITTEN IN v2.4. The previous version documented seventeen relations; that was necessary but not sufficient. Two halves, and the ORDER IS THE POINT. First, inventory what the emulation already carries - chemistry by grade at whatever element count and sampling stations MEASUREMENT SHOWS - the v2.4 text said twelve elements across three stations and that was taken from a document; measurement found THREE elements at ONE station, so the inventory records what is there, additives by grade, sequence grouping, crew rotation, ladle reline counters, cold-furnace and maintenance reheating, downtime propagation, roll wear, lubrication windows, and the seventeen planted relations with their negative controls. Second, write the 36-CHART BLUEPRINT: six primary presentation pages times six visual stories, with the seventh dashboard kept as the technical backup page. For each chart state what it must SHOW - not which correlation it must prove. The acceptance standard for the dataset changes here: every one of the 36 widgets needs an intentional visual story, sufficient population and cardinality, realistic variation, and at least one meaningful drill or filter interaction. NOT every chart must reveal a correlation. Planting a hundred clean correlations would make the plant look fabricated, which costs more credibility than a flat chart does. | I8: Two artifacts in the evidence folder: the emulation inventory with a source and a row count per structure, and the blueprint with 36 rows each naming its page, chart type, and the visual story it must tell. A reviewer must be able to say, for each of the 36, what would make that chart boring - because that is the specification the data has to beat. | J8: 10 | K8: Done | L8: Completed / no assignment | M8: CLOSED | N8: No new work. Preserve evidence and do not reopen unless a regression proves it. | O8: — | P8: CARRIED v2.9.2 | Q8: Done — backlog-claimed; closure evidence not reloaded in this pass | S8: No new contradiction identified in this pass | V8: — | W8: CLOSED | X8: Low / not newly identified | Y8: Deep design reconciliation 16-Aug-2026; Chapter 3/4 + Layer-B architecture + latest source/audit evidence | Z8: Track 1 — Presentation / Demo | AA8: 2026-08-20 Presentation RC | AB8: M1 Contract | AC8: Presentation-visible contract. Prepared Fleet v2 topology is allowed; no fake product behaviour and no production-only scope. | AD8: Closed | AE8: CLOSED | AF8: Closed / evidence preserved | AG8: Closed | AH8: 0 | AI8: 0 | AJ8: =IF($K8="Done",0,MAX(0.25,$J8/$AH8)) -> 0 | AK8: =IF($K8="Done",0,$AJ8*$AI8) -> 0 | AL8: CLOSED | AM8: Closed — do not reopen without contradictory regression evidence. | AN8: No active lock. | AO8: None — preserve evidence.
A9: T-008 | B9: M1 | C9: M1-P1 | D9: Presentation Phenomena and Widget Coverage Matrix, part 2: map, classify, close | E9: Testing | F9: Dashboard | G9: Critical | H9: REOPENED IN v2.5 alongside part one, for the same reason: it cites effect sizes and defect codes that do not exist in the staged data. R1 CRACK_LONG at 9.3x, R2 INCLUSION at 4.5x and R4 SLIPPAGE_MARK at 28.9x have NO corresponding staged defect code. Aluminium, sulfur, niobium and nitrogen are absent, so four relation families cannot exist here whatever the document says. The 104 rows are kept as the SPECIFICATION OF WHAT THE FLEET MUST CARRY, and become the input to the Fleet v2 target rather than a description of what exists. This task ALSO closes here, before any generator work, and it carries one addition: PREDECLARE the expected direction, the acceptable effect band and the negative control for every phenomenon. Declaring them before the data exists is what stops the later proof from being self-fulfilling. REWRITTEN IN v2.4 as part two of the matrix. One row per phenomenon, with these columns: phenomenon; source systems; population; variables; intended effect; noise; primary chart; secondary chart; dashboard; expected analysis result; NEGATIVE CONTROL; genealogy requirement; current status EXISTING, ENRICH or NEW; and the exact automated assertion that validates it. Target roughly 85 to 110 micro-variations, distributed as 18-25 strong discoverable relationships, 20-25 moderate or conditional, 15-20 shift, crew, campaign and maintenance regimes, 8-12 temporal drifts or regime changes, 8-12 outliers or short abnormal events, and 15-20 negative controls and noise. Most of those will be extensions of the seventeen existing relation families rather than new inventions. Then map each of the 36 charts to at least one phenomenon or to a legitimate operational baseline, and give every widget a decision: KEEP, ENHANCE, REBIND, ADD WIDGET, EXTEND EMULATION, NEEDS RELATIONSHIP SLICE, or REMOVE. Weak bindings are not data shortages - Defects by Equipment returned one row in the last audit and the remedy is canonical equipment attribution or relationship resolution, never more rows. | I9: docs/m1/evidence/phenomena_widget_matrix.csv with no blank cells. Every one of the 36 charts references at least one phenomenon or a named operational baseline. Every EXTEND EMULATION row names the exact field, so the generator work has a closed list. Every phenomenon carries its automated assertion, so the statistical QA task has nothing left to invent. | J9: 10 | K9: Done | L9: Completed / no assignment | M9: CLOSED | N9: No new work. Preserve evidence and do not reopen unless a regression proves it. | O9: — | P9: CARRIED v2.9.2 | Q9: Done — backlog-claimed; closure evidence not reloaded in this pass | S9: No new contradiction identified in this pass | V9: — | W9: CLOSED | X9: Low / not newly identified | Y9: Deep design reconciliation 16-Aug-2026; Chapter 3/4 + Layer-B architecture + latest source/audit evidence | Z9: Track 1 — Presentation / Demo | AA9: 2026-08-20 Presentation RC | AB9: M1 Contract | AC9: Presentation-visible contract. Prepared Fleet v2 topology is allowed; no fake product behaviour and no production-only scope. | AD9: Closed | AE9: CLOSED | AF9: Closed / evidence preserved | AG9: Closed | AH9: 0 | AI9: 0 | AJ9: =IF($K9="Done",0,MAX(0.25,$J9/$AH9)) -> 0 | AK9: =IF($K9="Done",0,$AJ9*$AI9) -> 0 | AL9: CLOSED | AM9: Closed — do not reopen without contradictory regression evidence. | AN9: No active lock. | AO9: None — preserve evidence.
A10: T-009 | B10: M1 | C10: M1-P1 | D10: Downtime two-quantity contract: final schema and domain slice | E10: Backend | F10: Canonical model | G10: Critical | H10: CORRECTED IN v2.1, and this was a materially wrong task. v2.0 treated the downtime work as data seeding only. It is not. The canonical DowntimeEvent entity carries timestamps, equipment, a DowntimeType and a reason, but it does NOT carry the two quantities the design requires. Chapter 3 4.5.4 specifies stopped_minutes and production_impact_minutes as separate columns, both NOT NULL and both greater than or equal to zero, because they are different quantities and one may never stand in for the other - a twenty-minute mill stoppage absorbed by buffer slabs costs no production, while a three-minute caster pump stoppage can force a sequence rebuild and cost six hours. Add both fields to the domain entity, write the migration, and extend the projection mapping so a projected downtime row carries both. Use the final column names so M2a extends rather than migrates. | I10: Project a downtime batch and assert every row has both columns populated and non-negative. Attempt an insert with a null production_impact_minutes and confirm the database rejects it. Confirm no code path derives one quantity from the other. | J10: 6 | K10: Done | L10: Completed / no assignment | M10: CLOSED | N10: No new work. Preserve evidence and do not reopen unless a regression proves it. | O10: — | P10: CARRIED v2.9.2 | Q10: Done — backlog-claimed; closure evidence not reloaded in this pass | S10: No new contradiction identified in this pass | V10: — | W10: CLOSED | X10: Low / not newly identified | Y10: Deep design reconciliation 16-Aug-2026; Chapter 3/4 + Layer-B architecture + latest source/audit evidence | Z10: Track 1 — Presentation / Demo | AA10: 2026-08-20 Presentation RC | AB10: M1 Contract | AC10: Presentation-visible contract. Prepared Fleet v2 topology is allowed; no fake product behaviour and no production-only scope. | AD10: Closed | AE10: CLOSED | AF10: Closed / evidence preserved | AG10: Closed | AH10: 0 | AI10: 0 | AJ10: =IF($K10="Done",0,MAX(0.25,$J10/$AH10)) -> 0 | AK10: =IF($K10="Done",0,$AJ10*$AI10) -> 0 | AL10: CLOSED | AM10: Closed — do not reopen without contradictory regression evidence. | AN10: No active lock. | AO10: None — preserve evidence.
A11: T-010 | B11: M1 | C11: M1-P1 | D11: Run the canonical semantic path end to end through the M1 compatibility boundaries | E11: Engine | F11: Presentation data | G11: Critical | H11: CORRECTED IN v2.1. The v2.0 wording implied the final physical topology is in place. It is not, and it is not supposed to be before M2a. What M1 proves is the canonical SEMANTIC path: connection test, dataset registration, incremental import into staging, canonical projection through the customer-authored mapping, genealogy, feature and outcome refresh, then an analysis run - each step reached through the product's own services, never by loading a target table directly. Record row counts at every stage. Note the sequencing: the final external definition contract is built later in M1-P2, so this walk is repeated once it lands - the second walk is what proves the contract did not change behaviour. | I11: One command log showing a single row entering at the source and appearing in material_units and the canonical views, with stage counts that are monotonic and explainable. Every write on the path goes through the final service interface, not a table name - which is what lets M2a replace the storage without this test changing. | J11: 8 | K11: Done | L11: Completed / no assignment | M11: CLOSED | N11: No new work. Preserve evidence and do not reopen unless a regression proves it. | O11: — | P11: CARRIED v2.9.2 | Q11: Done — backlog-claimed; closure evidence not reloaded in this pass | S11: No new contradiction identified in this pass | V11: — | W11: CLOSED | X11: Low / not newly identified | Y11: Deep design reconciliation 16-Aug-2026; Chapter 3/4 + Layer-B architecture + latest source/audit evidence | Z11: Track 1 — Presentation / Demo | AA11: 2026-08-20 Presentation RC | AB11: M1 Contract | AC11: Presentation-visible contract. Prepared Fleet v2 topology is allowed; no fake product behaviour and no production-only scope. | AD11: Closed | AE11: CLOSED | AF11: Closed / evidence preserved | AG11: Closed | AH11: 0 | AI11: 0 | AJ11: =IF($K11="Done",0,MAX(0.25,$J11/$AH11)) -> 0 | AK11: =IF($K11="Done",0,$AJ11*$AI11) -> 0 | AL11: CLOSED | AM11: Closed — do not reopen without contradictory regression evidence. | AN11: No active lock. | AO11: None — preserve evidence.
A12: T-011 | B12: M1 | C12: M1-P1 | D12: Establish and fix the architecture test pool reliability | E12: Testing | F12: CI/CD | G12: Very Important | H12: NEW IN v2.1, raised by a real failure. The navigation contract pack auto-reverted on a gate that reported 15 files and 57 tests passing with one error: a vitest worker failed to START for noMojibake.test.ts and never ran. A re-run went green, which means the gate is intermittent. The diagnostic inventory found the cause candidate: all 16 architecture test files declare no environment and none needs a DOM, yet the suite spends 40 to 45 seconds of a 62 to 68 second run on environment setup and teardown - roughly two thirds of the wall time paid for a browser environment nothing uses. Add // @vitest-environment node to the architecture test files, or set it for that directory in the vitest config. Do not raise a timeout and do not add a retry: a gate that is argued with is a gate that gets switched off, and one that fails at random teaches the team to re-run until green, which is how a real failure gets ignored. | I12: Ten consecutive runs of the architecture suite on a clean tree, all green, with zero worker-start timeouts, recorded in the evidence folder. Report the wall time before and after; the environment share should fall sharply. This matters because M1-P5 certification depends on this pool - the golden journey and the visual and accessibility gates run on it, on the two days when there is no time left to diagnose anything. | J12: 6 | K12: Done | L12: Completed / no assignment | M12: CLOSED | N12: No new work. Preserve evidence and do not reopen unless a regression proves it. | O12: — | P12: CARRIED v2.9.2 | Q12: Done — backlog-claimed; closure evidence not reloaded in this pass | S12: No new contradiction identified in this pass | V12: — | W12: CLOSED | X12: Low / not newly identified | Y12: Deep design reconciliation 16-Aug-2026; Chapter 3/4 + Layer-B architecture + latest source/audit evidence | Z12: Track 1 — Presentation / Demo | AA12: 2026-08-20 Presentation RC | AB12: M1 Contract | AC12: Presentation-visible contract. Prepared Fleet v2 topology is allowed; no fake product behaviour and no production-only scope. | AD12: Closed | AE12: CLOSED | AF12: Closed / evidence preserved | AG12: Closed | AH12: 0 | AI12: 0 | AJ12: =IF($K12="Done",0,MAX(0.25,$J12/$AH12)) -> 0 | AK12: =IF($K12="Done",0,$AJ12*$AI12) -> 0 | AL12: CLOSED | AM12: Closed — do not reopen without contradictory regression evidence. | AN12: No active lock. | AO12: None — preserve evidence.
A13: T-012 | B13: M1 | C13: M1-P1 | D13: Canonicalise the JourneyRail to J1 to J15 | E13: Frontend | F13: Journey | G13: Critical | H13: NEW IN v2.3, raised by the presented-surface audit and it is a Rule 3 violation that has been on every authenticated page. JourneyRail.tsx declares its OWN fifteen-stage journey in a hardcoded STAGES array and renders it as Step N of 15. It is not the canonical J1 to J15: different steps, different order, same numbering. Rule 3 says a second journey written anywhere is deleted rather than reconciled. Four further defects sit on top. Stage 4 Prepare mapping has only /data-integration/prepare as its match prefix, which stage 2 already claims, and the longest-prefix tie-break takes the first, so stage 4 can never become the current stage. Stage 5 points at /data-integration/author-mapping, which the audit rules out of inventory. Stage 8 points at AnalysisJobConfigPage, which leaves the M1 navigation. Stage 12 is labelled AI/ML jobs and points at the Jobs Monitor. Stage 15 points at /assistant, but Chapter 3 gives the assistant no route because G1 is a shell component. Rewrite STAGES to the canonical journey with the Chapter 2 3.3.1 labels, render J1 to J3 as completed commissioning so the count is honest, give each stage exactly one unambiguous match prefix, and repoint stages 5, 8 and 15. | I13: A test asserting the rail's stage count and labels equal the canonical journey, in the same shape as PPIQ-T12. Walk every presented route and confirm the rail highlights exactly one stage, and that the stage it highlights is the journey step that route serves. No stage may be unreachable. | J13: 6 | K13: Done | L13: Completed / no assignment | M13: CLOSED | N13: No new work. Preserve evidence and do not reopen unless a regression proves it. | O13: — | P13: CARRIED v2.9.2 | Q13: Done — backlog-claimed; closure evidence not reloaded in this pass | S13: No new contradiction identified in this pass | V13: — | W13: CLOSED | X13: Low / not newly identified | Y13: Deep design reconciliation 16-Aug-2026; Chapter 3/4 + Layer-B architecture + latest source/audit evidence | Z13: Track 1 — Presentation / Demo | AA13: 2026-08-20 Presentation RC | AB13: M1 Contract | AC13: Presentation-visible contract. Prepared Fleet v2 topology is allowed; no fake product behaviour and no production-only scope. | AD13: Closed | AE13: CLOSED | AF13: Closed / evidence preserved | AG13: Closed | AH13: 0 | AI13: 0 | AJ13: =IF($K13="Done",0,MAX(0.25,$J13/$AH13)) -> 0 | AK13: =IF($K13="Done",0,$AJ13*$AI13) -> 0 | AL13: CLOSED | AM13: Closed — do not reopen without contradictory regression evidence. | AN13: No active lock. | AO13: None — preserve evidence.
... A44: T-043 | B44: M1 | C44: M1-P3 | D44: Bring the workspace to the final D1 anatomy | E44: Frontend | F44: Dashboard | G44: Critical | H44: EXPANDED IN v2.1. v2.0 described header, selections bar, grid and associative strip, and treated the current DashboardFilterBar as the final architecture. Chapter 4 5.1.2 asks for more: header, PERMANENT selection bar, associative strip, SHEET NAVIGATOR, and a 12-column widget grid. It also defines the relationship between a filter WIDGET placed on the page and the page-level selection state, and the as-of and edit semantics. Do not freeze DashboardFilterBar as the final shape - align it to the specified selection bar, and add the sheet navigator so a page with more than one sheet is navigable. | I44: Screenshot against the 5.1.2 diagram. Apply three selections and confirm three removable chips appear and that removing one updates every widget. Add a second sheet and confirm the navigator switches between them while the selection bar persists. Place a filter widget on the page and confirm it composes with the page-level selection rather than competing with it. | J44: 12 | K44: Done | L44: Completed / no assignment | M44: CLOSED | N44: No new work. Preserve evidence and do not reopen unless a regression proves it. | O44: — | P44: CARRIED v2.9.2 | Q44: Done — backlog-claimed; closure evidence not reloaded in this pass | S44: No new contradiction identified in this pass | V44: — | W44: CLOSED | X44: Low / not newly identified | Y44: Deep design reconciliation 16-Aug-2026; Chapter 3/4 + Layer-B architecture + latest source/audit evidence | Z44: Track 1 — Presentation / Demo | AA44: 2026-08-20 Presentation RC | AB44: M1 Contract | AC44: Presentation-visible contract. Prepared Fleet v2 topology is allowed; no fake product behaviour and no production-only scope. | AD44: Closed | AE44: CLOSED | AF44: Closed / evidence preserved | AG44: Closed | AH44: 0 | AI44: 0 | AJ44: =IF($K44="Done",0,MAX(0.25,$J44/$AH44)) -> 0 | AK44: =IF($K44="Done",0,$AJ44*$AI44) -> 0 | AL44: CLOSED | AM44: Closed — do not reopen without contradictory regression evidence. | AN44: No active lock. | AO44: None — preserve evidence.
A45: T-044 | B45: M1 | C45: M1-P3 | D45: Certify the three operational dashboards and fix their bindings | E45: Frontend | F45: Dashboard | G45: Critical | H45: SPLIT IN v2.3 to respect the twelve-hour rule. Part one covers the three OPERATIONAL pages: Production and Shift, Quality and Chemistry, Equipment and Downtime and Flow. The seeded set is already seven and it already matches the intended story, so this is certification, not construction. Working from the coverage matrix, fix each failing widget in this order of preference: correct the widget definition in the seed script; then the chart type; only then the code. A single-row bar chart is a binding defect, not a data shortage - the last audit found Defects by Equipment returning one row, and the remedy there is canonical equipment attribution or relationship resolution, never generating more rows. AUDIT HARDENING IN v2.9.2. Treat presentation semantics as part of the binding contract. A widget is not certified merely because it returns rows: do not present raw GUIDs/technical identifiers when a registry/customer label exists, do not promote `unknown` into a meaningful business category unless the source genuinely carries an unknown bucket, and do not use a dimension whose usable cardinality makes the chart analytically degenerate. Fix the reusable binding/relationship/label path rather than Fleet-v2 screenshot-patching. | I45: Every widget on these three pages returns rows and renders the chart type its title implies. Confirm no widget title describes something other than what it plots. The chemistry conditional format draws its limits from the grade specification source data, never from a literal in the product. For every presented widget, record dimension cardinality and the human-readable label source. No raw UUID/GUID is visible where a registry label is resolvable. A Pie/Donut with one effective category, a Heatmap with only one meaningful axis, or a trend whose x-axis is merely an arbitrary date bucket for a non-temporal question fails acceptance even if it renders. | J45: 8 | K45: Done | L45: Completed / no assignment | M45: CLOSED | N45: No new work. Preserve evidence and do not reopen unless a regression proves it. | O45: — | P45: CARRIED v2.9.2 | Q45: Done — evidenced | R45: f966719f functional/data closure + 55157a98 EF/runtime migration parity | S45: Execution closed; no new design contradiction identified in this pass | V45: — | W45: CLOSED | X45: Low / not newly identified | Y45: Deep design reconciliation 16-Aug-2026; Chapter 3/4 + Layer-B architecture + latest source/audit evidence | Z45: Track 1 — Presentation / Demo | AA45: 2026-08-20 Presentation RC | AB45: M1 Contract | AC45: Presentation-visible contract. Prepared Fleet v2 topology is allowed; no fake product behaviour and no production-only scope. | AD45: Closed | AE45: CLOSED | AF45: Closed / evidence preserved | AG45: Closed | AH45: 0 | AI45: 0 | AJ45: =IF($K45="Done",0,MAX(0.25,$J45/$AH45)) -> 0 | AK45: =IF($K45="Done",0,$AJ45*$AI45) -> 0 | AL45: CLOSED | AM45: Closed — do not reopen without contradictory regression evidence. | AN45: No active lock. | AO45: None — preserve evidence.
A46: T-045 | B46: M1 | C46: M1-P3 | D46: Certify the analysis and model dashboards and choose the six shown | E46: Frontend | F46: Dashboard | G46: Critical | H46: SPLIT IN v2.3, part two. Covers Parameter Deep Analysis, Correlation and Statistical Findings, Risk Intelligence and Model Insights. Correlation is the weakest today - roughly two widgets - and it is the page that should exploit the planted relations hardest. Model Insights must stay honest: if the production model is not ready, show the five readiness dimensions with their measured values beside their thresholds rather than a fabricated prediction curve, because that refusal IS the selling point. Then record the decision: ALL SEVEN are certified, SIX are shown, and which six depends on the audience - an operations-heavy customer sees Risk and Model Insights is held back; a technical customer sees Model Insights and Risk is shortened. Nothing is deleted from the product to make a number. AUDIT HARDENING IN v2.9.2. A technically rendered but information-free visual is not an insight. A flat-zero series, single-slice donut or constant risk-class chart must be rebound to a meaningful supported question, or replaced by the honest readiness/coverage/refusal state that explains why no analytical variation exists. Prefer measured readiness, population, evidence coverage and contributor/refusal semantics over decorative empty charts. | I46: Every widget on these four pages returns rows. Confirm Model Insights makes no claim a live model has predicted anything unless one has. Record the primary six, the backup, and the reason for each choice, in the demonstration script. The six customer-facing pages contain no chart whose visible distribution is constant or single-category unless the visual is intentionally and explicitly a readiness/refusal/coverage statement. Model Insights and Risk must communicate measured state and evidence, not create the appearance of intelligence from a constant series. | J46: 6 | K46: Done | L46: Presentation lane (Workers 1/2) | M46: CLOSED | N46: Presentation target is active. Worker 3 must not edit M1 pages, presentation DB/seeds, current assistant wiring or runtime behaviour. | O46: Current M1 sequence / presentation owner hand-off | P46: CARRIED v2.9.2 | Q46: Done — evidenced | R46: T-045-R1 closed: c56008c0 / dd9a6b04 / 39ce59ef / 283aae2c | S46: Execution closed; no new design contradiction identified in this pass | V46: Current M1 sequence / presentation owner hand-off | W46: CLOSED | X46: Low / not newly identified | Y46: Deep design reconciliation 16-Aug-2026; Chapter 3/4 + Layer-B architecture + latest source/audit evidence | Z46: Track 1 — Presentation / Demo | AA46: 2026-08-20 Presentation RC | AB46: M1 Contract | AC46: Presentation-visible contract. Prepared Fleet v2 topology is allowed; no fake product behaviour and no production-only scope. | AD46: Closed | AE46: CLOSED | AF46: Closed / evidence preserved | AG46: Closed | AH46: 0 | AI46: 0 | AJ46: =IF($K46="Done",0,MAX(0.25,$J46/$AH46)) -> 0 | AK46: =IF($K46="Done",0,$AJ46*$AI46) -> 0 | AL46: CLOSED | AM46: Closed — do not reopen without contradictory regression evidence. | AN46: No active lock. | AO46: None — preserve evidence.
A47: T-046 | B47: M1 | C47: M1-P3 | D47: Register the final chart grammar and implement the presentation subset | E47: Backend | F47: Registry | G47: Critical | H47: CORRECTED IN v2.1, and this was a real design conflict. v2.0 declared the ten currently implemented chart types as the closed grammar and said do not extend it. Chapter 4 5.1.5 defines seventeen: Bar, stacked Column, Line, Area, Combo, Pie, Donut, Scatter, Heatmap, Pareto, Box plot, Histogram, Gauge, Waterfall, Table, Pivot table and KPI. Freezing ten would show the customer a smaller product than the one they receive. The correction is not to build seventeen renderers in ten days: declare the FINAL seventeen in the registry with an implemented or not-yet-available state, implement only the subset the six presentation pages need, and have the switcher offer compatible implemented types while saying in one sentence why an unavailable or incompatible type is not offered. ORDERED IN v2.2 to run before the six-grammar task, which selects from this registry. AUDIT HARDENING IN v2.9.2. Compatibility is semantic, not only renderer-capability metadata. Encode and test at minimum: temporal+numeric -> Line/Area or appropriate Bar; categorical+numeric -> Bar/Pareto; two meaningful categorical axes plus a measure -> Heatmap; numeric×numeric -> Scatter; numeric distribution -> Histogram/Box; low-cardinality categorical share -> Pie/Donut. Do not offer Pie/Donut-by-date, a Heatmap without two meaningful axes and an intensity, or a one-value categorical Pie merely because the renderer can draw it. | I47: The registry returns seventeen chart types. The switcher on a temporal-dimension widget offers only compatible implemented types and gives a reason for each omission. Flip one type from not-yet-available to implemented in the registry and confirm it becomes selectable with no code change. Switch a KPI to Bar and back to KPI and confirm the round trip works. Add known-compatible and known-incompatible binding tests for those pairings. A switcher must explain why an incompatible type is unavailable. Deliberately pass Date+measure to Pie/Donut and one-axis data to Heatmap and prove both are refused before rendering. | J47: 8 | K47: Done | L47: Presentation lane (Workers 1/2) | M47: CLOSED | N47: Presentation target is active. Worker 3 must not edit M1 pages, presentation DB/seeds, current assistant wiring or runtime behaviour. | O47: Current M1 sequence / presentation owner hand-off | P47: CARRIED v2.9.2 | Q47: Done — evidenced | R47: 56ade951 R1 generic heatmap/combo; prior grammar fc146483 | S47: Execution closed; no new design contradiction identified in this pass | V47: Current M1 sequence / presentation owner hand-off | W47: CLOSED | X47: Low / not newly identified | Y47: Deep design reconciliation 16-Aug-2026; Chapter 3/4 + Layer-B architecture + latest source/audit evidence | Z47: Track 1 — Presentation / Demo | AA47: 2026-08-20 Presentation RC | AB47: M1 Contract | AC47: Presentation-visible contract. Prepared Fleet v2 topology is allowed; no fake product behaviour and no production-only scope. | AD47: Closed | AE47: CLOSED | AF47: Closed / evidence preserved | AG47: Closed | AH47: 0 | AI47: 0 | AJ47: =IF($K47="Done",0,MAX(0.25,$J47/$AH47)) -> 0 | AK47: =IF($K47="Done",0,$AJ47*$AI47) -> 0 | AL47: CLOSED | AM47: Closed — do not reopen without contradictory regression evidence. | AN47: No active lock. | AO47: None — preserve evidence.
A48: T-047 | B48: M1 | C48: M1-P3 | D48: Give the seven pages distinct visual grammars from the registered grammar | E48: Frontend | F48: Dashboard | G48: Very Important | H48: Runs AFTER the chart grammar registry, because the grammars are chosen from the FINAL registered set rather than from whichever types happen to be implemented today. Seven pages that are all bar charts read as one page shown seven times. The intended languages, page by page: Production takes KPI with trend, stacked column by shift, bar by grade, area for weekly throughput and a detail table; Quality takes KPI with sparkline, Pareto by defect type, stacked bar by grade, a positional heatmap of defects along coil length and width, and a conditionally formatted chemistry table; Equipment takes bar, Pareto and a paired-column comparison of equipment stoppage against production impact; Parameter Deep Analysis takes histogram, box plot by grade and scatter; Correlation takes a parameter-by-outcome heatmap, a ranked contributor bar and a before-and-after conditioning pair; Risk takes KPI, trend, distribution and a contribution table; Model Insights takes the five readiness dimensions as status cards with coverage bars. AUDIT HARDENING IN v2.9.2. Distinct analytical grammars must still look like one product. Every page uses the same application typography, spacing scale, control primitives, card anatomy, state colours, focus language and motion rules; variation comes from the analytical story and chart grammar, not from page-local design systems. | I48: Place the seven pages side by side as screenshots. A reviewer who has not seen the product must be able to say what each page is for from the shapes alone. Every chart type used appears in the registry as implemented. The conditional-formatting table must draw its limits from the grade specification source data, never from a literal in the product. In the seven-page screenshot comparison, reject any page that introduces a different font scale, card language, control styling or motion vocabulary. The pages must be recognisably different in analytical purpose and recognisably identical in product identity. | J48: 10 | K48: Done | L48: Presentation lane (Workers 1/2) | M48: CLOSED | N48: Presentation target is active. Worker 3 must not edit M1 pages, presentation DB/seeds, current assistant wiring or runtime behaviour. | O48: Current M1 sequence / presentation owner hand-off | P48: CARRIED v2.9.2 | Q48: Done — evidenced | R48: 4b431463 semantic/data certification + 3cdd3a23 frontend conformance | S48: Execution closed; no new design contradiction identified in this pass | V48: Current M1 sequence / presentation owner hand-off | W48: CLOSED | X48: Low / not newly identified | Y48: Deep design reconciliation 16-Aug-2026; Chapter 3/4 + Layer-B architecture + latest source/audit evidence | Z48: Track 1 — Presentation / Demo | AA48: 2026-08-20 Presentation RC | AB48: M1 Contract | AC48: Presentation-visible contract. Prepared Fleet v2 topology is allowed; no fake product behaviour and no production-only scope. | AD48: Closed | AE48: CLOSED | AF48: Closed / evidence preserved | AG48: Closed | AH48: 0 | AI48: 0 | AJ48: =IF($K48="Done",0,MAX(0.25,$J48/$AH48)) -> 0 | AK48: =IF($K48="Done",0,$AJ48*$AI48) -> 0 | AL48: CLOSED | AM48: Closed — do not reopen without contradictory regression evidence. | AN48: No active lock. | AO48: None — preserve evidence.
A49: T-048 | B49: M1 | C49: M1-P3 | D49: Associative model, part 1: the alternative state and registry-driven fields | E49: Frontend | F49: Dashboard | G49: Very Important | H49: SPLIT IN v2.2 by dependency. Part 1 has no dependency outside this phase and runs here; part 2 needs the relationship resolver and runs in M1-P4 after it exists. Do not rebuild the excluded pivot - it already works, an excluded value can be clicked and the selection pivots. The work here is twofold: add the ALTERNATIVE state, which is the fourth state Chapter 4 5.1.3 requires and which is missing today; and make the associative field set registry-driven instead of a fixed list. | I49: All four states render distinctly - selected, possible, excluded, alternative - on the token colours, selection Electric Cyan and excluded Muted Steel. Add a dimension through the registry and confirm it appears in the strip with no code change. | J49: 4 | K49: Done | L49: Presentation lane (Workers 1/2) | M49: CLOSED | N49: Presentation target is active. Worker 3 must not edit M1 pages, presentation DB/seeds, current assistant wiring or runtime behaviour. | O49: Current M1 sequence / presentation owner hand-off | P49: CARRIED v2.9.2 | Q49: Done — evidenced | R49: b687cba4 associative selection states | S49: Execution closed; no new design contradiction identified in this pass | V49: Current M1 sequence / presentation owner hand-off | W49: CLOSED | X49: Low / not newly identified | Y49: Deep design reconciliation 16-Aug-2026; Chapter 3/4 + Layer-B architecture + latest source/audit evidence | Z49: Track 1 — Presentation / Demo | AA49: 2026-08-20 Presentation RC | AB49: M1 Contract | AC49: Presentation-visible contract. Prepared Fleet v2 topology is allowed; no fake product behaviour and no production-only scope. | AD49: Closed | AE49: CLOSED | AF49: Closed / evidence preserved | AG49: Closed | AH49: 0 | AI49: 0 | AJ49: =IF($K49="Done",0,MAX(0.25,$J49/$AH49)) -> 0 | AK49: =IF($K49="Done",0,$AJ49*$AI49) -> 0 | AL49: CLOSED | AM49: Closed — do not reopen without contradictory regression evidence. | AN49: No active lock. | AO49: None — preserve evidence.
A50: T-049 | B50: M1 | C50: M1-P3 | D50: Certify layout drag, resize, save, reload and responsive behaviour | E50: Frontend | F50: Dashboard | G50: Important | H50: REDUCED IN v2.1 from implementation to certification. useDashboardGridLayout and useDashboardLayoutPersistence already serialise, save and reload the grid through the API. The work is hardening and proof, not building: confirm the Save layout control confirms with a toast, that a reload restores exactly what was saved, and that the behaviour holds at 1920x1080, 1440x900 and 1280x800. | I50: Move and resize three widgets, save, hard-reload, and confirm the layout is identical. Repeat at each of the three widths. Record a short screen capture into the evidence folder. v2.10.2 ACCEPTANCE CORRECTION — each viewport is isolated. Snapshot the original persisted layout, perform a relative mutation that is guaranteed to differ from the starting canonical geometry, SAVE and capture the PATCH layoutJson, poll until the DOM converges to the saved active-breakpoint geometry, hard reload, prove GET layoutJson == PATCH layoutJson and poll to the same rendered geometry, then restore the original layout in a finally/cleanup path. 'Changed' means the stable post-save canonical/rendered state, not transient mouse-up pixels. Run 1920x1080, 1440x900 and 1280x800 serially with zero skips and no cross-test state contamination. | J50: 4 | K50: Done | L50: Presentation lane (Workers 1/2) | M50: CLOSED | N50: Presentation target is active. Worker 3 must not edit M1 pages, presentation DB/seeds, current assistant wiring or runtime behaviour. | O50: Current M1 sequence / presentation owner hand-off | P50: v2.10.2 — isolated canonical round-trip acceptance after R1-R4 test-oracle findings | Q50: In Progress — canonical PATCH/GET persistence proven; final isolated viewport certification and baseline restoration remain. | R50: 16-Aug-2026 R1–R4: auth/license + canonical persistence green; current work is final test isolation/oracle convergence, not backend persistence. | S50: REVISE — important design/coverage issue | T50: F-070 [Very Important] — R1-R4 exposed two test-design flaws: viewport runs share the same persisted dashboard and contaminate each other, and transient post-mouse DOM was treated as authoritative changed state even when Save canonicalised/compacted to different geometry. | U50: F-070 — Each viewport must snapshot/restore its original layout in finally, mutate relative to its starting state, use PATCH canonical as authoritative changed state, poll DOM to converge after save/reload, and then restore baseline. No more diagnostic-only packs. | V50: Current M1 sequence / presentation owner hand-off | W50: Presentation lane; Worker 3 only by explicit formal reassignment after zero-overlap + stable-prerequisite check | X50: MEDIUM | Y50: Deep design reconciliation 16-Aug-2026; Chapter 3/4 + Layer-B architecture + latest source/audit evidence | Z50: Track 1 — Presentation / Demo | AA50: 2026-08-20 Presentation RC | AB50: M1 Contract | AC50: Presentation-visible contract. Prepared Fleet v2 topology is allowed; no fake product behaviour and no production-only scope. | AD50: Medium | AE50: Worker 2 | AF50: Presentation BI/UX + E2E release integration | AG50: E2E/debug convergence | AH50: 5.3333333 | AI50: 2 | AJ50: =IF($K50="Done",0,MAX(0.25,$J50/$AH50)) -> 0 | AK50: =IF($K50="Done",0,$AJ50*$AI50) -> 0 | AL50: M1-A — parallel foundations | AM50: GO now. Final isolated certification only; no more diagnostic-only iteration. | AN50: Own Dashboard/workspace/shared shell/AnalysisToolbox/E2E. No W1 active vertical files; no W3 Jobs/Findings/Assistant files. | AO50: Commit before downstream consumer starts; consumer must use the contract, not redesign producer-owned semantics.
A51: T-050 | B51: M1 | C51: M1-P3 | D51: Drill to population, provenance and evidence | E51: Frontend | F51: Dashboard | G51: Very Important | H51: RETARGETED IN v2.1. The v2.0 assessment of the drawer's visual state was stale, and the real value is not the transition. Focus on the chain: click a point, see the POPULATION behind it, see its PROVENANCE, and reach the source evidence. Correct the off-palette colours to the token set and position the drawer logically with inline-start and inline-end so RTL mirrors correctly. Add the open transition and respect prefers-reduced-motion, but treat that as the smallest part of the task. | I51: Click a bar and confirm the drawer lists the underlying population with a resolvable provenance handle and a path to the source rows. Set prefers-reduced-motion and confirm the transition is suppressed. Switch to RTL and confirm the drawer opens from the correct edge. Confirm every colour used appears in the token set. | J51: 6 | K51: Done | L51: Presentation lane (Workers 1/2) | M51: CLOSED | N51: Presentation target is active. Worker 3 must not edit M1 pages, presentation DB/seeds, current assistant wiring or runtime behaviour. | O51: Current M1 sequence / presentation owner hand-off | P51: CARRIED v2.9.2 | Q51: Not Started | S51: No new contradiction identified in this pass | V51: Current M1 sequence / presentation owner hand-off | W51: Presentation lane; Worker 3 only by explicit formal reassignment after zero-overlap + stable-prerequisite check | X51: Low / not newly identified | Y51: Deep design reconciliation 16-Aug-2026; Chapter 3/4 + Layer-B architecture + latest source/audit evidence | Z51: Track 1 — Presentation / Demo | AA51: 2026-08-20 Presentation RC | AB51: M1 Contract | AC51: Presentation-visible contract. Prepared Fleet v2 topology is allowed; no fake product behaviour and no production-only scope. | AD51: Medium | AE51: Worker 2 | AF51: Presentation BI/UX + E2E release integration | AG51: Frontend/UI feature | AH51: 9 | AI51: 1.5 | AJ51: =IF($K51="Done",0,MAX(0.25,$J51/$AH51)) -> 0 | AK51: =IF($K51="Done",0,$AJ51*$AI51) -> 0 | AL51: M1-A — parallel foundations | AM51: Current M1 sequence / presentation owner hand-off | AN51: Own Dashboard/workspace/shared shell/AnalysisToolbox/E2E. No W1 active vertical files; no W3 Jobs/Findings/Assistant files. | AO51: Commit before downstream consumer starts; consumer must use the contract, not redesign producer-owned semantics.
A52: T-051 | B52: M1 | C52: M1-P3 | D52: Widget failure isolation and the seven states | E52: Frontend | F52: Dashboard | G52: Critical | H52: Chapter 4 requires that one widget failing never destroys the page, and that filtered-empty is distinguishable from genuinely empty. Wrap each widget in its own boundary and implement all seven states with the correct colour semantics: Blocked and Refused in Amber, Failed in Hot Red, Empty and Filtered-empty in Muted Steel with different wording. | I52: Inject a failure into one widget query and confirm the other widgets on the page continue to render and interact. Apply a filter that returns no rows and confirm the widget says the selection returned nothing, not that there is no data. | J52: 6 | K52: Done | L52: Presentation lane (Workers 1/2) | M52: CLOSED | N52: Presentation target is active. Worker 3 must not edit M1 pages, presentation DB/seeds, current assistant wiring or runtime behaviour. | O52: Current M1 sequence / presentation owner hand-off | P52: CARRIED v2.9.2 | Q52: Not Started | S52: No new contradiction identified in this pass | V52: Current M1 sequence / presentation owner hand-off | W52: Presentation lane; Worker 3 only by explicit formal reassignment after zero-overlap + stable-prerequisite check | X52: Low / not newly identified | Y52: Deep design reconciliation 16-Aug-2026; Chapter 3/4 + Layer-B architecture + latest source/audit evidence | Z52: Track 1 — Presentation / Demo | AA52: 2026-08-20 Presentation RC | AB52: M1 Contract | AC52: Presentation-visible contract. Prepared Fleet v2 topology is allowed; no fake product behaviour and no production-only scope. | AD52: Medium | AE52: Worker 2 | AF52: Presentation BI/UX + E2E release integration | AG52: Frontend/UI feature | AH52: 9 | AI52: 1.5 | AJ52: =IF($K52="Done",0,MAX(0.25,$J52/$AH52)) -> 0 | AK52: =IF($K52="Done",0,$AJ52*$AI52) -> 0 | AL52: M1-A — parallel foundations | AM52: Current M1 sequence / presentation owner hand-off | AN52: Own Dashboard/workspace/shared shell/AnalysisToolbox/E2E. No W1 active vertical files; no W3 Jobs/Findings/Assistant files. | AO52: Commit before downstream consumer starts; consumer must use the contract, not redesign producer-owned semantics.
A53: T-052 | B53: M1 | C53: M1-P3 | D53: Remove the hardcoded parameter default from the API client | E53: Frontend | F53: Dashboard | G53: Critical | H53: Frontend/PlantProcess.Web/src/api/productCoreApiClient.runtime.ts line 300 reads `parameterCode: filters.parameterCode || "CastingSpeed"`. That is a steel-specific literal in product logic and a Rule 1 violation reachable by a customer. Remove the fallback. When no parameter is selected, either omit the field or resolve a default from the parameter registry returned by the metadata endpoint. | I53: Grep the whole src tree for CastingSpeed and confirm the only remaining hits are in demo content or test fixtures, never in product code paths. Load a parameter widget with no parameter selected and confirm it either shows a chooser or a registry-resolved default, and does not silently query a steel parameter. | J53: 4 | K53: Done | L53: Presentation lane (Workers 1/2) | M53: CLOSED | N53: Presentation target is active. Worker 3 must not edit M1 pages, presentation DB/seeds, current assistant wiring or runtime behaviour. | O53: Current M1 sequence / presentation owner hand-off | P53: CARRIED v2.9.2 | Q53: Not Started | S53: No new contradiction identified in this pass | V53: Current M1 sequence / presentation owner hand-off | W53: Presentation lane; Worker 3 only by explicit formal reassignment after zero-overlap + stable-prerequisite check | X53: Low / not newly identified | Y53: Deep design reconciliation 16-Aug-2026; Chapter 3/4 + Layer-B architecture + latest source/audit evidence | Z53: Track 1 — Presentation / Demo | AA53: 2026-08-20 Presentation RC | AB53: M1 Contract | AC53: Presentation-visible contract. Prepared Fleet v2 topology is allowed; no fake product behaviour and no production-only scope. | AD53: Medium | AE53: Worker 2 | AF53: Presentation BI/UX + E2E release integration | AG53: Frontend/UI feature | AH53: 9 | AI53: 1.5 | AJ53: =IF($K53="Done",0,MAX(0.25,$J53/$AH53)) -> 0 | AK53: =IF($K53="Done",0,$AJ53*$AI53) -> 0 | AL53: M1-A — parallel foundations | AM53: Current M1 sequence / presentation owner hand-off | AN53: Own Dashboard/workspace/shared shell/AnalysisToolbox/E2E. No W1 active vertical files; no W3 Jobs/Findings/Assistant files. | AO53: Commit before downstream consumer starts; consumer must use the contract, not redesign producer-owned semantics.
